Workbook

Sheet Sheet1
A1: 7 | B1: 1 | C1: 9999 | D1: 99
A2: id | B2: 商品Id | C2: 商品名称 | D2: 所属渠道 | E2: 商品价格 | F2: 商品类型 | G2: 充值钻石 | H2: 额外奖励钻石 | I2: 第一次充值奖励 | J2: 充值钻石数累计 | K2: 商品描述 | L2: 钱币类型 | M2: 图标 | N2: 是否显示 | O2: 是否开启打折 | P2: 开启时间 | Q2: 结束时间 | R2: 折扣实际金额 | S2: 开启时间check | T2: 结束时间check | U2: 月卡标记 | V2: 月卡类型 | W2: 2次购买之间的时间间隔(分钟) | X2: 商品的图片地址 | Y2: 退款时是否需要封禁 | Z2: 退款时扣除资源 | AA2: 网页切支付 | AB2: 网页切支付屏蔽渠道 | AC2: 网页切支付打开渠道
A3: id | B3: paymentId | C3: paymentName | D3: channels | E3: needMoney | F3: paymentType | G3: payDiamond | H3: freeDiamond | I3: firstReward | J3: accumulateDiamond | K3: paymentDesc | L3: moneyType | M3: icon | N3: isShow | O3: IsOpenDiscount | P3: startDate | Q3: endDate | R3: discountMoney | S3: startDateCheck | T3: endDateCheck | U3: monthCardId | V3: monthCardType | W3: intervalTime | X3: paymentUrl | Y3: banOnRefund | Z3: costItemOnRefund | AA3: webPayOpen | AB3: webPayCloseChannel | AC3: webPayOpenChannel
A4: int | B4: string | C4: string | D4: string | E4: double | F4: string | G4: int | H4: int | I4: int | J4: int | K4: string | L4: string | M4: string | N4: int | O4: int | P4: string | Q4: string | R4: double | S4: string | T4: string | U4: string | V4: int | W4: int | X4: string | Y4: int | Z4: string | AA4: int | AB4: string | AC4: string
A5: primary | B5: none | C5: none | D5: none | E5: none | F5: none | G5: none | H5: none | I5: none | J5: none | K5: none | L5: none | M5: none | N5: none | O5: none | P5: none | Q5: none | R5: none | S5: none | T5: none | U5: none | V5: none | W5: none | X5: none | Y5: none | Z5: none | AA5: none | AB5: none | AC5: none
A6: id | B6: paymentId | C6: paymentName | D6: channels | E6: needMoney | F6: paymentType | G6: payDiamond | H6: freeDiamond | I6: firstReward | J6: accumulateDiamond | K6: paymentDesc | L6: moneyType | M6: icon | N6: isShow | O6: IsOpenDiscount | P6: startDate | Q6: endDate | R6: discountMoney | S6: startDateCheck | T6: endDateCheck | U6: monthCardId | V6: monthCardType | W6: intervalTime | X6: paymentUrl | Y6: banOnRefund | Z6: costItemOnRefund | AA6: webPayOpen | AB6: webPayCloseChannel | AC6: webPayOpenChannel
A7: 50001 | B7: com.Aligames.hhw.300 | C7: 贸易通行证 | D7: IOS0019;IOS0019_1;IOS0019_TRANSFER;AND0117_HHW_12_8;AND0117_HHW_12_TRANSFER;AND0117_HHW_11_TRANSFER;AND0117_HHW_12_3;AND0117_TRANSFER;AND0117_HHW_13_TRANSFER;AND0117_HHW_12_4 | E7: 30 | F7: month | G7: 300 | H7: 0 | I7: 0 | J7: 300 | K7: 购买后获得300彩钻，连续30天每天可领取100彩钻 | L7: CNY | M7: cz-xkz | N7: 1 | O7: 0 | P7: 2018-01-01 00:00:00 | Q7: 2019-01-01 00:00:00 | R7: 30 | S7: 2018-01-01 00:00:00 | T7: 2019-01-01 00:00:00 | U7: defaultMonthCard | V7: 1 | W7: 36000 | Y7: 0 | AA7: =IF(OR(F7="month",F7="navigation_pass"),0,1) -> 0 | AB7: =IF(OR(AA7=1,AA7=2),"AND0013","")
A8: 50002 | B8: com.Aligames.hhw.880 | C8: 商贸许可证 | D8: IOS0019;IOS0019_1;IOS0019_TRANSFER;AND0117_HHW_12_8;AND0117_HHW_12_TRANSFER;AND0117_HHW_11_TRANSFER;AND0117_HHW_12_3;AND0117_TRANSFER;AND0117_HHW_13_TRANSFER;AND0117_HHW_12_4 | E8: 88 | F8: month | G8: 888 | H8: 0 | I8: 0 | J8: 888 | K8: 购买后获得888彩钻，连续90天每天可领取120彩钻 | L8: CNY | M8: cz-smxkz | N8: 0 | O8: 0 | P8: 2018-01-01 00:00:00 | Q8: 2019-01-01 00:00:00 | R8: 88 | S8: 2018-01-01 00:00:00 | T8: 2019-01-01 00:00:00 | U8: quarterlyMonthCard | V8: 4 | W8: 36000 | Y8: 1 | AA8: =IF(OR(F8="month",F8="navigation_pass"),0,1) -> 0 | AB8: =IF(OR(AA8=1,AA8=2),"AND0013","")
A9: 50003 | B9: com.Aligames.hhw.310 | C9: 海岛嘉奖令 | D9: IOS0019;IOS0019_1;IOS0019_TRANSFER;AND0117_HHW_12_8;AND0117_HHW_12_TRANSFER;AND0117_HHW_11_TRANSFER;AND0117_HHW_12_3;AND0117_TRANSFER;AND0117_HHW_13_TRANSFER;AND0117_HHW_12_4 | E9: 30 | F9: month | G9: 300 | H9: 0 | I9: 0 | J9: 300 | K9: 购买后激活海岛争霸月卡 | L9: CNY | M9: cz-zzq | N9: 0 | O9: 0 | P9: 2018-01-01 00:00:00 | Q9: 2019-01-01 00:00:00 | R9: 30 | S9: 2018-01-01 00:00:00 | T9: 2019-01-01 00:00:00 | U9: autoChessMonthCard | V9: 2 | W9: 36000 | Y9: 1 | AA9: =IF(OR(F9="month",F9="navigation_pass"),0,1) -> 0 | AB9: =IF(OR(AA9=1,AA9=2),"AND0013","")
A10: 50004 | B10: com.Aligames.hhw.xd.50 | C10: 家园建设证 | D10: IOS0019;IOS0019_1;IOS0019_TRANSFER;AND0117_HHW_12_8;AND0117_HHW_12_TRANSFER;AND0117_HHW_11_TRANSFER;AND0117_HHW_12_3;AND0117_TRANSFER;AND0117_HHW_13_TRANSFER;AND0117_HHW_12_4 | E10: 68 | F10: month | G10: 680 | H10: 0 | I10: 0 | J10: 680 | K10: 购买后激活家园月卡 | L10: CNY | M10: cz-jy | N10: 1 | O10: 0 | P10: 2018-01-01 00:00:00 | Q10: 2019-01-01 00:00:00 | R10: 68 | S10: 2018-01-01 00:00:00 | T10: 2019-01-01 00:00:00 | U10: homelandMonthCard | V10: 3 | W10: 36000 | Y10: 1 | AA10: =IF(OR(F10="month",F10="navigation_pass"),0,1) -> 0 | AB10: =IF(OR(AA10=1,AA10=2),"AND0013","")
A11: 50005 | B11: com.Aligames.hhw.6 | C11: 彩钻60 | D11: IOS0019;IOS0019_1;IOS0019_TRANSFER;AND0117_HHW_12_8;AND0117_HHW_12_TRANSFER;AND0117_HHW_11_TRANSFER;AND0117_HHW_12_3;AND0117_TRANSFER;AND0117_HHW_13_TRANSFER;AND0117_HHW_12_4 | E11: 6 | F11: once | G11: 60 | H11: 0 | I11: 60 | J11: 60 | K11: 充值6元可获得60彩钻 | L11: CNY | M11: cz-1 | N11: 1 | O11: 0 | P11: 2018-01-01 00:00:00 | Q11: 2019-01-01 00:00:00 | R11: 6 | S11: 2018-01-01 00:00:00 | T11: 2019-01-01 00:00:00 | V11: 0 | W11: 0 | Y11: 0 | AA11: =IF(OR(F11="month",F11="navigation_pass"),0,1) -> 1 | AB11: =IF(OR(AA11=1,AA11=2),"AND0013","") -> AND0013
A12: 50006 | B12: com.Aligames.hhw.30 | C12: 彩钻300 | D12: IOS0019;IOS0019_1;IOS0019_TRANSFER;AND0117_HHW_12_8;AND0117_HHW_12_TRANSFER;AND0117_HHW_11_TRANSFER;AND0117_HHW_12_3;AND0117_TRANSFER;AND0117_HHW_13_TRANSFER;AND0117_HHW_12_4 | E12: 30 | F12: once | G12: 300 | H12: 0 | I12: 300 | J12: 300 | K12: 充值30元可获得300彩钻 | L12: CNY | M12: cz-2 | N12: 1 | O12: 0 | P12: 2018-01-01 00:00:00 | Q12: 2019-01-01 00:00:00 | R12: 30 | S12: 2018-01-01 00:00:00 | T12: 2019-01-01 00:00:00 | V12: 0 | W12: 0 | Y12: 0 | AA12: =IF(OR(F12="month",F12="navigation_pass"),0,1) -> 1 | AB12: =IF(OR(AA12=1,AA12=2),"AND0013","") -> AND0013
A13: 50007 | B13: com.Aligames.hhw.68 | C13: 彩钻680 | D13: IOS0019;IOS0019_1;IOS0019_TRANSFER;AND0117_HHW_12_8;AND0117_HHW_12_TRANSFER;AND0117_HHW_11_TRANSFER;AND0117_HHW_12_3;AND0117_TRANSFER;AND0117_HHW_13_TRANSFER;AND0117_HHW_12_4 | E13: 68 | F13: once | G13: 680 | H13: 70 | I13: 680 | J13: 680 | K13: 充值68元可获得680彩钻 | L13: CNY | M13: cz-3 | N13: 1 | O13: 0 | P13: 2018-01-01 00:00:00 | Q13: 2019-01-01 00:00:00 | R13: 68 | S13: 2018-01-01 00:00:00 | T13: 2019-01-01 00:00:00 | V13: 0 | W13: 0 | Y13: 0 | AA13: =IF(OR(F13="month",F13="navigation_pass"),0,1) -> 1 | AB13: =IF(OR(AA13=1,AA13=2),"AND0013","") -> AND0013
A14: 50008 | B14: com.Aligames.hhw.128 | C14: 彩钻1280 | D14: IOS0019;IOS0019_1;IOS0019_TRANSFER;AND0117_HHW_12_8;AND0117_HHW_12_TRANSFER;AND0117_HHW_11_TRANSFER;AND0117_HHW_12_3;AND0117_TRANSFER;AND0117_HHW_13_TRANSFER;AND0117_HHW_12_4 | E14: 128 | F14: once | G14: 1280 | H14: 150 | I14: 1280 | J14: 1280 | K14: 充值128元可获得1280彩钻 | L14: CNY | M14: cz-4 | N14: 1 | O14: 0 | P14: 2018-01-01 00:00:00 | Q14: 2019-01-01 00:00:00 | R14: 128 | S14: 2018-01-01 00:00:00 | T14: 2019-01-01 00:00:00 | V14: 0 | W14: 0 | Y14: 0 | AA14: =IF(OR(F14="month",F14="navigation_pass"),0,1) -> 1 | AB14: =IF(OR(AA14=1,AA14=2),"AND0013","") -> AND0013
A15: 50009 | B15: com.Aligames.hhw.328 | C15: 彩钻3280 | D15: IOS0019;IOS0019_1;IOS0019_TRANSFER;AND0117_HHW_12_8;AND0117_HHW_12_TRANSFER;AND0117_HHW_11_TRANSFER;AND0117_HHW_12_3;AND0117_TRANSFER;AND0117_HHW_13_TRANSFER;AND0117_HHW_12_4 | E15: 328 | F15: once | G15: 3280 | H15: 580 | I15: 3280 | J15: 3280 | K15: 充值328元可获得3280彩钻 | L15: CNY | M15: cz-5 | N15: 1 | O15: 0 | P15: 2018-01-01 00:00:00 | Q15: 2019-01-01 00:00:00 | R15: 328 | S15: 2018-01-01 00:00:00 | T15: 2019-01-01 00:00:00 | V15: 0 | W15: 0 | Y15: 0 | AA15: =IF(OR(F15="month",F15="navigation_pass"),0,1) -> 1 | AB15: =IF(OR(AA15=1,AA15=2),"AND0013","") -> AND0013
A16: 50010 | B16: com.Aligames.hhw.648 | C16: 彩钻6480 | D16: IOS0019;IOS0019_1;IOS0019_TRANSFER;AND0117_HHW_12_8;AND0117_HHW_12_TRANSFER;AND0117_HHW_11_TRANSFER;AND0117_HHW_12_3;AND0117_TRANSFER;AND0117_HHW_13_TRANSFER;AND0117_HHW_12_4 | E16: 648 | F16: once | G16: 6480 | H16: 1608 | I16: 6480 | J16: 6480 | K16: 充值648元可获得6480彩钻 | L16: CNY | M16: cz-6 | N16: 1 | O16: 0 | P16: 2018-01-01 00:00:00 | Q16: 2019-01-01 00:00:00 | R16: 648 | S16: 2018-01-01 00:00:00 | T16: 2019-01-01 00:00:00 | V16: 0 | W16: 0 | Y16: 0 | AA16: =IF(OR(F16="month",F16="navigation_pass"),0,1) -> 1 | AB16: =IF(OR(AA16=1,AA16=2),"AND0013","") -> AND0013
A17: 50011 | B17: com.Aligames.hhw.998 | C17: 彩钻9980 | D17: IOS0019;IOS0019_1;IOS0019_TRANSFER;AND0117_HHW_12_8;AND0117_HHW_12_TRANSFER;AND0117_HHW_11_TRANSFER;AND0117_HHW_12_3;AND0117_TRANSFER;AND0117_HHW_13_TRANSFER;AND0117_HHW_12_4 | E17: 998 | F17: once | G17: 9980 | H17: 3000 | I17: 9980 | J17: 9980 | K17: 充值998元可获得9980彩钻 | L17: CNY | M17: cz-7 | N17: 1 | O17: 0 | P17: 2018-01-01 00:00:00 | Q17: 2019-01-01 00:00:00 | R17: 998 | S17: 2018-01-01 00:00:00 | T17: 2019-01-01 00:00:00 | V17: 0 | W17: 0 | Y17: 0 | AA17: =IF(OR(F17="month",F17="navigation_pass"),0,1) -> 1 | AB17: =IF(OR(AA17=1,AA17=2),"AND0013","") -> AND0013
A18: 50012 | B18: com.Aligames.hhw.1 | C18: 1元优惠礼包 | D18: IOS0019;IOS0019_1;IOS0019_TRANSFER;AND0117_HHW_12_8;AND0117_HHW_12_TRANSFER;AND0117_HHW_11_TRANSFER;AND0117_HHW_12_3;AND0117_TRANSFER;AND0117_HHW_13_TRANSFER;AND0117_HHW_12_4 | E18: 1 | F18: gift | J18: 10 | K18: 1元档礼包 | L18: CNY | M18: cz-2 | N18: 0 | O18: 1 | P18: 2021-06-30 22:00:00 | Q18: 2021-07-07 21:59:59 | R18: 1 | S18: 2021-06-30 20:00:00 | T18: 2021-07-08 6:59:59 | V18: 0 | W18: 0 | Y18: 1 | AA18: =IF(OR(F18="month",F18="navigation_pass"),0,1) -> 1 | AB18: =IF(OR(AA18=1,AA18=2),"AND0013","") -> AND0013
A19: 50013 | B19: com.Aligames.hhw.3 | C19: 3元特惠礼包 | D19: IOS0019;IOS0019_1;IOS0019_TRANSFER;AND0117_HHW_12_8;AND0117_HHW_12_TRANSFER;AND0117_HHW_11_TRANSFER;AND0117_HHW_12_3;AND0117_TRANSFER;AND0117_HHW_13_TRANSFER;AND0117_HHW_12_4 | E19: 3 | F19: gift | J19: 30 | K19: 3元档礼包 | L19: CNY | M19: cz-2 | N19: 0 | O19: 1 | P19: 2021-06-30 22:00:00 | Q19: 2021-07-07 21:59:59 | R19: 3 | S19: 2021-06-30 20:00:00 | T19: 2021-07-08 6:59:59 | V19: 0 | W19: 0 | Y19: 1 | AA19: =IF(OR(F19="month",F19="navigation_pass"),0,1) -> 1 | AB19: =IF(OR(AA19=1,AA19=2),"AND0013","") -> AND0013
A20: 50014 | B20: com.Aligames.hhw.7 | C20: 6元特惠礼包 | D20: IOS0019;IOS0019_1;IOS0019_TRANSFER;AND0117_HHW_12_8;AND0117_HHW_12_TRANSFER;AND0117_HHW_11_TRANSFER;AND0117_HHW_12_3;AND0117_TRANSFER;AND0117_HHW_13_TRANSFER;AND0117_HHW_12_4 | E20: 6 | F20: gift | J20: 60 | K20: 6元档礼包 | L20: CNY | M20: cz-2 | N20: 0 | O20: 1 | P20: 2021-06-30 22:00:00 | Q20: 2021-07-07 21:59:59 | R20: 3 | S20: 2021-06-30 20:00:00 | T20: 2021-07-08 6:59:59 | V20: 0 | W20: 0 | Y20: 1 | AA20: =IF(OR(F20="month",F20="navigation_pass"),0,1) -> 1 | AB20: =IF(OR(AA20=1,AA20=2),"AND0013","") -> AND0013
A21: 50015 | B21: com.Aligames.hhw.12 | C21: 12元优惠礼包 | D21: IOS0019;IOS0019_1;IOS0019_TRANSFER;AND0117_HHW_12_8;AND0117_HHW_12_TRANSFER;AND0117_HHW_11_TRANSFER;AND0117_HHW_12_3;AND0117_TRANSFER;AND0117_HHW_13_TRANSFER;AND0117_HHW_12_4 | E21: 12 | F21: gift | J21: 120 | K21: 12元档礼包 | L21: CNY | M21: cz-2 | N21: 0 | O21: 1 | P21: 2021-06-30 22:00:00 | Q21: 2021-07-07 21:59:59 | R21: 6 | S21: 2021-06-30 20:00:00 | T21: 2021-07-08 6:59:59 | V21: 0 | W21: 0 | Y21: 1 | AA21: =IF(OR(F21="month",F21="navigation_pass"),0,1) -> 1 | AB21: =IF(OR(AA21=1,AA21=2),"AND0013","") -> AND0013
A22: 50016 | B22: com.Aligames.hhw.32 | C22: 30元优惠礼包 | D22: IOS0019;IOS0019_1;IOS0019_TRANSFER;AND0117_HHW_12_8;AND0117_HHW_12_TRANSFER;AND0117_HHW_11_TRANSFER;AND0117_HHW_12_3;AND0117_TRANSFER;AND0117_HHW_13_TRANSFER;AND0117_HHW_12_4 | E22: 30 | F22: gift | J22: 300 | K22: 30元档礼包 | L22: CNY | M22: cz-2 | N22: 0 | O22: 1 | P22: 2021-06-30 22:00:00 | Q22: 2021-07-07 21:59:59 | R22: 25 | S22: 2021-06-30 20:00:00 | T22: 2021-07-08 6:59:59 | V22: 0 | W22: 0 | Y22: 1 | AA22: =IF(OR(F22="month",F22="navigation_pass"),0,1) -> 1 | AB22: =IF(OR(AA22=1,AA22=2),"AND0013","") -> AND0013
A23: 50017 | B23: com.Aligames.hhw.50 | C23: 50元特惠礼包 | D23: IOS0019;IOS0019_1;IOS0019_TRANSFER;AND0117_HHW_12_8;AND0117_HHW_12_TRANSFER;AND0117_HHW_11_TRANSFER;AND0117_HHW_12_3;AND0117_TRANSFER;AND0117_HHW_13_TRANSFER;AND0117_HHW_12_4 | E23: 50 | F23: gift | J23: 500 | K23: 50元档礼包 | L23: CNY | M23: cz-2 | N23: 0 | O23: 1 | P23: 2021-06-30 22:00:00 | Q23: 2021-07-07 21:59:59 | R23: 40 | S23: 2021-06-30 20:00:00 | T23: 2021-07-08 6:59:59 | V23: 0 | W23: 0 | Y23: 1 | AA23: =IF(OR(F23="month",F23="navigation_pass"),0,1) -> 1 | AB23: =IF(OR(AA23=1,AA23=2),"AND0013","") -> AND0013
A24: 50018 | B24: com.Aligames.hhw.69 | C24: 68元优惠礼包 | D24: IOS0019;IOS0019_1;IOS0019_TRANSFER;AND0117_HHW_12_8;AND0117_HHW_12_TRANSFER;AND0117_HHW_11_TRANSFER;AND0117_HHW_12_3;AND0117_TRANSFER;AND0117_HHW_13_TRANSFER;AND0117_HHW_12_4 | E24: 68 | F24: gift | J24: 680 | K24: 68元档礼包 | L24: CNY | M24: cz-2 | N24: 0 | O24: 1 | P24: 2021-06-30 22:00:00 | Q24: 2021-07-07 21:59:59 | R24: 50 | S24: 2021-06-30 20:00:00 | T24: 2021-07-08 6:59:59 | V24: 0 | W24: 0 | Y24: 1 | AA24: =IF(OR(F24="month",F24="navigation_pass"),0,1) -> 1 | AB24: =IF(OR(AA24=1,AA24=2),"AND0013","") -> AND0013
A25: 50019 | B25: com.Aligames.hhw.88 | C25: 88元特惠礼包 | D25: IOS0019;IOS0019_1;IOS0019_TRANSFER;AND0117_HHW_12_8;AND0117_HHW_12_TRANSFER;AND0117_HHW_11_TRANSFER;AND0117_HHW_12_3;AND0117_TRANSFER;AND0117_HHW_13_TRANSFER;AND0117_HHW_12_4 | E25: 88 | F25: gift | J25: 880 | K25: 88元档礼包 | L25: CNY | M25: cz-2 | N25: 0 | O25: 1 | P25: 2021-06-30 22:00:00 | Q25: 2021-07-07 21:59:59 | R25: 88 | S25: 2021-06-30 20:00:00 | T25: 2021-07-08 6:59:59 | V25: 0 | W25: 0 | Y25: 1 | AA25: =IF(OR(F25="month",F25="navigation_pass"),0,1) -> 1 | AB25: =IF(OR(AA25=1,AA25=2),"AND0013","") -> AND0013
A26: 50020 | B26: com.Aligames.hhw.89 | C26: 88元礼包 | D26: IOS0019;IOS0019_1;IOS0019_TRANSFER;AND0117_HHW_12_8;AND0117_HHW_12_TRANSFER;AND0117_HHW_11_TRANSFER;AND0117_HHW_12_3;AND0117_TRANSFER;AND0117_HHW_13_TRANSFER;AND0117_HHW_12_4 | E26: 88 | F26: gift | J26: 880 | K26: 88元档礼包 | L26: CNY | M26: cz-2 | N26: 0 | O26: 1 | P26: 2021-06-30 22:00:00 | Q26: 2021-07-07 21:59:59 | R26: 88 | S26: 2021-06-30 20:00:00 | T26: 2021-07-08 6:59:59 | V26: 0 | W26: 0 | Y26: 1 | AA26: =IF(OR(F26="month",F26="navigation_pass"),0,1) -> 1 | AB26: =IF(OR(AA26=1,AA26=2),"AND0013","") -> AND0013
A27: 50021 | B27: com.Aligames.hhw.98 | C27: 98元特惠礼包 | D27: IOS0019;IOS0019_1;IOS0019_TRANSFER;AND0117_HHW_12_8;AND0117_HHW_12_TRANSFER;AND0117_HHW_11_TRANSFER;AND0117_HHW_12_3;AND0117_TRANSFER;AND0117_HHW_13_TRANSFER;AND0117_HHW_12_4 | E27: 98 | F27: gift | J27: 980 | K27: 98元档礼包 | L27: CNY | M27: cz-2 | N27: 0 | O27: 1 | P27: 2021-06-30 22:00:00 | Q27: 2021-07-07 21:59:59 | R27: 78 | S27: 2021-06-30 20:00:00 | T27: 2021-07-08 6:59:59 | V27: 0 | W27: 0 | Y27: 1 | AA27: =IF(OR(F27="month",F27="navigation_pass"),0,1) -> 1 | AB27: =IF(OR(AA27=1,AA27=2),"AND0013","") -> AND0013
A28: 50022 | B28: com.Aligames.hhw.129 | C28: 128元特惠礼包 | D28: IOS0019;IOS0019_1;IOS0019_TRANSFER;AND0117_HHW_12_8;AND0117_HHW_12_TRANSFER;AND0117_HHW_11_TRANSFER;AND0117_HHW_12_3;AND0117_TRANSFER;AND0117_HHW_13_TRANSFER;AND0117_HHW_12_4 | E28: 128 | F28: gift | J28: 1280 | K28: 128元档礼包 | L28: CNY | M28: cz-2 | N28: 0 | O28: 1 | P28: 2021-06-30 22:00:00 | Q28: 2021-07-07 21:59:59 | R28: 98 | S28: 2021-06-30 20:00:00 | T28: 2021-07-08 6:59:59 | V28: 0 | W28: 0 | Y28: 1 | AA28: =IF(OR(F28="month",F28="navigation_pass"),0,1) -> 1 | AB28: =IF(OR(AA28=1,AA28=2),"AND0013","") -> AND0013
A29: 50023 | B29: com.Aligames.hhw.xh.168 | C29: 168元特惠礼包 | D29: IOS0019;IOS0019_1;IOS0019_TRANSFER;AND0117_HHW_12_8;AND0117_HHW_12_TRANSFER;AND0117_HHW_11_TRANSFER;AND0117_HHW_12_3;AND0117_TRANSFER;AND0117_HHW_13_TRANSFER;AND0117_HHW_12_4 | E29: 168 | F29: gift | J29: 1680 | K29: 168元档礼包 | L29: CNY | M29: cz-2 | N29: 0 | O29: 1 | P29: 2021-06-30 22:00:00 | Q29: 2021-07-07 21:59:59 | R29: 128 | S29: 2021-06-30 20:00:00 | T29: 2021-07-08 6:59:59 | V29: 0 | W29: 0 | Y29: 1 | AA29: =IF(OR(F29="month",F29="navigation_pass"),0,1) -> 1 | AB29: =IF(OR(AA29=1,AA29=2),"AND0013","") -> AND0013
... A49: 50043 | B49: com.Aligames.hhw.kfhd648 | C49: 强者同行礼包 | D49: IOS0019;IOS0019_1;IOS0019_TRANSFER;AND0117_HHW_12_8;AND0117_HHW_12_TRANSFER;AND0117_HHW_11_TRANSFER;AND0117_HHW_12_3;AND0117_TRANSFER;AND0117_HHW_13_TRANSFER;AND0117_HHW_12_4 | E49: 648 | F49: gift | J49: 6480 | K49: 购买后立刻获得强者同行任选箱，使用后可以在ssr英雄杰克斯与ssr英雄黑胡子中选择一个获得 | L49: CNY | M49: cz-6 | N49: 1 | O49: 0 | P49: 2018-01-01 00:00:00 | Q49: 2019-01-01 00:00:00 | R49: 648 | S49: 2018-01-01 00:00:01 | T49: 2019-01-01 00:00:01 | V49: 0 | W49: 0 | Y49: 1 | AA49: =IF(OR(F49="month",F49="navigation_pass"),0,1) -> 1 | AB49: =IF(OR(AA49=1,AA49=2),"AND0013","") -> AND0013
A50: 50044 | B50: onepieceAlimini.bridge.0006 | C50: 60彩钻 | D50: IOS0019;IOS0019_1;AND0117_HHW_16;AND0117_HHW_12;AND0117_HHW_20;AND0117_HHW_21;AND0117_HHW_22;AND0117_HHW_13;AND0117_HHW_11;AND0117_HHW_9;AND0117_HHW_15;AND0117_HHW_5;AND0117_HHW_10;AND0117_HHW_14;AND0117_HHW_17;AND0117_HHW_18;AND0117_HHW_19;AND0117;AND0147;AND0117_HHW_25;AND0052;AND0058;AND0052_TF_2;AND0117_HHW_24;AND0026;IOS0019_TRANSFER;AND0117_HHW_24_TRANSFER;AND0117_HHW_10_TRANSFER;AND0117_HHW_25_TRANSFER;AND0117_HHW_12_8;AND0117_HHW_12_TRANSFER;AND0117_HHW_11_TRANSFER;AND0117_HHW_12_3;AND0117_TRANSFER;AND0117_HHW_13_TRANSFER;AND0117_HHW_12_4 | E50: 6 | F50: once | G50: 60 | H50: 0 | I50: 110 | J50: 60 | K50: 充值6元可获得60彩钻 | L50: CNY | M50: cz-1 | N50: 0 | O50: 0 | P50: 2018-01-01 00:00:00 | Q50: 2019-01-01 00:00:00 | R50: 6 | S50: 2018-01-01 00:00:00 | T50: 2019-01-01 00:00:00 | V50: 0 | W50: 0 | X50: https://op-1251258258.cos.ap-guangzhou.myqcloud.com/paymentImg/cz-1.png | Y50: 0 | AA50: =IF(OR(F50="month",F50="navigation_pass"),0,1) -> 1 | AB50: =IF(OR(AA50=1,AA50=2),"AND0013","") -> AND0013
A51: 50045 | B51: onepieceAlimini.bridge.0030 | C51: 300彩钻 | D51: IOS0019;IOS0019_1;IOS0019_TRANSFER;AND0117_HHW_12_8;AND0117_HHW_12_TRANSFER;AND0117_HHW_11_TRANSFER;AND0117_HHW_12_3;AND0117_TRANSFER;AND0117_HHW_13_TRANSFER;AND0117_HHW_12_4 | E51: 30 | F51: once | G51: 300 | H51: 0 | I51: 350 | J51: 300 | K51: 充值30元可获得300彩钻 | L51: CNY | M51: cz-2 | N51: 0 | O51: 0 | P51: 2018-01-01 00:00:00 | Q51: 2019-01-01 00:00:00 | R51: 30 | S51: 2018-01-01 00:00:00 | T51: 2019-01-01 00:00:00 | V51: 0 | W51: 0 | X51: https://op-1251258258.cos.ap-guangzhou.myqcloud.com/paymentImg/cz-2.png | Y51: 0 | AA51: =IF(OR(F51="month",F51="navigation_pass"),0,1) -> 1 | AB51: =IF(OR(AA51=1,AA51=2),"AND0013","") -> AND0013
A52: 50046 | B52: onepieceAlimini.bridge.0068 | C52: 680彩钻 | D52: IOS0019;IOS0019_1;IOS0019_TRANSFER;AND0117_HHW_12_8;AND0117_HHW_12_TRANSFER;AND0117_HHW_11_TRANSFER;AND0117_HHW_12_3;AND0117_TRANSFER;AND0117_HHW_13_TRANSFER;AND0117_HHW_12_4 | E52: 68 | F52: once | G52: 680 | H52: 70 | I52: 780 | J52: 680 | K52: 充值68元可获得680彩钻 | L52: CNY | M52: cz-3 | N52: 0 | O52: 0 | P52: 2018-01-01 00:00:00 | Q52: 2019-01-01 00:00:00 | R52: 68 | S52: 2018-01-01 00:00:00 | T52: 2019-01-01 00:00:00 | V52: 0 | W52: 0 | X52: https://op-1251258258.cos.ap-guangzhou.myqcloud.com/paymentImg/cz-3.png | Y52: 0 | AA52: =IF(OR(F52="month",F52="navigation_pass"),0,1) -> 1 | AB52: =IF(OR(AA52=1,AA52=2),"AND0013","") -> AND0013
A53: 50047 | B53: onepieceAlimini.bridge.0128 | C53: 1280彩钻 | D53: IOS0019;IOS0019_1;IOS0019_TRANSFER;AND0117_HHW_12_8;AND0117_HHW_12_TRANSFER;AND0117_HHW_11_TRANSFER;AND0117_HHW_12_3;AND0117_TRANSFER;AND0117_HHW_13_TRANSFER;AND0117_HHW_12_4 | E53: 128 | F53: once | G53: 1280 | H53: 150 | I53: 1380 | J53: 1280 | K53: 充值128元可获得1280彩钻 | L53: CNY | M53: cz-4 | N53: 0 | O53: 0 | P53: 2018-01-01 00:00:00 | Q53: 2019-01-01 00:00:00 | R53: 128 | S53: 2018-01-01 00:00:00 | T53: 2019-01-01 00:00:00 | V53: 0 | W53: 0 | X53: https://op-1251258258.cos.ap-guangzhou.myqcloud.com/paymentImg/cz-4.png | Y53: 0 | AA53: =IF(OR(F53="month",F53="navigation_pass"),0,1) -> 1 | AB53: =IF(OR(AA53=1,AA53=2),"AND0013","") -> AND0013
A54: 50048 | B54: onepieceAlimini.bridge.0328 | C54: 3280彩钻 | D54: IOS0019;IOS0019_1;IOS0019_TRANSFER;AND0117_HHW_12_8;AND0117_HHW_12_TRANSFER;AND0117_HHW_11_TRANSFER;AND0117_HHW_12_3;AND0117_TRANSFER;AND0117_HHW_13_TRANSFER;AND0117_HHW_12_4 | E54: 328 | F54: once | G54: 3280 | H54: 820 | I54: 3780 | J54: 3280 | K54: 充值328元可获得3280彩钻 | L54: CNY | M54: cz-5 | N54: 0 | O54: 0 | P54: 2018-01-01 00:00:00 | Q54: 2019-01-01 00:00:00 | R54: 328 | S54: 2018-01-01 00:00:00 | T54: 2019-01-01 00:00:00 | V54: 0 | W54: 0 | X54: https://op-1251258258.cos.ap-guangzhou.myqcloud.com/paymentImg/cz-5.png | Y54: 0 | AA54: =IF(OR(F54="month",F54="navigation_pass"),0,1) -> 1 | AB54: =IF(OR(AA54=1,AA54=2),"AND0013","") -> AND0013
A55: 50049 | B55: onepieceAlimini.bridge.0648 | C55: 6480彩钻 | D55: IOS0019;IOS0019_1;IOS0019_TRANSFER;AND0117_HHW_12_8;AND0117_HHW_12_TRANSFER;AND0117_HHW_11_TRANSFER;AND0117_HHW_12_3;AND0117_TRANSFER;AND0117_HHW_13_TRANSFER;AND0117_HHW_12_4 | E55: 648 | F55: once | G55: 6480 | H55: 1944 | I55: 6980 | J55: 6480 | K55: 充值648元可获得6480彩钻 | L55: CNY | M55: cz-6 | N55: 0 | O55: 0 | P55: 2018-01-01 00:00:00 | Q55: 2019-01-01 00:00:00 | R55: 648 | S55: 2018-01-01 00:00:00 | T55: 2019-01-01 00:00:00 | V55: 0 | W55: 0 | X55: https://op-1251258258.cos.ap-guangzhou.myqcloud.com/paymentImg/cz-6.png | Y55: 0 | AA55: =IF(OR(F55="month",F55="navigation_pass"),0,1) -> 1 | AB55: =IF(OR(AA55=1,AA55=2),"AND0013","") -> AND0013
A56: 50050 | B56: onepieceAlimini.bridge.1000 | C56: 10000彩钻 | D56: IOS0019;IOS0019_1;IOS0019_TRANSFER;AND0117_HHW_12_8;AND0117_HHW_12_TRANSFER;AND0117_HHW_11_TRANSFER;AND0117_HHW_12_3;AND0117_TRANSFER;AND0117_HHW_13_TRANSFER;AND0117_HHW_12_4 | E56: 1000 | F56: once | G56: 10000 | H56: 3500 | I56: 10500 | J56: 10000 | K56: 充值1000元可获得10000彩钻 | L56: CNY | M56: cz-7 | N56: 0 | O56: 0 | P56: 2018-01-01 00:00:00 | Q56: 2019-01-01 00:00:00 | R56: 1000 | S56: 2018-01-01 00:00:00 | T56: 2019-01-01 00:00:00 | V56: 0 | W56: 0 | X56: https://op-1251258258.cos.ap-guangzhou.myqcloud.com/paymentImg/cz-7.png | Y56: 0 | AA56: =IF(OR(F56="month",F56="navigation_pass"),0,1) -> 1 | AB56: =IF(OR(AA56=1,AA56=2),"AND0013","") -> AND0013
A57: 50051 | B57: onepieceAlimini.bridge.dailyset.0006 | C57: 60彩钻 | D57: IOS0019;IOS0019_1;IOS0019_TRANSFER;AND0117_HHW_12_8;AND0117_HHW_12_TRANSFER;AND0117_HHW_11_TRANSFER;AND0117_HHW_12_3;AND0117_TRANSFER;AND0117_HHW_13_TRANSFER;AND0117_HHW_12_4 | E57: 1 | F57: once | G57: 60 | H57: 0 | I57: 0 | J57: 60 | K57: 充值1元可获得60彩钻 | L57: CNY | M57: cz-1 | N57: 0 | O57: 0 | P57: 2018-01-01 00:00:00 | Q57: 2019-01-01 00:00:00 | R57: 1 | S57: 2018-01-01 00:00:00 | T57: 2019-01-01 00:00:00 | V57: 0 | W57: 0 | X57: https://op-1251258258.cos.ap-guangzhou.myqcloud.com/paymentImg/cz-1.png | Y57: 0 | AA57: =IF(OR(F57="month",F57="navigation_pass"),0,1) -> 1 | AB57: =IF(OR(AA57=1,AA57=2),"AND0013","") -> AND0013
A58: 50052 | B58: onepieceAlimini.bridge.40000001 | C58: 68元档 | D58: IOS0019;IOS0019_1;IOS0019_TRANSFER;AND0117_HHW_12_8;AND0117_HHW_12_TRANSFER;AND0117_HHW_11_TRANSFER;AND0117_HHW_12_3;AND0117_TRANSFER;AND0117_HHW_13_TRANSFER;AND0117_HHW_12_4 | E58: 68 | F58: gift | J58: 680 | K58: 68元档礼包 | L58: CNY | M58: cz-2 | N58: 0 | O58: 0 | P58: 2021-07-01 00:00:00 | Q58: 2021-10-07 23:59:59 | R58: 68 | S58: 2021-06-30 22:00:00 | T58: 2021-10-08 6:59:59 | V58: 0 | W58: 0 | X58: https://op-1251258258.cos.ap-guangzhou.myqcloud.com/paymentImg/cz-2.png | Y58: 1 | AA58: =IF(OR(F58="month",F58="navigation_pass"),0,1) -> 1 | AB58: =IF(OR(AA58=1,AA58=2),"AND0013","") -> AND0013
A59: 50053 | B59: onepieceAlimini.bridge.40000002 | C59: 328元档 | D59: IOS0019;IOS0019_1;IOS0019_TRANSFER;AND0117_HHW_12_8;AND0117_HHW_12_TRANSFER;AND0117_HHW_11_TRANSFER;AND0117_HHW_12_3;AND0117_TRANSFER;AND0117_HHW_13_TRANSFER;AND0117_HHW_12_4 | E59: 328 | F59: gift | J59: 3280 | K59: 328元档礼包 | L59: CNY | M59: cz-5 | N59: 0 | O59: 0 | P59: 2021-07-01 00:00:00 | Q59: 2021-10-07 23:59:59 | R59: 328 | S59: 2021-06-30 22:00:00 | T59: 2021-10-08 6:59:59 | V59: 0 | W59: 0 | X59: https://op-1251258258.cos.ap-guangzhou.myqcloud.com/paymentImg/cz-5.png | Y59: 1 | AA59: =IF(OR(F59="month",F59="navigation_pass"),0,1) -> 1 | AB59: =IF(OR(AA59=1,AA59=2),"AND0013","") -> AND0013
...

Sheet 渠道
A1: 渠道ID | C1: 渠道说明 | F1: 游戏名称 | G1: 渠道名称 | H1: 子渠道名称 | I1: SDKId | J1: ChannelId | K1: SDK版本 | L1: 内部版本 | M1: 状态 | N1: 是否隐藏 | O1: 大区
A2: IOS0019_1 | D2: IOS0019 | E2: =COUNTIFS(A:A,D2) -> 1 | F2: 航海王：燃烧意志 | G2: 360手机助手 | I2: And360 | J2: AND0003 | K2: 2.3.4_782 | L2: 1.06 | M2: 启用 | N2: 显示 | O2: 北海大区 | P2: 安混渠道 | Q2: AND0003;AND0004;AND0006;AND0007;AND0010;AND0035;AND0040;AND0043;AND0051;AND0056;AND0061;AND0062;AND0100;AND0103;AND0109;AND0111;AND0117_HHW_12_2;AND0117_HHW_26;AND0117_HHW_27;AND0118;AND0120;AND0121;AND0121_CHUIZI;AND0121_MEITU;AND0121_ZTE;AND0123;AND0124;AND0125;AND0126;AND0127;AND0128;AND0129;AND0130;AND0131;AND0133;AND0138;AND0140;AND0143;AND0143_1;AND0144;AND0145;AND0146;AND0151;AND0152;AND0155;ANDDQ00117_1;ANDDQ00117_10;ANDDQ00117_11;ANDDQ00117_12;ANDDQ00117_13;ANDDQ00117_14;ANDDQ00117_15;ANDDQ00117_16;ANDDQ00117_17;ANDDQ00117_18;ANDDQ00117_19;ANDDQ00117_2;ANDDQ00117_20;ANDDQ00117_3;ANDDQ00117_4;ANDDQ00117_5;ANDDQ00117_6;ANDDQ00117_7;ANDDQ00117_8;ANDDQ00117_9;AndOpenSDK_WD_001
A3: AND0147 | D3: IOS0019_1 | E3: =COUNTIFS(A:A,D3) -> 1 | F3: 航海王：燃烧意志 | G3: 4399手机开放平台 | I3: And4399 | J3: AND0004 | K3: V3.12.1 | L3: 1.13 | M3: 启用 | N3: 显示 | O3: 北海大区 | P3: IOS+官网 | Q3: IOS0019;IOS0019_1;AND0117_HHW_16;AND0117_HHW_12;AND0117_HHW_20;AND0117_HHW_21;AND0117_HHW_22;AND0117_HHW_13;AND0117_HHW_11;AND0117_HHW_9;AND0117_HHW_15;AND0117_HHW_5;AND0117_HHW_10;AND0117_HHW_14;AND0117_HHW_17;AND0117_HHW_18;AND0117_HHW_19;AND0117;AND0147;AND0117_HHW_25;AND0052;AND0058;AND0052_TF_2;AND0117_HHW_24
A4: AND0000 | B4: com.yunchang.onepiece | C4: OpenSDK新版 | D4: AND0147 | E4: =COUNTIFS(A:A,D4) -> 1 | F4: 航海王：燃烧意志 | G4: 安智市场 | I4: AndAnZhi | J4: AND0006 | K4: 5.0_20190821 | L4: 1.01 | M4: 启用 | N4: 隐藏 | O4: 北海大区
A5: AND0000_0027 | B5: com.yunchang.onepiece | C5: 联想-opensdk支付 | D5: AND0117_HHW_16 | E5: =COUNTIFS(A:A,D5) -> 1 | F5: 航海王：燃烧意志 | G5: 百度游戏 | I5: AndBaiDu | J5: AND0007 | K5: 4.4.6 | L5: 1.03 | M5: 启用 | N5: 显示 | O5: 北海大区 | P5: IOS+官网+安混 | Q5: IOS0019;IOS0019_1;AND0117_HHW_16;AND0117_HHW_12;AND0117_HHW_20;AND0117_HHW_21;AND0117_HHW_22;AND0117_HHW_13;AND0117_HHW_11;AND0117_HHW_9;AND0117_HHW_15;AND0117_HHW_5;AND0117_HHW_10;AND0117_HHW_14;AND0117_HHW_17;AND0117_HHW_18;AND0117_HHW_19;AND0117;AND0147;AND0117_HHW_25;AND0052;AND0058;AND0052_TF_2;AND0117_HHW_24;AND0003;AND0004;AND0006;AND0007;AND0010;AND0035;AND0040;AND0043;AND0051;AND0056;AND0061;AND0062;AND0100;AND0103;AND0109;AND0111;AND0117_HHW_12_2;AND0117_HHW_26;AND0117_HHW_27;AND0118;AND0120;AND0121;AND0121_CHUIZI;AND0121_MEITU;AND0121_ZTE;AND0123;AND0124;AND0125;AND0126;AND0127;AND0128;AND0129;AND0130;AND0131;AND0133;AND0138;AND0140;AND0143;AND0143_1;AND0144;AND0145;AND0146;AND0151;AND0152;AND0155;ANDDQ00117_1;ANDDQ00117_10;ANDDQ00117_11;ANDDQ00117_12;ANDDQ00117_13;ANDDQ00117_14;ANDDQ00117_15;ANDDQ00117_16;ANDDQ00117_17;ANDDQ00117_18;ANDDQ00117_19;ANDDQ00117_2;ANDDQ00117_20;ANDDQ00117_3;ANDDQ00117_4;ANDDQ00117_5;ANDDQ00117_6;ANDDQ00117_7;ANDDQ00117_8;ANDDQ00117_9;AndOpenSDK_WD_001
A6: AND0117 | B6: com.yunchang.onepiece | C6: 官网 | D6: AND0117_HHW_12 | E6: =COUNTIFS(A:A,D6) -> 1 | F6: 航海王：燃烧意志 | G6: 当乐 | I6: AndDangLe | J6: AND0010 | K6: 4.7.1_4711 | L6: 1.11 | M6: 启用 | N6: 隐藏 | O6: 北海大区 | P6: 同上，去公式 | Q6: IOS0019;IOS0019_1;AND0117_HHW_16;AND0117_HHW_12;AND0117_HHW_20;AND0117_HHW_21;AND0117_HHW_22;AND0117_HHW_13;AND0117_HHW_11;AND0117_HHW_9;AND0117_HHW_15;AND0117_HHW_5;AND0117_HHW_10;AND0117_HHW_14;AND0117_HHW_17;AND0117_HHW_18;AND0117_HHW_19;AND0117;AND0147;AND0117_HHW_25;AND0052;AND0058;AND0052_TF_2;AND0117_HHW_24;AND0003;AND0004;AND0006;AND0007;AND0010;AND0035;AND0040;AND0043;AND0051;AND0056;AND0061;AND0062;AND0100;AND0103;AND0109;AND0111;AND0117_HHW_12_2;AND0117_HHW_26;AND0117_HHW_27;AND0118;AND0120;AND0121;AND0121_CHUIZI;AND0121_MEITU;AND0121_ZTE;AND0123;AND0124;AND0125;AND0126;AND0127;AND0128;AND0129;AND0130;AND0131;AND0133;AND0138;AND0140;AND0143;AND0143_1;AND0144;AND0145;AND0146;AND0151;AND0152;AND0155;ANDDQ00117_1;ANDDQ00117_10;ANDDQ00117_11;ANDDQ00117_12;ANDDQ00117_13;ANDDQ00117_14;ANDDQ00117_15;ANDDQ00117_16;ANDDQ00117_17;ANDDQ00117_18;ANDDQ00117_19;ANDDQ00117_2;ANDDQ00117_20;ANDDQ00117_3;ANDDQ00117_4;ANDDQ00117_5;ANDDQ00117_6;ANDDQ00117_7;ANDDQ00117_8;ANDDQ00117_9;AndOpenSDK_WD_001
A7: AND0117_HHW_1 | B7: com.yunchang.onepiece | C7: 阿里原生 | D7: AND0117_HHW_20 | E7: =COUNTIFS(A:A,D7) -> 1 | F7: 航海王：燃烧意志 | G7: 爱奇艺PPS | I7: AndPPS | J7: AND0035 | K7: 8.8.0 | L7: 1.01 | M7: 启用 | N7: 隐藏 | O7: 北海大区
A8: AND0117_HHW_10 | B8: com.yunchang.onepiece | C8: 备用包1 | D8: AND0117_HHW_21 | E8: =COUNTIFS(A:A,D8) -> 1 | F8: 航海王：燃烧意志 | G8: 阿里整合-UC(九游) | I8: AndUC | J8: AND0040 | K8: 9.5.8 | L8: 1.11 | M8: 启用 | N8: 显示 | O8: 北海大区
A9: AND0117_HHW_11 | B9: com.yunchang.onepiece | C9: 好游快爆 | D9: AND0117_HHW_22 | E9: =COUNTIFS(A:A,D9) -> 1 | F9: 航海王：燃烧意志 | G9: 小米应用商店 | I9: AndXiaoMi | J9: AND0043 | K9: 3.3.0.7 | L9: 1.06 | M9: 启用 | N9: 显示 | O9: 北海大区
A10: AND0117_HHW_12 | B10: com.yunchang.onepiece | C10: 热云投放 | D10: AND0117_HHW_13 | E10: =COUNTIFS(A:A,D10) -> 1 | F10: 航海王：燃烧意志 | G10: 搜狗 | I10: AndSouGou | J10: AND0051 | K10: 2.8.5 | L10: 1.01 | M10: 启用 | N10: 隐藏 | O10: 北海大区
A11: AND0117_HHW_12_1 | B11: com.yunchang.onepiece | C11: 热云投放_新 | D11: AND0117_HHW_11 | E11: =COUNTIFS(A:A,D11) -> 1 | F11: 航海王：燃烧意志 | G11: 布卡漫画 | I11: AndBuKaManHua | J11: AND0056 | K11: v4.0.4 | L11: 1 | M11: 启用 | N11: 隐藏 | O11: 北海大区
A12: AND0117_HHW_13 | B12: com.yunchang.onepiece | C12: TAPTAP | D12: AND0117_HHW_9 | E12: =COUNTIFS(A:A,D12) -> 1 | F12: 航海王：燃烧意志 | G12: 斗鱼TV | I12: AndDouYuTV | J12: AND0061 | K12: 3.2.0 | L12: 1.04 | M12: 启用 | N12: 显示 | O12: 北海大区
A13: AND0117_HHW_14 | B13: com.yunchang.onepiece | C13: 备用包2 | D13: AND0117_HHW_15 | E13: =COUNTIFS(A:A,D13) -> 1 | F13: 航海王：燃烧意志 | G13: 啪啪游戏厅 | I13: AndPaPaYouXiTing | J13: AND0062 | K13: 3.3.0.x | L13: 1 | M13: 启用 | N13: 隐藏 | O13: 北海大区
A14: AND0117_HHW_15 | B14: com.yunchang.onepiece | C14: 品专 | D14: AND0117_HHW_5 | E14: =COUNTIFS(A:A,D14) -> 1 | F14: 航海王：燃烧意志 | G14: 手盟 | I14: AndShouMeng | J14: AND0100 | K14: 2.0.0 | L14: 1.02 | M14: 启用 | N14: 隐藏 | O14: 北海大区
A15: AND0117_HHW_16 | B15: com.yunchang.onepiece | C15: 抖音投放3 | D15: AND0117_HHW_10 | E15: =COUNTIFS(A:A,D15) -> 1 | F15: 航海王：燃烧意志 | G15: A站 | I15: AndAcFun | J15: AND0103 | K15: v2.0.1 | L15: 1 | M15: 启用 | N15: 隐藏 | O15: 北海大区
A16: AND0117_HHW_17 | B16: com.yunchang.onepiece | C16: 备用包3 | D16: AND0117_HHW_14 | E16: =COUNTIFS(A:A,D16) -> 1 | F16: 航海王：燃烧意志 | G16: 努比亚 | I16: AndNubia | J16: AND0109 | K16: V2.5.5 | L16: 1.02 | M16: 启用 | N16: 显示 | O16: 北海大区
A17: AND0117_HHW_18 | B17: com.yunchang.onepiece | C17: 阿里渠道转移测试临时用 | D17: AND0117_HHW_17 | E17: =COUNTIFS(A:A,D17) -> 1 | F17: 航海王：燃烧意志 | G17: 三星网游联运 | I17: AndSamSungPro | J17: AND0111 | K17: 1.7.4 | L17: 1.04 | M17: 启用 | N17: 显示 | O17: 北海大区
A18: AND0117_HHW_19 | B18: com.yunchang.onepiece | C18: 抖音投放5 | D18: AND0117_HHW_18 | E18: =COUNTIFS(A:A,D18) -> 1 | F18: 航海王：燃烧意志 | G18: opensdk新版 | H18: 官网安混-GS | I18: AndOpenSDK | J18: AND0117_HHW_12_2 | K18: 2.0.4.8 | L18: 1.82 | M18: 启用 | N18: 显示 | O18: 北海大区
A19: AND0117_HHW_2 | B19: com.yunchang.onepiece | C19: 阿里原生 | D19: AND0117_HHW_19 | E19: =COUNTIFS(A:A,D19) -> 1 | F19: 航海王：燃烧意志 | G19: 阿里原生 | H19: 官网安混 | I19: AndALi | J19: AND0117_HHW_26 | K19: 3.8.3.21 | L19: 1.15 | M19: 启用 | N19: 显示 | O19: 北海大区
A20: AND0117_HHW_20 | B20: com.yunchang.onepiece | C20: 抖音投放6 | D20: AND0117 | E20: =COUNTIFS(A:A,D20) -> 1 | F20: 航海王：燃烧意志 | G20: 阿里原生 | H20: CPS合作1 | I20: AndALi | J20: AND0117_HHW_27 | K20: 3.8.3.21 | L20: 1.15 | M20: 启用 | N20: 显示 | O20: 北海大区
A21: AND0117_HHW_21 | B21: com.yunchang.onepiece | C21: 抖音投放7 | F21: 航海王：燃烧意志 | G21: 小七 | I21: AndXiaoQi | J21: AND0118 | K21: 7.39.0 | L21: 1.06 | M21: 启用 | N21: 显示 | O21: 北海大区
A22: AND0117_HHW_22 | B22: com.yunchang.onepiece | C22: 热云投放-备用包3 | F22: 航海王：燃烧意志 | G22: 快看 | I22: AndKuaiKan | J22: AND0120 | K22: 4.1.1 | L22: 1.01 | M22: 启用 | N22: 隐藏 | O22: 北海大区
A23: AND0117_HHW_23 | B23: com.yunchang.onepiece | C23: 抖音投放8 | D23: IOS0019 | E23: =COUNTIFS(A:A,D23) -> 1 | F23: 航海王：燃烧意志 | G23: 玩咖 | H23: 玩咖-8848 | I23: AndWanKa | J23: AND0121 | K23: v2.2.8 | L23: 1 | M23: 启用 | N23: 隐藏 | O23: 北海大区
A24: AND0117_HHW_24 | B24: com.yunchang.onepiece | C24: 品专PC | D24: IOS0019_1 | E24: =COUNTIFS(A:A,D24) -> 1 | F24: 航海王：燃烧意志 | G24: 玩咖 | H24: 玩咖-锤子 | I24: AndWanKa | J24: AND0121_CHUIZI | K24: v2.2.8 | L24: 1 | M24: 启用 | N24: 显示 | O24: 北海大区
A25: AND0117_HHW_25 | B25: com.yunchang.onepiece | C25: 品专移动 | D25: AND0117_HHW_16 | E25: =COUNTIFS(A:A,D25) -> 1 | F25: 航海王：燃烧意志 | G25: 玩咖 | H25: 玩咖-美图 | I25: AndWanKa | J25: AND0121_MEITU | K25: v2.2.8 | L25: 1 | M25: 启用 | N25: 隐藏 | O25: 北海大区
A26: AND0117_HHW_26 | B26: com.yunchang.onepiece | C26: 官网安混 | D26: AND0117_HHW_12 | E26: =COUNTIFS(A:A,D26) -> 1 | F26: 航海王：燃烧意志 | G26: 玩咖 | H26: 玩咖-中兴 | I26: AndWanKa | J26: AND0121_ZTE | K26: v2.2.8 | L26: 1 | M26: 启用 | N26: 隐藏 | O26: 北海大区
A27: AND0117_HHW_27 | B27: com.yunchang.onepiece | C27: CPS合作1 | D27: AND0117_HHW_20 | E27: =COUNTIFS(A:A,D27) -> 1 | F27: 航海王：燃烧意志 | G27: 阅文 | I27: AndYueWen | J27: AND0123 | K27: 3.0.0 | L27: 1 | M27: 启用 | N27: 隐藏 | O27: 北海大区
A28: AND0117_HHW_28 | B28: com.yunchang.onepiece | C28: 万代安混临时测试包 | D28: AND0117_HHW_21 | E28: =COUNTIFS(A:A,D28) -> 1 | F28: 航海王：燃烧意志 | G28: 网易云音乐 | I28: AndWangYiMusic | J28: AND0124 | K28: 5.5.0 | L28: 1.09 | M28: 启用 | N28: 显示 | O28: 北海大区
A29: AND0117_HHW_29 | B29: com.yunchang.onepiece | C29: 官网硬核 | D29: AND0117_HHW_22 | E29: =COUNTIFS(A:A,D29) -> 1 | F29: 航海王：燃烧意志 | G29: 网易MuMu | I29: AndWangYiMuMu | J29: AND0125 | K29: 3.2.20 | L29: 1.04 | M29: 启用 | N29: 显示 | O29: 北海大区
A30: AND0117_HHW_3 | B30: com.yunchang.onepiece | C30: 阿里原生 | D30: AND0117_HHW_13 | E30: =COUNTIFS(A:A,D30) -> 1 | F30: 航海王：燃烧意志 | G30: 快手 | I30: AndKuaiShou | J30: AND0126 | K30: 1.10.17 | L30: 1.03 | M30: 启用 | N30: 隐藏 | O30: 北海大区
A31: AND0117_HHW_30 | B31: com.yunchang.onepiece | C31: 官网2.0测试 | D31: AND0117_HHW_11 | E31: =COUNTIFS(A:A,D31) -> 1 | F31: 航海王：燃烧意志 | G31: 人人视频 | I31: AndYYeTs | J31: AND0127 | K31: 4.2.0 | L31: 1.03 | M31: 启用 | N31: 显示 | O31: 北海大区
A32: AND0117_HHW_31 | B32: com.yunchang.onepiece | C32: TAPTAP2.0测试 | D32: AND0117_HHW_9 | E32: =COUNTIFS(A:A,D32) -> 1 | F32: 航海王：燃烧意志 | G32: 蓝叠模拟器 | I32: AndLanDie | J32: AND0128 | K32: 1.5.1.2 | L32: 1 | M32: 启用 | N32: 隐藏 | O32: 北海大区
A33: AND0117_HHW_32 | B33: com.yunchang.onepiece | C33: 好游快爆2.0测试 | D33: AND0117_HHW_15 | E33: =COUNTIFS(A:A,D33) -> 1 | F33: 航海王：燃烧意志 | G33: 有玩 | I33: AndYouWan | J33: AND0129 | K33: v1.5.3 | L33: 1 | M33: 启用 | N33: 隐藏 | O33: 北海大区
A34: AND0117_HHW_33 | B34: com.yunchang.onepiece | C34: 热云投放2.0测试 | D34: AND0117_HHW_5 | E34: =COUNTIFS(A:A,D34) -> 1 | F34: 航海王：燃烧意志 | G34: 小y游戏 | I34: AndXiaoY | J34: AND0130 | K34: 2.2.1 | L34: 1.04 | M34: 启用 | N34: 显示 | O34: 北海大区
A35: AND0117_HHW_34 | B35: com.yunchang.onepiece | C35: 官网-KOC新卡测试 | D35: AND0117_HHW_10 | E35: =COUNTIFS(A:A,D35) -> 1 | F35: 航海王：燃烧意志 | G35: 游戏鲸 | I35: AndYouXiJing | J35: AND0131 | K35: 6.9 | L35: 1.03 | M35: 启用 | N35: 显示 | O35: 北海大区
A36: AND0117_HHW_35 | B36: com.yunchang.onepiece | C36: 官网-投放使用 | D36: AND0117_HHW_14 | E36: =COUNTIFS(A:A,D36) -> 1 | F36: 航海王：燃烧意志 | G36: 雷电模拟器 | I36: AndLeiDian | J36: AND0133 | K36: 2.4.7 | L36: 1.05 | M36: 启用 | N36: 显示 | O36: 北海大区
A37: AND0117_HHW_36 | B37: com.yunchang.onepiece | C37: 官网-版署提审 | D37: AND0117_HHW_17 | E37: =COUNTIFS(A:A,D37) -> 1 | F37: 航海王：燃烧意志 | G37: 玩么 | H37: 玩咖-美图-新 | I37: AndWanMe | J37: AND0138 | K37: 19-8-13-v8 | L37: 1 | M37: 启用 | N37: 显示 | O37: 北海大区
A38: AND0117_HHW_4 | B38: com.yunchang.onepiece | C38: 阿里原生 | D38: AND0117_HHW_18 | E38: =COUNTIFS(A:A,D38) -> 1 | F38: 航海王：燃烧意志 | G38: 虎牙 | I38: AndHuYa | J38: AND0140 | K38: 1.2.6-326 | L38: 1.05 | M38: 启用 | N38: 显示 | O38: 北海大区
A39: AND0117_HHW_5 | B39: com.yunchang.onepiece | C39: 短信push包 | D39: AND0117_HHW_19 | E39: =COUNTIFS(A:A,D39) -> 1 | F39: 航海王：燃烧意志 | G39: 咪咕云游戏 | I39: AndMigu | J39: AND0143 | K39: 80011 | L39: 1.03 | M39: 启用 | N39: 显示 | O39: 北海大区
A40: AND0117_HHW_6 | B40: com.yunchang.onepiece | C40: 阿里原生 | D40: AND0117 | E40: =COUNTIFS(A:A,D40) -> 1 | F40: 航海王：燃烧意志 | G40: 咪咕云游戏 | H40: 咪咕游戏TV | I40: AndMigu | J40: AND0143_1 | K40: 80011 | L40: 1.03 | M40: 启用 | N40: 显示 | O40: 北海大区
...

Sheet Sheet2
A1: 渠道
A2: default | B2: =COUNTIF(渠道!J:J,Sheet2!A2) -> 0
A3: IOS0019;IOS0019_1 | B3: =COUNTIF(渠道!J:J,Sheet2!A3) -> 0
A4: AND0117_HHW_16;AND0117_HHW_12;AND0117_HHW_20;AND0117_HHW_21;AND0117_HHW_22;AND0117_HHW_13;AND0117_HHW_11;AND0117_HHW_9;AND0117_HHW_15;AND0117_HHW_5;AND0117_HHW_10;AND0117_HHW_14;AND0117_HHW_17;AND0117_HHW_18;AND0117_HHW_19;AND0117;AND0117_HHW_25;AND0052;AND0058;AND0052_TF_2;AND0117_HHW_24 | B4: =COUNTIF(渠道!J:J,Sheet2!A4) -> #VALUE!
A5: AND0147 | B5: =COUNTIF(渠道!J:J,Sheet2!A5) -> 0
A6: AND0111 | B6: =COUNTIF(渠道!J:J,Sheet2!A6) -> 1
A7: AND0026 | B7: =COUNTIF(渠道!J:J,Sheet2!A7) -> 0
A8: IOS0019;IOS0019_1;AND0117_HHW_16;AND0117_HHW_12;AND0117_HHW_20;AND0117_HHW_21;AND0117_HHW_22;AND0117_HHW_13;AND0117_HHW_11;AND0117_HHW_9;AND0117_HHW_15;AND0117_HHW_5;AND0117_HHW_10;AND0117_HHW_14;AND0117_HHW_17;AND0117_HHW_18;AND0117_HHW_19;AND0117;AND0147;AND0117_HHW_25;AND0052;AND0058;AND0052_TF_2;AND0117_HHW_24 | B8: =COUNTIF(渠道!J:J,Sheet2!A8) -> #VALUE!
A13: IF(OR(F7="month",F7="navigation_pass"),0,1 | C13: once
C14: activity_invest
C15: navigation_pass
C16: LTInvest_pass
C17: CrawlTower_pass
