Workbook

Sheet Sheet1
A1: 7 | B1: 1 | C1: 9999 | D1: 4
A2: id | B2: 文件名 | C2: 文件类型 | D2: 是否有版权问题（1是0否）
A3: id | B3: fileName | C3: fileType | D3: copyrightProblem
A4: int | B4: string | C4: string(intern) | D4: int
A5: primary | B5: index | C5: index | D5: none
A7: 1 | B7: plot/0001-01 | C7: 0 | D7: 1
A8: 2 | B8: plot/0001-02 | C8: 0 | D8: 1
A9: 3 | B9: plot/0001-03 | C9: 0 | D9: 1
A10: 4 | B10: plot/0001-04 | C10: 0 | D10: 1
A11: 5 | B11: plot/0001-05 | C11: 0 | D11: 1
A12: 6 | B12: plot/0001-06 | C12: 0 | D12: 1
A13: 7 | B13: plot/0002-01 | C13: 0 | D13: 1
A14: 8 | B14: plot/0002-02 | C14: 0 | D14: 1
A15: 9 | B15: plot/0002-03 | C15: 0 | D15: 1
A16: 10 | B16: plot/0002-04 | C16: 0 | D16: 1
A17: 11 | B17: plot/0002-05 | C17: 0 | D17: 1
A18: 12 | B18: plot/0002-06 | C18: 0 | D18: 1
... A1295: 1289 | B1295: CV_zoro06 | C1295: 0 | D1295: 0

Sheet Sheet2
B1: plot/0001-01 | C1: 0 | D1: =VLOOKUP(B1,Sheet1!$B$7:$D$1144,3,FALSE) -> 1
B2: plot/0001-02 | C2: 0 | D2: =VLOOKUP(B2,Sheet1!$B$7:$D$1144,3,FALSE) -> 1
B3: plot/0001-03 | C3: 0 | D3: =VLOOKUP(B3,Sheet1!$B$7:$D$1144,3,FALSE) -> 1
B4: plot/0001-04 | C4: 0 | D4: =VLOOKUP(B4,Sheet1!$B$7:$D$1144,3,FALSE) -> 1
B5: plot/0001-05 | C5: 0 | D5: =VLOOKUP(B5,Sheet1!$B$7:$D$1144,3,FALSE) -> 1
B6: plot/0001-06 | C6: 0 | D6: =VLOOKUP(B6,Sheet1!$B$7:$D$1144,3,FALSE) -> 1
B7: plot/0002-01 | C7: 0 | D7: =VLOOKUP(B7,Sheet1!$B$7:$D$1144,3,FALSE) -> 1
B8: plot/0002-02 | C8: 0 | D8: =VLOOKUP(B8,Sheet1!$B$7:$D$1144,3,FALSE) -> 1
B9: plot/0002-03 | C9: 0 | D9: =VLOOKUP(B9,Sheet1!$B$7:$D$1144,3,FALSE) -> 1
B10: plot/0002-04 | C10: 0 | D10: =VLOOKUP(B10,Sheet1!$B$7:$D$1144,3,FALSE) -> 1
B11: plot/0002-05 | C11: 0 | D11: =VLOOKUP(B11,Sheet1!$B$7:$D$1144,3,FALSE) -> 1
B12: plot/0002-06 | C12: 0 | D12: =VLOOKUP(B12,Sheet1!$B$7:$D$1144,3,FALSE) -> 1
... B27: plot/0102-05 | C27: 0 | D27: =VLOOKUP(B27,Sheet1!$B$7:$D$1144,3,FALSE) -> 1
B28: plot/0102-06 | C28: 0 | D28: =VLOOKUP(B28,Sheet1!$B$7:$D$1144,3,FALSE) -> 1 | I28: BGM_loop01
B29: plot/0102-07 | C29: 0 | D29: =VLOOKUP(B29,Sheet1!$B$7:$D$1144,3,FALSE) -> 1 | I29: BGM_loop02
B30: plot/0102-08 | C30: 0 | D30: =VLOOKUP(B30,Sheet1!$B$7:$D$1144,3,FALSE) -> 1 | I30: BGM_loop03
B31: plot/NEW0102-(00) | C31: 0 | D31: =VLOOKUP(B31,Sheet1!$B$7:$D$1144,3,FALSE) -> 1 | I31: bgm_temp01
B32: plot/NEW0102-(-01) | C32: 0 | D32: =VLOOKUP(B32,Sheet1!$B$7:$D$1144,3,FALSE) -> 1 | I32: bgm_temp02
B33: plot/0103-01 | C33: 0 | D33: =VLOOKUP(B33,Sheet1!$B$7:$D$1144,3,FALSE) -> 0 | I33: bgm_temp03
B34: plot/0103-02 | C34: 0 | D34: =VLOOKUP(B34,Sheet1!$B$7:$D$1144,3,FALSE) -> 0 | I34: bgm_temp04
B35: plot/NEW0103-01(01) | C35: 0 | D35: =VLOOKUP(B35,Sheet1!$B$7:$D$1144,3,FALSE) -> 0 | I35: bgm_temp05
B36: plot/NEW0103-01(02) | C36: 0 | D36: =VLOOKUP(B36,Sheet1!$B$7:$D$1144,3,FALSE) -> 0 | I36: bgm_temp06
B37: plot/NEW0103-01(03) | C37: 0 | D37: =VLOOKUP(B37,Sheet1!$B$7:$D$1144,3,FALSE) -> 0 | I37: bgm_temp07
B38: plot/NEW0103-02(01) | C38: 0 | D38: =VLOOKUP(B38,Sheet1!$B$7:$D$1144,3,FALSE) -> 0 | I38: bgm_temp08
B39: plot/NEW0103-02(02) | C39: 0 | D39: =VLOOKUP(B39,Sheet1!$B$7:$D$1144,3,FALSE) -> 0 | I39: bgm_temp09
... B535: plot/Union_upgrade | C535: 0 | D535: =VLOOKUP(B535,Sheet1!$B$7:$D$1144,3,FALSE) -> 0 | I535: CV_nami05
I536: CV_nami06
I537: CV_nami07
I538: CV_nami08
I539: CV_nami09
A540: BACKUP_DATA | B540: 20180817 | C540: CBT4 | I540: CV_nami10
I541: CV_nami11
A542: 1 | B542: plot/0001-01 | C542: 0 | D542: 1 | I542: CV_newgate_hit01
A543: 2 | B543: plot/0001-02 | C543: 0 | D543: 1 | I543: CV_newgate_hit02
A544: 3 | B544: plot/0001-03 | C544: 0 | D544: 1 | I544: CV_newgate_hit03
A545: 4 | B545: plot/0001-04 | C545: 0 | D545: 1 | I545: CV_perona_hit01
A546: 5 | B546: plot/0001-05 | C546: 0 | D546: 1 | I546: CV_perona_hit02
A547: 6 | B547: plot/0001-06 | C547: 0 | D547: 1 | I547: CV_perona_hit03
A548: 7 | B548: plot/0002-01 | C548: 0 | D548: 1 | I548: CV_robin_hit01
A549: 8 | B549: plot/0002-02 | C549: 0 | D549: 1 | I549: CV_robin_hit02
...
