Workbook

Sheet Sheet1
A1: 7 | B1: 1 | C1: 9999 | D1: 20
A2: ID | B2: 规则ID | C2: 装备ID 根据对应的装备id取相应的属性 | D2: 属性类型 | E2: 属性最小值 | F2: 属性最大值 | G2: 权重 | H2: 是否稀有 | I2: 稀有属性标记 | J2: 备注（策划看）
A3: id | B3: ruleId | C3: equipId | D3: attrType | E3: attrValueMin | F3: attrValueMax | G3: weight | H3: isRare | I3: rareAttrPos
A4: int | B4: int | C4: int | D4: string | E4: string | F4: string | G4: int | H4: int | I4: string
A5: primary | B5: none | C5: none | D5: none | E5: none | F5: none | G5: none | H5: none | I5: none
A6: id | B6: ruleId | C6: equipId | D6: attrType | E6: attrValueMin | F6: attrValueMax | G6: weight | H6: isRare | I6: rareAttrPos

Sheet Sheet2
A1: id | B1: 部位 | C1: 备注
A2: 120001 | B2: 1 | C2: Lv.20普通武器
A3: 120002 | B3: 2 | C3: Lv.20普通衣服
A4: 120003 | B4: 3 | C4: Lv.20普通戒指
A5: 120004 | B5: 4 | C5: Lv.20普通项链
A6: 130001 | B6: 1 | C6: Lv.30普通武器
A7: 130002 | B7: 2 | C7: Lv.30普通衣服
A8: 130003 | B8: 3 | C8: Lv.30普通戒指
A9: 130004 | B9: 4 | C9: Lv.30普通项链
A10: 140001 | B10: 1 | C10: Lv.40普通武器-均衡
A11: 140002 | B11: 2 | C11: Lv.40普通衣服-均衡
A12: 140003 | B12: 3 | C12: Lv.40普通戒指-均衡
A13: 140004 | B13: 4 | C13: Lv.40普通项链-均衡
... A185: 260904 | B185: 4 | C185: Lv.60英雄项链-物理辅助

Sheet Sheet3
C1: id | D1: attr | E1: value
B2: 101 | C2: 120001 | D2: 1 | E2: 37 | H2: Lv.20普通武器
B3: 101 | C3: 130001 | D3: 1 | E3: 48 | H3: Lv.30普通武器
B4: 101 | C4: 140001 | D4: 1 | E4: 74 | H4: Lv.40普通武器-均衡
B5: 101 | C5: 140101 | D5: 1 | E5: 93 | H5: Lv.40普通武器-输出
B6: 101 | C6: 140201 | D6: 1 | E6: 60 | H6: Lv.40普通武器-生存
B7: 101 | C7: 150101 | D7: 1 | E7: 160 | H7: Lv.50普通武器-物理坦克
B8: 101 | C8: 150201 | D8: 1 | E8: 160 | H8: Lv.50普通武器-元素坦克
B9: 101 | C9: 150301 | D9: 1 | E9: 160 | H9: Lv.50普通武器-元素战士
B10: 101 | C10: 150401 | D10: 1 | E10: 160 | H10: Lv.50普通武器-物理战士
B11: 101 | C11: 150501 | D11: 1 | E11: 160 | H11: Lv.50普通武器-元素刺客
B12: 101 | C12: 150601 | D12: 1 | E12: 160 | H12: Lv.50普通武器-敏暴刺客
B13: 101 | C13: 150701 | D13: 1 | E13: 160 | H13: Lv.50普通武器-闪避刺客
... B47: 103 | C47: 150201 | D47: 8 | E47: 0.0107 | H47: Lv.50普通武器-元素坦克
B48: 103 | C48: 150301 | D48: 8,26 | E48: 0.0078,0.0103 | H48: Lv.50普通武器-元素战士
B49: 103 | C49: 150401 | D49: 8 | E49: 0.0129 | H49: Lv.50普通武器-物理战士
B50: 103 | C50: 150501 | D50: 8,26 | E50: 0.0086,0.0258 | H50: Lv.50普通武器-元素刺客
B51: 103 | C51: 150601 | D51: 8,9 | E51: 0.0043,0.0288 | H51: Lv.50普通武器-敏暴刺客
B52: 103 | C52: 150701 | D52: 4,9 | E52: 0.0106,0.0144 | H52: Lv.50普通武器-闪避刺客
B53: 103 | C53: 150801 | D53: 5,9 | E53: 0.005,0.0096 | H53: Lv.50普通武器-元素辅助
B54: 103 | C54: 150901 | D54: 5,9,11 | E54: 0.0062,0.012,0.0014 | H54: Lv.50普通武器-物理辅助
B55: 103 | C55: 160101 | D55: 8 | E55: 0.0072 | H55: Lv.60普通武器-物理坦克
B56: 103 | C56: 160201 | D56: 8 | E56: 0.0143 | H56: Lv.60普通武器-元素坦克
B57: 103 | C57: 160301 | D57: 8,26 | E57: 0.0129,0.0172 | H57: Lv.60普通武器-元素战士
B58: 103 | C58: 160401 | D58: 8 | E58: 0.0215 | H58: Lv.60普通武器-物理战士
B59: 103 | C59: 160501 | D59: 8,26 | E59: 0.0143,0.043 | H59: Lv.60普通武器-元素刺客
B60: 103 | C60: 160601 | D60: 8,9 | E60: 0.0072,0.048 | H60: Lv.60普通武器-敏暴刺客
B61: 103 | C61: 160701 | D61: 4,9 | E61: 0.0175,0.024 | H61: Lv.60普通武器-闪避刺客
B62: 103 | C62: 160801 | D62: 5,9 | E62: 0.0083,0.016 | H62: Lv.60普通武器-元素辅助
B63: 103 | C63: 160901 | D63: 5,9,11 | E63: 0.0105,0.02,0.0022 | H63: Lv.60普通武器-物理辅助
B64: 104 | C64: 150101 | D64: 8 | E64: 0.0082 | H64: Lv.50普通武器-物理坦克
B65: 104 | C65: 150101 | D65: 4 | E65: 11.656
B66: 104 | C66: 150201 | D66: 8 | E66: 0.0164 | H66: Lv.50普通武器-元素坦克
B67: 104 | C67: 150201 | D67: 4 | E67: 11.656
B68: 104 | C68: 150301 | D68: 8 | E68: 0.0147 | H68: Lv.50普通武器-元素战士
B69: 104 | C69: 150301 | D69: 4 | E69: 11.656
B70: 104 | C70: 150301 | D70: 26 | E70: 0.0197
B71: 104 | C71: 150401 | D71: 8 | E71: 0.0246 | H71: Lv.50普通武器-物理战士
B72: 104 | C72: 150401 | D72: 4 | E72: 11.656
B73: 104 | C73: 150501 | D73: 8 | E73: 0.0164 | H73: Lv.50普通武器-元素刺客
...

Sheet Sheet4
B1: 英雄 | C1: attr | H1: attr | P1: 普通 | Q1: 0.8 | AA1: 复制用
A2: 101 | B2: 220001 | C2: 1 | D2: 46 | H2: 1 | K2: =IF(D2="","",IF(OR(RIGHT($A2,1)="1",RIGHT($A2,1)="2"),D2,IF(H2=4,D2*2,D2*6))) -> 46 | L2: =IF(E2="","",IF(OR(RIGHT($A2,1)="1",RIGHT($A2,1)="2"),E2,IF(I2=4,E2*2,E2*6))) | M2: =IF(F2="","",IF(OR(RIGHT($A2,1)="1",RIGHT($A2,1)="2"),F2,IF(J2=4,F2*2,F2*6))) | N2: =IF(G2="","",IF(OR(RIGHT($A2,1)="1",RIGHT($A2,1)="2"),G2,IF(J2=4,G2*2,G2*6))) | P2: =B2-100000 -> 120001 | Q2: =ROUND(D2*$Q$1,0) -> 37 | V2: =IF(K2="","",IF(K2<1,ROUND(K2,4),CEILING(K2,5))) -> 50 | W2: =IF(L2="","",IF(L2<1,ROUND(L2,4),CEILING(L2,5))) | X2: =IF(M2="","",IF(M2<1,ROUND(M2,4),CEILING(M2,5))) | AB2: =_xlfn.TEXTJOIN(",",TRUE,V2,W2,X2) -> 50 | AF2: Lv.20普通武器
A3: 101 | B3: 230001 | C3: 1 | D3: 60 | H3: 1 | K3: =IF(D3="","",IF(OR(RIGHT($A3,1)="1",RIGHT($A3,1)="2"),D3,IF(H3=4,D3*2,D3*6))) -> 60 | L3: =IF(E3="","",IF(OR(RIGHT($A3,1)="1",RIGHT($A3,1)="2"),E3,IF(I3=4,E3*2,E3*6))) | M3: =IF(F3="","",IF(OR(RIGHT($A3,1)="1",RIGHT($A3,1)="2"),F3,IF(J3=4,F3*2,F3*6))) | N3: =IF(G3="","",IF(OR(RIGHT($A3,1)="1",RIGHT($A3,1)="2"),G3,IF(J3=4,G3*2,G3*6))) | P3: =B3-100000 -> 130001 | Q3: =ROUND(D3*$Q$1,0) -> 48 | V3: =IF(K3="","",IF(K3<1,ROUND(K3,4),CEILING(K3,5))) -> 60 | W3: =IF(L3="","",IF(L3<1,ROUND(L3,4),CEILING(L3,5))) | X3: =IF(M3="","",IF(M3<1,ROUND(M3,4),CEILING(M3,5))) | AB3: =_xlfn.TEXTJOIN(",",TRUE,V3,W3,X3) -> 60 | AF3: Lv.30普通武器
A4: 101 | B4: 240001 | C4: 1 | D4: 93 | H4: 1 | K4: =IF(D4="","",IF(OR(RIGHT($A4,1)="1",RIGHT($A4,1)="2"),D4,IF(H4=4,D4*2,D4*6))) -> 93 | L4: =IF(E4="","",IF(OR(RIGHT($A4,1)="1",RIGHT($A4,1)="2"),E4,IF(I4=4,E4*2,E4*6))) | M4: =IF(F4="","",IF(OR(RIGHT($A4,1)="1",RIGHT($A4,1)="2"),F4,IF(J4=4,F4*2,F4*6))) | N4: =IF(G4="","",IF(OR(RIGHT($A4,1)="1",RIGHT($A4,1)="2"),G4,IF(J4=4,G4*2,G4*6))) | P4: =B4-100000 -> 140001 | Q4: =ROUND(D4*$Q$1,0) -> 74 | V4: =IF(K4="","",IF(K4<1,ROUND(K4,4),CEILING(K4,5))) -> 95 | W4: =IF(L4="","",IF(L4<1,ROUND(L4,4),CEILING(L4,5))) | X4: =IF(M4="","",IF(M4<1,ROUND(M4,4),CEILING(M4,5))) | AB4: =_xlfn.TEXTJOIN(",",TRUE,V4,W4,X4) -> 95 | AF4: Lv.40普通武器-均衡
A5: 101 | B5: 240101 | C5: 1 | D5: 116 | H5: 1 | K5: =IF(D5="","",IF(OR(RIGHT($A5,1)="1",RIGHT($A5,1)="2"),D5,IF(H5=4,D5*2,D5*6))) -> 116 | L5: =IF(E5="","",IF(OR(RIGHT($A5,1)="1",RIGHT($A5,1)="2"),E5,IF(I5=4,E5*2,E5*6))) | M5: =IF(F5="","",IF(OR(RIGHT($A5,1)="1",RIGHT($A5,1)="2"),F5,IF(J5=4,F5*2,F5*6))) | N5: =IF(G5="","",IF(OR(RIGHT($A5,1)="1",RIGHT($A5,1)="2"),G5,IF(J5=4,G5*2,G5*6))) | P5: =B5-100000 -> 140101 | Q5: =ROUND(D5*$Q$1,0) -> 93 | V5: =IF(K5="","",IF(K5<1,ROUND(K5,4),CEILING(K5,5))) -> 120 | W5: =IF(L5="","",IF(L5<1,ROUND(L5,4),CEILING(L5,5))) | X5: =IF(M5="","",IF(M5<1,ROUND(M5,4),CEILING(M5,5))) | AB5: =_xlfn.TEXTJOIN(",",TRUE,V5,W5,X5) -> 120 | AF5: Lv.40普通武器-输出
A6: 101 | B6: 240201 | C6: 1 | D6: 75 | H6: 1 | K6: =IF(D6="","",IF(OR(RIGHT($A6,1)="1",RIGHT($A6,1)="2"),D6,IF(H6=4,D6*2,D6*6))) -> 75 | L6: =IF(E6="","",IF(OR(RIGHT($A6,1)="1",RIGHT($A6,1)="2"),E6,IF(I6=4,E6*2,E6*6))) | M6: =IF(F6="","",IF(OR(RIGHT($A6,1)="1",RIGHT($A6,1)="2"),F6,IF(J6=4,F6*2,F6*6))) | N6: =IF(G6="","",IF(OR(RIGHT($A6,1)="1",RIGHT($A6,1)="2"),G6,IF(J6=4,G6*2,G6*6))) | P6: =B6-100000 -> 140201 | Q6: =ROUND(D6*$Q$1,0) -> 60 | V6: =IF(K6="","",IF(K6<1,ROUND(K6,4),CEILING(K6,5))) -> 75 | W6: =IF(L6="","",IF(L6<1,ROUND(L6,4),CEILING(L6,5))) | X6: =IF(M6="","",IF(M6<1,ROUND(M6,4),CEILING(M6,5))) | AB6: =_xlfn.TEXTJOIN(",",TRUE,V6,W6,X6) -> 75 | AF6: Lv.40普通武器-生存
A7: 101 | B7: 250101 | C7: 1 | D7: 200 | H7: 1 | K7: =IF(D7="","",IF(OR(RIGHT($A7,1)="1",RIGHT($A7,1)="2"),D7,IF(H7=4,D7*2,D7*6))) -> 200 | L7: =IF(E7="","",IF(OR(RIGHT($A7,1)="1",RIGHT($A7,1)="2"),E7,IF(I7=4,E7*2,E7*6))) | M7: =IF(F7="","",IF(OR(RIGHT($A7,1)="1",RIGHT($A7,1)="2"),F7,IF(J7=4,F7*2,F7*6))) | N7: =IF(G7="","",IF(OR(RIGHT($A7,1)="1",RIGHT($A7,1)="2"),G7,IF(J7=4,G7*2,G7*6))) | P7: =B7-100000 -> 150101 | Q7: =ROUND(D7*$Q$1,0) -> 160 | V7: =IF(K7="","",IF(K7<1,ROUND(K7,4),CEILING(K7,5))) -> 200 | W7: =IF(L7="","",IF(L7<1,ROUND(L7,4),CEILING(L7,5))) | X7: =IF(M7="","",IF(M7<1,ROUND(M7,4),CEILING(M7,5))) | AB7: =_xlfn.TEXTJOIN(",",TRUE,V7,W7,X7) -> 200 | AF7: Lv.50普通武器-物理坦克
A8: 101 | B8: 250201 | C8: 1 | D8: 200 | H8: 1 | K8: =IF(D8="","",IF(OR(RIGHT($A8,1)="1",RIGHT($A8,1)="2"),D8,IF(H8=4,D8*2,D8*6))) -> 200 | L8: =IF(E8="","",IF(OR(RIGHT($A8,1)="1",RIGHT($A8,1)="2"),E8,IF(I8=4,E8*2,E8*6))) | M8: =IF(F8="","",IF(OR(RIGHT($A8,1)="1",RIGHT($A8,1)="2"),F8,IF(J8=4,F8*2,F8*6))) | N8: =IF(G8="","",IF(OR(RIGHT($A8,1)="1",RIGHT($A8,1)="2"),G8,IF(J8=4,G8*2,G8*6))) | P8: =B8-100000 -> 150201 | Q8: =ROUND(D8*$Q$1,0) -> 160 | V8: =IF(K8="","",IF(K8<1,ROUND(K8,4),CEILING(K8,5))) -> 200 | W8: =IF(L8="","",IF(L8<1,ROUND(L8,4),CEILING(L8,5))) | X8: =IF(M8="","",IF(M8<1,ROUND(M8,4),CEILING(M8,5))) | AB8: =_xlfn.TEXTJOIN(",",TRUE,V8,W8,X8) -> 200 | AF8: Lv.50普通武器-元素坦克
A9: 101 | B9: 250301 | C9: 1 | D9: 200 | H9: 1 | K9: =IF(D9="","",IF(OR(RIGHT($A9,1)="1",RIGHT($A9,1)="2"),D9,IF(H9=4,D9*2,D9*6))) -> 200 | L9: =IF(E9="","",IF(OR(RIGHT($A9,1)="1",RIGHT($A9,1)="2"),E9,IF(I9=4,E9*2,E9*6))) | M9: =IF(F9="","",IF(OR(RIGHT($A9,1)="1",RIGHT($A9,1)="2"),F9,IF(J9=4,F9*2,F9*6))) | N9: =IF(G9="","",IF(OR(RIGHT($A9,1)="1",RIGHT($A9,1)="2"),G9,IF(J9=4,G9*2,G9*6))) | P9: =B9-100000 -> 150301 | Q9: =ROUND(D9*$Q$1,0) -> 160 | V9: =IF(K9="","",IF(K9<1,ROUND(K9,4),CEILING(K9,5))) -> 200 | W9: =IF(L9="","",IF(L9<1,ROUND(L9,4),CEILING(L9,5))) | X9: =IF(M9="","",IF(M9<1,ROUND(M9,4),CEILING(M9,5))) | AB9: =_xlfn.TEXTJOIN(",",TRUE,V9,W9,X9) -> 200 | AF9: Lv.50普通武器-元素战士
A10: 101 | B10: 250401 | C10: 1 | D10: 200 | H10: 1 | K10: =IF(D10="","",IF(OR(RIGHT($A10,1)="1",RIGHT($A10,1)="2"),D10,IF(H10=4,D10*2,D10*6))) -> 200 | L10: =IF(E10="","",IF(OR(RIGHT($A10,1)="1",RIGHT($A10,1)="2"),E10,IF(I10=4,E10*2,E10*6))) | M10: =IF(F10="","",IF(OR(RIGHT($A10,1)="1",RIGHT($A10,1)="2"),F10,IF(J10=4,F10*2,F10*6))) | N10: =IF(G10="","",IF(OR(RIGHT($A10,1)="1",RIGHT($A10,1)="2"),G10,IF(J10=4,G10*2,G10*6))) | P10: =B10-100000 -> 150401 | Q10: =ROUND(D10*$Q$1,0) -> 160 | V10: =IF(K10="","",IF(K10<1,ROUND(K10,4),CEILING(K10,5))) -> 200 | W10: =IF(L10="","",IF(L10<1,ROUND(L10,4),CEILING(L10,5))) | X10: =IF(M10="","",IF(M10<1,ROUND(M10,4),CEILING(M10,5))) | AB10: =_xlfn.TEXTJOIN(",",TRUE,V10,W10,X10) -> 200 | AF10: Lv.50普通武器-物理战士
A11: 101 | B11: 250501 | C11: 1 | D11: 200 | H11: 1 | K11: =IF(D11="","",IF(OR(RIGHT($A11,1)="1",RIGHT($A11,1)="2"),D11,IF(H11=4,D11*2,D11*6))) -> 200 | L11: =IF(E11="","",IF(OR(RIGHT($A11,1)="1",RIGHT($A11,1)="2"),E11,IF(I11=4,E11*2,E11*6))) | M11: =IF(F11="","",IF(OR(RIGHT($A11,1)="1",RIGHT($A11,1)="2"),F11,IF(J11=4,F11*2,F11*6))) | N11: =IF(G11="","",IF(OR(RIGHT($A11,1)="1",RIGHT($A11,1)="2"),G11,IF(J11=4,G11*2,G11*6))) | P11: =B11-100000 -> 150501 | Q11: =ROUND(D11*$Q$1,0) -> 160 | V11: =IF(K11="","",IF(K11<1,ROUND(K11,4),CEILING(K11,5))) -> 200 | W11: =IF(L11="","",IF(L11<1,ROUND(L11,4),CEILING(L11,5))) | X11: =IF(M11="","",IF(M11<1,ROUND(M11,4),CEILING(M11,5))) | AB11: =_xlfn.TEXTJOIN(",",TRUE,V11,W11,X11) -> 200 | AF11: Lv.50普通武器-元素刺客
A12: 101 | B12: 250601 | C12: 1 | D12: 200 | H12: 1 | K12: =IF(D12="","",IF(OR(RIGHT($A12,1)="1",RIGHT($A12,1)="2"),D12,IF(H12=4,D12*2,D12*6))) -> 200 | L12: =IF(E12="","",IF(OR(RIGHT($A12,1)="1",RIGHT($A12,1)="2"),E12,IF(I12=4,E12*2,E12*6))) | M12: =IF(F12="","",IF(OR(RIGHT($A12,1)="1",RIGHT($A12,1)="2"),F12,IF(J12=4,F12*2,F12*6))) | N12: =IF(G12="","",IF(OR(RIGHT($A12,1)="1",RIGHT($A12,1)="2"),G12,IF(J12=4,G12*2,G12*6))) | P12: =B12-100000 -> 150601 | Q12: =ROUND(D12*$Q$1,0) -> 160 | V12: =IF(K12="","",IF(K12<1,ROUND(K12,4),CEILING(K12,5))) -> 200 | W12: =IF(L12="","",IF(L12<1,ROUND(L12,4),CEILING(L12,5))) | X12: =IF(M12="","",IF(M12<1,ROUND(M12,4),CEILING(M12,5))) | AB12: =_xlfn.TEXTJOIN(",",TRUE,V12,W12,X12) -> 200 | AF12: Lv.50普通武器-敏暴刺客
A13: 101 | B13: 250701 | C13: 1 | D13: 200 | H13: 1 | K13: =IF(D13="","",IF(OR(RIGHT($A13,1)="1",RIGHT($A13,1)="2"),D13,IF(H13=4,D13*2,D13*6))) -> 200 | L13: =IF(E13="","",IF(OR(RIGHT($A13,1)="1",RIGHT($A13,1)="2"),E13,IF(I13=4,E13*2,E13*6))) | M13: =IF(F13="","",IF(OR(RIGHT($A13,1)="1",RIGHT($A13,1)="2"),F13,IF(J13=4,F13*2,F13*6))) | N13: =IF(G13="","",IF(OR(RIGHT($A13,1)="1",RIGHT($A13,1)="2"),G13,IF(J13=4,G13*2,G13*6))) | P13: =B13-100000 -> 150701 | Q13: =ROUND(D13*$Q$1,0) -> 160 | V13: =IF(K13="","",IF(K13<1,ROUND(K13,4),CEILING(K13,5))) -> 200 | W13: =IF(L13="","",IF(L13<1,ROUND(L13,4),CEILING(L13,5))) | X13: =IF(M13="","",IF(M13<1,ROUND(M13,4),CEILING(M13,5))) | AB13: =_xlfn.TEXTJOIN(",",TRUE,V13,W13,X13) -> 200 | AF13: Lv.50普通武器-闪避刺客
... A45: 102 | B45: 260901 | C45: 1 | D45: 563 | H45: 1 | K45: =IF(D45="","",IF(OR(RIGHT($A45,1)="1",RIGHT($A45,1)="2"),D45,IF(H45=4,D45*2,D45*6))) -> 563 | L45: =IF(E45="","",IF(OR(RIGHT($A45,1)="1",RIGHT($A45,1)="2"),E45,IF(I45=4,E45*2,E45*6))) | M45: =IF(F45="","",IF(OR(RIGHT($A45,1)="1",RIGHT($A45,1)="2"),F45,IF(J45=4,F45*2,F45*6))) | N45: =IF(G45="","",IF(OR(RIGHT($A45,1)="1",RIGHT($A45,1)="2"),G45,IF(J45=4,G45*2,G45*6))) | P45: =B45-100000 -> 160901 | Q45: =ROUND(D45*$Q$1,0) -> 450 | V45: =IF(K45="","",IF(K45<1,ROUND(K45,4),CEILING(K45,5))) -> 565 | W45: =IF(L45="","",IF(L45<1,ROUND(L45,4),CEILING(L45,5))) | X45: =IF(M45="","",IF(M45<1,ROUND(M45,4),CEILING(M45,5))) | AB45: =_xlfn.TEXTJOIN(",",TRUE,V45,W45,X45) -> 565 | AF45: Lv.60普通武器-物理辅助
A46: 103 | B46: 250101 | C46: 8 | D46: 0.0054 | H46: 8 | K46: =IF(D46="","",IF(OR(RIGHT($A46,1)="1",RIGHT($A46,1)="2"),D46,IF(H46=4,D46*2,D46*6))) -> 0.0324 | L46: =IF(E46="","",IF(OR(RIGHT($A46,1)="1",RIGHT($A46,1)="2"),E46,IF(I46=4,E46*2,E46*6))) | M46: =IF(F46="","",IF(OR(RIGHT($A46,1)="1",RIGHT($A46,1)="2"),F46,IF(J46=4,F46*2,F46*6))) | N46: =IF(G46="","",IF(OR(RIGHT($A46,1)="1",RIGHT($A46,1)="2"),G46,IF(J46=4,G46*2,G46*6))) | P46: =B46-100000 -> 150101 | Q46: =ROUND(D46*0.8,4) -> 0.0043 | R46: , | V46: =IF(K46="","",IF(K46<1,ROUND(K46,4),CEILING(K46,5))) -> 0.0324 | W46: =IF(L46="","",IF(L46<1,ROUND(L46,4),CEILING(L46,5))) | X46: =IF(M46="","",IF(M46<1,ROUND(M46,4),CEILING(M46,5))) | AB46: =_xlfn.TEXTJOIN(",",TRUE,V46,W46,X46) -> 0.0324 | AF46: Lv.50普通武器-物理坦克
A47: 103 | B47: 250201 | C47: 8 | D47: 0.0107 | H47: 8 | K47: =IF(D47="","",IF(OR(RIGHT($A47,1)="1",RIGHT($A47,1)="2"),D47,IF(H47=4,D47*2,D47*6))) -> 0.0642 | L47: =IF(E47="","",IF(OR(RIGHT($A47,1)="1",RIGHT($A47,1)="2"),E47,IF(I47=4,E47*2,E47*6))) | M47: =IF(F47="","",IF(OR(RIGHT($A47,1)="1",RIGHT($A47,1)="2"),F47,IF(J47=4,F47*2,F47*6))) | N47: =IF(G47="","",IF(OR(RIGHT($A47,1)="1",RIGHT($A47,1)="2"),G47,IF(J47=4,G47*2,G47*6))) | P47: =B47-100000 -> 150201 | Q47: =ROUND(D47*0.8,4) -> 0.0086 | R47: , | V47: =IF(K47="","",IF(K47<1,ROUND(K47,4),CEILING(K47,5))) -> 0.0642 | W47: =IF(L47="","",IF(L47<1,ROUND(L47,4),CEILING(L47,5))) | X47: =IF(M47="","",IF(M47<1,ROUND(M47,4),CEILING(M47,5))) | AB47: =_xlfn.TEXTJOIN(",",TRUE,V47,W47,X47) -> 0.0642 | AF47: Lv.50普通武器-元素坦克
A48: 103 | B48: 250301 | C48: 8,26 | D48: 0.0097 | E48: 0.0129 | H48: 8 | I48: 26 | K48: =IF(D48="","",IF(OR(RIGHT($A48,1)="1",RIGHT($A48,1)="2"),D48,IF(H48=4,D48*2,D48*6))) -> 0.0582 | L48: =IF(E48="","",IF(OR(RIGHT($A48,1)="1",RIGHT($A48,1)="2"),E48,IF(I48=4,E48*2,E48*6))) -> 0.0774 | M48: =IF(F48="","",IF(OR(RIGHT($A48,1)="1",RIGHT($A48,1)="2"),F48,IF(J48=4,F48*2,F48*6))) | N48: =IF(G48="","",IF(OR(RIGHT($A48,1)="1",RIGHT($A48,1)="2"),G48,IF(J48=4,G48*2,G48*6))) | P48: =B48-100000 -> 150301 | Q48: =ROUND(D48*0.8,4) -> 0.0078 | R48: , | S48: =ROUND(E48*$Q$1,4) -> 0.0103 | V48: =IF(K48="","",IF(K48<1,ROUND(K48,4),CEILING(K48,5))) -> 0.0582 | W48: =IF(L48="","",IF(L48<1,ROUND(L48,4),CEILING(L48,5))) -> 0.0774 | X48: =IF(M48="","",IF(M48<1,ROUND(M48,4),CEILING(M48,5))) | Z48: =Q48&R48&S48&T48&U48 -> 0.0078,0.0103 | AA48: 0.0078,0.0103 | AB48: =_xlfn.TEXTJOIN(",",TRUE,V48,W48,X48) -> 0.0582,0.0774 | AF48: Lv.50普通武器-元素战士
A49: 103 | B49: 250401 | C49: 8 | D49: 0.0161 | H49: 8 | K49: =IF(D49="","",IF(OR(RIGHT($A49,1)="1",RIGHT($A49,1)="2"),D49,IF(H49=4,D49*2,D49*6))) -> 0.0966 | L49: =IF(E49="","",IF(OR(RIGHT($A49,1)="1",RIGHT($A49,1)="2"),E49,IF(I49=4,E49*2,E49*6))) | M49: =IF(F49="","",IF(OR(RIGHT($A49,1)="1",RIGHT($A49,1)="2"),F49,IF(J49=4,F49*2,F49*6))) | N49: =IF(G49="","",IF(OR(RIGHT($A49,1)="1",RIGHT($A49,1)="2"),G49,IF(J49=4,G49*2,G49*6))) | P49: =B49-100000 -> 150401 | Q49: =ROUND(D49*0.8,4) -> 0.0129 | R49: , | S49: =ROUND(E49*$Q$1,4) -> 0 | V49: =IF(K49="","",IF(K49<1,ROUND(K49,4),CEILING(K49,5))) -> 0.0966 | W49: =IF(L49="","",IF(L49<1,ROUND(L49,4),CEILING(L49,5))) | X49: =IF(M49="","",IF(M49<1,ROUND(M49,4),CEILING(M49,5))) | Z49: =Q49&R49&S49&T49&U49 -> 0.0129,0 | AA49: 0.0129 | AB49: =_xlfn.TEXTJOIN(",",TRUE,V49,W49,X49) -> 0.0966 | AF49: Lv.50普通武器-物理战士
A50: 103 | B50: 250501 | C50: 8,26 | D50: 0.0107 | E50: 0.0323 | H50: 8 | I50: 26 | K50: =IF(D50="","",IF(OR(RIGHT($A50,1)="1",RIGHT($A50,1)="2"),D50,IF(H50=4,D50*2,D50*6))) -> 0.0642 | L50: =IF(E50="","",IF(OR(RIGHT($A50,1)="1",RIGHT($A50,1)="2"),E50,IF(I50=4,E50*2,E50*6))) -> 0.1938 | M50: =IF(F50="","",IF(OR(RIGHT($A50,1)="1",RIGHT($A50,1)="2"),F50,IF(J50=4,F50*2,F50*6))) | N50: =IF(G50="","",IF(OR(RIGHT($A50,1)="1",RIGHT($A50,1)="2"),G50,IF(J50=4,G50*2,G50*6))) | P50: =B50-100000 -> 150501 | Q50: =ROUND(D50*0.8,4) -> 0.0086 | R50: , | S50: =ROUND(E50*$Q$1,4) -> 0.0258 | V50: =IF(K50="","",IF(K50<1,ROUND(K50,4),CEILING(K50,5))) -> 0.0642 | W50: =IF(L50="","",IF(L50<1,ROUND(L50,4),CEILING(L50,5))) -> 0.1938 | X50: =IF(M50="","",IF(M50<1,ROUND(M50,4),CEILING(M50,5))) | Z50: =Q50&R50&S50&T50&U50 -> 0.0086,0.0258 | AA50: 0.0086,0.0258 | AB50: =_xlfn.TEXTJOIN(",",TRUE,V50,W50,X50) -> 0.0642,0.1938 | AF50: Lv.50普通武器-元素刺客
A51: 103 | B51: 250601 | C51: 8,9 | D51: 0.0054 | E51: 0.036 | H51: 8 | I51: 9 | K51: =IF(D51="","",IF(OR(RIGHT($A51,1)="1",RIGHT($A51,1)="2"),D51,IF(H51=4,D51*2,D51*6))) -> 0.0324 | L51: =IF(E51="","",IF(OR(RIGHT($A51,1)="1",RIGHT($A51,1)="2"),E51,IF(I51=4,E51*2,E51*6))) -> 0.216 | M51: =IF(F51="","",IF(OR(RIGHT($A51,1)="1",RIGHT($A51,1)="2"),F51,IF(J51=4,F51*2,F51*6))) | N51: =IF(G51="","",IF(OR(RIGHT($A51,1)="1",RIGHT($A51,1)="2"),G51,IF(J51=4,G51*2,G51*6))) | P51: =B51-100000 -> 150601 | Q51: =ROUND(D51*0.8,4) -> 0.0043 | R51: , | S51: =ROUND(E51*$Q$1,4) -> 0.0288 | V51: =IF(K51="","",IF(K51<1,ROUND(K51,4),CEILING(K51,5))) -> 0.0324 | W51: =IF(L51="","",IF(L51<1,ROUND(L51,4),CEILING(L51,5))) -> 0.216 | X51: =IF(M51="","",IF(M51<1,ROUND(M51,4),CEILING(M51,5))) | Z51: =Q51&R51&S51&T51&U51 -> 0.0043,0.0288 | AA51: 0.0043,0.0288 | AB51: =_xlfn.TEXTJOIN(",",TRUE,V51,W51,X51) -> 0.0324,0.216 | AF51: Lv.50普通武器-敏暴刺客
A52: 103 | B52: 250701 | C52: 4,9 | D52: 0.0132 | E52: 0.018 | H52: 4 | I52: 9 | K52: =IF(D52="","",IF(OR(RIGHT($A52,1)="1",RIGHT($A52,1)="2"),D52,IF(H52=4,D52*2,D52*6))) -> 0.0264 | L52: =IF(E52="","",IF(OR(RIGHT($A52,1)="1",RIGHT($A52,1)="2"),E52,IF(I52=4,E52*2,E52*6))) -> 0.108 | M52: =IF(F52="","",IF(OR(RIGHT($A52,1)="1",RIGHT($A52,1)="2"),F52,IF(J52=4,F52*2,F52*6))) | N52: =IF(G52="","",IF(OR(RIGHT($A52,1)="1",RIGHT($A52,1)="2"),G52,IF(J52=4,G52*2,G52*6))) | P52: =B52-100000 -> 150701 | Q52: =ROUND(D52*0.8,4) -> 0.0106 | R52: , | S52: =ROUND(E52*$Q$1,4) -> 0.0144 | V52: =IF(K52="","",IF(K52<1,ROUND(K52,4),CEILING(K52,5))) -> 0.0264 | W52: =IF(L52="","",IF(L52<1,ROUND(L52,4),CEILING(L52,5))) -> 0.108 | X52: =IF(M52="","",IF(M52<1,ROUND(M52,4),CEILING(M52,5))) | Z52: =Q52&R52&S52&T52&U52 -> 0.0106,0.0144 | AA52: 0.0106,0.0144 | AB52: =_xlfn.TEXTJOIN(",",TRUE,V52,W52,X52) -> 0.0264,0.108 | AF52: Lv.50普通武器-闪避刺客
A53: 103 | B53: 250801 | C53: 5,9 | D53: 0.0063 | E53: 0.012 | H53: 5 | I53: 9 | K53: =IF(D53="","",IF(OR(RIGHT($A53,1)="1",RIGHT($A53,1)="2"),D53,IF(H53=4,D53*2,D53*6))) -> 0.0378 | L53: =IF(E53="","",IF(OR(RIGHT($A53,1)="1",RIGHT($A53,1)="2"),E53,IF(I53=4,E53*2,E53*6))) -> 0.072 | M53: =IF(F53="","",IF(OR(RIGHT($A53,1)="1",RIGHT($A53,1)="2"),F53,IF(J53=4,F53*2,F53*6))) | N53: =IF(G53="","",IF(OR(RIGHT($A53,1)="1",RIGHT($A53,1)="2"),G53,IF(J53=4,G53*2,G53*6))) | P53: =B53-100000 -> 150801 | Q53: =ROUND(D53*0.8,4) -> 0.005 | R53: , | S53: =ROUND(E53*$Q$1,4) -> 0.0096 | V53: =IF(K53="","",IF(K53<1,ROUND(K53,4),CEILING(K53,5))) -> 0.0378 | W53: =IF(L53="","",IF(L53<1,ROUND(L53,4),CEILING(L53,5))) -> 0.072 | X53: =IF(M53="","",IF(M53<1,ROUND(M53,4),CEILING(M53,5))) | Z53: =Q53&R53&S53&T53&U53 -> 0.005,0.0096 | AA53: 0.005,0.0096 | AB53: =_xlfn.TEXTJOIN(",",TRUE,V53,W53,X53) -> 0.0378,0.072 | AF53: Lv.50普通武器-元素辅助
A54: 103 | B54: 250901 | C54: 5,9,11 | D54: 0.0078 | E54: 0.015 | F54: 0.0017 | H54: 5 | I54: 9 | J54: 11 | K54: =IF(D54="","",IF(OR(RIGHT($A54,1)="1",RIGHT($A54,1)="2"),D54,IF(H54=4,D54*2,D54*6))) -> 0.0468 | L54: =IF(E54="","",IF(OR(RIGHT($A54,1)="1",RIGHT($A54,1)="2"),E54,IF(I54=4,E54*2,E54*6))) -> 0.09 | M54: =IF(F54="","",IF(OR(RIGHT($A54,1)="1",RIGHT($A54,1)="2"),F54,IF(J54=4,F54*2,F54*6))) -> 0.0102 | N54: =IF(G54="","",IF(OR(RIGHT($A54,1)="1",RIGHT($A54,1)="2"),G54,IF(J54=4,G54*2,G54*6))) | P54: =B54-100000 -> 150901 | Q54: =ROUND(D54*0.8,4) -> 0.0062 | R54: , | S54: =ROUND(E54*$Q$1,4) -> 0.012 | T54: , | U54: =ROUND(F54*$Q$1,4) -> 0.0014 | V54: =IF(K54="","",IF(K54<1,ROUND(K54,4),CEILING(K54,5))) -> 0.0468 | W54: =IF(L54="","",IF(L54<1,ROUND(L54,4),CEILING(L54,5))) -> 0.09 | X54: =IF(M54="","",IF(M54<1,ROUND(M54,4),CEILING(M54,5))) -> 0.0102 | Z54: =Q54&R54&S54&T54&U54 -> 0.0062,0.012,0.0014 | AA54: 0.0062,0.012,0.0014 | AB54: =_xlfn.TEXTJOIN(",",TRUE,V54,W54,X54) -> 0.0468,0.09,0.0102 | AF54: Lv.50普通武器-物理辅助
A55: 103 | B55: 260101 | C55: 8 | D55: 0.009 | H55: 8 | K55: =IF(D55="","",IF(OR(RIGHT($A55,1)="1",RIGHT($A55,1)="2"),D55,IF(H55=4,D55*2,D55*6))) -> 0.054 | L55: =IF(E55="","",IF(OR(RIGHT($A55,1)="1",RIGHT($A55,1)="2"),E55,IF(I55=4,E55*2,E55*6))) | M55: =IF(F55="","",IF(OR(RIGHT($A55,1)="1",RIGHT($A55,1)="2"),F55,IF(J55=4,F55*2,F55*6))) | N55: =IF(G55="","",IF(OR(RIGHT($A55,1)="1",RIGHT($A55,1)="2"),G55,IF(J55=4,G55*2,G55*6))) | P55: =B55-100000 -> 160101 | Q55: =ROUND(D55*0.8,4) -> 0.0072 | R55: , | S55: =ROUND(E55*$Q$1,4) -> 0 | T55: , | U55: =ROUND(F55*$Q$1,4) -> 0 | V55: =IF(K55="","",IF(K55<1,ROUND(K55,4),CEILING(K55,5))) -> 0.054 | W55: =IF(L55="","",IF(L55<1,ROUND(L55,4),CEILING(L55,5))) | X55: =IF(M55="","",IF(M55<1,ROUND(M55,4),CEILING(M55,5))) | Z55: =Q55&R55&S55&T55&U55 -> 0.0072,0,0 | AA55: 0.0072 | AB55: =_xlfn.TEXTJOIN(",",TRUE,V55,W55,X55) -> 0.054 | AF55: Lv.60普通武器-物理坦克
A56: 103 | B56: 260201 | C56: 8 | D56: 0.0179 | H56: 8 | K56: =IF(D56="","",IF(OR(RIGHT($A56,1)="1",RIGHT($A56,1)="2"),D56,IF(H56=4,D56*2,D56*6))) -> 0.1074 | L56: =IF(E56="","",IF(OR(RIGHT($A56,1)="1",RIGHT($A56,1)="2"),E56,IF(I56=4,E56*2,E56*6))) | M56: =IF(F56="","",IF(OR(RIGHT($A56,1)="1",RIGHT($A56,1)="2"),F56,IF(J56=4,F56*2,F56*6))) | N56: =IF(G56="","",IF(OR(RIGHT($A56,1)="1",RIGHT($A56,1)="2"),G56,IF(J56=4,G56*2,G56*6))) | P56: =B56-100000 -> 160201 | Q56: =ROUND(D56*0.8,4) -> 0.0143 | R56: , | S56: =ROUND(E56*$Q$1,4) -> 0 | T56: , | U56: =ROUND(F56*$Q$1,4) -> 0 | V56: =IF(K56="","",IF(K56<1,ROUND(K56,4),CEILING(K56,5))) -> 0.1074 | W56: =IF(L56="","",IF(L56<1,ROUND(L56,4),CEILING(L56,5))) | X56: =IF(M56="","",IF(M56<1,ROUND(M56,4),CEILING(M56,5))) | Z56: =Q56&R56&S56&T56&U56 -> 0.0143,0,0 | AA56: 0.0143 | AB56: =_xlfn.TEXTJOIN(",",TRUE,V56,W56,X56) -> 0.1074 | AF56: Lv.60普通武器-元素坦克
A57: 103 | B57: 260301 | C57: 8,26 | D57: 0.0161 | E57: 0.0215 | H57: 8 | I57: 26 | K57: =IF(D57="","",IF(OR(RIGHT($A57,1)="1",RIGHT($A57,1)="2"),D57,IF(H57=4,D57*2,D57*6))) -> 0.0966 | L57: =IF(E57="","",IF(OR(RIGHT($A57,1)="1",RIGHT($A57,1)="2"),E57,IF(I57=4,E57*2,E57*6))) -> 0.129 | M57: =IF(F57="","",IF(OR(RIGHT($A57,1)="1",RIGHT($A57,1)="2"),F57,IF(J57=4,F57*2,F57*6))) | N57: =IF(G57="","",IF(OR(RIGHT($A57,1)="1",RIGHT($A57,1)="2"),G57,IF(J57=4,G57*2,G57*6))) | P57: =B57-100000 -> 160301 | Q57: =ROUND(D57*0.8,4) -> 0.0129 | R57: , | S57: =ROUND(E57*$Q$1,4) -> 0.0172 | T57: , | U57: =ROUND(F57*$Q$1,4) -> 0 | V57: =IF(K57="","",IF(K57<1,ROUND(K57,4),CEILING(K57,5))) -> 0.0966 | W57: =IF(L57="","",IF(L57<1,ROUND(L57,4),CEILING(L57,5))) -> 0.129 | X57: =IF(M57="","",IF(M57<1,ROUND(M57,4),CEILING(M57,5))) | Z57: =Q57&R57&S57&T57&U57 -> 0.0129,0.0172,0 | AA57: 0.0129,0.0172 | AB57: =_xlfn.TEXTJOIN(",",TRUE,V57,W57,X57) -> 0.0966,0.129 | AF57: Lv.60普通武器-元素战士
A58: 103 | B58: 260401 | C58: 8 | D58: 0.0269 | H58: 8 | K58: =IF(D58="","",IF(OR(RIGHT($A58,1)="1",RIGHT($A58,1)="2"),D58,IF(H58=4,D58*2,D58*6))) -> 0.1614 | L58: =IF(E58="","",IF(OR(RIGHT($A58,1)="1",RIGHT($A58,1)="2"),E58,IF(I58=4,E58*2,E58*6))) | M58: =IF(F58="","",IF(OR(RIGHT($A58,1)="1",RIGHT($A58,1)="2"),F58,IF(J58=4,F58*2,F58*6))) | N58: =IF(G58="","",IF(OR(RIGHT($A58,1)="1",RIGHT($A58,1)="2"),G58,IF(J58=4,G58*2,G58*6))) | P58: =B58-100000 -> 160401 | Q58: =ROUND(D58*0.8,4) -> 0.0215 | R58: , | S58: =ROUND(E58*$Q$1,4) -> 0 | T58: , | U58: =ROUND(F58*$Q$1,4) -> 0 | V58: =IF(K58="","",IF(K58<1,ROUND(K58,4),CEILING(K58,5))) -> 0.1614 | W58: =IF(L58="","",IF(L58<1,ROUND(L58,4),CEILING(L58,5))) | X58: =IF(M58="","",IF(M58<1,ROUND(M58,4),CEILING(M58,5))) | Z58: =Q58&R58&S58&T58&U58 -> 0.0215,0,0 | AA58: 0.0215 | AB58: =_xlfn.TEXTJOIN(",",TRUE,V58,W58,X58) -> 0.1614 | AF58: Lv.60普通武器-物理战士
A59: 103 | B59: 260501 | C59: 8,26 | D59: 0.0179 | E59: 0.0537 | H59: 8 | I59: 26 | K59: =IF(D59="","",IF(OR(RIGHT($A59,1)="1",RIGHT($A59,1)="2"),D59,IF(H59=4,D59*2,D59*6))) -> 0.1074 | L59: =IF(E59="","",IF(OR(RIGHT($A59,1)="1",RIGHT($A59,1)="2"),E59,IF(I59=4,E59*2,E59*6))) -> 0.3222 | M59: =IF(F59="","",IF(OR(RIGHT($A59,1)="1",RIGHT($A59,1)="2"),F59,IF(J59=4,F59*2,F59*6))) | N59: =IF(G59="","",IF(OR(RIGHT($A59,1)="1",RIGHT($A59,1)="2"),G59,IF(J59=4,G59*2,G59*6))) | P59: =B59-100000 -> 160501 | Q59: =ROUND(D59*0.8,4) -> 0.0143 | R59: , | S59: =ROUND(E59*$Q$1,4) -> 0.043 | T59: , | U59: =ROUND(F59*$Q$1,4) -> 0 | V59: =IF(K59="","",IF(K59<1,ROUND(K59,4),CEILING(K59,5))) -> 0.1074 | W59: =IF(L59="","",IF(L59<1,ROUND(L59,4),CEILING(L59,5))) -> 0.3222 | X59: =IF(M59="","",IF(M59<1,ROUND(M59,4),CEILING(M59,5))) | Z59: =Q59&R59&S59&T59&U59 -> 0.0143,0.043,0 | AA59: 0.0143,0.043 | AB59: =_xlfn.TEXTJOIN(",",TRUE,V59,W59,X59) -> 0.1074,0.3222 | AF59: Lv.60普通武器-元素刺客
A60: 103 | B60: 260601 | C60: 8,9 | D60: 0.009 | E60: 0.06 | H60: 8 | I60: 9 | K60: =IF(D60="","",IF(OR(RIGHT($A60,1)="1",RIGHT($A60,1)="2"),D60,IF(H60=4,D60*2,D60*6))) -> 0.054 | L60: =IF(E60="","",IF(OR(RIGHT($A60,1)="1",RIGHT($A60,1)="2"),E60,IF(I60=4,E60*2,E60*6))) -> 0.36 | M60: =IF(F60="","",IF(OR(RIGHT($A60,1)="1",RIGHT($A60,1)="2"),F60,IF(J60=4,F60*2,F60*6))) | N60: =IF(G60="","",IF(OR(RIGHT($A60,1)="1",RIGHT($A60,1)="2"),G60,IF(J60=4,G60*2,G60*6))) | P60: =B60-100000 -> 160601 | Q60: =ROUND(D60*0.8,4) -> 0.0072 | R60: , | S60: =ROUND(E60*$Q$1,4) -> 0.048 | T60: , | U60: =ROUND(F60*$Q$1,4) -> 0 | V60: =IF(K60="","",IF(K60<1,ROUND(K60,4),CEILING(K60,5))) -> 0.054 | W60: =IF(L60="","",IF(L60<1,ROUND(L60,4),CEILING(L60,5))) -> 0.36 | X60: =IF(M60="","",IF(M60<1,ROUND(M60,4),CEILING(M60,5))) | Z60: =Q60&R60&S60&T60&U60 -> 0.0072,0.048,0 | AA60: 0.0072,0.048 | AB60: =_xlfn.TEXTJOIN(",",TRUE,V60,W60,X60) -> 0.054,0.36 | AF60: Lv.60普通武器-敏暴刺客
A61: 103 | B61: 260701 | C61: 4,9 | D61: 0.0219 | E61: 0.03 | H61: 4 | I61: 9 | K61: =IF(D61="","",IF(OR(RIGHT($A61,1)="1",RIGHT($A61,1)="2"),D61,IF(H61=4,D61*2,D61*6))) -> 0.0438 | L61: =IF(E61="","",IF(OR(RIGHT($A61,1)="1",RIGHT($A61,1)="2"),E61,IF(I61=4,E61*2,E61*6))) -> 0.18 | M61: =IF(F61="","",IF(OR(RIGHT($A61,1)="1",RIGHT($A61,1)="2"),F61,IF(J61=4,F61*2,F61*6))) | N61: =IF(G61="","",IF(OR(RIGHT($A61,1)="1",RIGHT($A61,1)="2"),G61,IF(J61=4,G61*2,G61*6))) | P61: =B61-100000 -> 160701 | Q61: =ROUND(D61*0.8,4) -> 0.0175 | R61: , | S61: =ROUND(E61*$Q$1,4) -> 0.024 | T61: , | U61: =ROUND(F61*$Q$1,4) -> 0 | V61: =IF(K61="","",IF(K61<1,ROUND(K61,4),CEILING(K61,5))) -> 0.0438 | W61: =IF(L61="","",IF(L61<1,ROUND(L61,4),CEILING(L61,5))) -> 0.18 | X61: =IF(M61="","",IF(M61<1,ROUND(M61,4),CEILING(M61,5))) | Z61: =Q61&R61&S61&T61&U61 -> 0.0175,0.024,0 | AA61: 0.0175,0.024 | AB61: =_xlfn.TEXTJOIN(",",TRUE,V61,W61,X61) -> 0.0438,0.18 | AF61: Lv.60普通武器-闪避刺客
A62: 103 | B62: 260801 | C62: 5,9 | D62: 0.0104 | E62: 0.02 | H62: 5 | I62: 9 | K62: =IF(D62="","",IF(OR(RIGHT($A62,1)="1",RIGHT($A62,1)="2"),D62,IF(H62=4,D62*2,D62*6))) -> 0.0624 | L62: =IF(E62="","",IF(OR(RIGHT($A62,1)="1",RIGHT($A62,1)="2"),E62,IF(I62=4,E62*2,E62*6))) -> 0.12 | M62: =IF(F62="","",IF(OR(RIGHT($A62,1)="1",RIGHT($A62,1)="2"),F62,IF(J62=4,F62*2,F62*6))) | N62: =IF(G62="","",IF(OR(RIGHT($A62,1)="1",RIGHT($A62,1)="2"),G62,IF(J62=4,G62*2,G62*6))) | P62: =B62-100000 -> 160801 | Q62: =ROUND(D62*0.8,4) -> 0.0083 | R62: , | S62: =ROUND(E62*$Q$1,4) -> 0.016 | T62: , | U62: =ROUND(F62*$Q$1,4) -> 0 | V62: =IF(K62="","",IF(K62<1,ROUND(K62,4),CEILING(K62,5))) -> 0.0624 | W62: =IF(L62="","",IF(L62<1,ROUND(L62,4),CEILING(L62,5))) -> 0.12 | X62: =IF(M62="","",IF(M62<1,ROUND(M62,4),CEILING(M62,5))) | Z62: =Q62&R62&S62&T62&U62 -> 0.0083,0.016,0 | AA62: 0.0083,0.016 | AB62: =_xlfn.TEXTJOIN(",",TRUE,V62,W62,X62) -> 0.0624,0.12 | AF62: Lv.60普通武器-元素辅助
A63: 103 | B63: 260901 | C63: 5,9,11 | D63: 0.0131 | E63: 0.025 | F63: 0.0028 | H63: 5 | I63: 9 | J63: 11 | K63: =IF(D63="","",IF(OR(RIGHT($A63,1)="1",RIGHT($A63,1)="2"),D63,IF(H63=4,D63*2,D63*6))) -> 0.0786 | L63: =IF(E63="","",IF(OR(RIGHT($A63,1)="1",RIGHT($A63,1)="2"),E63,IF(I63=4,E63*2,E63*6))) -> 0.15 | M63: =IF(F63="","",IF(OR(RIGHT($A63,1)="1",RIGHT($A63,1)="2"),F63,IF(J63=4,F63*2,F63*6))) -> 0.0168 | N63: =IF(G63="","",IF(OR(RIGHT($A63,1)="1",RIGHT($A63,1)="2"),G63,IF(J63=4,G63*2,G63*6))) | P63: =B63-100000 -> 160901 | Q63: =ROUND(D63*0.8,4) -> 0.0105 | R63: , | S63: =ROUND(E63*$Q$1,4) -> 0.02 | T63: , | U63: =ROUND(F63*$Q$1,4) -> 0.0022 | V63: =IF(K63="","",IF(K63<1,ROUND(K63,4),CEILING(K63,5))) -> 0.0786 | W63: =IF(L63="","",IF(L63<1,ROUND(L63,4),CEILING(L63,5))) -> 0.15 | X63: =IF(M63="","",IF(M63<1,ROUND(M63,4),CEILING(M63,5))) -> 0.0168 | Z63: =Q63&R63&S63&T63&U63 -> 0.0105,0.02,0.0022 | AA63: 0.0105,0.02,0.0022 | AB63: =_xlfn.TEXTJOIN(",",TRUE,V63,W63,X63) -> 0.0786,0.15,0.0168 | AF63: Lv.60普通武器-物理辅助
A64: 104 | B64: 250101 | C64: 8 | D64: 0.0102 | H64: 8 | K64: =IF(D64="","",IF(OR(RIGHT($A64,1)="1",RIGHT($A64,1)="2"),D64,IF(H64=4,D64*2,D64*6))) -> 0.0612 | L64: =IF(E64="","",IF(OR(RIGHT($A64,1)="1",RIGHT($A64,1)="2"),E64,IF(I64=4,E64*2,E64*6))) | M64: =IF(F64="","",IF(OR(RIGHT($A64,1)="1",RIGHT($A64,1)="2"),F64,IF(J64=4,F64*2,F64*6))) | N64: =IF(G64="","",IF(OR(RIGHT($A64,1)="1",RIGHT($A64,1)="2"),G64,IF(J64=4,G64*2,G64*6))) | P64: =B64-100000 -> 150101 | Q64: =ROUND(D64*0.8,4) -> 0.0082 | R64: , | S64: =ROUND(E64*$Q$1,4) -> 0 | T64: , | U64: =ROUND(F64*$Q$1,4) -> 0 | V64: =IF(K64="","",IF(K64<1,ROUND(K64,4),CEILING(K64,5))) -> 0.0612 | W64: =IF(L64="","",IF(L64<1,ROUND(L64,4),CEILING(L64,5))) | X64: =IF(M64="","",IF(M64<1,ROUND(M64,4),CEILING(M64,5))) | Z64: =Q64 -> 0.0082 | AA64: 0.0082 | AB64: =_xlfn.TEXTJOIN(",",TRUE,V64,W64,X64) -> 0.0612 | AF64: Lv.50普通武器-物理坦克
A65: 104 | B65: 250101 | C65: 4 | D65: 14.57 | H65: 4 | K65: =IF(D65="","",IF(OR(RIGHT($A65,1)="1",RIGHT($A65,1)="2"),D65,IF(H65=4,D65*2,D65*6))) -> 29.14 | L65: =IF(E65="","",IF(OR(RIGHT($A65,1)="1",RIGHT($A65,1)="2"),E65,IF(I65=4,E65*2,E65*6))) | M65: =IF(F65="","",IF(OR(RIGHT($A65,1)="1",RIGHT($A65,1)="2"),F65,IF(J65=4,F65*2,F65*6))) | N65: =IF(G65="","",IF(OR(RIGHT($A65,1)="1",RIGHT($A65,1)="2"),G65,IF(J65=4,G65*2,G65*6))) | P65: =B65-100000 -> 150101 | Q65: =ROUND(D65*0.8,4) -> 11.656 | R65: , | S65: =ROUND(E65*$Q$1,4) -> 0 | T65: , | U65: =ROUND(F65*$Q$1,4) -> 0 | V65: =IF(K65="","",IF(K65<1,ROUND(K65,4),CEILING(K65,5))) -> 30 | W65: =IF(L65="","",IF(L65<1,ROUND(L65,4),CEILING(L65,5))) | X65: =IF(M65="","",IF(M65<1,ROUND(M65,4),CEILING(M65,5))) | Z65: =Q65 -> 11.656 | AA65: 11.656 | AB65: =_xlfn.TEXTJOIN(",",TRUE,V65,W65,X65) -> 30
A66: 104 | B66: 250201 | C66: 8 | D66: 0.0205 | H66: 8 | K66: =IF(D66="","",IF(OR(RIGHT($A66,1)="1",RIGHT($A66,1)="2"),D66,IF(H66=4,D66*2,D66*6))) -> 0.123 | L66: =IF(E66="","",IF(OR(RIGHT($A66,1)="1",RIGHT($A66,1)="2"),E66,IF(I66=4,E66*2,E66*6))) | M66: =IF(F66="","",IF(OR(RIGHT($A66,1)="1",RIGHT($A66,1)="2"),F66,IF(J66=4,F66*2,F66*6))) | N66: =IF(G66="","",IF(OR(RIGHT($A66,1)="1",RIGHT($A66,1)="2"),G66,IF(J66=4,G66*2,G66*6))) | P66: =B66-100000 -> 150201 | Q66: =ROUND(D66*0.8,4) -> 0.0164 | R66: , | S66: =ROUND(E66*$Q$1,4) -> 0 | T66: , | U66: =ROUND(F66*$Q$1,4) -> 0 | V66: =IF(K66="","",IF(K66<1,ROUND(K66,4),CEILING(K66,5))) -> 0.123 | W66: =IF(L66="","",IF(L66<1,ROUND(L66,4),CEILING(L66,5))) | X66: =IF(M66="","",IF(M66<1,ROUND(M66,4),CEILING(M66,5))) | Z66: =Q66 -> 0.0164 | AA66: 0.0164 | AB66: =_xlfn.TEXTJOIN(",",TRUE,V66,W66,X66) -> 0.123 | AF66: Lv.50普通武器-元素坦克
A67: 104 | B67: 250201 | C67: 4 | D67: 14.57 | H67: 4 | K67: =IF(D67="","",IF(OR(RIGHT($A67,1)="1",RIGHT($A67,1)="2"),D67,IF(H67=4,D67*2,D67*6))) -> 29.14 | L67: =IF(E67="","",IF(OR(RIGHT($A67,1)="1",RIGHT($A67,1)="2"),E67,IF(I67=4,E67*2,E67*6))) | M67: =IF(F67="","",IF(OR(RIGHT($A67,1)="1",RIGHT($A67,1)="2"),F67,IF(J67=4,F67*2,F67*6))) | N67: =IF(G67="","",IF(OR(RIGHT($A67,1)="1",RIGHT($A67,1)="2"),G67,IF(J67=4,G67*2,G67*6))) | P67: =B67-100000 -> 150201 | Q67: =ROUND(D67*0.8,4) -> 11.656 | R67: , | S67: =ROUND(E67*$Q$1,4) -> 0 | T67: , | U67: =ROUND(F67*$Q$1,4) -> 0 | V67: =IF(K67="","",IF(K67<1,ROUND(K67,4),CEILING(K67,5))) -> 30 | W67: =IF(L67="","",IF(L67<1,ROUND(L67,4),CEILING(L67,5))) | X67: =IF(M67="","",IF(M67<1,ROUND(M67,4),CEILING(M67,5))) | Z67: =Q67 -> 11.656 | AA67: 11.656 | AB67: =_xlfn.TEXTJOIN(",",TRUE,V67,W67,X67) -> 30
A68: 104 | B68: 250301 | C68: 8 | D68: 0.0184 | H68: 8 | K68: =IF(D68="","",IF(OR(RIGHT($A68,1)="1",RIGHT($A68,1)="2"),D68,IF(H68=4,D68*2,D68*6))) -> 0.1104 | L68: =IF(E68="","",IF(OR(RIGHT($A68,1)="1",RIGHT($A68,1)="2"),E68,IF(I68=4,E68*2,E68*6))) | M68: =IF(F68="","",IF(OR(RIGHT($A68,1)="1",RIGHT($A68,1)="2"),F68,IF(J68=4,F68*2,F68*6))) | N68: =IF(G68="","",IF(OR(RIGHT($A68,1)="1",RIGHT($A68,1)="2"),G68,IF(J68=4,G68*2,G68*6))) | P68: =B68-100000 -> 150301 | Q68: =ROUND(D68*0.8,4) -> 0.0147 | R68: , | S68: =ROUND(E68*$Q$1,4) -> 0 | T68: , | U68: =ROUND(F68*$Q$1,4) -> 0 | V68: =IF(K68="","",IF(K68<1,ROUND(K68,4),CEILING(K68,5))) -> 0.1104 | W68: =IF(L68="","",IF(L68<1,ROUND(L68,4),CEILING(L68,5))) | X68: =IF(M68="","",IF(M68<1,ROUND(M68,4),CEILING(M68,5))) | Z68: =Q68 -> 0.0147 | AA68: 0.0147 | AB68: =_xlfn.TEXTJOIN(",",TRUE,V68,W68,X68) -> 0.1104 | AF68: Lv.50普通武器-元素战士
A69: 104 | B69: 250301 | C69: 4 | D69: 14.57 | H69: 4 | K69: =IF(D69="","",IF(OR(RIGHT($A69,1)="1",RIGHT($A69,1)="2"),D69,IF(H69=4,D69*2,D69*6))) -> 29.14 | L69: =IF(E69="","",IF(OR(RIGHT($A69,1)="1",RIGHT($A69,1)="2"),E69,IF(I69=4,E69*2,E69*6))) | M69: =IF(F69="","",IF(OR(RIGHT($A69,1)="1",RIGHT($A69,1)="2"),F69,IF(J69=4,F69*2,F69*6))) | N69: =IF(G69="","",IF(OR(RIGHT($A69,1)="1",RIGHT($A69,1)="2"),G69,IF(J69=4,G69*2,G69*6))) | P69: =B69-100000 -> 150301 | Q69: =ROUND(D69*0.8,4) -> 11.656 | R69: , | S69: =ROUND(E69*$Q$1,4) -> 0 | T69: , | U69: =ROUND(F69*$Q$1,4) -> 0 | V69: =IF(K69="","",IF(K69<1,ROUND(K69,4),CEILING(K69,5))) -> 30 | W69: =IF(L69="","",IF(L69<1,ROUND(L69,4),CEILING(L69,5))) | X69: =IF(M69="","",IF(M69<1,ROUND(M69,4),CEILING(M69,5))) | Z69: =Q69 -> 11.656 | AA69: 11.656 | AB69: =_xlfn.TEXTJOIN(",",TRUE,V69,W69,X69) -> 30
A70: 104 | B70: 250301 | C70: 26 | D70: 0.0246 | H70: 26 | K70: =IF(D70="","",IF(OR(RIGHT($A70,1)="1",RIGHT($A70,1)="2"),D70,IF(H70=4,D70*2,D70*6))) -> 0.1476 | L70: =IF(E70="","",IF(OR(RIGHT($A70,1)="1",RIGHT($A70,1)="2"),E70,IF(I70=4,E70*2,E70*6))) | M70: =IF(F70="","",IF(OR(RIGHT($A70,1)="1",RIGHT($A70,1)="2"),F70,IF(J70=4,F70*2,F70*6))) | N70: =IF(G70="","",IF(OR(RIGHT($A70,1)="1",RIGHT($A70,1)="2"),G70,IF(J70=4,G70*2,G70*6))) | P70: =B70-100000 -> 150301 | Q70: =ROUND(D70*0.8,4) -> 0.0197 | R70: , | S70: =ROUND(E70*$Q$1,4) -> 0 | T70: , | U70: =ROUND(F70*$Q$1,4) -> 0 | V70: =IF(K70="","",IF(K70<1,ROUND(K70,4),CEILING(K70,5))) -> 0.1476 | W70: =IF(L70="","",IF(L70<1,ROUND(L70,4),CEILING(L70,5))) | X70: =IF(M70="","",IF(M70<1,ROUND(M70,4),CEILING(M70,5))) | Z70: =Q70 -> 0.0197 | AA70: 0.0197 | AB70: =_xlfn.TEXTJOIN(",",TRUE,V70,W70,X70) -> 0.1476
A71: 104 | B71: 250401 | C71: 8 | D71: 0.0307 | H71: 8 | K71: =IF(D71="","",IF(OR(RIGHT($A71,1)="1",RIGHT($A71,1)="2"),D71,IF(H71=4,D71*2,D71*6))) -> 0.1842 | L71: =IF(E71="","",IF(OR(RIGHT($A71,1)="1",RIGHT($A71,1)="2"),E71,IF(I71=4,E71*2,E71*6))) | M71: =IF(F71="","",IF(OR(RIGHT($A71,1)="1",RIGHT($A71,1)="2"),F71,IF(J71=4,F71*2,F71*6))) | N71: =IF(G71="","",IF(OR(RIGHT($A71,1)="1",RIGHT($A71,1)="2"),G71,IF(J71=4,G71*2,G71*6))) | P71: =B71-100000 -> 150401 | Q71: =ROUND(D71*0.8,4) -> 0.0246 | R71: , | S71: =ROUND(E71*$Q$1,4) -> 0 | T71: , | U71: =ROUND(F71*$Q$1,4) -> 0 | V71: =IF(K71="","",IF(K71<1,ROUND(K71,4),CEILING(K71,5))) -> 0.1842 | W71: =IF(L71="","",IF(L71<1,ROUND(L71,4),CEILING(L71,5))) | X71: =IF(M71="","",IF(M71<1,ROUND(M71,4),CEILING(M71,5))) | Z71: =Q71 -> 0.0246 | AA71: 0.0246 | AB71: =_xlfn.TEXTJOIN(",",TRUE,V71,W71,X71) -> 0.1842 | AF71: Lv.50普通武器-物理战士
...

Sheet Sheet5
C1: 词条1 | E1: 词条2（百分比） | G1: 词条3 | J1: 词条4 | P1: 词条1 | R1: 词条2（百分比） | T1: 词条3 | W1: 词条4 | AB1: 词条3汇总 | AC1: 词条4汇总
A2: 120001 | B2: Lv.20普通武器 | C2: 攻击 | P2: 45 | AA2: =IF(N2="","",_xlfn.XLOOKUP(N2,Sheet6!$E:$E,Sheet6!$D:$D,"",0,1)) | AB2: =_xlfn.TEXTJOIN(",",TRUE,T2,U2,V2) | AC2: =_xlfn.TEXTJOIN(",",TRUE,X2,Y2,Z2,AA2)
A3: 120002 | B3: Lv.20普通衣服 | C3: 防御 | D3: 生命 | P3: 15 | Q3: 185 | AA3: =IF(N3="","",_xlfn.XLOOKUP(N3,Sheet6!$E:$E,Sheet6!$D:$D,"",0,1)) | AB3: =_xlfn.TEXTJOIN(",",TRUE,T3,U3,V3) | AC3: =_xlfn.TEXTJOIN(",",TRUE,X3,Y3,Z3,AA3)
A4: 120003 | B4: Lv.20普通戒指 | C4: 攻击 | D4: 防御 | P4: 23 | Q4: 7 | AA4: =IF(N4="","",_xlfn.XLOOKUP(N4,Sheet6!$E:$E,Sheet6!$D:$D,"",0,1)) | AB4: =_xlfn.TEXTJOIN(",",TRUE,T4,U4,V4) | AC4: =_xlfn.TEXTJOIN(",",TRUE,X4,Y4,Z4,AA4)
A5: 120004 | B5: Lv.20普通项链 | C5: 防御 | D5: 生命 | P5: 7 | Q5: 375 | AA5: =IF(N5="","",_xlfn.XLOOKUP(N5,Sheet6!$E:$E,Sheet6!$D:$D,"",0,1)) | AB5: =_xlfn.TEXTJOIN(",",TRUE,T5,U5,V5) | AC5: =_xlfn.TEXTJOIN(",",TRUE,X5,Y5,Z5,AA5)
A6: 220001 | B6: Lv.20英雄武器 | C6: 攻击 | P6: 45 | AA6: =IF(N6="","",_xlfn.XLOOKUP(N6,Sheet6!$E:$E,Sheet6!$D:$D,"",0,1)) | AB6: =_xlfn.TEXTJOIN(",",TRUE,T6,U6,V6) | AC6: =_xlfn.TEXTJOIN(",",TRUE,X6,Y6,Z6,AA6)
A7: 220002 | B7: Lv.20英雄衣服 | C7: 防御 | D7: 生命 | P7: 15 | Q7: 185 | AA7: =IF(N7="","",_xlfn.XLOOKUP(N7,Sheet6!$E:$E,Sheet6!$D:$D,"",0,1)) | AB7: =_xlfn.TEXTJOIN(",",TRUE,T7,U7,V7) | AC7: =_xlfn.TEXTJOIN(",",TRUE,X7,Y7,Z7,AA7)
A8: 220003 | B8: Lv.20英雄戒指 | C8: 攻击 | D8: 防御 | P8: 23 | Q8: 7 | AA8: =IF(N8="","",_xlfn.XLOOKUP(N8,Sheet6!$E:$E,Sheet6!$D:$D,"",0,1)) | AB8: =_xlfn.TEXTJOIN(",",TRUE,T8,U8,V8) | AC8: =_xlfn.TEXTJOIN(",",TRUE,X8,Y8,Z8,AA8)
A9: 220004 | B9: Lv.20英雄项链 | C9: 防御 | D9: 生命 | P9: 7 | Q9: 375 | AA9: =IF(N9="","",_xlfn.XLOOKUP(N9,Sheet6!$E:$E,Sheet6!$D:$D,"",0,1)) | AB9: =_xlfn.TEXTJOIN(",",TRUE,T9,U9,V9) | AC9: =_xlfn.TEXTJOIN(",",TRUE,X9,Y9,Z9,AA9)
A10: 130001 | B10: Lv.30普通武器 | C10: 攻击 | P10: 60 | AA10: =IF(N10="","",_xlfn.XLOOKUP(N10,Sheet6!$E:$E,Sheet6!$D:$D,"",0,1)) | AB10: =_xlfn.TEXTJOIN(",",TRUE,T10,U10,V10) | AC10: =_xlfn.TEXTJOIN(",",TRUE,X10,Y10,Z10,AA10)
A11: 130002 | B11: Lv.30普通衣服 | C11: 防御 | D11: 生命 | P11: 18 | Q11: 240 | AA11: =IF(N11="","",_xlfn.XLOOKUP(N11,Sheet6!$E:$E,Sheet6!$D:$D,"",0,1)) | AB11: =_xlfn.TEXTJOIN(",",TRUE,T11,U11,V11) | AC11: =_xlfn.TEXTJOIN(",",TRUE,X11,Y11,Z11,AA11)
A12: 130003 | B12: Lv.30普通戒指 | C12: 攻击 | D12: 防御 | P12: 30 | Q12: 9 | AA12: =IF(N12="","",_xlfn.XLOOKUP(N12,Sheet6!$E:$E,Sheet6!$D:$D,"",0,1)) | AB12: =_xlfn.TEXTJOIN(",",TRUE,T12,U12,V12) | AC12: =_xlfn.TEXTJOIN(",",TRUE,X12,Y12,Z12,AA12)
A13: 130004 | B13: Lv.30普通项链 | C13: 防御 | D13: 生命 | P13: 9 | Q13: 480 | AA13: =IF(N13="","",_xlfn.XLOOKUP(N13,Sheet6!$E:$E,Sheet6!$D:$D,"",0,1)) | AB13: =_xlfn.TEXTJOIN(",",TRUE,T13,U13,V13) | AC13: =_xlfn.TEXTJOIN(",",TRUE,X13,Y13,Z13,AA13)
A14: 230001 | B14: Lv.30英雄武器 | C14: 攻击 | P14: 60 | AA14: =IF(N14="","",_xlfn.XLOOKUP(N14,Sheet6!$E:$E,Sheet6!$D:$D,"",0,1)) | AB14: =_xlfn.TEXTJOIN(",",TRUE,T14,U14,V14) | AC14: =_xlfn.TEXTJOIN(",",TRUE,X14,Y14,Z14,AA14)
A15: 230002 | B15: Lv.30英雄衣服 | C15: 防御 | D15: 生命 | P15: 18 | Q15: 240 | AA15: =IF(N15="","",_xlfn.XLOOKUP(N15,Sheet6!$E:$E,Sheet6!$D:$D,"",0,1)) | AB15: =_xlfn.TEXTJOIN(",",TRUE,T15,U15,V15) | AC15: =_xlfn.TEXTJOIN(",",TRUE,X15,Y15,Z15,AA15)
A16: 230003 | B16: Lv.30英雄戒指 | C16: 攻击 | D16: 防御 | P16: 30 | Q16: 9 | AA16: =IF(N16="","",_xlfn.XLOOKUP(N16,Sheet6!$E:$E,Sheet6!$D:$D,"",0,1)) | AB16: =_xlfn.TEXTJOIN(",",TRUE,T16,U16,V16) | AC16: =_xlfn.TEXTJOIN(",",TRUE,X16,Y16,Z16,AA16)
A17: 230004 | B17: Lv.30英雄项链 | C17: 防御 | D17: 生命 | P17: 9 | Q17: 480 | AA17: =IF(N17="","",_xlfn.XLOOKUP(N17,Sheet6!$E:$E,Sheet6!$D:$D,"",0,1)) | AB17: =_xlfn.TEXTJOIN(",",TRUE,T17,U17,V17) | AC17: =_xlfn.TEXTJOIN(",",TRUE,X17,Y17,Z17,AA17)
A18: 140001 | B18: Lv.40普通武器-均衡 | C18: 攻击 | E18: 攻击 | P18: =P22*0.8 -> 76 | R18: 0.65 | AA18: =IF(N18="","",_xlfn.XLOOKUP(N18,Sheet6!$E:$E,Sheet6!$D:$D,"",0,1)) | AB18: =_xlfn.TEXTJOIN(",",TRUE,T18,U18,V18) | AC18: =_xlfn.TEXTJOIN(",",TRUE,X18,Y18,Z18,AA18)
A19: 140002 | B19: Lv.40普通衣服-均衡 | C19: 防御 | D19: 生命 | E19: 防御 | F19: 生命 | P19: =P23*0.8 -> 22.4 | Q19: =Q23*0.8 -> 298.4 | R19: 0.65 | S19: 0.65 | AA19: =IF(N19="","",_xlfn.XLOOKUP(N19,Sheet6!$E:$E,Sheet6!$D:$D,"",0,1)) | AB19: =_xlfn.TEXTJOIN(",",TRUE,T19,U19,V19) | AC19: =_xlfn.TEXTJOIN(",",TRUE,X19,Y19,Z19,AA19)
A20: 140003 | B20: Lv.40普通戒指-均衡 | C20: 攻击 | D20: 防御 | E20: 攻击 | F20: 防御 | P20: =P24*0.8 -> 36.8 | Q20: =Q24*0.8 -> 11.2 | R20: 0.65 | S20: 0.65 | AA20: =IF(N20="","",_xlfn.XLOOKUP(N20,Sheet6!$E:$E,Sheet6!$D:$D,"",0,1)) | AB20: =_xlfn.TEXTJOIN(",",TRUE,T20,U20,V20) | AC20: =_xlfn.TEXTJOIN(",",TRUE,X20,Y20,Z20,AA20)
A21: 140004 | B21: Lv.40普通项链-均衡 | C21: 防御 | D21: 生命 | E21: 防御 | F21: 生命 | P21: =P25*0.8 -> 11.2 | Q21: =Q25*0.8 -> 596.8 | R21: 0.65 | S21: 0.65 | AA21: =IF(N21="","",_xlfn.XLOOKUP(N21,Sheet6!$E:$E,Sheet6!$D:$D,"",0,1)) | AB21: =_xlfn.TEXTJOIN(",",TRUE,T21,U21,V21) | AC21: =_xlfn.TEXTJOIN(",",TRUE,X21,Y21,Z21,AA21)
A22: 240001 | B22: Lv.40英雄武器-均衡 | C22: 攻击 | E22: 攻击 | P22: 95 | R22: 0.65 | AA22: =IF(N22="","",_xlfn.XLOOKUP(N22,Sheet6!$E:$E,Sheet6!$D:$D,"",0,1)) | AB22: =_xlfn.TEXTJOIN(",",TRUE,T22,U22,V22) | AC22: =_xlfn.TEXTJOIN(",",TRUE,X22,Y22,Z22,AA22)
A23: 240002 | B23: Lv.40英雄衣服-均衡 | C23: 防御 | D23: 生命 | E23: 防御 | F23: 生命 | P23: 28 | Q23: 373 | R23: 0.65 | S23: 0.65 | AA23: =IF(N23="","",_xlfn.XLOOKUP(N23,Sheet6!$E:$E,Sheet6!$D:$D,"",0,1)) | AB23: =_xlfn.TEXTJOIN(",",TRUE,T23,U23,V23) | AC23: =_xlfn.TEXTJOIN(",",TRUE,X23,Y23,Z23,AA23)
A24: 240003 | B24: Lv.40英雄戒指-均衡 | C24: 攻击 | D24: 防御 | E24: 攻击 | F24: 防御 | P24: 46 | Q24: 14 | R24: 0.65 | S24: 0.65 | AA24: =IF(N24="","",_xlfn.XLOOKUP(N24,Sheet6!$E:$E,Sheet6!$D:$D,"",0,1)) | AB24: =_xlfn.TEXTJOIN(",",TRUE,T24,U24,V24) | AC24: =_xlfn.TEXTJOIN(",",TRUE,X24,Y24,Z24,AA24)
A25: 240004 | B25: Lv.40英雄项链-均衡 | C25: 防御 | D25: 生命 | E25: 防御 | F25: 生命 | P25: 14 | Q25: 746 | R25: 0.65 | S25: 0.65 | AA25: =IF(N25="","",_xlfn.XLOOKUP(N25,Sheet6!$E:$E,Sheet6!$D:$D,"",0,1)) | AB25: =_xlfn.TEXTJOIN(",",TRUE,T25,U25,V25) | AC25: =_xlfn.TEXTJOIN(",",TRUE,X25,Y25,Z25,AA25)
A26: 140101 | B26: Lv.40普通武器-输出 | C26: 攻击 | E26: 攻击 | P26: =P30*0.8 -> 92.8 | R26: 0.65 | AA26: =IF(N26="","",_xlfn.XLOOKUP(N26,Sheet6!$E:$E,Sheet6!$D:$D,"",0,1)) | AB26: =_xlfn.TEXTJOIN(",",TRUE,T26,U26,V26) | AC26: =_xlfn.TEXTJOIN(",",TRUE,X26,Y26,Z26,AA26)
A27: 140102 | B27: Lv.40普通衣服-输出 | C27: 防御 | D27: 生命 | E27: 防御 | F27: 生命 | P27: =P31*0.8 -> 17.6 | Q27: =Q31*0.8 -> 238.4 | R27: 0.65 | S27: 0.65 | AA27: =IF(N27="","",_xlfn.XLOOKUP(N27,Sheet6!$E:$E,Sheet6!$D:$D,"",0,1)) | AB27: =_xlfn.TEXTJOIN(",",TRUE,T27,U27,V27) | AC27: =_xlfn.TEXTJOIN(",",TRUE,X27,Y27,Z27,AA27)
A28: 140103 | B28: Lv.40普通戒指-输出 | C28: 攻击 | D28: 防御 | E28: 攻击 | F28: 防御 | P28: =P32*0.8 -> 46.4 | Q28: =Q32*0.8 -> 8.8 | R28: 0.65 | S28: 0.65 | AA28: =IF(N28="","",_xlfn.XLOOKUP(N28,Sheet6!$E:$E,Sheet6!$D:$D,"",0,1)) | AB28: =_xlfn.TEXTJOIN(",",TRUE,T28,U28,V28) | AC28: =_xlfn.TEXTJOIN(",",TRUE,X28,Y28,Z28,AA28)
A29: 140104 | B29: Lv.40普通项链-输出 | C29: 防御 | D29: 生命 | E29: 防御 | F29: 生命 | P29: =P33*0.8 -> 8.8 | Q29: =Q33*0.8 -> 477.6 | R29: 0.65 | S29: 0.65 | AA29: =IF(N29="","",_xlfn.XLOOKUP(N29,Sheet6!$E:$E,Sheet6!$D:$D,"",0,1)) | AB29: =_xlfn.TEXTJOIN(",",TRUE,T29,U29,V29) | AC29: =_xlfn.TEXTJOIN(",",TRUE,X29,Y29,Z29,AA29)
A30: 240101 | B30: Lv.40普通武器-输出 | C30: 攻击 | E30: 攻击 | P30: 116 | R30: 0.65 | AA30: =IF(N30="","",_xlfn.XLOOKUP(N30,Sheet6!$E:$E,Sheet6!$D:$D,"",0,1)) | AB30: =_xlfn.TEXTJOIN(",",TRUE,T30,U30,V30) | AC30: =_xlfn.TEXTJOIN(",",TRUE,X30,Y30,Z30,AA30)
A31: 240102 | B31: Lv.40英雄衣服-输出 | C31: 防御 | D31: 生命 | E31: 防御 | F31: 生命 | P31: 22 | Q31: 298 | R31: 0.65 | S31: 0.65 | AA31: =IF(N31="","",_xlfn.XLOOKUP(N31,Sheet6!$E:$E,Sheet6!$D:$D,"",0,1)) | AB31: =_xlfn.TEXTJOIN(",",TRUE,T31,U31,V31) | AC31: =_xlfn.TEXTJOIN(",",TRUE,X31,Y31,Z31,AA31)
A32: 240103 | B32: Lv.40英雄戒指-输出 | C32: 攻击 | D32: 防御 | E32: 攻击 | F32: 防御 | P32: 58 | Q32: 11 | R32: 0.65 | S32: 0.65 | AA32: =IF(N32="","",_xlfn.XLOOKUP(N32,Sheet6!$E:$E,Sheet6!$D:$D,"",0,1)) | AB32: =_xlfn.TEXTJOIN(",",TRUE,T32,U32,V32) | AC32: =_xlfn.TEXTJOIN(",",TRUE,X32,Y32,Z32,AA32)
A33: 240104 | B33: Lv.40英雄项链-输出 | C33: 防御 | D33: 生命 | E33: 防御 | F33: 生命 | P33: 11 | Q33: 597 | R33: 0.65 | S33: 0.65 | AA33: =IF(N33="","",_xlfn.XLOOKUP(N33,Sheet6!$E:$E,Sheet6!$D:$D,"",0,1)) | AB33: =_xlfn.TEXTJOIN(",",TRUE,T33,U33,V33) | AC33: =_xlfn.TEXTJOIN(",",TRUE,X33,Y33,Z33,AA33)
A34: 140201 | B34: Lv.40普通武器-生存 | C34: 攻击 | E34: 攻击 | P34: =P38*0.8 -> 59.2 | R34: 0.65 | AA34: =IF(N34="","",_xlfn.XLOOKUP(N34,Sheet6!$E:$E,Sheet6!$D:$D,"",0,1)) | AB34: =_xlfn.TEXTJOIN(",",TRUE,T34,U34,V34) | AC34: =_xlfn.TEXTJOIN(",",TRUE,X34,Y34,Z34,AA34)
A35: 140202 | B35: Lv.40普通衣服-生存 | C35: 防御 | D35: 生命 | E35: 防御 | F35: 生命 | P35: =P39*0.8 -> 28 | Q35: =Q39*0.8 -> 372.8 | R35: 0.65 | S35: 0.65 | AA35: =IF(N35="","",_xlfn.XLOOKUP(N35,Sheet6!$E:$E,Sheet6!$D:$D,"",0,1)) | AB35: =_xlfn.TEXTJOIN(",",TRUE,T35,U35,V35) | AC35: =_xlfn.TEXTJOIN(",",TRUE,X35,Y35,Z35,AA35)
A36: 140203 | B36: Lv.40普通戒指-生存 | C36: 攻击 | D36: 防御 | E36: 攻击 | F36: 防御 | P36: =P40*0.8 -> 29.6 | Q36: =Q40*0.8 -> 13.6 | R36: 0.65 | S36: 0.65 | AA36: =IF(N36="","",_xlfn.XLOOKUP(N36,Sheet6!$E:$E,Sheet6!$D:$D,"",0,1)) | AB36: =_xlfn.TEXTJOIN(",",TRUE,T36,U36,V36) | AC36: =_xlfn.TEXTJOIN(",",TRUE,X36,Y36,Z36,AA36)
A37: 140204 | B37: Lv.40普通项链-生存 | C37: 防御 | D37: 生命 | E37: 防御 | F37: 生命 | P37: =P41*0.8 -> 13.6 | Q37: =Q41*0.8 -> 746.4 | R37: 0.65 | S37: 0.65 | AA37: =IF(N37="","",_xlfn.XLOOKUP(N37,Sheet6!$E:$E,Sheet6!$D:$D,"",0,1)) | AB37: =_xlfn.TEXTJOIN(",",TRUE,T37,U37,V37) | AC37: =_xlfn.TEXTJOIN(",",TRUE,X37,Y37,Z37,AA37)
A38: 240201 | B38: Lv.40英雄武器-生存 | C38: 攻击 | E38: 攻击 | P38: 74 | R38: 0.65 | AA38: =IF(N38="","",_xlfn.XLOOKUP(N38,Sheet6!$E:$E,Sheet6!$D:$D,"",0,1)) | AB38: =_xlfn.TEXTJOIN(",",TRUE,T38,U38,V38) | AC38: =_xlfn.TEXTJOIN(",",TRUE,X38,Y38,Z38,AA38)
A39: 240202 | B39: Lv.40英雄衣服-生存 | C39: 防御 | D39: 生命 | E39: 防御 | F39: 生命 | P39: 35 | Q39: 466 | R39: 0.65 | S39: 0.65 | AA39: =IF(N39="","",_xlfn.XLOOKUP(N39,Sheet6!$E:$E,Sheet6!$D:$D,"",0,1)) | AB39: =_xlfn.TEXTJOIN(",",TRUE,T39,U39,V39) | AC39: =_xlfn.TEXTJOIN(",",TRUE,X39,Y39,Z39,AA39)
A40: 240203 | B40: Lv.40英雄戒指-生存 | C40: 攻击 | D40: 防御 | E40: 攻击 | F40: 防御 | P40: 37 | Q40: 17 | R40: 0.65 | S40: 0.65 | AA40: =IF(N40="","",_xlfn.XLOOKUP(N40,Sheet6!$E:$E,Sheet6!$D:$D,"",0,1)) | AB40: =_xlfn.TEXTJOIN(",",TRUE,T40,U40,V40) | AC40: =_xlfn.TEXTJOIN(",",TRUE,X40,Y40,Z40,AA40)
...

Sheet Sheet6
D5: 1 | E5: 攻击
D6: 2 | E6: 生命
D7: 3 | E7: 防御
D8: 4 | E8: 速度
D9: 5 | E9: 暴击
D10: 6 | E10: 韧性
D11: 7 | E11: 闪避
D12: 8 | E12: 命中
D13: 9 | E13: 暴伤
D14: 10 | E14: 格挡
D15: 11 | E15: 破击
D30: 26 | E30: 属伤
D39: 35 | E39: 属抗

Sheet Sheet7
C1: 103 | D1: 150101 | E1: 8 | J1: 0.0967 | P1: 100 | Q1: Lv.50英雄低速武器-物理坦克 | U1: =IF(J1="","",IF(J1=23,"",ROUND(J1*4/6,4))) -> 0.0645 | V1: =IF(K1="","",IF(K1=23,"",ROUND(K1*4/6,4))) | W1: =IF(L1="","",IF(L1=23,"",ROUND(L1*4/6,4))) | Y1: =IF(E1="","",IF(E1=35,INT(U1*3385),IF(E1=26,INT(U1*3385),U1))) -> 0.0645 | Z1: =IF(F1="","",IF(F1=35,INT(V1*3385),IF(F1=26,INT(V1*3385),V1))) | AA1: =IF(G1="","",IF(G1=35,INT(W1*3385),IF(G1=26,INT(W1*3385),W1))) | AB1: =IF(H1="","",IF(H1=35,X1*3385,IF(H1=26,X1*3385,X1))) | AE1: =IF(M1="","",IF(M1=23,"",ROUND(M1*4/6,4))) | AF1: =_xlfn.TEXTJOIN(",",TRUE,Y1,Z1,AA1,AB1) -> 0.0645
C2: 203 | D2: 150102 | E2: 6 | J2: 0.1693 | P2: 100 | Q2: Lv.50英雄低速衣服-物理坦克 | U2: =IF(J2="","",IF(J2=23,"",ROUND(J2*4/6,4))) -> 0.1129 | V2: =IF(K2="","",IF(K2=23,"",ROUND(K2*4/6,4))) | W2: =IF(L2="","",IF(L2=23,"",ROUND(L2*4/6,4))) | Y2: =IF(E2="","",IF(E2=35,INT(U2*3385),IF(E2=26,INT(U2*3385),U2))) -> 0.1129 | Z2: =IF(F2="","",IF(F2=35,INT(V2*3385),IF(F2=26,INT(V2*3385),V2))) | AA2: =IF(G2="","",IF(G2=35,INT(W2*3385),IF(G2=26,INT(W2*3385),W2))) | AB2: =IF(H2="","",IF(H2=35,X2*3385,IF(H2=26,X2*3385,X2))) | AE2: =IF(M2="","",IF(M2=23,"",ROUND(M2*4/6,4))) | AF2: =_xlfn.TEXTJOIN(",",TRUE,Y2,Z2,AA2,AB2) -> 0.1129
C3: 303 | D3: 150103 | E3: 7 | J3: 0.0967 | P3: 100 | Q3: Lv.50英雄低速戒指-物理坦克 | U3: =IF(J3="","",IF(J3=23,"",ROUND(J3*4/6,4))) -> 0.0645 | V3: =IF(K3="","",IF(K3=23,"",ROUND(K3*4/6,4))) | W3: =IF(L3="","",IF(L3=23,"",ROUND(L3*4/6,4))) | Y3: =IF(E3="","",IF(E3=35,INT(U3*3385),IF(E3=26,INT(U3*3385),U3))) -> 0.0645 | Z3: =IF(F3="","",IF(F3=35,INT(V3*3385),IF(F3=26,INT(V3*3385),V3))) | AA3: =IF(G3="","",IF(G3=35,INT(W3*3385),IF(G3=26,INT(W3*3385),W3))) | AB3: =IF(H3="","",IF(H3=35,X3*3385,IF(H3=26,X3*3385,X3))) | AE3: =IF(M3="","",IF(M3=23,"",ROUND(M3*4/6,4))) | AF3: =_xlfn.TEXTJOIN(",",TRUE,Y3,Z3,AA3,AB3) -> 0.0645
C4: 403 | D4: 150104 | E4: 10 | J4: 0.1838 | P4: 100 | Q4: Lv.50英雄低速项链-物理坦克 | U4: =IF(J4="","",IF(J4=23,"",ROUND(J4*4/6,4))) -> 0.1225 | V4: =IF(K4="","",IF(K4=23,"",ROUND(K4*4/6,4))) | W4: =IF(L4="","",IF(L4=23,"",ROUND(L4*4/6,4))) | Y4: =IF(E4="","",IF(E4=35,INT(U4*3385),IF(E4=26,INT(U4*3385),U4))) -> 0.1225 | Z4: =IF(F4="","",IF(F4=35,INT(V4*3385),IF(F4=26,INT(V4*3385),V4))) | AA4: =IF(G4="","",IF(G4=35,INT(W4*3385),IF(G4=26,INT(W4*3385),W4))) | AB4: =IF(H4="","",IF(H4=35,X4*3385,IF(H4=26,X4*3385,X4))) | AE4: =IF(M4="","",IF(M4=23,"",ROUND(M4*4/6,4))) | AF4: =_xlfn.TEXTJOIN(",",TRUE,Y4,Z4,AA4,AB4) -> 0.1225
C5: 103 | D5: 150201 | E5: 8 | J5: 0.0967 | P5: 100 | Q5: Lv.50英雄低速武器-元素坦克 | U5: =IF(J5="","",IF(J5=23,"",ROUND(J5*4/6,4))) -> 0.0645 | V5: =IF(K5="","",IF(K5=23,"",ROUND(K5*4/6,4))) | W5: =IF(L5="","",IF(L5=23,"",ROUND(L5*4/6,4))) | Y5: =IF(E5="","",IF(E5=35,INT(U5*3385),IF(E5=26,INT(U5*3385),U5))) -> 0.0645 | Z5: =IF(F5="","",IF(F5=35,INT(V5*3385),IF(F5=26,INT(V5*3385),V5))) | AA5: =IF(G5="","",IF(G5=35,INT(W5*3385),IF(G5=26,INT(W5*3385),W5))) | AB5: =IF(H5="","",IF(H5=35,X5*3385,IF(H5=26,X5*3385,X5))) | AE5: =IF(M5="","",IF(M5=23,"",ROUND(M5*4/6,4))) | AF5: =_xlfn.TEXTJOIN(",",TRUE,Y5,Z5,AA5,AB5) -> 0.0645
C6: 203 | D6: 150202 | E6: 6 | F6: 35 | J6: 0.0846 | K6: 0.1451 | P6: 100 | Q6: Lv.50英雄低速衣服-元素坦克 | U6: =IF(J6="","",IF(J6=23,"",ROUND(J6*4/6,4))) -> 0.0564 | V6: =IF(K6="","",IF(K6=23,"",ROUND(K6*4/6,4))) -> 0.0967 | W6: =IF(L6="","",IF(L6=23,"",ROUND(L6*4/6,4))) | Y6: =IF(E6="","",IF(E6=35,INT(U6*3385),IF(E6=26,INT(U6*3385),U6))) -> 0.0564 | Z6: =IF(F6="","",IF(F6=35,INT(V6*3385),IF(F6=26,INT(V6*3385),V6))) -> 327 | AA6: =IF(G6="","",IF(G6=35,INT(W6*3385),IF(G6=26,INT(W6*3385),W6))) | AB6: =IF(H6="","",IF(H6=35,X6*3385,IF(H6=26,X6*3385,X6))) | AE6: =IF(M6="","",IF(M6=23,"",ROUND(M6*4/6,4))) | AF6: =_xlfn.TEXTJOIN(",",TRUE,Y6,Z6,AA6,AB6) -> 0.0564,327
C7: 303 | D7: 150203 | E7: 7 | J7: 0.0967 | P7: 100 | Q7: Lv.50英雄低速戒指-元素坦克 | U7: =IF(J7="","",IF(J7=23,"",ROUND(J7*4/6,4))) -> 0.0645 | V7: =IF(K7="","",IF(K7=23,"",ROUND(K7*4/6,4))) | W7: =IF(L7="","",IF(L7=23,"",ROUND(L7*4/6,4))) | Y7: =IF(E7="","",IF(E7=35,INT(U7*3385),IF(E7=26,INT(U7*3385),U7))) -> 0.0645 | Z7: =IF(F7="","",IF(F7=35,INT(V7*3385),IF(F7=26,INT(V7*3385),V7))) | AA7: =IF(G7="","",IF(G7=35,INT(W7*3385),IF(G7=26,INT(W7*3385),W7))) | AB7: =IF(H7="","",IF(H7=35,X7*3385,IF(H7=26,X7*3385,X7))) | AE7: =IF(M7="","",IF(M7=23,"",ROUND(M7*4/6,4))) | AF7: =_xlfn.TEXTJOIN(",",TRUE,Y7,Z7,AA7,AB7) -> 0.0645
C8: 403 | D8: 150204 | E8: 10 | F8: 35 | J8: 0.0919 | K8: 0.1451 | P8: 100 | Q8: Lv.50英雄低速项链-元素坦克 | U8: =IF(J8="","",IF(J8=23,"",ROUND(J8*4/6,4))) -> 0.0613 | V8: =IF(K8="","",IF(K8=23,"",ROUND(K8*4/6,4))) -> 0.0967 | W8: =IF(L8="","",IF(L8=23,"",ROUND(L8*4/6,4))) | Y8: =IF(E8="","",IF(E8=35,INT(U8*3385),IF(E8=26,INT(U8*3385),U8))) -> 0.0613 | Z8: =IF(F8="","",IF(F8=35,INT(V8*3385),IF(F8=26,INT(V8*3385),V8))) -> 327 | AA8: =IF(G8="","",IF(G8=35,INT(W8*3385),IF(G8=26,INT(W8*3385),W8))) | AB8: =IF(H8="","",IF(H8=35,X8*3385,IF(H8=26,X8*3385,X8))) | AE8: =IF(M8="","",IF(M8=23,"",ROUND(M8*4/6,4))) | AF8: =_xlfn.TEXTJOIN(",",TRUE,Y8,Z8,AA8,AB8) -> 0.0613,327
C9: 103 | D9: 150301 | E9: 8 | F9: 26 | J9: 0.1354 | K9: 0.1451 | P9: 100 | Q9: Lv.50英雄低速武器-元素战士 | U9: =IF(J9="","",IF(J9=23,"",ROUND(J9*4/6,4))) -> 0.0903 | V9: =IF(K9="","",IF(K9=23,"",ROUND(K9*4/6,4))) -> 0.0967 | W9: =IF(L9="","",IF(L9=23,"",ROUND(L9*4/6,4))) | Y9: =IF(E9="","",IF(E9=35,INT(U9*3385),IF(E9=26,INT(U9*3385),U9))) -> 0.0903 | Z9: =IF(F9="","",IF(F9=35,INT(V9*3385),IF(F9=26,INT(V9*3385),V9))) -> 327 | AA9: =IF(G9="","",IF(G9=35,INT(W9*3385),IF(G9=26,INT(W9*3385),W9))) | AB9: =IF(H9="","",IF(H9=35,X9*3385,IF(H9=26,X9*3385,X9))) | AE9: =IF(M9="","",IF(M9=23,"",ROUND(M9*4/6,4))) | AF9: =_xlfn.TEXTJOIN(",",TRUE,Y9,Z9,AA9,AB9) -> 0.0903,327
C10: 203 | D10: 150302 | E10: 6 | J10: 0.0846 | P10: 100 | Q10: Lv.50英雄低速衣服-元素战士 | U10: =IF(J10="","",IF(J10=23,"",ROUND(J10*4/6,4))) -> 0.0564 | V10: =IF(K10="","",IF(K10=23,"",ROUND(K10*4/6,4))) | W10: =IF(L10="","",IF(L10=23,"",ROUND(L10*4/6,4))) | Y10: =IF(E10="","",IF(E10=35,INT(U10*3385),IF(E10=26,INT(U10*3385),U10))) -> 0.0564 | Z10: =IF(F10="","",IF(F10=35,INT(V10*3385),IF(F10=26,INT(V10*3385),V10))) | AA10: =IF(G10="","",IF(G10=35,INT(W10*3385),IF(G10=26,INT(W10*3385),W10))) | AB10: =IF(H10="","",IF(H10=35,X10*3385,IF(H10=26,X10*3385,X10))) | AE10: =IF(M10="","",IF(M10=23,"",ROUND(M10*4/6,4))) | AF10: =_xlfn.TEXTJOIN(",",TRUE,Y10,Z10,AA10,AB10) -> 0.0564
C11: 303 | D11: 150303 | E11: 11 | J11: 0.0551 | P11: 100 | Q11: Lv.50英雄低速戒指-元素战士 | U11: =IF(J11="","",IF(J11=23,"",ROUND(J11*4/6,4))) -> 0.0367 | V11: =IF(K11="","",IF(K11=23,"",ROUND(K11*4/6,4))) | W11: =IF(L11="","",IF(L11=23,"",ROUND(L11*4/6,4))) | Y11: =IF(E11="","",IF(E11=35,INT(U11*3385),IF(E11=26,INT(U11*3385),U11))) -> 0.0367 | Z11: =IF(F11="","",IF(F11=35,INT(V11*3385),IF(F11=26,INT(V11*3385),V11))) | AA11: =IF(G11="","",IF(G11=35,INT(W11*3385),IF(G11=26,INT(W11*3385),W11))) | AB11: =IF(H11="","",IF(H11=35,X11*3385,IF(H11=26,X11*3385,X11))) | AE11: =IF(M11="","",IF(M11=23,"",ROUND(M11*4/6,4))) | AF11: =_xlfn.TEXTJOIN(",",TRUE,Y11,Z11,AA11,AB11) -> 0.0367
C12: 403 | D12: 150304 | E12: 5 | F12: 26 | J12: 0.0846 | K12: 0.1451 | P12: 100 | Q12: Lv.50英雄低速项链-元素战士 | U12: =IF(J12="","",IF(J12=23,"",ROUND(J12*4/6,4))) -> 0.0564 | V12: =IF(K12="","",IF(K12=23,"",ROUND(K12*4/6,4))) -> 0.0967 | W12: =IF(L12="","",IF(L12=23,"",ROUND(L12*4/6,4))) | Y12: =IF(E12="","",IF(E12=35,INT(U12*3385),IF(E12=26,INT(U12*3385),U12))) -> 0.0564 | Z12: =IF(F12="","",IF(F12=35,INT(V12*3385),IF(F12=26,INT(V12*3385),V12))) -> 327 | AA12: =IF(G12="","",IF(G12=35,INT(W12*3385),IF(G12=26,INT(W12*3385),W12))) | AB12: =IF(H12="","",IF(H12=35,X12*3385,IF(H12=26,X12*3385,X12))) | AE12: =IF(M12="","",IF(M12=23,"",ROUND(M12*4/6,4))) | AF12: =_xlfn.TEXTJOIN(",",TRUE,Y12,Z12,AA12,AB12) -> 0.0564,327
C13: 103 | D13: 150401 | E13: 8 | J13: 0.1934 | P13: 100 | Q13: Lv.50英雄低速武器-物理战士 | U13: =IF(J13="","",IF(J13=23,"",ROUND(J13*4/6,4))) -> 0.1289 | V13: =IF(K13="","",IF(K13=23,"",ROUND(K13*4/6,4))) | W13: =IF(L13="","",IF(L13=23,"",ROUND(L13*4/6,4))) | Y13: =IF(E13="","",IF(E13=35,INT(U13*3385),IF(E13=26,INT(U13*3385),U13))) -> 0.1289 | Z13: =IF(F13="","",IF(F13=35,INT(V13*3385),IF(F13=26,INT(V13*3385),V13))) | AA13: =IF(G13="","",IF(G13=35,INT(W13*3385),IF(G13=26,INT(W13*3385),W13))) | AB13: =IF(H13="","",IF(H13=35,X13*3385,IF(H13=26,X13*3385,X13))) | AE13: =IF(M13="","",IF(M13=23,"",ROUND(M13*4/6,4))) | AF13: =_xlfn.TEXTJOIN(",",TRUE,Y13,Z13,AA13,AB13) -> 0.1289
C14: 203 | D14: 150402 | E14: 6 | J14: 0.0846 | P14: 100 | Q14: Lv.50英雄低速衣服-物理战士 | U14: =IF(J14="","",IF(J14=23,"",ROUND(J14*4/6,4))) -> 0.0564 | V14: =IF(K14="","",IF(K14=23,"",ROUND(K14*4/6,4))) | W14: =IF(L14="","",IF(L14=23,"",ROUND(L14*4/6,4))) | Y14: =IF(E14="","",IF(E14=35,INT(U14*3385),IF(E14=26,INT(U14*3385),U14))) -> 0.0564 | Z14: =IF(F14="","",IF(F14=35,INT(V14*3385),IF(F14=26,INT(V14*3385),V14))) | AA14: =IF(G14="","",IF(G14=35,INT(W14*3385),IF(G14=26,INT(W14*3385),W14))) | AB14: =IF(H14="","",IF(H14=35,X14*3385,IF(H14=26,X14*3385,X14))) | AE14: =IF(M14="","",IF(M14=23,"",ROUND(M14*4/6,4))) | AF14: =_xlfn.TEXTJOIN(",",TRUE,Y14,Z14,AA14,AB14) -> 0.0564
C15: 303 | D15: 150403 | E15: 11 | J15: 0.1838 | P15: 100 | Q15: Lv.50英雄低速戒指-物理战士 | U15: =IF(J15="","",IF(J15=23,"",ROUND(J15*4/6,4))) -> 0.1225 | V15: =IF(K15="","",IF(K15=23,"",ROUND(K15*4/6,4))) | W15: =IF(L15="","",IF(L15=23,"",ROUND(L15*4/6,4))) | Y15: =IF(E15="","",IF(E15=35,INT(U15*3385),IF(E15=26,INT(U15*3385),U15))) -> 0.1225 | Z15: =IF(F15="","",IF(F15=35,INT(V15*3385),IF(F15=26,INT(V15*3385),V15))) | AA15: =IF(G15="","",IF(G15=35,INT(W15*3385),IF(G15=26,INT(W15*3385),W15))) | AB15: =IF(H15="","",IF(H15=35,X15*3385,IF(H15=26,X15*3385,X15))) | AE15: =IF(M15="","",IF(M15=23,"",ROUND(M15*4/6,4))) | AF15: =_xlfn.TEXTJOIN(",",TRUE,Y15,Z15,AA15,AB15) -> 0.1225
C16: 403 | D16: 150404 | E16: 5 | J16: 0.0846 | P16: 100 | Q16: Lv.50英雄低速项链-物理战士 | U16: =IF(J16="","",IF(J16=23,"",ROUND(J16*4/6,4))) -> 0.0564 | V16: =IF(K16="","",IF(K16=23,"",ROUND(K16*4/6,4))) | W16: =IF(L16="","",IF(L16=23,"",ROUND(L16*4/6,4))) | Y16: =IF(E16="","",IF(E16=35,INT(U16*3385),IF(E16=26,INT(U16*3385),U16))) -> 0.0564 | Z16: =IF(F16="","",IF(F16=35,INT(V16*3385),IF(F16=26,INT(V16*3385),V16))) | AA16: =IF(G16="","",IF(G16=35,INT(W16*3385),IF(G16=26,INT(W16*3385),W16))) | AB16: =IF(H16="","",IF(H16=35,X16*3385,IF(H16=26,X16*3385,X16))) | AE16: =IF(M16="","",IF(M16=23,"",ROUND(M16*4/6,4))) | AF16: =_xlfn.TEXTJOIN(",",TRUE,Y16,Z16,AA16,AB16) -> 0.0564
C17: 103 | D17: 150501 | E17: 8 | F17: 26 | J17: 0.0967 | K17: 0.2901 | P17: 100 | Q17: Lv.50英雄低速武器-元素刺客 | U17: =IF(J17="","",IF(J17=23,"",ROUND(J17*4/6,4))) -> 0.0645 | V17: =IF(K17="","",IF(K17=23,"",ROUND(K17*4/6,4))) -> 0.1934 | W17: =IF(L17="","",IF(L17=23,"",ROUND(L17*4/6,4))) | Y17: =IF(E17="","",IF(E17=35,INT(U17*3385),IF(E17=26,INT(U17*3385),U17))) -> 0.0645 | Z17: =IF(F17="","",IF(F17=35,INT(V17*3385),IF(F17=26,INT(V17*3385),V17))) -> 654 | AA17: =IF(G17="","",IF(G17=35,INT(W17*3385),IF(G17=26,INT(W17*3385),W17))) | AB17: =IF(H17="","",IF(H17=35,X17*3385,IF(H17=26,X17*3385,X17))) | AE17: =IF(M17="","",IF(M17=23,"",ROUND(M17*4/6,4))) | AF17: =_xlfn.TEXTJOIN(",",TRUE,Y17,Z17,AA17,AB17) -> 0.0645,654
C18: 203 | D18: 150502 | E18: 11 | J18: 0.0551 | P18: 100 | Q18: Lv.50英雄低速衣服-元素刺客 | U18: =IF(J18="","",IF(J18=23,"",ROUND(J18*4/6,4))) -> 0.0367 | V18: =IF(K18="","",IF(K18=23,"",ROUND(K18*4/6,4))) | W18: =IF(L18="","",IF(L18=23,"",ROUND(L18*4/6,4))) | Y18: =IF(E18="","",IF(E18=35,INT(U18*3385),IF(E18=26,INT(U18*3385),U18))) -> 0.0367 | Z18: =IF(F18="","",IF(F18=35,INT(V18*3385),IF(F18=26,INT(V18*3385),V18))) | AA18: =IF(G18="","",IF(G18=35,INT(W18*3385),IF(G18=26,INT(W18*3385),W18))) | AB18: =IF(H18="","",IF(H18=35,X18*3385,IF(H18=26,X18*3385,X18))) | AE18: =IF(M18="","",IF(M18=23,"",ROUND(M18*4/6,4))) | AF18: =_xlfn.TEXTJOIN(",",TRUE,Y18,Z18,AA18,AB18) -> 0.0367
C19: 303 | D19: 150503 | E19: 5 | F19: 9 | J19: 0.0846 | K19: 0.266 | P19: 100 | Q19: Lv.50英雄低速戒指-元素刺客 | U19: =IF(J19="","",IF(J19=23,"",ROUND(J19*4/6,4))) -> 0.0564 | V19: =IF(K19="","",IF(K19=23,"",ROUND(K19*4/6,4))) -> 0.1773 | W19: =IF(L19="","",IF(L19=23,"",ROUND(L19*4/6,4))) | Y19: =IF(E19="","",IF(E19=35,INT(U19*3385),IF(E19=26,INT(U19*3385),U19))) -> 0.0564 | Z19: =IF(F19="","",IF(F19=35,INT(V19*3385),IF(F19=26,INT(V19*3385),V19))) -> 0.1773 | AA19: =IF(G19="","",IF(G19=35,INT(W19*3385),IF(G19=26,INT(W19*3385),W19))) | AB19: =IF(H19="","",IF(H19=35,X19*3385,IF(H19=26,X19*3385,X19))) | AE19: =IF(M19="","",IF(M19=23,"",ROUND(M19*4/6,4))) | AF19: =_xlfn.TEXTJOIN(",",TRUE,Y19,Z19,AA19,AB19) -> 0.0564,0.1773
