Workbook

Sheet Sheet1
A1: 7 | B1: 1 | C1: 9999 | D1: 31
A2: 礼包Id | B2: 礼包名称 | C2: 开服后持续小时数 | D2: 奖励 | E2: 价格 | F2: 真实价格 | G2: 消费类型 | H2: 标签类型 | I2: 刷新类型 | J2: 限购类型 | K2: 限购次数 | L2: 折扣 | M2: 图标下标 | N2: 计费点Id | O2: 开始日期（yyyy-MM-dd HH:mm:ss） | P2: 结束日期（yyyy-MM-dd HH:mm:ss） | Q2: 页类型（0限购，1限时） | R2: 是否重置 | S2: 是否隐藏 | T2: 菜单类型 | U2: 售卖服务器类型 | V2: 新服持续天数 | W2: 排序 | X2: 所属标签 | Y2: 自选礼包活动中可选道具池 | Z2: 自选可以选几个 | AA2: 防盖表经典怀旧判断 | AB2: EmptyKey-AB2
A3: giftId | D3: reward | F3: realPrice | W3: sort | Y3: commonItem | Z3: commonNum
A4: int | D4: string | F4: int | W4: int | Y4: string | Z4: int | AA4: int
A5: none | D5: none | F5: none | W5: none | Y5: none | Z5: none | AA5: none
A6: giftId | B6: giftName | C6: duringHour | D6: reward | E6: price | F6: realPrice | G6: costType | H6: labelType | I6: refreshType | J6: limitType | K6: limitNum | L6: discount | M6: iconIndex | N6: paymentId | O6: startDate | P6: endDate | Q6: giftPageType | R6: isResetable | S6: isHide | T6: menuLabel | U6: isNewServer | V6: newServerDuringDay | X6: titlefrom | Y6: commonItem | Z6: commonNum | AA6: dictServerType
A7: 680001 | B7: 超值经验宝箱 | C7: -1 | D7: 1001,216001,10;1001,215007,5;1001,225002,5;1001,452201,10 | E7: 68 | F7: 68 | G7: 0 | H7: 0 | I7: 1 | J7: 1 | K7: 1 | L7: 100 | M7: 0 | O7: 2020-08-10 0:00:00 | P7: 2020-08-29 0:00:00 | Q7: 0 | R7: 1 | T7: 2 | U7: 0 | V7: 0 | X7: 0 | AA7: 1
A8: 680002 | B8: 超值突破宝箱 | C8: -1 | D8: 1001,511303,1 | E8: 68 | F8: 68 | G8: 0 | H8: 0 | I8: 2 | J8: 1 | K8: 1 | L8: 100 | M8: 0 | O8: 2020-08-10 0:00:01 | P8: 2020-08-29 0:00:01 | Q8: 0 | R8: 1 | T8: 2 | U8: 0 | V8: 0 | X8: 0 | AA8: 1
A9: 680003 | B9: 超值贡献宝箱 | C9: -1 | D9: 1001,511304,5 | E9: 68 | F9: 68 | G9: 0 | H9: 0 | I9: 2 | J9: 1 | K9: 3 | L9: 100 | M9: 0 | O9: 2020-08-10 0:00:02 | P9: 2020-08-29 0:00:02 | Q9: 0 | R9: 1 | T9: 4 | U9: 0 | V9: 0 | X9: 0 | AA9: 1
A10: 1280001 | B10: 超值训练宝箱 | C10: -1 | D10: 1001,211021,15;1001,212021,30;1001,213021,45;1001,214021,60;1001,215021,75 | E10: 128 | F10: 128 | G10: 0 | H10: 0 | I10: 2 | J10: 1 | K10: 3 | L10: 100 | M10: 1 | O10: 2020-08-10 0:00:03 | P10: 2020-08-29 0:00:03 | Q10: 0 | R10: 1 | T10: 2 | U10: 0 | V10: 0 | X10: 0 | AA10: 1
A11: 1280002 | B11: 超值重铸宝箱 | C11: -1 | D11: 1001,216002,40;1,0,200;5,0,200000 | E11: 128 | F11: 128 | G11: 0 | H11: 0 | I11: 2 | J11: 1 | K11: 3 | L11: 100 | M11: 1 | O11: 2020-08-10 0:00:04 | P11: 2020-08-29 0:00:04 | Q11: 0 | R11: 1 | T11: 3 | U11: 0 | V11: 0 | X11: 0 | AA11: 1
A12: 1280003 | B12: 优质经验宝箱 | C12: -1 | D12: 1001,216001,10;1001,452201,30;3,0,3888 | E12: 128 | F12: 128 | G12: 0 | H12: 0 | I12: 0 | J12: 1 | K12: 2 | L12: 100 | M12: 1 | O12: 2020-08-10 0:00:05 | P12: 2020-08-29 0:00:05 | Q12: 0 | R12: 1 | T12: 2 | U12: 0 | V12: 0 | X12: 0 | AA12: 1
A13: 150 | B13: 家园桥梁图纸 | C13: -1 | D13: 1001,511306,1 | E13: 128 | F13: 128 | G13: 0 | H13: 0 | I13: 0 | J13: 1 | K13: 1 | L13: 100 | M13: 1 | N13: 3006,com.Aligames.hhw.yz128 | O13: 2020-08-10 0:00:06 | P13: 2020-08-29 0:00:06 | Q13: 0 | R13: 1 | T13: 2 | U13: 0 | V13: 0 | X13: 0 | AA13: 1
A14: 3280001 | B14: 豪华附魂宝箱 | C14: -1 | D14: 1001,720001,120;1001,215005,30;3,0,1000 | E14: 328 | F14: 328 | G14: 0 | H14: 0 | I14: 2 | J14: 1 | K14: 3 | L14: 100 | M14: 3 | O14: 2020-08-10 0:00:07 | P14: 2020-08-29 0:00:07 | Q14: 0 | R14: 1 | T14: 2 | U14: 0 | V14: 0 | X14: 0 | AA14: 1
A15: 3280002 | B15: 豪华精炼宝箱 | C15: -1 | D15: 1001,214003,200;1001,214014,20;1001,215002,50 | E15: 328 | F15: 328 | G15: 0 | H15: 0 | I15: 2 | J15: 1 | K15: 3 | L15: 100 | M15: 3 | O15: 2020-08-10 0:00:08 | P15: 2020-08-29 0:00:08 | Q15: 0 | R15: 1 | T15: 3 | U15: 0 | V15: 0 | X15: 0 | AA15: 1
A16: 3280003 | B16: 豪华战魂宝箱 | C16: -1 | D16: 1001,215005,60;1001,216001,20;1,0,1000 | E16: 328 | F16: 328 | G16: 0 | H16: 0 | I16: 0 | J16: 1 | K16: 1 | L16: 100 | M16: 3 | O16: 2020-08-10 0:00:09 | P16: 2020-08-29 0:00:09 | Q16: 0 | R16: 1 | T16: 2 | U16: 0 | V16: 0 | X16: 0 | AA16: 1
A17: 6480001 | B17: 豪华宝石宝箱 | C17: -1 | D17: 1001,511169,10;1001,215004,8;3,0,2000 | E17: 648 | F17: 648 | G17: 0 | H17: 0 | I17: 2 | J17: 1 | K17: 1 | L17: 100 | M17: 2 | O17: 2020-08-10 0:00:10 | P17: 2020-08-29 0:00:10 | Q17: 0 | R17: 1 | T17: 2 | U17: 0 | V17: 0 | X17: 0 | AA17: 1
A18: 6480002 | B18: 豪华培养宝箱 | C18: -1 | D18: 1001,215011,35;1001,215005,20;1001,214003,20;1,0,2000 | E18: 648 | F18: 648 | G18: 0 | H18: 2 | I18: 2 | J18: 1 | K18: 2 | L18: 100 | M18: 2 | O18: 2020-08-10 0:00:11 | P18: 2020-08-29 0:00:11 | Q18: 0 | R18: 1 | T18: 2 | U18: 0 | V18: 0 | X18: 0 | AA18: 1
A19: 6480003 | B19: 豪华重铸宝箱 | C19: -1 | D19: 1001,216002,260;1001,214003,10;1001,214014,5 | E19: 648 | F19: 648 | G19: 0 | H19: 0 | I19: 2 | J19: 1 | K19: 2 | L19: 100 | M19: 2 | O19: 2020-08-10 0:00:12 | P19: 2020-08-29 0:00:12 | Q19: 0 | R19: 1 | T19: 3 | U19: 0 | V19: 0 | X19: 0 | AA19: 1
A20: 6480004 | B20: 豪华招募宝箱 | C20: -1 | D20: 1001,215011,60;1001,216001,10;1,0,1000 | E20: 648 | F20: 648 | G20: 0 | H20: 0 | I20: 0 | J20: 1 | K20: 1 | L20: 100 | M20: 2 | O20: 2020-08-10 0:00:13 | P20: 2020-08-29 0:00:13 | Q20: 0 | R20: 1 | T20: 3 | U20: 0 | V20: 0 | X20: 0 | AA20: 1
A21: 9990001 | B21: 金币资源礼包 | C21: -1 | D21: 4,0,500000;1001,225001,5;3,0,200 | E21: 1000 | F21: 1000 | G21: 1 | H21: 0 | I21: 3 | J21: 1 | K21: 5 | L21: 100 | M21: 9 | O21: 2020-08-10 0:00:14 | P21: 2020-08-29 0:00:14 | Q21: 0 | R21: 1 | T21: 4 | U21: 0 | V21: 0 | X21: 0 | AA21: 1
A22: 9990002 | B22: 经验资源礼包 | C22: -1 | D22: 1001,215001,50;1001,225002,5;3,0,200 | E22: 1000 | F22: 1000 | G22: 1 | H22: 0 | I22: 3 | J22: 1 | K22: 5 | L22: 100 | M22: 16 | O22: 2020-08-10 0:00:15 | P22: 2020-08-29 0:00:15 | Q22: 0 | R22: 1 | T22: 4 | U22: 0 | V22: 0 | X22: 0 | AA22: 1
A23: 16010001 | B23: 巨鲸号角 | C23: -1 | D23: 1001,511313,1 | E23: 68 | F23: 68 | G23: 0 | H23: 0 | I23: 0 | J23: 1 | K23: 1 | L23: 100 | M23: 0 | N23: 3003,com.Aligames.hhw.yz68 | O23: 2020-08-10 0:00:00 | P23: 2020-08-29 0:00:00 | Q23: 0 | R23: 0 | T23: 1 | U23: 0 | V23: 0 | X23: 0 | AA23: 1
A24: 16010002 | B24: 樱花祭神树 | C24: -1 | D24: 1001,16010002,1 | E24: 328 | F24: 328 | G24: 0 | H24: 0 | I24: 0 | J24: 1 | K24: 1 | L24: 100 | M24: 0 | N24: 3009,com.Aligames.hhw.yz328 | O24: 2020-08-10 0:00:00 | P24: 2020-08-29 0:00:00 | Q24: 0 | R24: 0 | T24: 1 | U24: 0 | V24: 0 | X24: 0 | AA24: 1
A25: 16010003 | B25: 樱花祭五重塔 | C25: -1 | D25: 1001,16010003,1 | E25: 128 | F25: 128 | G25: 0 | H25: 0 | I25: 0 | J25: 1 | K25: 1 | L25: 100 | M25: 0 | N25: 3006,com.Aligames.hhw.yz128 | O25: 2020-08-10 0:00:00 | P25: 2020-08-29 0:00:00 | Q25: 0 | R25: 0 | T25: 1 | U25: 0 | V25: 0 | X25: 0 | AA25: 1
A26: 16010004 | B26: 樱花装扮礼包 | C26: -1 | D26: 1001,16010004,1;1001,16010005,1;1001,16010006,1;1001,16010007,1;1001,16010008,1;1001,16010009,1 | E26: 648 | F26: 648 | G26: 0 | H26: 0 | I26: 0 | J26: 1 | K26: 1 | L26: 100 | M26: 0 | N26: 3010,com.Aligames.hhw.yz648 | O26: 2020-08-10 0:00:00 | P26: 2020-08-29 0:00:00 | Q26: 0 | R26: 0 | T26: 1 | U26: 0 | V26: 0 | X26: 0 | AA26: 1
A27: 20916001 | B27: 周年庆特惠礼包 | C27: -1 | D27: 1001,215011,1;1001,215005,1;5,0,50000 | E27: 6 | F27: 6 | G27: 0 | H27: 0 | I27: 1 | J27: 1 | K27: 1 | L27: 100 | M27: 0 | O27: 2020-09-16 0:00:00 | P27: 2020-09-23 19:05:59 | Q27: 1 | R27: 0 | T27: 1 | U27: 0 | V27: 0 | X27: 0 | AA27: 1
A28: 20916002 | B28: 周年庆超值礼包 | C28: -1 | D28: 1001,215011,30;1001,215005,60;1001,720001,60;1001,511170,2;3,0,2000 | E28: 648 | F28: 648 | G28: 0 | H28: 0 | I28: 0 | J28: 1 | K28: 1 | L28: 100 | M28: 2 | O28: 2020-09-16 0:00:00 | P28: 2020-09-23 19:05:59 | Q28: 1 | R28: 0 | T28: 1 | U28: 0 | V28: 0 | X28: 0 | AA28: 1
A29: 20923001 | B29: 周年庆特惠礼包 | C29: -1 | D29: 1001,215011,1;1001,215005,1;5,0,50000 | E29: 6 | F29: 6 | G29: 0 | H29: 0 | I29: 1 | J29: 1 | K29: 1 | L29: 100 | M29: 0 | O29: 2020-09-23 19:06:00 | P29: 2020-09-30 19:06:00 | Q29: 1 | R29: 0 | T29: 1 | U29: 0 | V29: 0 | X29: 0 | AA29: 1
A30: 20923002 | B30: 周年庆超值礼包 | C30: -1 | D30: 1001,215011,30;1001,215005,60;1001,720001,60;1001,511170,2;3,0,2000 | E30: 648 | F30: 648 | G30: 0 | H30: 0 | I30: 0 | J30: 1 | K30: 1 | L30: 100 | M30: 2 | O30: 2020-09-23 19:06:00 | P30: 2020-09-30 19:06:00 | Q30: 1 | R30: 0 | T30: 1 | U30: 0 | V30: 0 | X30: 0 | AA30: 1
A31: 20929001 | B31: 周年庆特惠礼包 | C31: -1 | D31: 1001,215005,10;5,0,100000;1001,452201,5 | E31: 30 | F31: 30 | G31: 0 | H31: 0 | I31: 0 | J31: 1 | K31: 3 | L31: 100 | M31: 0 | O31: 2020-09-29 00:00:00 | P31: 2020-10-07 23:59:59 | Q31: 1 | R31: 0 | T31: 1 | U31: 0 | V31: 0 | X31: 0 | AA31: 1
A32: 20929002 | B32: 周年庆超值礼包 | C32: -1 | D32: 1001,216001,30;1001,225002,10;1001,452201,20 | E32: 128 | F32: 128 | G32: 0 | H32: 0 | I32: 0 | J32: 1 | K32: 3 | L32: 100 | M32: 2 | O32: 2020-09-29 00:00:00 | P32: 2020-10-07 23:59:59 | Q32: 1 | R32: 0 | T32: 1 | U32: 0 | V32: 0 | X32: 0 | AA32: 1
A33: 20929003 | B33: 周年庆豪华礼包 | C33: -1 | D33: 1001,215005,150;1001,720001,30;3,0,2000;1001,452201,20 | E33: 648 | F33: 648 | G33: 0 | H33: 0 | I33: 0 | J33: 1 | K33: 1 | L33: 100 | M33: 3 | O33: 2020-09-29 00:00:00 | P33: 2020-10-07 23:59:59 | Q33: 1 | R33: 0 | T33: 1 | U33: 0 | V33: 0 | X33: 0 | AA33: 1
A34: 20929004 | B34: 周年庆特惠礼包 | C34: -1 | D34: 1001,215005,10;5,0,100000;1001,452201,5 | E34: 30 | F34: 30 | G34: 0 | H34: 0 | I34: 0 | J34: 1 | K34: 3 | L34: 100 | M34: 0 | O34: 2020-10-08 00:00:00 | P34: 2020-10-14 23:59:59 | Q34: 1 | R34: 0 | T34: 1 | U34: 0 | V34: 0 | X34: 0 | AA34: 1
A35: 20929005 | B35: 周年庆超值礼包 | C35: -1 | D35: 1001,216001,30;1001,225002,10;1001,452201,20 | E35: 128 | F35: 128 | G35: 0 | H35: 0 | I35: 0 | J35: 1 | K35: 3 | L35: 100 | M35: 2 | O35: 2020-10-08 00:00:00 | P35: 2020-10-14 23:59:59 | Q35: 1 | R35: 0 | T35: 1 | U35: 0 | V35: 0 | X35: 0 | AA35: 1
A36: 20929006 | B36: 周年庆豪华礼包 | C36: -1 | D36: 1001,215005,150;1001,720001,30;3,0,2000;1001,452201,20 | E36: 648 | F36: 648 | G36: 0 | H36: 0 | I36: 0 | J36: 1 | K36: 1 | L36: 100 | M36: 3 | O36: 2020-10-08 00:00:00 | P36: 2020-10-14 23:59:59 | Q36: 1 | R36: 0 | T36: 1 | U36: 0 | V36: 0 | X36: 0 | AA36: 1
A37: 20102001 | B37: 超值培养礼包 | C37: -1 | D37: 1001,215011,1;1001,215005,1;5,0,50000 | E37: 6 | F37: 6 | G37: 0 | H37: 0 | I37: 1 | J37: 1 | K37: 1 | L37: 100 | M37: 0 | O37: 2020-10-20 00:00:00 | P37: 2020-10-28 23:59:59 | Q37: 1 | R37: 0 | T37: 1 | U37: 0 | V37: 0 | X37: 0 | AA37: 1
A38: 20102002 | B38: 超值经验礼包 | C38: -1 | D38: 1001,216001,30;1001,225002,10;1001,452201,20 | E38: 128 | F38: 128 | G38: 0 | H38: 0 | I38: 0 | J38: 1 | K38: 3 | L38: 100 | M38: 2 | O38: 2020-10-20 00:00:00 | P38: 2020-10-28 23:59:59 | Q38: 1 | R38: 0 | T38: 1 | U38: 0 | V38: 0 | X38: 0 | AA38: 1
... A50: 20111803 | B50: 豪华养成礼包 | C50: -1 | D50: 1001,215005,150;1001,720001,30;3,0,2000;1001,452201,20 | E50: 648 | F50: 648 | G50: 0 | H50: 0 | I50: 0 | J50: 1 | K50: 1 | L50: 100 | M50: 3 | O50: 2020-11-18 00:00:00 | P50: 2020-11-25 23:59:59 | Q50: 1 | R50: 0 | T50: 1 | U50: 0 | V50: 0 | X50: 0 | AA50: 1
A51: 20112501 | B51: 超值培养礼包 | C51: -1 | D51: 1001,215011,1;1001,215005,1;5,0,50000 | E51: 6 | F51: 6 | G51: 0 | H51: 0 | I51: 1 | J51: 1 | K51: 1 | L51: 100 | M51: 0 | N51: 1003,com.Aligames.hhw.3 | O51: 2020-11-25 00:00:00 | P51: 2020-12-02 23:59:59 | Q51: 1 | R51: 0 | T51: 1 | U51: 0 | V51: 0 | X51: 0 | AA51: 1
...

Sheet Sheet2
K4: 玩家 | L4: 角色 | M4: 战斗 | N4: 冒险 | O4: 商业 | P4: 竞技 | Q4: 社交
K5: 战队等级 | L5: 卡牌数量 | M5: 战斗场次 | N5: 副本通关章节数 | P5: 竞技场排名 | Q5: 玩家好友数量
B6: 成就类型 | E6: 条件类型 | F6: 描述 | K6: 累计登陆天数 | N6: 血战到达层数 | P6: 天梯积分 | Q6: 公会等级
B7: 1 | C7: 玩家 | E7: 1 | F7: 等级 | N7: 神秘海域探索值
B8: 2 | C8: 角色 | E8: 2 | F8: 亲密度等级
B9: 3 | C9: 战斗 | E9: 3 | F9: 突破等级 | H9: 生活技能等级
B10: 4 | C10: 冒险 | E10: 4 | F10: 星级
B11: 5 | C11: 商业
B12: 6 | C12: 竞技
B13: 7 | C13: 社交
A22: 138 | B22: 138 | C22: 31 | D22: 5 | F22: 累计在交易市场完成5次交易
A23: 139 | B23: 139 | C23: 31 | D23: 10 | F23: 累计在交易市场完成10次交易
A24: 140 | B24: 140 | C24: 31 | D24: 20 | F24: 累计在交易市场完成20次交易
A25: 141 | B25: 141 | C25: 31 | D25: 30 | F25: 累计在交易市场完成30次交易
A26: 142 | B26: 142 | C26: 31 | D26: 50 | F26: 累计在交易市场完成50次交易

Sheet Sheet3
B2: 礼包Id | C2: 礼包名称 | D2: 奖励 | E2: 价格 | F2: 真实价格 | G2: 消费类型 | H2: 标签类型 | I2: 刷新类型 | J2: 限购类型 | K2: 限购次数 | L2: 计费点Id | M2: 开始日期（yyyy-MM-dd HH:mm:ss） | N2: 结束日期（yyyy-MM-dd HH:mm:ss） | O2: 排序 | P2: 自选礼包活动中可选道具池 | Q2: 自选可以选几个
B3: giftId | D3: reward | F3: realPrice | O3: sort | P3: commonItem | Q3: commonNum
B4: int | D4: string | F4: int | O4: int | P4: string | Q4: int
B5: none | D5: none | F5: none | O5: none | P5: none | Q5: none
B6: giftId | C6: giftName | D6: reward | E6: price | F6: realPrice | G6: costType | H6: labelType | I6: refreshType | J6: limitType | K6: limitNum | L6: paymentId | M6: startDate | N6: endDate | P6: commonItem | Q6: commonNum
B7: 80000001 | C7: 新禧红包 | D7: =VLOOKUP(B7,Sheet4!T:Y,4,FALSE) -> 1001,619424,1;1001,214001,5;1001,214007,5;5,0,100000 | E7: =VLOOKUP(B7,Sheet4!T:Y,2,FALSE) -> 0 | F7: =VLOOKUP(B7,Sheet4!T:Y,2,FALSE) -> 0 | G7: 1 | H7: 9 | I7: 0 | J7: 1 | K7: =VLOOKUP(B7,Sheet4!T:Y,3,FALSE) -> 1 | M7: 2025-01-23 00:00:00 | N7: 2025-02-07 00:00:00 | O7: 1 | P7: =VLOOKUP(B7,Sheet4!T:Y,5,FALSE) -> 1001,619425,1;1001,216002,5;1001,800002,2;1001,215011,1;1001,221011,1; | Q7: =VLOOKUP(B7,Sheet4!T:Y,6,FALSE) -> 1
B8: 80000002 | C8: 招募红包 | D8: =VLOOKUP(B8,Sheet4!T:Y,4,FALSE) -> 1001,215011,1;1001,216001,5;1001,215007,5;5,0,180000 | E8: =VLOOKUP(B8,Sheet4!T:Y,2,FALSE) -> 6 | F8: =VLOOKUP(B8,Sheet4!T:Y,2,FALSE) -> 6 | G8: 0 | H8: 9 | I8: 0 | J8: 1 | K8: =VLOOKUP(B8,Sheet4!T:Y,3,FALSE) -> 1 | M8: 2025-01-23 00:00:00 | N8: 2025-02-07 00:00:00 | O8: 2 | P8: =VLOOKUP(B8,Sheet4!T:Y,5,FALSE) -> 1001,221011,1;1001,216002,5;1001,511168,1;1001,619425,1; | Q8: =VLOOKUP(B8,Sheet4!T:Y,6,FALSE) -> 1
B9: 80000003 | C9: 月卡宝库 | D9: =VLOOKUP(B9,Sheet4!T:Y,4,FALSE) -> 1001,910001,1;1001,210121,3;1001,216001,5;1001,215007,5;5,0,180000;1001,800005,3; | E9: =VLOOKUP(B9,Sheet4!T:Y,2,FALSE) -> 30 | F9: =VLOOKUP(B9,Sheet4!T:Y,2,FALSE) -> 30 | G9: 0 | H9: 9 | I9: 0 | J9: 1 | K9: =VLOOKUP(B9,Sheet4!T:Y,3,FALSE) -> 2 | M9: 2025-01-23 00:00:00 | N9: 2025-02-07 00:00:00 | O9: 3 | P9: =VLOOKUP(B9,Sheet4!T:Y,5,FALSE) -> 1001,619424,2;1001,216002,20;1001,511168,1;1001,215015,3;1001,215011,3; | Q9: =VLOOKUP(B9,Sheet4!T:Y,6,FALSE) -> 2
B10: 80000004 | C10: 金魂宝库 | D10: =VLOOKUP(B10,Sheet4!T:Y,4,FALSE) -> 1001,910003,1;1001,210121,3;1001,216001,5;1001,215007,5;5,0,180000;1001,800005,3; | E10: =VLOOKUP(B10,Sheet4!T:Y,2,FALSE) -> 168 | F10: =VLOOKUP(B10,Sheet4!T:Y,2,FALSE) -> 168 | G10: 0 | H10: 9 | I10: 0 | J10: 1 | K10: =VLOOKUP(B10,Sheet4!T:Y,3,FALSE) -> 2 | M10: 2025-01-23 00:00:00 | N10: 2025-02-07 00:00:00 | O10: 4 | P10: =VLOOKUP(B10,Sheet4!T:Y,5,FALSE) -> 1001,619424,6;1001,216002,50;1001,511170,1;1001,215015,6;1001,215011,6;1,0,1888 | Q10: =VLOOKUP(B10,Sheet4!T:Y,6,FALSE) -> 2
B11: 80000005 | C11: 惊禧红包 | D11: =VLOOKUP(B11,Sheet4!T:Y,4,FALSE) -> 1001,619424,15;1001,216001,20;1001,215007,20;1001,210121,20;1001,720001,20;1010,0,20 | E11: =VLOOKUP(B11,Sheet4!T:Y,2,FALSE) -> 328 | F11: =VLOOKUP(B11,Sheet4!T:Y,2,FALSE) -> 328 | G11: 0 | H11: 9 | I11: 0 | J11: 1 | K11: =VLOOKUP(B11,Sheet4!T:Y,3,FALSE) -> 2 | M11: 2025-01-23 00:00:00 | N11: 2025-02-07 00:00:00 | O11: 5 | P11: =VLOOKUP(B11,Sheet4!T:Y,5,FALSE) -> 1001,1200001,1;1001,514032,180;1001,216002,180;1001,511588,2;1001,215015,30;1001,215011,30;1001,221011,30; | Q11: =VLOOKUP(B11,Sheet4!T:Y,6,FALSE) -> 1
B12: 80000006 | C12: 双福红包 | D12: =VLOOKUP(B12,Sheet4!T:Y,4,FALSE) -> 1001,619424,25;1001,216001,20;1001,215007,20;1001,210121,20;1001,720001,20;1010,0,20 | E12: =VLOOKUP(B12,Sheet4!T:Y,2,FALSE) -> 648 | F12: =VLOOKUP(B12,Sheet4!T:Y,2,FALSE) -> 648 | G12: 0 | H12: 9 | I12: 0 | J12: 1 | K12: =VLOOKUP(B12,Sheet4!T:Y,3,FALSE) -> 2 | M12: 2025-01-23 00:00:00 | N12: 2025-02-07 00:00:00 | O12: 6 | P12: =VLOOKUP(B12,Sheet4!T:Y,5,FALSE) -> 1001,1200001,2;1001,511588,5;1001,216002,380;1001,215015,68;1001,215011,68;1001,221011,68;1001,514032,400; | Q12: =VLOOKUP(B12,Sheet4!T:Y,6,FALSE) -> 1

Sheet Sheet4
A1: 0彩钻 | B1: 彩钻红包 | C1: 1 | D1: 高级经验卷轴 | E1: 5 | F1: 高级秘传书 | G1: 5 | H1: 金块 | I1: 100000 | P1: =Q1&VLOOKUP(B1,Sheet5!E:F,2,FALSE)&R1&C1&S1&Q1&VLOOKUP(D1,Sheet5!E:F,2,FALSE)&R1&E1&S1&Q1&VLOOKUP(F1,Sheet5!E:F,2,FALSE)&R1&G1&S1&"5,0,100000" -> 1001,619055,1;1001,214001,5;1001,214007,5;5,0,100000 | Q1: 1001, | R1: , | S1: ; | V1: 限购 | W1: 必拿 | X1: 可选 | Y1: 可选数量
A2: 6R | B2: 强者招募券 | C2: 1 | D2: 奥义经验卷轴 | E2: 5 | F2: 奥义秘传书 | G2: 5 | H2: 金块 | I2: 180000 | P2: =Q2&VLOOKUP(B2,Sheet5!E:F,2,FALSE)&R2&C2&S2&Q2&VLOOKUP(D2,Sheet5!E:F,2,FALSE)&R2&E2&S2&Q2&VLOOKUP(F2,Sheet5!E:F,2,FALSE)&R2&G2&S2&"5,0,180000" -> 1001,215011,1;1001,216001,5;1001,215007,5;5,0,180000 | Q2: 1001, | R2: , | S2: ; | T2: 80000001 | U2: 0 | V2: 1 | W2: 1001,619424,1;1001,214001,5;1001,214007,5;5,0,100000 | X2: 1001,619425,1;1001,216002,5;1001,800002,2;1001,215011,1;1001,221011,1; | Y2: 1
A3: 30R | B3: 月卡宝库钥匙 | C3: 1 | D3: 冲刺训练书 | E3: 3 | F3: 奥义经验卷轴 | G3: 5 | H3: 奥义秘传书 | I3: 5 | J3: 金块 | K3: 180000 | L3: 突破材料宝箱 | M3: 3 | P3: =Q3&VLOOKUP(B3,Sheet5!E:F,2,FALSE)&R3&C3&S3&Q3&VLOOKUP(D3,Sheet5!E:F,2,FALSE)&R3&E3&S3&Q3&VLOOKUP(F3,Sheet5!E:F,2,FALSE)&R3&G3&S3&Q3&VLOOKUP(H3,Sheet5!E:F,2,FALSE)&R3&I3&S3&"5,0,180000"&S1&Q3&VLOOKUP(L3,Sheet5!E:F,2,FALSE)&R3&M3&S3 -> 1001,910001,1;1001,210121,3;1001,216001,5;1001,215007,5;5,0,180000;1001,800005,3; | Q3: 1001, | R3: , | S3: ; | T3: 80000002 | U3: 6 | V3: 1 | W3: 1001,215011,1;1001,216001,5;1001,215007,5;5,0,180000 | X3: 1001,221011,1;1001,216002,5;1001,511168,1;1001,619425,1; | Y3: 1
A4: 168R | B4: 金魂宝库钥匙 | C4: 1 | D4: 冲刺训练书 | E4: 3 | F4: 奥义经验卷轴 | G4: 5 | H4: 奥义秘传书 | I4: 5 | J4: 金块 | K4: 180000 | L4: 突破材料宝箱 | M4: 3 | P4: =Q4&VLOOKUP(B4,Sheet5!E:F,2,FALSE)&R4&C4&S4&Q4&VLOOKUP(D4,Sheet5!E:F,2,FALSE)&R4&E4&S4&Q4&VLOOKUP(F4,Sheet5!E:F,2,FALSE)&R4&G4&S4&Q4&VLOOKUP(H4,Sheet5!E:F,2,FALSE)&R4&I4&S4&"5,0,180000"&S2&Q4&VLOOKUP(L4,Sheet5!E:F,2,FALSE)&R4&M4&S4 -> 1001,910003,1;1001,210121,3;1001,216001,5;1001,215007,5;5,0,180000;1001,800005,3; | Q4: 1001, | R4: , | S4: ; | T4: 80000003 | U4: 30 | V4: 2 | W4: 1001,910001,1;1001,210121,3;1001,216001,5;1001,215007,5;5,0,180000;1001,800005,3; | X4: 1001,619424,2;1001,216002,20;1001,511168,1;1001,215015,3;1001,215011,3; | Y4: 2
A5: 328R | B5: 彩钻红包 | C5: 15 | D5: 奥义经验卷轴 | E5: 20 | F5: 奥义秘传书 | G5: 20 | H5: 冲刺训练书 | I5: 20 | J5: 搜魂券 | K5: 20 | L5: 七彩原石头 | M5: 20 | P5: =Q5&VLOOKUP(B5,Sheet5!E:F,2,FALSE)&R5&C5&S5&Q5&VLOOKUP(D5,Sheet5!E:F,2,FALSE)&R5&E5&S5&Q5&VLOOKUP(F5,Sheet5!E:F,2,FALSE)&R5&G5&S5&Q5&VLOOKUP(H5,Sheet5!E:F,2,FALSE)&R5&I5&S5&Q5&VLOOKUP(J5,Sheet5!E:F,2,FALSE)&R5&K5&S5&"1010,0,20" -> 1001,619055,15;1001,216001,20;1001,215007,20;1001,210121,20;1001,720001,20;1010,0,20 | Q5: 1001, | R5: , | S5: ; | T5: 80000004 | U5: 168 | V5: 2 | W5: 1001,910003,1;1001,210121,3;1001,216001,5;1001,215007,5;5,0,180000;1001,800005,3; | X5: 1001,619424,6;1001,216002,50;1001,511170,1;1001,215015,6;1001,215011,6;1,0,1888 | Y5: 2
A6: 648R | B6: 彩钻红包 | C6: 25 | D6: 奥义经验卷轴 | E6: 20 | F6: 奥义秘传书 | G6: 20 | H6: 冲刺训练书 | I6: 20 | J6: 搜魂券 | K6: 20 | L6: 七彩原石头 | M6: 20 | P6: =Q6&VLOOKUP(B6,Sheet5!E:F,2,FALSE)&R6&C6&S6&Q6&VLOOKUP(D6,Sheet5!E:F,2,FALSE)&R6&E6&S6&Q6&VLOOKUP(F6,Sheet5!E:F,2,FALSE)&R6&G6&S6&Q6&VLOOKUP(H6,Sheet5!E:F,2,FALSE)&R6&I6&S6&Q6&VLOOKUP(J6,Sheet5!E:F,2,FALSE)&R6&K6&S6&"1010,0,20" -> 1001,619055,25;1001,216001,20;1001,215007,20;1001,210121,20;1001,720001,20;1010,0,20 | Q6: 1001, | R6: , | S6: ; | T6: 80000005 | U6: 328 | V6: 2 | W6: 1001,619424,15;1001,216001,20;1001,215007,20;1001,210121,20;1001,720001,20;1010,0,20 | X6: 1001,1200001,1;1001,514032,180;1001,216002,180;1001,511588,2;1001,215015,30;1001,215011,30;1001,221011,30; | Y6: 1
T7: 80000006 | U7: 648 | V7: 2 | W7: 1001,619424,25;1001,216001,20;1001,215007,20;1001,210121,20;1001,720001,20;1010,0,20 | X7: 1001,1200001,2;1001,511588,5;1001,216002,380;1001,215015,68;1001,215011,68;1001,221011,68;1001,514032,400; | Y7: 1
B9: 道具红包 | C9: 1 | D9: 重铸符文石 | E9: 5 | F9: 精致宝石袋 | G9: 2 | H9: 强者招募券 | I9: 1 | J9: UR招募券 | K9: 1 | P9: =Q9&VLOOKUP(B9,Sheet5!E:F,2,FALSE)&R9&C9&S9&Q9&VLOOKUP(D9,Sheet5!E:F,2,FALSE)&R9&E9&S9&Q9&VLOOKUP(F9,Sheet5!E:F,2,FALSE)&R9&G9&S9&Q9&VLOOKUP(H9,Sheet5!E:F,2,FALSE)&R9&I9&S9&Q9&VLOOKUP(J9,Sheet5!E:F,2,FALSE)&R9&K9&S9 -> 1001,619056,1;1001,216002,5;1001,800002,2;1001,215011,1;1001,221011,1; | Q9: 1001, | R9: , | S9: ;
B10: UR招募券 | C10: 1 | D10: 重铸符文石 | E10: 5 | F10: 6级宝石任选箱 | G10: 1 | H10: 道具红包 | I10: 1 | P10: =Q10&VLOOKUP(B10,Sheet5!E:F,2,FALSE)&R10&C10&S10&Q10&VLOOKUP(D10,Sheet5!E:F,2,FALSE)&R10&E10&S10&Q10&VLOOKUP(F10,Sheet5!E:F,2,FALSE)&R10&G10&S10&Q10&VLOOKUP(H10,Sheet5!E:F,2,FALSE)&R10&I10&S10 -> 1001,221011,1;1001,216002,5;1001,511168,1;1001,619056,1; | Q10: 1001, | R10: , | S10: ;
B11: 彩钻红包 | C11: 2 | D11: 重铸符文石 | E11: 20 | F11: 6级宝石任选箱 | G11: 1 | H11: 限时铸造券 | I11: 3 | J11: 强者招募券 | K11: 3 | P11: =Q11&VLOOKUP(B11,Sheet5!E:F,2,FALSE)&R11&C11&S11&Q11&VLOOKUP(D11,Sheet5!E:F,2,FALSE)&R11&E11&S11&Q11&VLOOKUP(F11,Sheet5!E:F,2,FALSE)&R11&G11&S11&Q11&VLOOKUP(H11,Sheet5!E:F,2,FALSE)&R11&I11&S11&Q11&VLOOKUP(J11,Sheet5!E:F,2,FALSE)&R11&K11&S11 -> 1001,619055,2;1001,216002,20;1001,511168,1;1001,215015,3;1001,215011,3; | Q11: 1001, | R11: , | S11: ;
B12: 彩钻红包 | C12: 6 | D12: 重铸符文石 | E12: 50 | F12: 8级宝石任选箱 | G12: 1 | H12: 限时铸造券 | I12: 6 | J12: 强者招募券 | K12: 6 | L12: 彩钻 | M12: 1888 | P12: =Q12&VLOOKUP(B12,Sheet5!E:F,2,FALSE)&R12&C12&S12&Q12&VLOOKUP(D12,Sheet5!E:F,2,FALSE)&R12&E12&S12&Q12&VLOOKUP(F12,Sheet5!E:F,2,FALSE)&R12&G12&S12&Q12&VLOOKUP(H12,Sheet5!E:F,2,FALSE)&R12&I12&S12&Q12&VLOOKUP(J12,Sheet5!E:F,2,FALSE)&R12&K12&S12&"1,0,1888" -> 1001,619055,6;1001,216002,50;1001,511170,1;1001,215015,6;1001,215011,6;1,0,1888 | Q12: 1001, | R12: , | S12: ;
B13: 七彩炫光 | C13: 1 | D13: 战船洗练石 | E13: 180 | F13: 重铸符文石 | G13: 180 | H13: 8级七彩宝石任选袋 | I13: 2 | J13: 限时铸造券 | K13: 30 | L13: 强者招募券 | M13: 30 | N13: UR招募券 | O13: 30 | P13: =Q13&VLOOKUP(B13,Sheet5!E:F,2,FALSE)&R13&C13&S13&Q13&VLOOKUP(D13,Sheet5!E:F,2,FALSE)&R13&E13&S13&Q13&VLOOKUP(F13,Sheet5!E:F,2,FALSE)&R13&G13&S13&Q13&VLOOKUP(H13,Sheet5!E:F,2,FALSE)&R13&I13&S13&Q13&VLOOKUP(J13,Sheet5!E:F,2,FALSE)&R13&K13&S13&Q13&VLOOKUP(L13,Sheet5!E:F,2,FALSE)&R13&M13&S13&Q13&VLOOKUP(N13,Sheet5!E:F,2,FALSE)&R13&O13&S13 -> 1001,1200001,1;1001,514032,180;1001,216002,180;1001,511588,2;1001,215015,30;1001,215011,30;1001,221011,30; | Q13: 1001, | R13: , | S13: ;
B14: 七彩炫光 | C14: 2 | D14: 8级七彩宝石任选袋 | E14: 5 | F14: 重铸符文石 | G14: 380 | H14: 限时铸造券 | I14: 68 | J14: 强者招募券 | K14: 68 | L14: UR招募券 | M14: 68 | N14: 战船洗练石 | O14: 400 | P14: =Q14&VLOOKUP(B14,Sheet5!E:F,2,FALSE)&R14&C14&S14&Q14&VLOOKUP(D14,Sheet5!E:F,2,FALSE)&R14&E14&S14&Q14&VLOOKUP(F14,Sheet5!E:F,2,FALSE)&R14&G14&S14&Q14&VLOOKUP(H14,Sheet5!E:F,2,FALSE)&R14&I14&S14&Q14&VLOOKUP(J14,Sheet5!E:F,2,FALSE)&R14&K14&S14&Q14&VLOOKUP(L14,Sheet5!E:F,2,FALSE)&R14&M14&S14&Q14&VLOOKUP(N14,Sheet5!E:F,2,FALSE)&R14&O14&S14 -> 1001,1200001,2;1001,511588,5;1001,216002,380;1001,215015,68;1001,215011,68;1001,221011,68;1001,514032,400; | Q14: 1001, | R14: , | S14: ;

Sheet Sheet5
A1: 1 | B1: 9999 | C1: 44 | F1: 7
A2: 物品大类型 | B2: 物品子类型 | C2: 背包类型 | D2: 名字 | E2: 名字文本 | F2: 物品id | G2: 描述文本
A3: itemType | B3: itemSubType | C3: bagType | E3: name | F3: itemId | G3: intro
A4: int | B4: int | C4: int | E4: string(intern) | F4: int | G4: string(intern)
A5: none | B5: index | C5: none | E5: none | F5: primary | G5: none
A6: itemType | B6: itemSubType | C6: bagType | E6: nameIndex | F6: itemId | G6: introIndex
A7: 1001 | B7: 1 | C7: 1001 | D7: 经验卷轴 | E7: 经验卷轴 | F7: 112001 | G7: 经验道具，用于增加角色经验。
A8: 1001 | B8: 1 | C8: 1001 | D8: 精炼石 | E8: 精炼石 | F8: 112002 | G8: 装备精炼道具，用于提高装备的精炼等级。
A9: 1001 | B9: 1 | C9: 1001 | D9: 招募券 | E9: 招募券 | F9: 112003 | G9: 招募道具，用于在招募界面进行船员招募。
A10: 1001 | B10: 1 | C10: 1001 | D10: 秘传书 | E10: 秘传书 | F10: 112004 | G10: 可以增加角色的技能点，用于技能升级。
A11: 1001 | B11: 1 | C11: 1001 | D11: 蓝钻 | E11: 蓝钻 | F11: 122001 | G11: 航海王中珍贵的货币，可用于购买活动次数、商城兑换等。
A12: 1001 | B12: 1 | C12: 1001 | D12: 经验 | E12: 经验 | F12: 122002 | G12: 玩家和角色升级所需的经验。
A13: 1001 | B13: 1 | C13: 1001 | D13: 金块 | E13: 金块 | F13: 122003 | G13: 航海王中常用的货币，用于日常消费。
A14: 1001 | B14: 1 | C14: 1001 | D14: 千里阳光号 | E14: 千里阳光号 | F14: 122004 | G14: 由宝树亚当制成的草帽一伙的海盗船！是穿越千里大海的梦想之船。
A15: 1001 | B15: 1 | C15: 1001 | D15: 海军战舰 | E15: 海军战舰 | F15: 122005 | G15: 为将目标全部粉碎的大型军舰。由海军总部中将担任指挥。
A16: 1001 | B16: 1 | C16: 1001 | D16: 黄金梅丽号 | E16: 黄金梅丽号 | F16: 122006 | G16: 伴随草帽海盗团的成长，是草帽一伙形影不离、不可或缺的伙伴。
A17: 1001 | B17: 1 | C17: 1001 | D17: 黑色战士号 | E17: 黑色战士号 | F17: 122007 | G17: 黑猫海盗团的船，标志就是船头的黑猫，是船长克洛的标志。
A18: 1001 | B18: 1 | C18: 1001 | D18: 海军军舰 | E18: 海军军舰 | F18: 122008 | G18: 标准的海军船。装备有和总部联络用的各种电话虫。
A19: 1001 | B19: 1 | C19: 1001 | D19: 可爱小鸭号 | E19: 可爱小鸭号 | F19: 122009 | G19: 船头是一只可爱的天鹅，船帆有“2”的标志，是Mr.2的船。
... A48: 1001 | B48: 1 | C48: 1001 | D48: 奥义经验卷轴 | E48: 奥义经验卷轴 | F48: 216001 | G48: 记录角色冒险经历的奥义经验卷轴，使用后增加角色30000点角色经验。
A49: 1001 | B49: 1 | C49: 1001 | D49: 1 | E49: 1 | F49: 217001 | G49: 1
A50: 1001 | B50: 8 | C50: 1001 | D50: 低级精炼石 | E50: 初级精炼石 | F50: 212002 | G50: 稀有的金属矿石，可以用于提高装备精炼等级。
A51: 1001 | B51: 8 | C51: 1001 | D51: 中级精炼石 | E51: 中级精炼石 | F51: 213002 | G51: 稀有的金属矿石，可以用于提高装备精炼等级。
A52: 1001 | B52: 8 | C52: 1001 | D52: 高级精炼石 | E52: 高级精炼石 | F52: 214002 | G52: 稀有的金属矿石，可以用于提高装备精炼等级。
A53: 1001 | B53: 8 | C53: 1001 | D53: 超级精炼石 | E53: 超级精炼石 | F53: 215002 | G53: 稀有的金属矿石，可以用于提高装备精炼等级。
A54: 1001 | B54: 2 | C54: 1001 | D54: 重铸符文石 | E54: 重铸符文石 | F54: 216002 | G54: 由工匠们制造的刻有符号的石头，可以用于重新鉴定装备属性。
A55: 1001 | B55: 19 | C55: 1001 | D55: 精钢石 | E55: 精钢石 | F55: 212004 | G55: 由珍稀矿石淬炼而成的精钢石，可用于40级装备的宝石打孔。
A56: 1001 | B56: 19 | C56: 1001 | D56: 海蓝石 | E56: 海蓝石 | F56: 213004 | G56: 由珍稀矿石淬炼而成的海蓝石，可用于50至60级装备的宝石打孔。
A57: 1001 | B57: 19 | C57: 1001 | D57: 钢岩石 | E57: 钢岩石 | F57: 214004 | G57: 由珍稀矿石淬炼而成的钢岩石，可用于80级装备的宝石打孔。
A58: 1001 | B58: 19 | C58: 1001 | D58: 圣辉石 | E58: 圣辉石 | F58: 215004 | G58: 由珍稀矿石淬炼而成的圣辉石，可用于100级装备的宝石打孔。
A59: 1001 | B59: 2 | C59: 1001 | D59: 精淬石 | E59: 精淬石 | F59: 218004 | G59: 稀有金属炼成的晶石，用于装备的精淬。
A60: 1001 | B60: 1 | C60: 1001 | D60: 古铜战魂 | E60: 古铜战魂 | F60: 214005 | G60: 承载着强大海上战士的信念，用于R品质和SR品质角色超越。
A61: 1001 | B61: 1 | C61: 1001 | D61: 黄金战魂 | E61: 黄金战魂 | F61: 215005 | G61: 承载着英勇海上战士的信念，用于SSR品质角色超越。
... A72: 1001 | B72: 6 | C72: 1001 | D72: 一袋蓝钻 | E72: 一袋蓝钻 | F72: 219006 | G72: 一大袋鼓鼓的蓝钻，开启获得200蓝钻。
A73: 1001 | B73: 6 | C73: 1001 | F73: 214107
A74: 1001 | B74: 18 | C74: 1001 | D74: 初级秘传书 | E74: 初级秘传书 | F74: 212007 | G74: 记载如何更好发掘自身潜力的初级书籍，使用后角色获得2技能点数。
A75: 1001 | B75: 18 | C75: 1001 | D75: 中级秘传书 | E75: 中级秘传书 | F75: 213007 | G75: 记载如何更好发掘自身潜力的中级书籍，使用后角色获得4技能点数。
A76: 1001 | B76: 18 | C76: 1001 | D76: 高级秘传书 | E76: 高级秘传书 | F76: 214007 | G76: 记载如何更好发掘自身潜力的高级书籍，使用后角色获得6技能点数。
A77: 1001 | B77: 18 | C77: 1001 | D77: 奥义秘传书 | E77: 奥义秘传书 | F77: 215007 | G77: 记载如何更好发掘自身潜力的奥义书籍，使用后角色获得8技能点数。
A78: 1001 | C78: 1001 | D78: 觉醒秘传书 | E78: 觉醒秘传书 | F78: 216007 | G78: 晋升后使用的秘传书，使用后角色获得10技能点数。
...
