Workbook

Sheet Sheet1
A1: 7 | B1: 1 | C1: 9999 | D1: 20
A2: id | B2: EmptyKey-B2 | C2: 动画名称 | D2: 动画icon | E2: 动画描述文字 | F2: 附加声音 | G2: 声音延迟 | H2: 附加特效 | I2: 是否在表情面板显示 3 | J2: 是否在场景显示 1 | K2: 是否在阵容显示 2 | L2: 台词 | M2: 台词位置调整 | N2: 台词时长 | O2: 模型Id | P2: 是否在换装页面显示 | Q2: 是否在装备抽奖界面显示 | R2: 是否是骑乘动作 | S2: 动画触发条件 | T2: 是否在个性形象模型界面显示 | U2: EmptyKey-T2 | V2: EmptyKey-U2 | W2: ↓超 | X2: 动画icon-W2 | Y2: 动画描述文字-X2
A3: id | C3: animName | D3: animIcon | E3: animText | F3: sound | G3: soundDelay | H3: effect | I3: showInEmoji | J3: showInScene | K3: showInFormation | L3: lines | M3: linesOffset | N3: linesDuration | O3: modelId | P3: showInFashion | Q3: showInEquipLuckDraw | R3: showInRide | S3: triggerCondition | T3: showPersonalityModel | X3: animIcon | Y3: animText
A4: int | C4: string(intern) | D4: string(intern) | E4: string(intern) | F4: string | G4: float | H4: string | I4: int | J4: int | K4: int | L4: string | M4: string | N4: float | O4: int | P4: int | Q4: int | R4: int | S4: string(intern) | T4: int | X4: string(intern) | Y4: string(intern)
A5: primary | C5: none | D5: none | E5: none | F5: none | G5: none | H5: none | I5: none | J5: none | K5: none | L5: none | M5: none | N5: none | O5: index | P5: none | Q5: none | R5: none | S5: none | T5: none | X5: none | Y5: none
A7: =ROW()-6 -> 1 | B7: 113001 | C7: mood01 | D7: =X7 -> UI_icon_teshudognzuo_16 | E7: =W7 -> 挑衅 | F7: CV_CrocodileCZ_zhenrong01 | I7: 0 | J7: 1 | K7: 1 | L7: 把所有人都杀掉就好了 | M7: -40,100 | N7: 3.1 | O7: 35 | P7: 1 | U7: 克罗克达尔 | V7: 1 | W7: 挑衅 | X7: =IF(ISBLANK(W7),"",VLOOKUP($W7,Sheet2!$A$2:$E$29,3,FALSE)) -> UI_icon_teshudognzuo_16 | Y7: =IF(ISBLANK(W7),"",VLOOKUP($W7,Sheet2!$A$2:$E$29,4,FALSE)) -> BQ_mood16
A8: =ROW()-6 -> 2 | B8: 113001 | C8: mood02 | D8: =X8 -> UI_icon_teshudognzuo_05 | E8: =W8 -> 示威 | F8: CV_CrocodileCZ_zhenrong02 | I8: 0 | J8: 0 | K8: 1 | L8: 不要碍事！ | M8: -400,130 | N8: 2.5 | O8: 35 | P8: 0 | V8: 2 | W8: 示威 | X8: =IF(ISBLANK(W8),"",VLOOKUP($W8,Sheet2!$A$2:$E$29,3,FALSE)) -> UI_icon_teshudognzuo_05 | Y8: =IF(ISBLANK(W8),"",VLOOKUP($W8,Sheet2!$A$2:$E$29,4,FALSE)) -> BQ_mood05
A9: =ROW()-6 -> 3 | B9: 113001 | C9: mood03 | D9: =X9 -> UI_icon_teshudognzuo_27 | E9: =W9 -> 秀 | F9: CV_crocodile04 | I9: 1 | J9: 0 | K9: 0 | L9: 用我的右手把它风化吧 | M9: -400,150 | N9: 3.6 | O9: 35 | P9: 0 | V9: 3 | W9: 秀 | X9: =IF(ISBLANK(W9),"",VLOOKUP($W9,Sheet2!$A$2:$E$29,3,FALSE)) -> UI_icon_teshudognzuo_27 | Y9: =IF(ISBLANK(W9),"",VLOOKUP($W9,Sheet2!$A$2:$E$29,4,FALSE)) -> BQ_mood27
A10: =ROW()-6 -> 4 | B10: 113001 | C10: mood04 | D10: =X10 -> UI_icon_teshudognzuo_01 | E10: =W10 -> 认同 | I10: 1 | J10: 0 | K10: 0 | N10: 3 | O10: 35 | P10: 0 | V10: 4 | W10: 认同 | X10: =IF(ISBLANK(W10),"",VLOOKUP($W10,Sheet2!$A$2:$E$29,3,FALSE)) -> UI_icon_teshudognzuo_01 | Y10: =IF(ISBLANK(W10),"",VLOOKUP($W10,Sheet2!$A$2:$E$29,4,FALSE)) -> BQ_mood01
A11: =ROW()-6 -> 5 | B11: 113001 | C11: mood05 | D11: =X11 -> UI_icon_teshudognzuo_08 | E11: =W11 -> 休闲 | F11: CV_CrocodileCZ_zhenrong04 | I11: 0 | J11: 1 | K11: 1 | L11: 需要一点点兵力，怎么样？跟我一起来吗？ | M11: -420,10 | N11: 4.9 | O11: 35 | P11: 1 | V11: 5 | W11: 休闲 | X11: =IF(ISBLANK(W11),"",VLOOKUP($W11,Sheet2!$A$2:$E$29,3,FALSE)) -> UI_icon_teshudognzuo_08 | Y11: =IF(ISBLANK(W11),"",VLOOKUP($W11,Sheet2!$A$2:$E$29,4,FALSE)) -> BQ_mood08
A12: =ROW()-6 -> 6 | B12: 113001 | C12: mood06 | D12: =X12 -> UI_icon_teshudognzuo_02 | E12: =W12 -> 拒绝 | F12: CV_CrocodileCZ_zhenrong05 | I12: 1 | J12: 1 | K12: 1 | L12: 你们太弱了… | M12: -40,150 | N12: 1.8 | O12: 35 | P12: 1 | V12: 6 | W12: 拒绝 | X12: =IF(ISBLANK(W12),"",VLOOKUP($W12,Sheet2!$A$2:$E$29,3,FALSE)) -> UI_icon_teshudognzuo_02 | Y12: =IF(ISBLANK(W12),"",VLOOKUP($W12,Sheet2!$A$2:$E$29,4,FALSE)) -> BQ_mood02
A13: =ROW()-6 -> 7 | B13: =B7+1 -> 113002 | C13: mood01 | D13: UI_icon_teshudognzuo_27 | E13: 秀 | F13: CV_EnelCZ_zhenrong02 | I13: 1 | J13: 0 | K13: 1 | L13: 我是神，万事都要顺我的意！ | M13: -30,75 | N13: 4.3 | O13: 36 | P13: 0 | U13: 艾尼路 | V13: 1 | W13: 秀 | X13: =IF(ISBLANK(W13),"",VLOOKUP($W13,Sheet2!$A$2:$E$29,3,FALSE)) -> UI_icon_teshudognzuo_27 | Y13: =IF(ISBLANK(W13),"",VLOOKUP($W13,Sheet2!$A$2:$E$29,4,FALSE)) -> BQ_mood27
A14: =ROW()-6 -> 8 | B14: =B8+1 -> 113002 | C14: mood02 | D14: UI_icon_teshudognzuo_05 | E14: 示威 | F14: CV_enel05 | I14: 1 | J14: 1 | K14: 0 | L14: 说话小心点，我是神！ | M14: -30,40 | N14: 3.8 | O14: 36 | P14: 0 | V14: 2 | W14: 示威 | X14: =IF(ISBLANK(W14),"",VLOOKUP($W14,Sheet2!$A$2:$E$29,3,FALSE)) -> UI_icon_teshudognzuo_05 | Y14: =IF(ISBLANK(W14),"",VLOOKUP($W14,Sheet2!$A$2:$E$29,4,FALSE)) -> BQ_mood05
A15: =ROW()-6 -> 9 | B15: =B9+1 -> 113002 | C15: mood03 | D15: UI_icon_teshudognzuo_18 | E15: 哈气 | F15: CV_EnelCZ_zhenrong01 | I15: 0 | J15: 1 | K15: 1 | L15: 没有什么是不可能的，我是全能之神！ | M15: -30,10 | N15: 5.5 | O15: 36 | P15: 0 | V15: 3 | W15: 哈气 | X15: =IF(ISBLANK(W15),"",VLOOKUP($W15,Sheet2!$A$2:$E$29,3,FALSE)) -> UI_icon_teshudognzuo_18 | Y15: =IF(ISBLANK(W15),"",VLOOKUP($W15,Sheet2!$A$2:$E$29,4,FALSE)) -> BQ_mood18
A16: =ROW()-6 -> 10 | B16: =B10+1 -> 113002 | C16: mood04 | D16: UI_icon_teshudognzuo_08 | E16: 休闲 | I16: 0 | J16: 1 | K16: 0 | N16: 6 | O16: 36 | P16: 0 | V16: 4 | W16: 休闲 | X16: =IF(ISBLANK(W16),"",VLOOKUP($W16,Sheet2!$A$2:$E$29,3,FALSE)) -> UI_icon_teshudognzuo_08 | Y16: =IF(ISBLANK(W16),"",VLOOKUP($W16,Sheet2!$A$2:$E$29,4,FALSE)) -> BQ_mood08
A17: =ROW()-6 -> 11 | B17: =B12+1 -> 113002 | C17: mood05 | D17: UI_icon_teshudognzuo_16 | E17: 挑衅 | F17: CV_EnelCZ_zhenrong03 | I17: 1 | J17: 0 | K17: 1 | L17: 怎么样，一起来看看这个国家毁灭的模样吧 | M17: -30,10 | N17: 6.3 | O17: 36 | P17: 0 | V17: 5 | W17: 挑衅 | X17: =IF(ISBLANK(W17),"",VLOOKUP($W17,Sheet2!$A$2:$E$29,3,FALSE)) -> UI_icon_teshudognzuo_16 | Y17: =IF(ISBLANK(W17),"",VLOOKUP($W17,Sheet2!$A$2:$E$29,4,FALSE)) -> BQ_mood16
A18: =ROW()-6 -> 12 | B18: =B13+1 -> 113003 | C18: mood01 | D18: UI_icon_teshudognzuo_13 | E18: 鼓掌 | I18: 1 | J18: 0 | K18: 0 | N18: 3 | O18: 16 | P18: 0 | U18: 青雉 | V18: 1 | W18: 鼓掌 | X18: =IF(ISBLANK(W18),"",VLOOKUP($W18,Sheet2!$A$2:$E$29,3,FALSE)) -> UI_icon_teshudognzuo_13 | Y18: =IF(ISBLANK(W18),"",VLOOKUP($W18,Sheet2!$A$2:$E$29,4,FALSE)) -> BQ_mood13
A19: =ROW()-6 -> 13 | B19: =B14+1 -> 113003 | C19: mood02 | D19: UI_icon_teshudognzuo_14 | E19: 无奈 | I19: 1 | J19: 1 | K19: 0 | N19: 3 | O19: 16 | P19: 0 | V19: 2 | W19: 无奈 | X19: =IF(ISBLANK(W19),"",VLOOKUP($W19,Sheet2!$A$2:$E$29,3,FALSE)) -> UI_icon_teshudognzuo_14 | Y19: =IF(ISBLANK(W19),"",VLOOKUP($W19,Sheet2!$A$2:$E$29,4,FALSE)) -> BQ_mood14
A20: =ROW()-6 -> 14 | B20: =B15+1 -> 113003 | C20: mood03 | D20: UI_icon_teshudognzuo_03 | E20: 打招呼 | F20: CV_kuzanCZ_02 | I20: 1 | J20: 0 | K20: 1 | L20: 这个舞台，对于你来说还太早了点！ | M20: -400,30 | N20: 3.5 | O20: 16 | P20: 0 | V20: 3 | W20: 打招呼 | X20: =IF(ISBLANK(W20),"",VLOOKUP($W20,Sheet2!$A$2:$E$29,3,FALSE)) -> UI_icon_teshudognzuo_03 | Y20: =IF(ISBLANK(W20),"",VLOOKUP($W20,Sheet2!$A$2:$E$29,4,FALSE)) -> BQ_mood03
A21: =ROW()-6 -> 15 | B21: =B16+1 -> 113003 | C21: mood04 | D21: UI_icon_teshudognzuo_04 | E21: 休闲 | F21: CV_kuzanCZ_01 | I21: 0 | J21: 1 | K21: 1 | L21: 哎吆喂，总算来到这里了吗… | M21: -400,55 | N21: 2.7 | O21: 16 | P21: 0 | V21: 4 | W21: 放松 | X21: =IF(ISBLANK(W21),"",VLOOKUP($W21,Sheet2!$A$2:$E$29,3,FALSE)) -> UI_icon_teshudognzuo_04 | Y21: =IF(ISBLANK(W21),"",VLOOKUP($W21,Sheet2!$A$2:$E$29,4,FALSE)) -> BQ_mood04
A22: =ROW()-6 -> 16 | B22: =B17+1 -> 113003 | C22: mood05 | D22: UI_icon_teshudognzuo_08 | E22: 休闲 | I22: 0 | J22: 1 | K22: 0 | N22: 6 | O22: 16 | P22: 0 | V22: 5 | W22: 休闲 | X22: =IF(ISBLANK(W22),"",VLOOKUP($W22,Sheet2!$A$2:$E$29,3,FALSE)) -> UI_icon_teshudognzuo_08 | Y22: =IF(ISBLANK(W22),"",VLOOKUP($W22,Sheet2!$A$2:$E$29,4,FALSE)) -> BQ_mood08
A23: =ROW()-6 -> 17 | B23: =B18+1 -> 113004 | C23: mood01 | D23: UI_icon_teshudognzuo_17 | E23: 抠鼻 | F23: CV_GarpCZ_zhenrong01 | I23: 1 | J23: 1 | K23: 1 | L23: 你真是大闹了一通啊 | M23: -50,80 | N23: 2 | O23: 42 | P23: 1 | U23: 卡普 | V23: 1 | W23: 抠鼻 | X23: =IF(ISBLANK(W23),"",VLOOKUP($W23,Sheet2!$A$2:$E$29,3,FALSE)) -> UI_icon_teshudognzuo_17 | Y23: =IF(ISBLANK(W23),"",VLOOKUP($W23,Sheet2!$A$2:$E$29,4,FALSE)) -> BQ_mood17
A24: =ROW()-6 -> 18 | B24: =B19+1 -> 113004 | C24: mood02 | D24: UI_icon_teshudognzuo_18 | E24: 哈气 | F24: CV_GarpCZ_zhenrong02 | I24: 0 | J24: 1 | K24: 1 | L24: 无聊！ | M24: -70,170 | N24: 1 | O24: 42 | P24: 1 | V24: 2 | W24: 哈气 | X24: =IF(ISBLANK(W24),"",VLOOKUP($W24,Sheet2!$A$2:$E$29,3,FALSE)) -> UI_icon_teshudognzuo_18 | Y24: =IF(ISBLANK(W24),"",VLOOKUP($W24,Sheet2!$A$2:$E$29,4,FALSE)) -> BQ_mood18
A25: =ROW()-6 -> 19 | B25: =B20+1 -> 113004 | C25: mood03 | D25: UI_icon_teshudognzuo_19 | E25: 哈气 | F25: CV_GarpCZ_zhenrong03 | I25: 1 | J25: 0 | K25: 1 | L25: 这样进去的话会比较帅嘛！ | M25: 10,80 | N25: 2.2 | O25: 42 | P25: 1 | V25: 3 | W25: 合影 | X25: =IF(ISBLANK(W25),"",VLOOKUP($W25,Sheet2!$A$2:$E$29,3,FALSE)) -> UI_icon_teshudognzuo_19 | Y25: =IF(ISBLANK(W25),"",VLOOKUP($W25,Sheet2!$A$2:$E$29,4,FALSE)) -> BQ_mood19
A26: =ROW()-6 -> 20 | B26: =B21+1 -> 113004 | C26: mood04 | D26: UI_icon_teshudognzuo_07 | E26: 观望 | I26: 0 | J26: 1 | K26: 0 | N26: 3 | O26: 42 | P26: 0 | V26: 4 | W26: 观望 | X26: =IF(ISBLANK(W26),"",VLOOKUP($W26,Sheet2!$A$2:$E$29,3,FALSE)) -> UI_icon_teshudognzuo_07 | Y26: =IF(ISBLANK(W26),"",VLOOKUP($W26,Sheet2!$A$2:$E$29,4,FALSE)) -> BQ_mood07
A27: =ROW()-6 -> 21 | B27: =B22+1 -> 113004 | C27: mood05 | D27: UI_icon_teshudognzuo_20 | E27: 睡觉 | I27: 1 | J27: 1 | K27: 0 | N27: 3 | O27: 42 | P27: 0 | V27: 5 | W27: 睡觉 | X27: =IF(ISBLANK(W27),"",VLOOKUP($W27,Sheet2!$A$2:$E$29,3,FALSE)) -> UI_icon_teshudognzuo_20 | Y27: =IF(ISBLANK(W27),"",VLOOKUP($W27,Sheet2!$A$2:$E$29,4,FALSE)) -> BQ_mood20
A28: =ROW()-6 -> 22 | B28: =B23+1 -> 113005 | C28: mood01 | D28: UI_icon_teshudognzuo_01 | E28: 认同 | F28: CV_moria04 | I28: 1 | J28: 0 | K28: 1 | L28: 你帮我做吧。 | M28: -30,100 | N28: 2 | O28: 53 | P28: 0 | U28: 莫利亚 | V28: 1 | W28: 认同 | X28: =IF(ISBLANK(W28),"",VLOOKUP($W28,Sheet2!$A$2:$E$29,3,FALSE)) -> UI_icon_teshudognzuo_01 | Y28: =IF(ISBLANK(W28),"",VLOOKUP($W28,Sheet2!$A$2:$E$29,4,FALSE)) -> BQ_mood01
A29: =ROW()-6 -> 23 | B29: =B24+1 -> 113005 | C29: mood02 | D29: UI_icon_teshudognzuo_02 | E29: 拒绝 | F29: CV_moria05 | I29: 1 | J29: 0 | K29: 1 | L29: 吵吵嚷嚷，烦死了！！ | M29: -30,80 | N29: 4 | O29: 53 | P29: 0 | V29: 2 | W29: 拒绝 | X29: =IF(ISBLANK(W29),"",VLOOKUP($W29,Sheet2!$A$2:$E$29,3,FALSE)) -> UI_icon_teshudognzuo_02 | Y29: =IF(ISBLANK(W29),"",VLOOKUP($W29,Sheet2!$A$2:$E$29,4,FALSE)) -> BQ_mood02
A30: =ROW()-6 -> 24 | B30: =B25+1 -> 113005 | C30: mood03 | D30: UI_icon_teshudognzuo_03 | E30: 打招呼 | I30: 1 | J30: 0 | K30: 0 | N30: 3 | O30: 53 | P30: 0 | V30: 3 | W30: 打招呼 | X30: =IF(ISBLANK(W30),"",VLOOKUP($W30,Sheet2!$A$2:$E$29,3,FALSE)) -> UI_icon_teshudognzuo_03 | Y30: =IF(ISBLANK(W30),"",VLOOKUP($W30,Sheet2!$A$2:$E$29,4,FALSE)) -> BQ_mood03
A31: =ROW()-6 -> 25 | B31: =B26+1 -> 113005 | C31: mood04 | D31: UI_icon_teshudognzuo_04 | E31: 休闲 | I31: 0 | J31: 4 | K31: 0 | N31: 3 | O31: 53 | P31: 0 | V31: 4 | W31: 放松 | X31: =IF(ISBLANK(W31),"",VLOOKUP($W31,Sheet2!$A$2:$E$29,3,FALSE)) -> UI_icon_teshudognzuo_04 | Y31: =IF(ISBLANK(W31),"",VLOOKUP($W31,Sheet2!$A$2:$E$29,4,FALSE)) -> BQ_mood04
A32: =ROW()-6 -> 26 | B32: =B27+1 -> 113005 | C32: mood05 | D32: UI_icon_teshudognzuo_27 | E32: 秀 | F32: CV_moria02 | I32: 1 | J32: 5 | K32: 1 | L32: 通过吸收别人的影子，我会变得更强，你知道吗？！ | M32: -20,10 | N32: 6.8 | O32: 53 | P32: 0 | V32: 5 | W32: 秀 | X32: =IF(ISBLANK(W32),"",VLOOKUP($W32,Sheet2!$A$2:$E$29,3,FALSE)) -> UI_icon_teshudognzuo_27 | Y32: =IF(ISBLANK(W32),"",VLOOKUP($W32,Sheet2!$A$2:$E$29,4,FALSE)) -> BQ_mood27
A33: =ROW()-6 -> 27 | B33: =B28+1 -> 113006 | C33: mood01 | D33: =X33 -> UI_icon_teshudognzuo_01 | E33: =W33 -> 认同 | F33: CV_kumaCZ_zhenrong03 | I33: 1 | J33: 0 | K33: 1 | L33: 小事一桩 | M33: -30,160 | N33: 1.3 | O33: 39 | P33: 0 | U33: 大熊 | V33: 1 | W33: 认同 | X33: =IF(ISBLANK(W33),"",VLOOKUP($W33,Sheet2!$A$2:$E$29,3,FALSE)) -> UI_icon_teshudognzuo_01 | Y33: =IF(ISBLANK(W33),"",VLOOKUP($W33,Sheet2!$A$2:$E$29,4,FALSE)) -> BQ_mood01
A34: =ROW()-6 -> 28 | B34: =B29+1 -> 113006 | C34: mood02 | D34: =X34 -> UI_icon_teshudognzuo_23 | E34: =W34 -> 摇头 | I34: 1 | J34: 0 | K34: 0 | N34: 3 | O34: 39 | P34: 0 | V34: 2 | W34: 摇头 | X34: =IF(ISBLANK(W34),"",VLOOKUP($W34,Sheet2!$A$2:$E$29,3,FALSE)) -> UI_icon_teshudognzuo_23 | Y34: =IF(ISBLANK(W34),"",VLOOKUP($W34,Sheet2!$A$2:$E$29,4,FALSE)) -> BQ_mood23
A35: =ROW()-6 -> 29 | B35: =B30+1 -> 113006 | C35: mood03 | D35: =X35 -> UI_icon_teshudognzuo_26 | E35: =W35 -> 看书 | I35: 1 | J35: 1 | K35: 0 | N35: 3 | O35: 39 | P35: 0 | V35: 3 | W35: 看书 | X35: =IF(ISBLANK(W35),"",VLOOKUP($W35,Sheet2!$A$2:$E$29,3,FALSE)) -> UI_icon_teshudognzuo_26 | Y35: =IF(ISBLANK(W35),"",VLOOKUP($W35,Sheet2!$A$2:$E$29,4,FALSE)) -> BQ_mood26
A36: =ROW()-6 -> 30 | B36: =B31+1 -> 113006 | C36: mood04 | D36: =X36 -> UI_icon_teshudognzuo_04 | E36: =W36 -> 放松 | F36: CV_kumaCZ_zhenrong01 | I36: 0 | J36: 1 | K36: 1 | L36: 要去旅行的话，你想去哪里呢？ | M36: -30,70 | N36: 3 | O36: 39 | P36: 0 | V36: 4 | W36: 放松 | X36: =IF(ISBLANK(W36),"",VLOOKUP($W36,Sheet2!$A$2:$E$29,3,FALSE)) -> UI_icon_teshudognzuo_04 | Y36: =IF(ISBLANK(W36),"",VLOOKUP($W36,Sheet2!$A$2:$E$29,4,FALSE)) -> BQ_mood04
A37: =ROW()-6 -> 31 | B37: =B32+1 -> 113006 | C37: mood05 | D37: =X37 -> UI_icon_teshudognzuo_28 | E37: =W37 -> 玩 | F37: CV_kumaCZ_zhenrong02 | I37: 1 | J37: 0 | K37: 1 | L37: 我是“肉球果实”的“肉球人” | M37: -30,100 | N37: 3 | O37: 39 | P37: 0 | V37: 5 | W37: 玩 | X37: =IF(ISBLANK(W37),"",VLOOKUP($W37,Sheet2!$A$2:$E$29,3,FALSE)) -> UI_icon_teshudognzuo_28 | Y37: =IF(ISBLANK(W37),"",VLOOKUP($W37,Sheet2!$A$2:$E$29,4,FALSE)) -> BQ_mood28
A38: =ROW()-6 -> 32 | B38: =B33+1 -> 113007 | C38: mood01 | D38: =X38 -> UI_icon_teshudognzuo_22 | E38: =W38 -> 大笑 | I38: 1 | J38: 0 | K38: 0 | N38: 3 | O38: 52 | P38: 0 | U38: 黄猿 | V38: 1 | W38: 大笑 | X38: =IF(ISBLANK(W38),"",VLOOKUP($W38,Sheet2!$A$2:$E$29,3,FALSE)) -> UI_icon_teshudognzuo_22 | Y38: =IF(ISBLANK(W38),"",VLOOKUP($W38,Sheet2!$A$2:$E$29,4,FALSE)) -> BQ_mood22
A39: =ROW()-6 -> 33 | B39: =B34+1 -> 113007 | C39: mood02 | D39: =X39 -> UI_icon_teshudognzuo_27 | E39: =W39 -> 秀 | F39: CV_borsalinoCZ_zhenrong_01 | I39: 1 | J39: 0 | K39: 1 | L39: 速度即“重量”…你被光速踢过吗？ | M39: -430,0 | N39: 7 | O39: 52 | P39: 0 | V39: 2 | W39: 秀 | X39: =IF(ISBLANK(W39),"",VLOOKUP($W39,Sheet2!$A$2:$E$29,3,FALSE)) -> UI_icon_teshudognzuo_27 | Y39: =IF(ISBLANK(W39),"",VLOOKUP($W39,Sheet2!$A$2:$E$29,4,FALSE)) -> BQ_mood27
A40: =ROW()-6 -> 34 | B40: =B35+1 -> 113007 | C40: mood03 | D40: =X40 -> UI_icon_teshudognzuo_04 | E40: =W40 -> 放松 | F40: CV_borsalinoCZ_zhenrong_02 | I40: 1 | J40: 1 | K40: 1 | L40: 没有实力，救不了的人即使拼尽全力也救不了… | M40: -20,0 | N40: 6.9 | O40: 52 | P40: 0 | V40: 3 | W40: 放松 | X40: =IF(ISBLANK(W40),"",VLOOKUP($W40,Sheet2!$A$2:$E$29,3,FALSE)) -> UI_icon_teshudognzuo_04 | Y40: =IF(ISBLANK(W40),"",VLOOKUP($W40,Sheet2!$A$2:$E$29,4,FALSE)) -> BQ_mood04
A41: =ROW()-6 -> 35 | B41: =B36+1 -> 113007 | C41: mood04 | D41: =X41 -> UI_icon_teshudognzuo_28 | E41: =W41 -> 玩 | F41: CV_borsalinoCZ_zhenrong_03 | I41: 0 | J41: 0 | K41: 1 | L41: 我是“闪光果实”的“闪光人” | M41: -20,0 | N41: 6.7 | O41: 52 | P41: 0 | V41: 4 | W41: 玩 | X41: =IF(ISBLANK(W41),"",VLOOKUP($W41,Sheet2!$A$2:$E$29,3,FALSE)) -> UI_icon_teshudognzuo_28 | Y41: =IF(ISBLANK(W41),"",VLOOKUP($W41,Sheet2!$A$2:$E$29,4,FALSE)) -> BQ_mood28
...

Sheet Sheet2
A1: txt | B1: icon | D1: 文本key | E1: txt
A2: 认同 | C2: UI_icon_teshudognzuo_01 | D2: BQ_mood01 | E2: =A2 -> 认同
A3: 拒绝 | C3: UI_icon_teshudognzuo_02 | D3: BQ_mood02 | E3: =A3 -> 拒绝
A4: 打招呼 | C4: UI_icon_teshudognzuo_03 | D4: BQ_mood03 | E4: =A4 -> 打招呼
A5: 放松 | C5: UI_icon_teshudognzuo_04 | D5: BQ_mood04 | E5: =A5 -> 放松
A6: 示威 | C6: UI_icon_teshudognzuo_05 | D6: BQ_mood05 | E6: =A6 -> 示威
A7: 行礼 | C7: UI_icon_teshudognzuo_06 | D7: BQ_mood06 | E7: =A7 -> 行礼
A8: 观望 | C8: UI_icon_teshudognzuo_07 | D8: BQ_mood07 | E8: =A8 -> 观望
A9: 休闲 | C9: UI_icon_teshudognzuo_08 | D9: BQ_mood08 | E9: =A9 -> 休闲
A10: 点头 | C10: UI_icon_teshudognzuo_09 | D10: BQ_mood09 | E10: =A10 -> 点头
A11: 生气 | C11: UI_icon_teshudognzuo_10 | D11: BQ_mood10 | E11: =A11 -> 生气
A12: 招手 | C12: UI_icon_teshudognzuo_11 | D12: BQ_mood11 | E12: =A12 -> 招手
A13: 迷茫 | C13: UI_icon_teshudognzuo_12 | D13: BQ_mood12 | E13: =A13 -> 迷茫
... A29: 玩 | C29: UI_icon_teshudognzuo_28 | D29: BQ_mood28 | E29: =A29 -> 玩

Sheet Sheet3
B1: mood01
B2: mood02
B3: mood03
B4: mood04
B5: mood05
B6: mood06
B7: mood01
B8: mood02
B9: mood03
B10: mood04
B11: mood05
B12: mood01
... B280: mood05

Sheet Sheet4
G7: heroId | H7: fashionId
G8: 1 | H8: 1
G9: 1 | H9: 0
G10: 0 | H10: 1
A21: =ROW()-6 -> 15 | B21: 113078 | C21: mood01 | D21: =IF(ISBLANK(C21),"",VLOOKUP($W21,Sheet2!$A$2:$E$29,3,FALSE)) -> UI_icon_teshudognzuo_05 | E21: =W21 -> 示威 | F21: CV_JieKe06 | I21: 1 | J21: 0 | K21: 1 | L21: 混账东西，这仗打定了啊。 | O21: 4015306 | P21: 1 | U21: 杰克人兽型变身时装 | W21: 示威 | X21: =IF(ISBLANK(W21),"",VLOOKUP($W21,Sheet2!$A$2:$E$29,3,FALSE)) -> UI_icon_teshudognzuo_05 | Y21: =IF(ISBLANK(W21),"",VLOOKUP($W21,Sheet2!$A$2:$E$29,4,FALSE)) -> BQ_mood05
A22: =ROW()-6 -> 16 | B22: 113078 | C22: mood02 | D22: =IF(ISBLANK(C22),"",VLOOKUP($W22,Sheet2!$A$2:$E$29,3,FALSE)) -> UI_icon_teshudognzuo_07 | E22: =W22 -> 观望 | F22: CV_JieKe07 | I22: 1 | J22: 0 | K22: 1 | L22: 我们是来跟他们打商量的吗？ | O22: 4015306 | P22: 1 | W22: 观望 | X22: =IF(ISBLANK(W22),"",VLOOKUP($W22,Sheet2!$A$2:$E$29,3,FALSE)) -> UI_icon_teshudognzuo_07 | Y22: =IF(ISBLANK(W22),"",VLOOKUP($W22,Sheet2!$A$2:$E$29,4,FALSE)) -> BQ_mood07
A23: =ROW()-6 -> 17 | B23: 113078 | C23: mood03 | D23: =IF(ISBLANK(C23),"",VLOOKUP($W23,Sheet2!$A$2:$E$29,3,FALSE)) -> UI_icon_teshudognzuo_10 | E23: =W23 -> 生气 | F23: CV_JieKe08 | I23: 1 | J23: 0 | K23: 1 | L23: “GIFTERS”，给我上！！！ | O23: 4015306 | P23: 1 | W23: 生气 | X23: =IF(ISBLANK(W23),"",VLOOKUP($W23,Sheet2!$A$2:$E$29,3,FALSE)) -> UI_icon_teshudognzuo_10 | Y23: =IF(ISBLANK(W23),"",VLOOKUP($W23,Sheet2!$A$2:$E$29,4,FALSE)) -> BQ_mood10
A24: =ROW()-6 -> 18 | B24: 113078 | C24: mood04 | D24: =IF(ISBLANK(C24),"",VLOOKUP($W24,Sheet2!$A$2:$E$29,3,FALSE)) -> UI_icon_teshudognzuo_15 | E24: =W24 -> 不屑 | I24: 1 | J24: 0 | K24: 1 | O24: 4015306 | P24: 1 | W24: 不屑 | X24: =IF(ISBLANK(W24),"",VLOOKUP($W24,Sheet2!$A$2:$E$29,3,FALSE)) -> UI_icon_teshudognzuo_15 | Y24: =IF(ISBLANK(W24),"",VLOOKUP($W24,Sheet2!$A$2:$E$29,4,FALSE)) -> BQ_mood15
A25: =ROW()-6 -> 19 | B25: 113078 | C25: mood05 | D25: =IF(ISBLANK(C25),"",VLOOKUP($W25,Sheet2!$A$2:$E$29,3,FALSE)) -> UI_icon_teshudognzuo_02 | E25: =W25 -> 拒绝 | F25: CV_JieKe03 | I25: 1 | J25: 0 | K25: 1 | L25: 谈过之后…………？我拒绝。 | O25: 4015306 | P25: 1 | W25: 拒绝 | X25: =IF(ISBLANK(W25),"",VLOOKUP($W25,Sheet2!$A$2:$E$29,3,FALSE)) -> UI_icon_teshudognzuo_02 | Y25: =IF(ISBLANK(W25),"",VLOOKUP($W25,Sheet2!$A$2:$E$29,4,FALSE)) -> BQ_mood02
A26: =ROW()-6 -> 20 | B26: 113078 | C26: mood06 | D26: =IF(ISBLANK(C26),"",VLOOKUP($W26,Sheet2!$A$2:$E$29,3,FALSE)) -> UI_icon_teshudognzuo_27 | E26: =W26 -> 秀 | I26: 0 | J26: 1 | K26: 0 | O26: 4015306 | P26: 0 | S26: 1,8 | W26: 秀 | X26: =IF(ISBLANK(W26),"",VLOOKUP($W26,Sheet2!$A$2:$E$29,3,FALSE)) -> UI_icon_teshudognzuo_27 | Y26: =IF(ISBLANK(W26),"",VLOOKUP($W26,Sheet2!$A$2:$E$29,4,FALSE)) -> BQ_mood27
A27: =ROW()-6 -> 21 | B27: 113078 | C27: mood07 | D27: =IF(ISBLANK(C27),"",VLOOKUP($W27,Sheet2!$A$2:$E$29,3,FALSE)) -> UI_icon_teshudognzuo_27 | E27: =W27 -> 秀 | I27: 0 | J27: 1 | K27: 0 | O27: 4015306 | P27: 0 | S27: 2,3 | W27: 秀 | X27: =IF(ISBLANK(W27),"",VLOOKUP($W27,Sheet2!$A$2:$E$29,3,FALSE)) -> UI_icon_teshudognzuo_27 | Y27: =IF(ISBLANK(W27),"",VLOOKUP($W27,Sheet2!$A$2:$E$29,4,FALSE)) -> BQ_mood27
A28: =ROW()-6 -> 22 | B28: 113078 | C28: ridemood01 | D28: =IF(ISBLANK(C28),"",VLOOKUP($W28,Sheet2!$A$2:$E$29,3,FALSE)) -> UI_icon_teshudognzuo_28 | E28: =W28 -> 玩 | I28: 1 | O28: 4015306 | R28: 1 | W28: 玩 | X28: =IF(ISBLANK(W28),"",VLOOKUP($W28,Sheet2!$A$2:$E$29,3,FALSE)) -> UI_icon_teshudognzuo_28 | Y28: =IF(ISBLANK(W28),"",VLOOKUP($W28,Sheet2!$A$2:$E$29,4,FALSE)) -> BQ_mood28
A29: =ROW()-6 -> 23 | B29: 113079 | C29: mood01 | D29: =IF(ISBLANK(C29),"",VLOOKUP($W29,Sheet2!$A$2:$E$29,3,FALSE)) -> UI_icon_teshudognzuo_05 | E29: =W29 -> 示威 | F29: CV_KuiYin_05 | I29: 1 | J29: 0 | K29: 1 | L29: 这个白痴！！ | O29: 4015307 | P29: 1 | U29: 昆因人兽型变身时装 | W29: 示威 | X29: =IF(ISBLANK(W29),"",VLOOKUP($W29,Sheet2!$A$2:$E$29,3,FALSE)) -> UI_icon_teshudognzuo_05 | Y29: =IF(ISBLANK(W29),"",VLOOKUP($W29,Sheet2!$A$2:$E$29,4,FALSE)) -> BQ_mood05
A30: =ROW()-6 -> 24 | B30: 113079 | C30: mood02 | D30: =IF(ISBLANK(C30),"",VLOOKUP($W30,Sheet2!$A$2:$E$29,3,FALSE)) -> UI_icon_teshudognzuo_07 | E30: =W30 -> 观望 | F30: CV_KuiYin_07 | I30: 1 | J30: 0 | K30: 1 | L30: 嗯？你问我要多少碗红豆汤？笨蛋！红豆汤可是我的氧气！！ | O30: 4015307 | P30: 1 | W30: 观望 | X30: =IF(ISBLANK(W30),"",VLOOKUP($W30,Sheet2!$A$2:$E$29,3,FALSE)) -> UI_icon_teshudognzuo_07 | Y30: =IF(ISBLANK(W30),"",VLOOKUP($W30,Sheet2!$A$2:$E$29,4,FALSE)) -> BQ_mood07
A31: =ROW()-6 -> 25 | B31: 113079 | C31: mood03 | D31: =IF(ISBLANK(C31),"",VLOOKUP($W31,Sheet2!$A$2:$E$29,3,FALSE)) -> UI_icon_teshudognzuo_15 | E31: =W31 -> 不屑 | F31: CV_KuiYin_04 | I31: 1 | J31: 0 | K31: 1 | L31: 我的最佳杰作！！ | O31: 4015307 | P31: 1 | W31: 不屑 | X31: =IF(ISBLANK(W31),"",VLOOKUP($W31,Sheet2!$A$2:$E$29,3,FALSE)) -> UI_icon_teshudognzuo_15 | Y31: =IF(ISBLANK(W31),"",VLOOKUP($W31,Sheet2!$A$2:$E$29,4,FALSE)) -> BQ_mood15
A32: =ROW()-6 -> 26 | B32: 113079 | C32: mood04 | D32: =IF(ISBLANK(C32),"",VLOOKUP($W32,Sheet2!$A$2:$E$29,3,FALSE)) -> UI_icon_teshudognzuo_02 | E32: =W32 -> 拒绝 | I32: 1 | J32: 0 | K32: 1 | O32: 4015307 | P32: 1 | W32: 拒绝 | X32: =IF(ISBLANK(W32),"",VLOOKUP($W32,Sheet2!$A$2:$E$29,3,FALSE)) -> UI_icon_teshudognzuo_02 | Y32: =IF(ISBLANK(W32),"",VLOOKUP($W32,Sheet2!$A$2:$E$29,4,FALSE)) -> BQ_mood02
A33: =ROW()-6 -> 27 | B33: 113079 | C33: mood05 | D33: =IF(ISBLANK(C33),"",VLOOKUP($W33,Sheet2!$A$2:$E$29,3,FALSE)) -> UI_icon_teshudognzuo_04 | E33: =W33 -> 放松 | F33: CV_KuiYin_09 | I33: 1 | J33: 0 | K33: 1 | L33: 去死！！ | O33: 4015307 | P33: 1 | W33: 放松 | X33: =IF(ISBLANK(W33),"",VLOOKUP($W33,Sheet2!$A$2:$E$29,3,FALSE)) -> UI_icon_teshudognzuo_04 | Y33: =IF(ISBLANK(W33),"",VLOOKUP($W33,Sheet2!$A$2:$E$29,4,FALSE)) -> BQ_mood04
A34: =ROW()-6 -> 28 | B34: 113079 | C34: mood06 | D34: =IF(ISBLANK(C34),"",VLOOKUP($W34,Sheet2!$A$2:$E$29,3,FALSE)) -> UI_icon_teshudognzuo_27 | E34: =W34 -> 秀 | I34: 0 | J34: 1 | K34: 0 | O34: 4015307 | P34: 0 | S34: 1,8 | W34: 秀 | X34: =IF(ISBLANK(W34),"",VLOOKUP($W34,Sheet2!$A$2:$E$29,3,FALSE)) -> UI_icon_teshudognzuo_27 | Y34: =IF(ISBLANK(W34),"",VLOOKUP($W34,Sheet2!$A$2:$E$29,4,FALSE)) -> BQ_mood27
A35: =ROW()-6 -> 29 | B35: 113079 | C35: mood07 | D35: =IF(ISBLANK(C35),"",VLOOKUP($W35,Sheet2!$A$2:$E$29,3,FALSE)) -> UI_icon_teshudognzuo_27 | E35: =W35 -> 秀 | I35: 0 | J35: 1 | K35: 0 | O35: 4015307 | P35: 0 | S35: 2,3 | W35: 秀 | X35: =IF(ISBLANK(W35),"",VLOOKUP($W35,Sheet2!$A$2:$E$29,3,FALSE)) -> UI_icon_teshudognzuo_27 | Y35: =IF(ISBLANK(W35),"",VLOOKUP($W35,Sheet2!$A$2:$E$29,4,FALSE)) -> BQ_mood27
A36: =ROW()-6 -> 30 | B36: 113079 | C36: ridemood01 | D36: =IF(ISBLANK(C36),"",VLOOKUP($W36,Sheet2!$A$2:$E$29,3,FALSE)) -> UI_icon_teshudognzuo_28 | E36: =W36 -> 玩 | I36: 1 | O36: 4015307 | R36: 1 | W36: 玩 | X36: =IF(ISBLANK(W36),"",VLOOKUP($W36,Sheet2!$A$2:$E$29,3,FALSE)) -> UI_icon_teshudognzuo_28 | Y36: =IF(ISBLANK(W36),"",VLOOKUP($W36,Sheet2!$A$2:$E$29,4,FALSE)) -> BQ_mood28
A37: =ROW()-6 -> 31 | B37: 113083 | C37: mood01 | D37: =IF(ISBLANK(C37),"",VLOOKUP($W37,Sheet2!$A$2:$E$29,3,FALSE)) -> UI_icon_teshudognzuo_04 | E37: =W37 -> 放松 | F37: CV_Jin04 | I37: 1 | J37: 0 | K37: 1 | L37: 杀了你 | O37: 4015308 | P37: 1 | U37: 烬人兽型变身时装 | W37: 放松 | X37: =IF(ISBLANK(W37),"",VLOOKUP($W37,Sheet2!$A$2:$E$29,3,FALSE)) -> UI_icon_teshudognzuo_04 | Y37: =IF(ISBLANK(W37),"",VLOOKUP($W37,Sheet2!$A$2:$E$29,4,FALSE)) -> BQ_mood04
A38: =ROW()-6 -> 32 | B38: 113083 | C38: mood02 | D38: =IF(ISBLANK(C38),"",VLOOKUP($W38,Sheet2!$A$2:$E$29,3,FALSE)) -> UI_icon_teshudognzuo_07 | E38: =W38 -> 观望 | F38: CV_Jin06 | I38: 1 | J38: 0 | K38: 1 | O38: 4015308 | P38: 1 | W38: 观望 | X38: =IF(ISBLANK(W38),"",VLOOKUP($W38,Sheet2!$A$2:$E$29,3,FALSE)) -> UI_icon_teshudognzuo_07 | Y38: =IF(ISBLANK(W38),"",VLOOKUP($W38,Sheet2!$A$2:$E$29,4,FALSE)) -> BQ_mood07
A39: =ROW()-6 -> 33 | B39: 113083 | C39: mood03 | D39: =IF(ISBLANK(C39),"",VLOOKUP($W39,Sheet2!$A$2:$E$29,3,FALSE)) -> UI_icon_teshudognzuo_08 | E39: =W39 -> 休闲 | F39: CV_Jin07 | I39: 1 | J39: 0 | K39: 1 | L39: 着急送死啊 | O39: 4015308 | P39: 1 | W39: 休闲 | X39: =IF(ISBLANK(W39),"",VLOOKUP($W39,Sheet2!$A$2:$E$29,3,FALSE)) -> UI_icon_teshudognzuo_08 | Y39: =IF(ISBLANK(W39),"",VLOOKUP($W39,Sheet2!$A$2:$E$29,4,FALSE)) -> BQ_mood08
A40: =ROW()-6 -> 34 | B40: 113083 | C40: mood04 | D40: =IF(ISBLANK(C40),"",VLOOKUP($W40,Sheet2!$A$2:$E$29,3,FALSE)) -> UI_icon_teshudognzuo_15 | E40: =W40 -> 不屑 | F40: CV_Jin03 | I40: 1 | J40: 0 | K40: 1 | L40: 我一个人就够了 | O40: 4015308 | P40: 1 | W40: 不屑 | X40: =IF(ISBLANK(W40),"",VLOOKUP($W40,Sheet2!$A$2:$E$29,3,FALSE)) -> UI_icon_teshudognzuo_15 | Y40: =IF(ISBLANK(W40),"",VLOOKUP($W40,Sheet2!$A$2:$E$29,4,FALSE)) -> BQ_mood15
A41: =ROW()-6 -> 35 | B41: 113083 | C41: mood05 | D41: =IF(ISBLANK(C41),"",VLOOKUP($W41,Sheet2!$A$2:$E$29,3,FALSE)) -> UI_icon_teshudognzuo_02 | E41: =W41 -> 拒绝 | F41: CV_Jin05 | I41: 1 | J41: 0 | K41: 1 | L41: 在那儿别动 | O41: 4015308 | P41: 1 | W41: 拒绝 | X41: =IF(ISBLANK(W41),"",VLOOKUP($W41,Sheet2!$A$2:$E$29,3,FALSE)) -> UI_icon_teshudognzuo_02 | Y41: =IF(ISBLANK(W41),"",VLOOKUP($W41,Sheet2!$A$2:$E$29,4,FALSE)) -> BQ_mood02
A42: =ROW()-6 -> 36 | B42: 113083 | C42: mood06 | D42: =IF(ISBLANK(C42),"",VLOOKUP($W42,Sheet2!$A$2:$E$29,3,FALSE)) -> UI_icon_teshudognzuo_27 | E42: =W42 -> 秀 | I42: 0 | J42: 1 | K42: 0 | O42: 4015308 | P42: 0 | S42: 1,8 | W42: 秀 | X42: =IF(ISBLANK(W42),"",VLOOKUP($W42,Sheet2!$A$2:$E$29,3,FALSE)) -> UI_icon_teshudognzuo_27 | Y42: =IF(ISBLANK(W42),"",VLOOKUP($W42,Sheet2!$A$2:$E$29,4,FALSE)) -> BQ_mood27
A43: =ROW()-6 -> 37 | B43: 113083 | C43: ridemood01 | D43: =IF(ISBLANK(C43),"",VLOOKUP($W43,Sheet2!$A$2:$E$29,3,FALSE)) -> UI_icon_teshudognzuo_28 | E43: =W43 -> 玩 | I43: 1 | O43: 4015308 | R43: 1 | W43: 玩 | X43: =IF(ISBLANK(W43),"",VLOOKUP($W43,Sheet2!$A$2:$E$29,3,FALSE)) -> UI_icon_teshudognzuo_28 | Y43: =IF(ISBLANK(W43),"",VLOOKUP($W43,Sheet2!$A$2:$E$29,4,FALSE)) -> BQ_mood28
A44: =ROW()-6 -> 38 | B44: 113083 | C44: mood07 | D44: =X44 -> UI_icon_teshudognzuo_27 | E44: =W44 -> 秀 | I44: 0 | J44: 1 | K44: 0 | O44: 4015308 | P44: 0 | S44: 2,3 | U44: 烬人兽型变身时装觉醒专属 | W44: 秀 | X44: =IF(ISBLANK(W44),"",VLOOKUP($W44,[3]Sheet2!$A$2:$E$29,3,FALSE)) -> UI_icon_teshudognzuo_27 | Y44: =IF(ISBLANK(W44),"",VLOOKUP($W44,[3]Sheet2!$A$2:$E$29,4,FALSE)) -> BQ_mood27
