Workbook

Sheet Sheet1
A1: 7 | B1: 1 | C1: 9999 | D1: 45
A2: 物品id | B2: 物品大类型 | C2: 物品子类型 | D2: 背包类型 | E2: 名字 | F2: 名字文本 | G2: 描述文本 | H2: 图标 | I2: 物品使用等级 | J2: 物品品质 | K2: 类别 | L2: 堆叠数量 | M2: 使用CD（秒） | N2: 功能 | O2: 功能扩展字段 | P2: 获得途径（弃用） | Q2: 获取途径跳转 | R2: 获取途径描述（弃用） | S2: 是否可以回收 | T2: 回收货币类型 | U2: 回收价格 | V2: 绑定类型 | W2: 是否可移仓库 | X2: 是否通过邮件拾取 | Y2: 是否为贵重物品 | Z2: 是否可以交易 | AA2: 回购货币类型 | AB2: 回购价格 | AC2: 排序权重 | AD2: 药品自动使用 | AE2: 可使用物品的展示类型 | AF2: 使用结果展示 | AG2: 公共CD类型 | AH2: 公共CD(秒) | AI2: 过期时间 | AJ2: 合成目标Id | AK2: 限制玩家单次获取最大值 | AL2: 是否显示绑定按钮 | AM2: 左上显示等级(宝石在宝石表里)，目前仅训练道具使用。 | AN2: 获取途径规则修改 | AO2: 物品属性类型显示索引() | AP2: 是否需要删除 | AQ2: 名字-AP2 | AR2: 可否由BI配置过期时间 | AS2: 防盖表经典怀旧判断
A3: itemId | B3: itemType | C3: itemSubType | D3: bagType | F3: nameIndex | G3: introIndex | I3: useLevel | J3: quality | K3: category | L3: foldCount | M3: cd | N3: function | O3: params | P3: resource | R3: resourceDes | S3: canSell | T3: currencyType | U3: sellPrice | V3: bindType | W3: cantoWarehourse | X3: pickupByMail | Y3: isPrecious | Z3: canDeal | AA3: buyBackType | AB3: buyBackPrice | AC3: sort | AG3: commonCdType | AH3: commonCd | AI3: expiredTime | AJ3: combineId | AK3: limitNum | AP3: needDelete | AR3: canDeployExpireTime | AS3: dictServerType
A4: int | B4: int | C4: int | D4: int | F4: string(intern) | G4: string(intern) | H4: string(intern) | I4: int | J4: int | K4: int | L4: int | M4: int | N4: int | O4: string | P4: string(intern) | Q4: string | R4: string(intern) | S4: int | T4: int | U4: int | V4: int | W4: int | X4: int | Y4: int | Z4: int | AA4: int | AB4: int | AC4: int | AD4: int | AE4: int | AF4: int | AG4: int | AH4: int | AI4: string | AJ4: int | AK4: int | AL4: int | AM4: int | AN4: string(intern) | AO4: string(intern) | AP4: int | AR4: int | AS4: int
A5: primary | B5: none | C5: index | D5: none | F5: none | G5: none | H5: none | I5: none | J5: none | K5: none | L5: none | M5: none | N5: none | O5: none | P5: none | Q5: none | R5: none | S5: none | T5: none | U5: none | V5: none | W5: none | X5: none | Y5: none | Z5: none | AA5: none | AB5: none | AC5: none | AD5: none | AE5: none | AF5: none | AG5: none | AH5: none | AI5: none | AJ5: none | AK5: none | AL5: none | AM5: none | AN5: none | AO5: none | AP5: none | AR5: none | AS5: none
A6: itemId | B6: itemType | C6: itemSubType | D6: bagType | F6: nameIndex | G6: introIndex | I6: useLevel | J6: quality | K6: category | L6: foldCount | M6: cd | N6: function | O6: params | P6: resource | R6: resourceDes | S6: canSell | T6: currencyType | U6: sellPrice | V6: bindType | W6: cantoWarehourse | X6: pickupByMail | Y6: isPrecious | Z6: canDeal | AA6: buyBackType | AB6: buyBackPrice | AC6: sort | AG6: commonCdType | AH6: commonCd | AI6: expiredTime | AJ6: combineId | AK6: limitNum | AP6: needDelete | AR6: canDeployExpireTime | AS6: dictServerType
A7: 112001 | B7: 1001 | C7: 1 | D7: 1001 | E7: 经验卷轴 | F7: 经验卷轴 | G7: 经验道具，用于增加角色经验。 | H7: item_112001 | I7: 1 | J7: 4 | K7: 1 | L7: 999 | S7: 0 | T7: 5 | U7: 10 | V7: 1 | W7: 0 | X7: 0 | Y7: 0 | Z7: 0 | AA7: 5 | AB7: 20 | AC7: 999 | AS7: 1
A8: 112002 | B8: 1001 | C8: 1 | D8: 1001 | E8: 精炼石 | F8: 精炼石 | G8: 装备精炼道具，用于提高装备的精炼等级。 | H8: item_112002 | I8: 1 | J8: 4 | K8: 1 | L8: 999 | S8: 1 | T8: 5 | U8: 10 | V8: 1 | W8: 0 | X8: 0 | Y8: 0 | Z8: 0 | AA8: 5 | AB8: 200 | AC8: 999 | AS8: 1
A9: 112003 | B9: 1001 | C9: 1 | D9: 1001 | E9: 招募券 | F9: 招募券 | G9: 招募道具，用于在招募界面进行船员招募。 | H9: item_112003 | I9: 1 | J9: 4 | K9: 1 | L9: 999 | S9: 0 | T9: 5 | U9: 10 | V9: 1 | W9: 0 | X9: 0 | Y9: 0 | Z9: 0 | AA9: 5 | AB9: 20 | AC9: 999 | AS9: 1
A10: 112004 | B10: 1001 | C10: 1 | D10: 1001 | E10: 秘传书 | F10: 秘传书 | G10: 可以增加角色的技能点，用于技能升级。 | H10: item_112004 | I10: 1 | J10: 4 | K10: 1 | L10: 999 | S10: 0 | T10: 5 | U10: 10 | V10: 1 | W10: 0 | X10: 0 | Y10: 0 | Z10: 0 | AA10: 5 | AB10: 20 | AC10: 999 | AS10: 1
A11: 122001 | B11: 1001 | C11: 1 | D11: 1001 | E11: 蓝钻 | F11: 蓝钻 | G11: 航海王中珍贵的货币，可用于购买活动次数、商城兑换等。 | H11: item_122001 | I11: 1 | J11: 4 | K11: 1 | L11: 999 | S11: 0 | T11: 5 | U11: 10 | V11: 1 | W11: 0 | X11: 0 | Y11: 0 | Z11: 0 | AA11: 5 | AB11: 20 | AC11: 999 | AP11: 1 | AS11: 1
A12: 122002 | B12: 1001 | C12: 1 | D12: 1001 | E12: 经验 | F12: 经验 | G12: 玩家和角色升级所需的经验。 | H12: item_122002 | I12: 1 | J12: 4 | K12: 1 | L12: 999 | S12: 0 | T12: 5 | U12: 10 | V12: 1 | W12: 0 | X12: 0 | Y12: 0 | Z12: 0 | AA12: 5 | AB12: 20 | AC12: 999 | AS12: 1
A13: 122003 | B13: 1001 | C13: 1 | D13: 1001 | E13: 金块 | F13: 金块 | G13: 航海王中常用的货币，用于日常消费。 | H13: item_122003 | I13: 1 | J13: 4 | K13: 1 | L13: 999 | S13: 0 | T13: 5 | U13: 10 | V13: 1 | W13: 0 | X13: 0 | Y13: 0 | Z13: 0 | AA13: 5 | AB13: 20 | AC13: 999 | AS13: 1
A14: 122004 | B14: 1001 | C14: 1 | D14: 1001 | E14: 千里阳光号 | F14: 千里阳光号 | G14: 由宝树亚当制成的草帽一伙的海盗船！是穿越千里大海的梦想之船。 | H14: ship_icon_10_1 | I14: 1 | J14: 2 | K14: 2 | L14: 999 | N14: 1026 | O14: 130006 | S14: 0 | T14: 5 | U14: 10 | V14: 0 | W14: 0 | X14: 1 | Y14: 0 | Z14: 0 | AA14: 5 | AB14: 20 | AC14: 300 | AE14: 1 | AF14: 2 | AS14: 1
A15: 122005 | B15: 1001 | C15: 1 | D15: 1001 | E15: 海军战舰 | F15: 海军战舰 | G15: 为将目标全部粉碎的大型军舰。由海军总部中将担任指挥。 | H15: ship_icon_8_1 | I15: 1 | J15: 3 | K15: 2 | L15: 999 | N15: 1026 | O15: 130009 | S15: 0 | T15: 5 | U15: 10 | V15: 0 | W15: 0 | X15: 1 | Y15: 0 | Z15: 0 | AA15: 5 | AB15: 200 | AC15: 300 | AE15: 1 | AF15: 2 | AS15: 1
A16: 122006 | B16: 1001 | C16: 1 | D16: 1001 | E16: 黄金梅丽号 | F16: 黄金梅丽号 | G16: 伴随草帽海盗团的成长，是草帽一伙形影不离、不可或缺的伙伴。 | H16: ship_icon_3_1 | I16: 1 | J16: 1 | K16: 2 | L16: 999 | N16: 1026 | O16: 130002 | S16: 0 | T16: 5 | U16: 10 | V16: 0 | W16: 0 | X16: 1 | Y16: 0 | Z16: 0 | AA16: 5 | AB16: 200 | AC16: 300 | AE16: 1 | AF16: 2 | AS16: 1
A17: 122007 | B17: 1001 | C17: 1 | D17: 1001 | E17: 黑色战士号 | F17: 黑色战士号 | G17: 黑猫海盗团的船，标志就是船头的黑猫，是船长克洛的标志。 | H17: ship_icon_4_1 | I17: 1 | J17: 1 | K17: 2 | L17: 999 | N17: 1026 | O17: 130003 | S17: 0 | T17: 5 | U17: 10 | V17: 0 | W17: 0 | X17: 1 | Y17: 0 | Z17: 0 | AA17: 5 | AB17: 200 | AC17: 300 | AE17: 1 | AF17: 2 | AS17: 1
A18: 122008 | B18: 1001 | C18: 1 | D18: 1001 | E18: 海军军舰 | F18: 海军军舰 | G18: 标准的海军船。装备有和总部联络用的各种电话虫。 | H18: ship_icon_7_1 | I18: 1 | J18: 1 | K18: 2 | L18: 999 | N18: 1026 | O18: 130004 | S18: 0 | T18: 5 | U18: 10 | V18: 0 | W18: 0 | X18: 1 | Y18: 0 | Z18: 0 | AA18: 5 | AB18: 200 | AC18: 300 | AE18: 1 | AF18: 2 | AS18: 1
A19: 122009 | B19: 1001 | C19: 1 | D19: 1001 | E19: 可爱小鸭号 | F19: 可爱小鸭号 | G19: 船头是一只可爱的天鹅，船帆有“2”的标志，是Mr.2的船。 | H19: ship_icon_6_1 | I19: 1 | J19: 2 | K19: 2 | L19: 999 | N19: 1026 | O19: 130005 | S19: 0 | T19: 5 | U19: 10 | V19: 0 | W19: 0 | X19: 1 | Y19: 0 | Z19: 0 | AA19: 5 | AB19: 200 | AC19: 300 | AE19: 1 | AF19: 2 | AS19: 1
A20: 122010 | B20: 1001 | C20: 1 | D20: 1001 | E20: 性感福克斯号 | F20: 性感福克斯号 | G20: 福克斯海盗团的船。船首和海盗旗、锁链等，都是醒目的狐狸标记。 | H20: ship_icon_5_1 | I20: 1 | J20: 2 | K20: 2 | L20: 999 | N20: 1026 | O20: 130007 | S20: 0 | T20: 5 | U20: 10 | V20: 0 | W20: 0 | X20: 1 | Y20: 0 | Z20: 0 | AA20: 5 | AB20: 200 | AC20: 300 | AE20: 1 | AF20: 2 | AS20: 1
A21: 122011 | B21: 1001 | C21: 1 | D21: 1001 | E21: 黑胡子木筏 | F21: 黑胡子木筏 | G21: 黑胡子一伙的标志性木筏。在四周都设有大炮。 | H21: ship_icon_9_1 | I21: 1 | J21: 3 | K21: 2 | L21: 999 | N21: 1026 | O21: 130008 | S21: 0 | T21: 5 | U21: 10 | V21: 0 | W21: 0 | X21: 1 | Y21: 0 | Z21: 0 | AA21: 5 | AB21: 200 | AC21: 300 | AE21: 1 | AF21: 2 | AS21: 1
A22: 122012 | B22: 1001 | C22: 1 | D22: 1001 | E22: 九蛇海盗船 | F22: 九蛇海盗船 | G22: 汉库珂所率领的九蛇海盗团的船。船头设有毒蛇，保护轮船不受敌人攻击。 | H22: ship_icon_11_1 | I22: 1 | J22: 5 | K22: 2 | L22: 999 | N22: 1026 | O22: 130010 | S22: 0 | T22: 5 | U22: 10 | V22: 0 | W22: 0 | X22: 1 | Y22: 0 | Z22: 0 | AA22: 5 | AB22: 200 | AC22: 300 | AE22: 1 | AF22: 2 | AS22: 1
A23: 122013 | B23: 1001 | C23: 1 | D23: 1001 | E23: 雷德·佛斯号 | F23: 雷德·佛斯号 | G23: 航行在新世界的后半段，以龙形船首为特征的杰克斯海盗团的船。 | H23: ship_icon_12_1 | I23: 1 | J23: 5 | K23: 2 | L23: 999 | N23: 1026 | O23: 130011 | S23: 0 | T23: 5 | U23: 10 | V23: 0 | W23: 0 | X23: 1 | Y23: 0 | Z23: 0 | AA23: 5 | AB23: 200 | AC23: 300 | AE23: 1 | AF23: 2 | AS23: 1
A24: 122014 | B24: 1001 | C24: 1 | D24: 1001 | E24: 巴拉蒂 | F24: 巴拉蒂 | G24: 漂浮在“东海”上的巨大海上餐厅。除了餐厅以外，还设有宽敞的厨房和储藏间。 | H24: ship_icon_13_1 | I24: 1 | J24: 3 | K24: 2 | L24: 999 | N24: 1026 | O24: 130012 | S24: 0 | T24: 5 | U24: 10 | V24: 0 | W24: 0 | X24: 1 | Y24: 0 | Z24: 0 | AA24: 5 | AB24: 200 | AC24: 300 | AE24: 1 | AF24: 2 | AS24: 1
A25: 122015 | B25: 1001 | C25: 1 | D25: 1001 | E25: 革命军船 | F25: 风·格拉玛号 | G25: 在各地不断掀起叛乱的，龙率领武装组织的船。以漆黑船体和龙头船首为特征的母舰。 | H25: ship_icon_19_1 | I25: 1 | J25: 5 | K25: 2 | L25: 999 | N25: 1026 | O25: 130013 | S25: 0 | T25: 5 | U25: 10 | V25: 0 | W25: 0 | X25: 1 | Y25: 0 | Z25: 0 | AA25: 5 | AB25: 200 | AC25: 300 | AE25: 1 | AF25: 2 | AS25: 1
... A43: 122038 | B43: 1001 | C43: 1 | D43: 1001 | E43: 吉贝克之剑号 | F43: 吉贝克之剑号 | G43: 黑胡子海贼团的主力战舰，承载着黑胡子颠覆大海的野心，追逐着最极致的宝藏。 | H43: ship_icon_36_1 | I43: 1 | J43: 5 | K43: 2 | L43: 999 | N43: 1026 | O43: 130034 | S43: 0 | T43: 5 | U43: 10 | V43: 0 | W43: 0 | X43: 1 | Y43: 0 | Z43: 0 | AA43: 5 | AB43: 200 | AC43: 300 | AE43: 1 | AF43: 2 | AS43: 1
A44: 123001 | B44: 1001 | C44: 6 | D44: 1001 | E44: 战船任选 | F44: 战船任选礼盒 | G44: 从风·格拉玛号、雷德·佛斯号、九蛇海盗船、幽灵船、黑桃海盗船中任选一个战船。 | H44: item_box_10 | I44: 1 | J44: 5 | K44: 2 | L44: 999 | M44: 0 | N44: 1018 | O44: 1:1001,122015,1;1001,122013,1;1001,122012,1;1001,122019,1;1001,122020,1 | S44: 0 | T44: 5 | U44: 10 | V44: 0 | W44: 0 | X44: 1 | Y44: 0 | Z44: 0 | AA44: 5 | AB44: 200 | AC44: 56 | AD44: 0 | AE44: 5 | AF44: 2 | AS44: 1
A45: 123002 | B45: 1001 | C45: 6 | D45: 1001 | E45: 阵法任选 | F45: 阵法任选礼盒 | G45: 从激进之阵、曙光之阵、元素之阵、冲击之阵、专注之阵中任选一个阵法图纸。 | H45: item_box_10 | I45: 1 | J45: 5 | K45: 2 | L45: 999 | M45: 0 | N45: 1018 | O45: 1:1001,233034,1;1001,233028,1;1001,233032,1;1001,233030,1;1001,233033,1 | S45: 0 | T45: 5 | U45: 10 | V45: 0 | W45: 0 | X45: 1 | Y45: 0 | Z45: 0 | AA45: 5 | AB45: 200 | AC45: 56 | AD45: 0 | AE45: 5 | AF45: 2 | AS45: 1
A46: 212001 | B46: 1001 | C46: 1 | D46: 1001 | E46: 初级经验卷轴 | F46: 初级经验卷轴 | G46: 记录角色冒险经历的初级经验卷轴，使用后可增加角色500点角色经验。 | H46: item_2001 | I46: 1 | J46: 2 | K46: 1 | L46: 9999 | M46: 0 | N46: 1013 | O46: 500 | P46: copy|1;mallshop|1;npcshop|1 | Q46: 强者挑战|12 | R46: 剧情回顾|从剧情回顾获得。;商城购买|商城购买获得。;NPC商店购买|NPC商店购买获得。 | S46: 1 | T46: 5 | U46: 110 | V46: 1 | W46: 1 | X46: 1 | Y46: 0 | Z46: 0 | AA46: 5 | AB46: 4180 | AC46: 830 | AE46: 0 | AF46: 0 | AH46: 1 | AL46: 1 | AN46: 主要产出途径：<color=#ba3901>经验副本</color> <color=#ba3901>剧情回顾</color> | AQ46: 初级经验卷轴 | AS46: 1
A47: 213001 | B47: 1001 | C47: 1 | D47: 1001 | E47: 中级经验卷轴 | F47: 中级经验卷轴 | G47: 记录角色冒险经历的中级经验卷轴，使用后可增加角色1500点角色经验。 | H47: item_3001 | I47: 1 | J47: 3 | K47: 1 | L47: 9999 | M47: 0 | N47: 1013 | O47: 1500 | P47: copy|1;mallshop|1;npcshop|1 | Q47: 强者挑战|12 | R47: 剧情回顾|从剧情回顾获得。;商城购买|商城购买获得。;NPC商店购买|NPC商店购买获得。 | S47: 1 | T47: 5 | U47: 140 | V47: 1 | W47: 1 | X47: 1 | Y47: 0 | Z47: 0 | AA47: 5 | AB47: 5320 | AC47: 830 | AE47: 0 | AF47: 0 | AH47: 1 | AL47: 1 | AN47: 主要产出途径：<color=#ba3901>经验副本</color> <color=#ba3901>剧情回顾</color> | AQ47: 中级经验卷轴 | AS47: 1
A48: 214001 | B48: 1001 | C48: 1 | D48: 1001 | E48: 高级经验卷轴 | F48: 高级经验卷轴 | G48: 记录角色冒险经历的高级经验卷轴，使用后可增加角色3000点角色经验。 | H48: item_4001 | I48: 1 | J48: 4 | K48: 1 | L48: 9999 | M48: 0 | N48: 1013 | O48: 3000 | P48: copy|1;mallshop|1;npcshop|1 | Q48: 强者挑战|12 | R48: 剧情回顾|从剧情回顾获得。;商城购买|商城购买获得。;NPC商店购买|NPC商店购买获得。 | S48: 1 | T48: 5 | U48: 170 | V48: 1 | W48: 1 | X48: 1 | Y48: 0 | Z48: 0 | AA48: 5 | AB48: 6460 | AC48: 830 | AE48: 0 | AF48: 0 | AH48: 1 | AL48: 1 | AN48: 主要产出途径：<color=#ba3901>经验副本</color> | AQ48: 高级经验卷轴 | AS48: 1
A49: 215001 | B49: 1001 | C49: 1 | D49: 1001 | E49: 超级经验卷轴 | F49: 超级经验卷轴 | G49: 记录角色冒险经历的超级经验卷轴，使用后增加角色10000点角色经验。 | H49: item_5001 | I49: 1 | J49: 5 | K49: 1 | L49: 9999 | M49: 0 | N49: 1013 | O49: 10000 | P49: copy|1;mallshop|1;npcshop|1 | Q49: 强者挑战|12 | R49: 剧情回顾|从剧情回顾获得。;商城购买|商城购买获得。;NPC商店购买|NPC商店购买获得。 | S49: 1 | T49: 5 | U49: 200 | V49: 1 | W49: 1 | X49: 1 | Y49: 0 | Z49: 0 | AA49: 5 | AB49: 7600 | AC49: 830 | AE49: 0 | AF49: 0 | AH49: 1 | AL49: 1 | AN49: 主要产出途径：<color=#ba3901>经验副本</color> | AQ49: 超级经验卷轴 | AS49: 1
A50: 216001 | B50: 1001 | C50: 1 | D50: 1001 | E50: 奥义经验卷轴 | F50: 奥义经验卷轴 | G50: 记录角色冒险经历的奥义经验卷轴，使用后增加角色30000点角色经验。 | H50: item_261001 | I50: 1 | J50: 5 | K50: 1 | L50: 9999 | M50: 0 | N50: 1013 | O50: 30000 | P50: copy|1;mallshop|1;npcshop|1 | Q50: 强者挑战|12 | R50: 剧情回顾|从剧情回顾获得。;商城购买|商城购买获得。;NPC商店购买|NPC商店购买获得。 | S50: 1 | T50: 5 | U50: 200 | V50: 1 | W50: 1 | X50: 1 | Y50: 0 | Z50: 0 | AA50: 5 | AB50: 7600 | AC50: 830 | AE50: 0 | AF50: 0 | AH50: 1 | AL50: 1 | AQ50: 奥义经验卷轴 | AS50: 1
A51: 217001 | B51: 1001 | C51: 1 | D51: 1001 | E51: 1 | F51: 1 | G51: 1 | H51: item_1 | I51: 1 | J51: 5 | K51: 1 | L51: 999 | M51: 0 | O51: 1 | S51: 1 | T51: 5 | U51: 200 | V51: 1 | W51: 1 | X51: 1 | Y51: 0 | Z51: 0 | AA51: 5 | AB51: 7600 | AC51: 830 | AE51: 0 | AF51: 0 | AH51: 1 | AL51: 1 | AQ51: 奥义经验卷轴 | AS51: 1
A52: 212002 | B52: 1001 | C52: 8 | D52: 1001 | E52: 低级精炼石 | F52: 初级精炼石 | G52: 稀有的金属矿石，可以用于提高装备精炼等级。 | H52: item_2002 | I52: 1 | J52: 2 | K52: 4 | L52: 9999 | M52: 0 | P52: copy|1;mallshop|1;npcshop|1 | Q52: 航海远征|9;剧情回顾|4 | R52: 剧情回顾|从剧情回顾获得。;商城购买|商城购买获得。;NPC商店购买|NPC商店购买获得。 | S52: 1 | T52: 5 | U52: 110 | V52: 1 | W52: 1 | X52: 1 | Y52: 0 | Z52: 0 | AA52: 5 | AB52: 4180 | AC52: 830 | AE52: 0 | AF52: 0 | AH52: 1 | AJ52: 213002 | AL52: 1 | AN52: 主要产出途径：<color=#ba3901>剧情回顾</color> <color=#ba3901>声望商店</color> | AQ52: 低级精炼石 | AS52: 1
A53: 213002 | B53: 1001 | C53: 8 | D53: 1001 | E53: 中级精炼石 | F53: 中级精炼石 | G53: 稀有的金属矿石，可以用于提高装备精炼等级。 | H53: item_3002 | I53: 1 | J53: 3 | K53: 4 | L53: 9999 | M53: 0 | P53: copy|1;mallshop|1;npcshop|1 | Q53: 航海远征|9;剧情回顾|4 | R53: 剧情回顾|从剧情回顾获得。;商城购买|商城购买获得。;NPC商店购买|NPC商店购买获得。 | S53: 1 | T53: 5 | U53: 140 | V53: 1 | W53: 1 | X53: 1 | Y53: 0 | Z53: 0 | AA53: 5 | AB53: 5320 | AC53: 830 | AE53: 0 | AF53: 0 | AH53: 1 | AJ53: 214002 | AL53: 1 | AN53: 主要产出途径：<color=#ba3901>剧情回顾</color> <color=#ba3901>声望商店</color> | AQ53: 中级精炼石 | AS53: 1
A54: 214002 | B54: 1001 | C54: 8 | D54: 1001 | E54: 高级精炼石 | F54: 高级精炼石 | G54: 稀有的金属矿石，可以用于提高装备精炼等级。 | H54: item_4002 | I54: 1 | J54: 4 | K54: 4 | L54: 9999 | M54: 0 | P54: copy|1;mallshop|1;npcshop|1 | Q54: 航海远征|9;剧情回顾|4 | R54: 剧情回顾|从剧情回顾获得。;商城购买|商城购买获得。;NPC商店购买|NPC商店购买获得。 | S54: 1 | T54: 5 | U54: 170 | V54: 1 | W54: 1 | X54: 1 | Y54: 0 | Z54: 0 | AA54: 5 | AB54: 6460 | AC54: 830 | AD54: 0 | AE54: 0 | AF54: 0 | AH54: 1 | AJ54: 215002 | AL54: 1 | AQ54: 高级精炼石 | AS54: 1
A55: 215002 | B55: 1001 | C55: 8 | D55: 1001 | E55: 超级精炼石 | F55: 超级精炼石 | G55: 稀有的金属矿石，可以用于提高装备精炼等级。 | H55: item_5002 | I55: 1 | J55: 5 | K55: 1 | L55: 9999 | M55: 0 | P55: copy|1;mallshop|1;npcshop|1 | Q55: 航海远征|9;剧情回顾|4 | R55: 剧情回顾|从剧情回顾获得。;商城购买|商城购买获得。;NPC商店购买|NPC商店购买获得。 | S55: 1 | T55: 5 | U55: 200 | V55: 1 | W55: 1 | X55: 1 | Y55: 0 | Z55: 0 | AA55: 5 | AB55: 7600 | AC55: 830 | AD55: 0 | AE55: 0 | AF55: 0 | AH55: 1 | AL55: 1 | AQ55: 超级精炼石 | AS55: 1
A56: 216002 | B56: 1001 | C56: 2 | D56: 1001 | E56: 重铸符文石 | F56: 重铸符文石 | G56: 由工匠们制造的刻有符号的石头，可以用于重新鉴定装备属性。 | H56: item_6002 | I56: 1 | J56: 5 | K56: 1 | L56: 9999 | M56: 0 | Q56: 商城购买|#42 | R56: 天梯商城|从天梯商城购买获得。;商城购买|彩钻商城购买获得。 | S56: 1 | T56: 5 | U56: 1000 | V56: 1 | W56: 1 | X56: 1 | Y56: 0 | Z56: 0 | AA56: 5 | AB56: 1000 | AC56: 830 | AH56: 1 | AL56: 1 | AS56: 1
A57: 216003 | B57: 1001 | C57: 2 | D57: 1001 | E57: 低级装备超载石 | F57: 低级装备超载石 | G57: 低级的超载重铸充能道具，使用后可立即填充30%的超载重铸充能 | H57: item_equipstone1 | I57: 1 | J57: 2 | K57: 1 | L57: 999 | M57: 0 | N57: 1053 | O57: 3000 | S57: 1 | T57: 5 | U57: 5 | V57: 1 | W57: 1 | X57: 1 | Y57: 0 | Z57: 0 | AA57: 5 | AB57: 500 | AC57: 830 | AL57: 1 | AQ57: 低级装备超载石 | AS57: 1
...

Sheet 物品ID定义
F1: category 1 时 ，function 不要增加资源
B4: itemType定义 | E4: category定义 | H4: function定义 | I4: 说明 | J4: 格式
B5: 1 | C5: 钻石 | E5: 1 | F5: 材料-不可在背包使用 | H5: 1 | I5: 增加资源（针对玩家） | J5: type,id,num;type,id,num
B6: 3 | C6: 蓝钻 | E6: 2 | F6: 主动使用，增加资源 | H6: 1001 | I6: 增加阵容上英雄血量（百分比） | J6: 10
B7: 4 | C7: 金币 | E7: 3 | F7: 英雄碎片 | H7: 1002 | I7: 增加阵容上英雄血量（具体值） | J7: 100 | M7: sjwq_0002
B8: 5 | C8: 金块 | E8: 4 | F8: 可用来合成 | H8: 1003 | I8: 增加玩家体力（具体值） | J8: 10 | M8: sjfj_0002
B9: 6 | C9: 体力 | H9: 1004 | I9: 英雄碎片合成 | J9: 英雄id，数量 | M9: sjjz_0002
B10: 7 | C10: 玩家经验 | H10: 1005 | I10: 重置英雄的技能点 | J10: 英雄id，英雄guid | M10: sjxl_0002
H11: 1006 | I11: 装备合成 | J11: 装备id，数量 | M11: sjwq_0002
H12: 1007 | I12: 增加道具属性 | J12: 装备id，属性值，数量 | M12: sjfj_0002
B13: 1001 | C13: 道具-材料 | H13: 1008 | I13: 使用电话虫发跑马灯(category 2) | M13: sjjz_0002
B14: 1002 | C14: 道具-宝石 | H14: 1009 | I14: 递减消除红名 | M14: sjxl_0002
B15: 1010 | C15: 战魂 | H15: 1010 | I15: 一次消除红名 | M15: sjwq_0003
B16: 1011 | C16: 声望 | H16: 1011 | I16: 增加buff | J16: buffId,buffId,buffId | M16: sjfj_0003
B17: 1100 | C17: 英雄 | H17: 1012 | I17: 永久增加属性 | J17: 属性类型,值;属性类型,值;… | M17: sjjz_0003
B18: 1101 | C18: 技能点 | H18: 1013 | I18: 增加经验 | M18: sjxl_0003
B19: 1102 | C19: 英雄经验 | H19: 1014 | I19: 增加技能点数 | J19: 技能点数 | M19: sjwq_0003
B20: 1200 | C20: 装备 | H20: 1016 | I20: 获得固定装备、道具、角色 | M20: sjfj_0003
B21: 1201 | C21: 装备箱子 | H21: 1017 | I21: 随机获得1个装备、道具、角色 | J21: 掉落组id | M21: sjjz_0003
B22: 1013 | C22: 天梯币 | H22: 1018 | I22: 从N个道具中选择M个 | M22: sjxl_0003
B23: 1012 | C23: 活力 | H23: 1019 | I23: 增加玩家活力值（具体值） | J23: 10 | M23: sjwq_0004
B24: 1300 | C24: 船 | H24: 1020 | I24: 恢复势气 | M24: sjfj_0004
H25: 1021 | I25: 增加某些玩法的次数 | M25: sjjz_0004
H26: 1022 | I26: 永久增加属性buff | J26: FightbuffId,FightbuffId,FightbuffId | M26: sjxl_0004
H27: 1023 | I27: 减少海航贸易需要的时间（毫秒） | J27: 值 | M27: sjwq_0004
H28: 1024 | I28: 增加航海贸易的刷新次数 | J28: 值 | M28: sjfj_0004
H29: 1025 | I29: 激活某个自走棋地图 | J29: mapId | M29: sjjz_0004
H30: 1026 | I30: 船只 | M30: sjxl_0004
H31: 1027 | I31: 特殊宝箱 | M31: tzwq_0003
H32: 1028 | I32: 自走棋地图道具 | M32: tzfj_0003
H33: 1029 | I33: 精炼加成道具 | M33: tzjz_0003
H34: 1031 | M34: tzxl_0003
H35: 1032 | I35: x | K35: 编号 | M35: sjwq_0001
H36: 1033 | I36: x | K36: 1-999 | M36: sjfj_0001
H37: 1034 | I37: 家园加速道具 | J37: [second]秒 | M37: sjjz_0001
M38: sjxl_0001
B44: ID排序规则 | J44: 加成值
B45: ID共6位 | C45: 范例：111001 为白色卡牌角色 | H45: 1030
B46: 第一位 | E46: 第二位-展示类 | H46: 第三位-角色
B47: 1 | C47: 角色 展示 | E47: 1 | F47: 道具 | H47: 1 | I47: R
...

Sheet 获取途径
F8: 获取途径 | G8: 说明
F9: copy|1 | G9: 从副本ID1回刷可获得
F10: mallshop|1 | G10: 商城获得
F11: npcshop|1 | G11: NPC商店获得
F12: actiraid|1 | G12: 活动副本获得
F13: collect|1 | G13: 采集获得。1是采集药品，2是伐木，3是钓鱼，4是挖矿。
F14: makegem | G14: 宝石屋获得
F15: makemedi | G15: 制药屋获得
F16: makecook | G16: 料理屋获得
F17: makeboat | G17: 造船厂获得
F18: itemcombine|itemid | G18: 物品合成
F19: gethero | G19: 抽卡
I24: 260007 | J24: 高级突破材料箱
I25: 260008 | J25: 攻击训练道具箱
I26: 260009 | J26: 防御训练道具箱
I27: 260010 | J27: 生命训练道具箱

Sheet 普通道具定义
C9: ID第一位 | D9: 序号 | E9: 道具 | G9: 特殊id（训练道具）
C10: 2 | D10: 001 | E10: 经验卷轴 | G10: 211017 | H10: 训练道具箱子
C11: 2 | D11: 002 | E11: 精炼石
C12: 2 | D12: 003 | E12: 英雄装备精炼石
C13: 2 | D13: 004 | E13: 打孔道具
C14: 2 | D14: 005 | E14: 体力恢复 | F14: 战魂
C15: 2 | D15: 006 | E15: 亲密度 | F15: 金币袋
C16: 2 | D16: 007 | E16: 技能点书
C17: 2 | D17: 008 | E17: 技能点重置
C18: 2 | D18: 009 | E18: 突破道具 | F18: 突破材料01
C19: 2 | D19: 010 | E19: 改名卡
C20: 2 | D20: 011 | E20: 抽卡券
C21: 2 | D21: 012 | E21: 电话虫
C22: 2 | D22: 013 | E22: 宝箱（精炼石、打孔道具）
C23: 2 | D23: 014 | E23: 普通装备宝箱
C24: 2 | D24: 015 | E24: 套装装备宝箱
C25: 2 | D25: 016 | E25: 角色宝箱
C26: 2 | D26: 017 | E26: 训练道具箱子
C27: 2 | D27: 018 | E27: 哑铃
C28: 2 | D28: 019 | E28: 沙袋
C29: 2 | D29: 020 | E29: 沙包
C30: 2 | D30: 100 | E30: 药
C31: 2 | D31: 101 | E31: 料理
D32: 111 | E32: 突破之石 | F32: 突破材料02
D33: 112 | E33: 突破水晶 | F33: 突破材料03
D34: 113 | E34: 突破彩晶 | F34: 突破材料04
D35: 114 | E35: 突破彩玉 | F35: 突破材料05
D36: 115 | E36: 突破魂玉 | F36: 突破材料06
D37: 116 | F37: 突破材料07
D38: 117 | F38: 突破材料08
D39: 118 | F39: 突破材料09
D40: 119 | F40: 突破材料10
D41: 120 | F41: 突破材料11
D42: 121 | F42: 突破材料12
D43: 122 | F43: 突破材料13
D44: 123 | F44: 突破材料14
D45: 124 | F45: 突破材料15
D46: 125 | F46: 突破材料16
D47: 126 | F47: 突破材料17
D48: 127 | F48: 突破材料18
...

Sheet Sheet2
B1: COMMON_NORMAL_BAG = 1; | E1: //公共库-普通背包
B2: COMMON_RECYCLING = 2; | E2: //公共库-回收箱
B3: COMMON_TASK_BAG = 3; | E3: //公共库-任务背包
B4: COMMON_STORAGE_ONE = 11; | D4: //公共库-仓库1
B5: COMMON_STORAGE_TWO = 12; | D5: //公共库-仓库2
B6: COMMON_STORAGE_THREE = 13; | D6: //公共库-仓库3
B7: COMMON_STORAGE_FOUR = 14; | D7: //公共库-仓库4
B8: COMMON_STORAGE_FIVE = 15; | D8: //公共库-仓库5
B9: CUSTOM_SHIP_BAG = 21; | E9: //船只
B10: CUSTOM_ITEM_BAG = 1001; //海贼--道具背包
B11: CUSTOM_EQUIP_BAG = 1002; //海贼--装备背包
B12: CUSTOM_GEM_BAG = 1003; //海贼--宝石背包
B13: CUSTOM_MATERIAL_BAG = 1004; //海贼--材料背包
B14: CUSTOM_TATTER_BAG = 1005; //海贼--碎片背包
H19: 1001 | I19: , | J19: 216001 | K19: , | L19: 1 | M19: , | N19: 150 | O19: ; | P19: =_xlfn.CONCAT(H19:O19) -> 1001,216001,1,150;
H20: 1001 | I20: , | J20: 214011 | K20: , | L20: 1 | M20: , | N20: 150 | O20: ; | P20: =_xlfn.CONCAT(H20:O20) -> 1001,214011,1,150;
H21: 1001 | I21: , | J21: 212014 | K21: , | L21: 1 | M21: , | N21: 50 | O21: ; | P21: =_xlfn.CONCAT(H21:O21) -> 1001,212014,1,50;
H22: 1001 | I22: , | J22: 618004 | K22: , | L22: 1 | M22: , | N22: 30 | O22: ; | P22: =_xlfn.CONCAT(H22:O22) -> 1001,618004,1,30;
H23: 1001 | I23: , | J23: 214003 | K23: , | L23: 1 | M23: , | N23: 150 | O23: ; | P23: =_xlfn.CONCAT(H23:O23) -> 1001,214003,1,150;
H24: 1001 | I24: , | J24: 214011 | K24: , | L24: 1 | M24: , | N24: 100 | O24: ; | P24: =_xlfn.CONCAT(H24:O24) -> 1001,214011,1,100;
H25: 1001 | I25: , | J25: 720001 | K25: , | L25: 1 | M25: , | N25: 70 | O25: ; | P25: =_xlfn.CONCAT(H25:O25) -> 1001,720001,1,70;
H26: 1001 | I26: , | J26: 213002 | K26: , | L26: 1 | M26: , | N26: 150 | O26: ; | P26: =_xlfn.CONCAT(H26:O26) -> 1001,213002,1,150;
H27: 1001 | I27: , | J27: 214008 | K27: , | L27: 1 | M27: , | N27: 30 | O27: ; | P27: =_xlfn.CONCAT(H27:O27) -> 1001,214008,1,30;
H28: 1001 | I28: , | J28: 800007 | K28: , | L28: 1 | M28: , | N28: 70 | O28: ; | P28: =_xlfn.CONCAT(H28:O28) -> 1001,800007,1,70;
H29: 1001 | I29: , | J29: 212004 | K29: , | L29: 1 | M29: , | N29: 50 | O29: ; | P29: =_xlfn.CONCAT(H29:O29) -> 1001,212004,1,50; | S29: =_xlfn.CONCAT(P19:P29) -> 1001,216001,1,150;1001,214011,1,150;1001,212014,1,50;1001,618004,1,30;1001,214003,1,150;1001,214011,1,100;1001,720001,1,70;1001,213002,1,150;1001,214008,1,30;1001,800007,1,70;1001,212004,1,50;
H34: 1001 | I34: , | J34: 215011 | K34: , | L34: 1 | M34: , | N34: 70 | O34: ; | P34: =_xlfn.CONCAT(H34:O34) -> 1001,215011,1,70;
H35: 1001 | I35: , | J35: 3 | K35: , | L35: 100 | M35: , | N35: 180 | O35: ; | P35: =_xlfn.CONCAT(H35:O35) -> 1001,3,100,180;
H36: 1001 | I36: , | J36: 618006 | K36: , | L36: 1 | M36: , | N36: 50 | O36: ; | P36: =_xlfn.CONCAT(H36:O36) -> 1001,618006,1,50;
H37: 1001 | I37: , | J37: 210121 | K37: , | L37: 1 | M37: , | N37: 150 | O37: ; | P37: =_xlfn.CONCAT(H37:O37) -> 1001,210121,1,150;
H38: 1001 | I38: , | J38: 210121 | K38: , | L38: 2 | M38: , | N38: 100 | O38: ; | P38: =_xlfn.CONCAT(H38:O38) -> 1001,210121,2,100;
H39: 1001 | I39: , | J39: 214014 | K39: , | L39: 1 | M39: , | N39: 50 | O39: ; | P39: =_xlfn.CONCAT(H39:O39) -> 1001,214014,1,50;
H40: 1001 | I40: , | J40: 214004 | K40: , | L40: 1 | M40: , | N40: 100 | O40: ; | P40: =_xlfn.CONCAT(H40:O40) -> 1001,214004,1,100;
H41: 1001 | I41: , | J41: 800003 | K41: , | L41: 1 | M41: , | N41: 100 | O41: ; | P41: =_xlfn.CONCAT(H41:O41) -> 1001,800003,1,100;
H42: 1001 | I42: , | J42: 216002 | K42: , | L42: 1 | M42: , | N42: 150 | O42: ; | P42: =_xlfn.CONCAT(H42:O42) -> 1001,216002,1,150;
H43: 1001 | I43: , | J43: 216002 | K43: , | L43: 2 | M43: , | N43: 50 | O43: ; | P43: =_xlfn.CONCAT(H43:O43) -> 1001,216002,2,50; | S43: =_xlfn.CONCAT(P34:P43) -> 1001,215011,1,70;1001,3,100,180;1001,618006,1,50;1001,210121,1,150;1001,210121,2,100;1001,214014,1,50;1001,214004,1,100;1001,800003,1,100;1001,216002,1,150;1001,216002,2,50;

Sheet Sheet3
B1: 1:
B2: 1:1001,620006,30;1001,620007,30;1001,620008,30;1001,620009,30;1001,620010,30;1001,620011,30;1001,620012,30;1001,620013,30;1001,620014,30;1001,620015,30;1001,620016,30;1001,620017,30;1001,620019,30;1001,620020,30;1001,620021,30;1001,620023,30;1001,620024,30;1001,620025,30;1001,620026,30;1001,620027,30;
B3: 1:1001,630063,50;1001,630002,50;1001,630003,50;1001,630007,50;1001,630008,50;1001,630009,50;1001,630011,50;1001,630012,50;1001,630013,50;1001,630014,50;1001,630016,50;1001,630020,50;1001,630021,50;1001,630022,50;1001,630023,50;1001,630024,50;1001,630025,50;1001,630026,50;1001,630027,50;1001,630028,50;1001,630029,50;1001,630030,50;1001,630031,50;1001,630032,50;1001,630033,50;1001,630034,50;1001,630035,50;1001,630036,50;1001,630037,50;1001,630038,50;1001,630039,50;1001,630040,50;1001,630041,50;1001,630042,50;1001,630043,50;1001,630044,50;1001,630045,50;1001,630046,50;1001,630047,50;1001,630049,50;1001,630050,50;1001,630051,50;1001,630052,50;1001,630053,50;1001,630054,50;1001,630055,50;1001,630056,50;1001,630057,50;1001,630058,50;1001,630059,50;1001,630060,50;1001,630061,50;1001,630062,50
B4: 1:1001,630063,50;1001,630003,50;1001,630007,50;1001,630008,50;1001,630009,50;1001,630011,50;1001,630012,50;1001,630013,50;1001,630014,50;1001,630020,50;1001,630021,50;1001,630022,50;1001,630023,50;1001,630025,50;1001,630026,50;1001,630028,50;1001,630029,50;1001,630031,50;1001,630032,50;1001,630033,50;1001,630035,50;1001,630036,50;1001,630037,50;1001,630038,50;1001,630039,50;1001,630040,50;1001,630042,50;1001,630044,50;1001,630045,50;1001,630046,50;1001,630047,50;1001,630052,50;1001,630053,50;1001,630055,50;1001,630056,50;1001,630058,50;1001,630060,50
J9: 物品子类型
F10: 新世界佩罗娜(礼服) | G10: =_xlfn.XLOOKUP(F10,Sheet1!E:E,Sheet1!A:A) -> 713080 | J10: 1.道具
F11: 阿菊（大铠） | G11: =_xlfn.XLOOKUP(F11,Sheet1!E:E,Sheet1!A:A) -> 713078 | J11: 2.材料
F12: 奶昔-泳装 | G12: =_xlfn.XLOOKUP(F12,Sheet1!E:E,Sheet1!A:A) -> 713064 | J12: 3.药品
F13: 丽久礼服 | G13: =_xlfn.XLOOKUP(F13,Sheet1!E:E,Sheet1!A:A) -> 713069 | J13: 4.食物
F14: 新世界路飞-唐装 | G14: =_xlfn.XLOOKUP(F14,Sheet1!E:E,Sheet1!A:A) -> 713037 | J14: 5.宝石
F15: 新世界路飞-“路西” | G15: =_xlfn.XLOOKUP(F15,Sheet1!E:E,Sheet1!A:A) -> 713050 | J15: 6.礼包
F16: 新世界佐罗-激战 | G16: =_xlfn.XLOOKUP(F16,Sheet1!E:E,Sheet1!A:A) -> 713031 | J16: 7.碎片
F17: 新世界佐罗-黑色西服 | G17: =_xlfn.XLOOKUP(F17,Sheet1!E:E,Sheet1!A:A) -> 713030 | J17: 8.精炼石 | Q17: 普通的木材 | R17: 普通的木材 | S17: 普通的木材，近期似乎有人在回收这写东西。活动期间内参与每日任务和剧情回顾有几率获得，可用于兑换特殊道具。 | T17: UI_item_icon_mu
F18: 新世界佩罗娜(礼服) | G18: =_xlfn.XLOOKUP(F18,Sheet1!E:E,Sheet1!A:A) -> 713080 | J18: 9.英雄石 | Q18: 驯鹿帽子 | R18: 驯鹿帽子 | S18: 被海盗掠走的驯鹿帽子。活动期间内参与讨伐任务有几率获得，可用于兑换特殊道具。 | T18: sjfj_0008
F19: 新世界佩罗娜(礼服) | G19: =_xlfn.XLOOKUP(F19,Sheet1!E:E,Sheet1!A:A) -> 713080 | J19: 10.复活物品
F20: 新世界佩罗娜(礼服) | G20: =_xlfn.XLOOKUP(F20,Sheet1!E:E,Sheet1!A:A) -> 713080 | J20: 11突破材料
F21: 新世界佩罗娜(礼服) | G21: =_xlfn.XLOOKUP(F21,Sheet1!E:E,Sheet1!A:A) -> 713080 | J21: 12.动物系技能书
F22: 新世界佩罗娜(礼服) | G22: =_xlfn.XLOOKUP(F22,Sheet1!E:E,Sheet1!A:A) -> 713080 | J22: 13.自然系技能书
F23: 新世界佩罗娜(礼服) | G23: =_xlfn.XLOOKUP(F23,Sheet1!E:E,Sheet1!A:A) -> 713080 | J23: 14.超人系技能书
J24: 15.剑道技能书
J25: 16.格斗技能
J26: 17.射击技能书
J27: 18.普通技能书
J28: 19.打孔石
J29: 20.家园加速
J30: 21.友好值道具
J37: 1
