Workbook

Sheet Sheet1
A1: 7 | B1: 1 | C1: 9999 | D1: 2
A2: 货物index | B2: 购买音效 | D2: 备注 | E2: EmptyKey-E2 | F2: EmptyKey-F2 | G2: EmptyKey-G2 | H2: EmptyKey-H2
A3: goodIndex | B3: BuySE
A4: int | B4: string(intern)
A5: primary | B5: none
A6: goodIndex | B6: BuySE | D6: 对应type,itemId,number | E6: 说明
A7: 1 | B7: Buy | D7: 1001 | E7: 215011 | F7: 1 | G7: =VLOOKUP(E7,Sheet2!$A$2:$B$986,2,FALSE) -> Buy | H7: =VLOOKUP(E7,Sheet2!$A$2:$E$986,4,FALSE) -> 高级抽卡券(天塌了也不改ID的神奇道具）
A8: 10 | B8: Buy_Keys | D8: 1001 | E8: 225001 | F8: 1 | G8: =VLOOKUP(E8,Sheet2!$A$2:$B$986,2,FALSE) -> Buy_Keys | H8: =VLOOKUP(E8,Sheet2!$A$2:$E$986,4,FALSE) -> 黄金之匙
A9: 11 | B9: Buy_Keys | D9: 1001 | E9: 225002 | F9: 1 | G9: =VLOOKUP(E9,Sheet2!$A$2:$B$986,2,FALSE) -> Buy_Keys | H9: =VLOOKUP(E9,Sheet2!$A$2:$E$986,4,FALSE) -> 勇者之匙
A10: 12 | B10: Buy | D10: 1001 | E10: 214012 | F10: 1 | G10: =VLOOKUP(E10,Sheet2!$A$2:$B$986,2,FALSE) -> Buy | H10: =VLOOKUP(E10,Sheet2!$A$2:$E$986,4,FALSE) -> 电话虫
A11: 13 | B11: Buy_Coin | D11: 1001 | E11: 215006 | F11: 1 | G11: =VLOOKUP(E11,Sheet2!$A$2:$B$986,2,FALSE) -> Buy_Coin | H11: =VLOOKUP(E11,Sheet2!$A$2:$E$986,4,FALSE) -> 一袋金币
A12: 14 | B12: Buy | D12: 1001 | E12: 214010 | F12: 1 | G12: =VLOOKUP(E12,Sheet2!$A$2:$B$986,2,FALSE) -> Buy | H12: =VLOOKUP(E12,Sheet2!$A$2:$E$986,4,FALSE) -> 改名卡
A13: 15 | B13: Buy | D13: 1001 | E13: 214008 | F13: 1 | G13: =VLOOKUP(E13,Sheet2!$A$2:$B$986,2,FALSE) -> Buy | H13: =VLOOKUP(E13,Sheet2!$A$2:$E$986,4,FALSE) -> 遗忘之书
A14: 24 | B14: Buy_Gem | D14: 1001 | E14: 217006 | F14: 1 | G14: =VLOOKUP(E14,Sheet2!$A$2:$B$986,2,FALSE) -> Buy_Gem | H14: =VLOOKUP(E14,Sheet2!$A$2:$E$986,4,FALSE) -> 一袋蓝钻
A15: 25 | B15: Buy_Jewel | D15: 1001 | E15: 800002 | F15: 1 | G15: =VLOOKUP(E15,Sheet2!$A$2:$B$986,2,FALSE) -> Buy_Chest | H15: =VLOOKUP(E15,Sheet2!$A$2:$E$986,4,FALSE) -> 精致宝石袋
A16: 26 | B16: Buy_Chest | D16: 1001 | E16: 800004 | F16: 1 | G16: =VLOOKUP(E16,Sheet2!$A$2:$B$986,2,FALSE) -> Buy | H16: =VLOOKUP(E16,Sheet2!$A$2:$E$986,4,FALSE) -> 技能书宝箱
A17: 28 | B17: Buy | D17: 1001 | E17: 800006 | F17: 1 | G17: =VLOOKUP(E17,Sheet2!$A$2:$B$986,2,FALSE) -> Buy | H17: =VLOOKUP(E17,Sheet2!$A$2:$E$986,4,FALSE) -> 打孔道具袋子
A18: 29 | B18: Buy_Jewel | D18: 1001 | E18: 800007 | F18: 1 | G18: =VLOOKUP(E18,Sheet2!$A$2:$B$986,2,FALSE) -> Buy_Gem | H18: =VLOOKUP(E18,Sheet2!$A$2:$E$986,4,FALSE) -> 精炼石袋子
... A121: 313 | B121: Buy_Equip | D121: 1201 | E121: 80000240 | F121: 1 | G121: =VLOOKUP(E121,Sheet2!$A$2:$B$986,2,FALSE) -> #N/A | H121: =VLOOKUP(E121,Sheet2!$A$2:$E$986,4,FALSE) -> #N/A
A122: 1001 | B122: Buy | D122: 10004 | E122: 0 | F122: 1;1014 | G122: =VLOOKUP(E122,Sheet2!$A$2:$B$986,2,FALSE) -> #N/A | H122: =VLOOKUP(E122,Sheet2!$A$2:$E$986,4,FALSE) -> #N/A
A123: 1002 | B123: Buy | D123: 1001 | E123: 233008 | F123: 1 | G123: =VLOOKUP(E123,Sheet2!$A$2:$B$986,2,FALSE) -> Buy | H123: =VLOOKUP(E123,Sheet2!$A$2:$E$986,4,FALSE) -> 会心之阵
A124: 1003 | B124: Buy | D124: 1001 | E124: 233009 | F124: 1 | G124: =VLOOKUP(E124,Sheet2!$A$2:$B$986,2,FALSE) -> Buy | H124: =VLOOKUP(E124,Sheet2!$A$2:$E$986,4,FALSE) -> 平静之阵
A125: 1004 | B125: Buy | D125: 1001 | E125: 233010 | F125: 1 | G125: =VLOOKUP(E125,Sheet2!$A$2:$B$986,2,FALSE) -> Buy | H125: =VLOOKUP(E125,Sheet2!$A$2:$E$986,4,FALSE) -> 疾行之阵
A126: 1005 | B126: Buy | D126: 1001 | E126: 233011 | F126: 1 | G126: =VLOOKUP(E126,Sheet2!$A$2:$B$986,2,FALSE) -> Buy | H126: =VLOOKUP(E126,Sheet2!$A$2:$E$986,4,FALSE) -> 治愈之阵
A127: 1006 | B127: Buy | D127: 1001 | E127: 233012 | F127: 1 | G127: =VLOOKUP(E127,Sheet2!$A$2:$B$986,2,FALSE) -> Buy | H127: =VLOOKUP(E127,Sheet2!$A$2:$E$986,4,FALSE) -> 沉稳之阵
A128: 1007 | B128: Buy | D128: 1001 | E128: 233013 | F128: 1 | G128: =VLOOKUP(E128,Sheet2!$A$2:$B$986,2,FALSE) -> Buy | H128: =VLOOKUP(E128,Sheet2!$A$2:$E$986,4,FALSE) -> 狂怒之阵
A129: 1008 | B129: Buy | D129: 1001 | E129: 233014 | F129: 1 | G129: =VLOOKUP(E129,Sheet2!$A$2:$B$986,2,FALSE) -> Buy | H129: =VLOOKUP(E129,Sheet2!$A$2:$E$986,4,FALSE) -> 壁垒之阵
A130: 1009 | B130: Buy | D130: 1001 | E130: 233015 | F130: 1 | G130: =VLOOKUP(E130,Sheet2!$A$2:$B$986,2,FALSE) -> Buy | H130: =VLOOKUP(E130,Sheet2!$A$2:$E$986,4,FALSE) -> 激励之阵
A131: 1010 | B131: Buy | D131: 1001 | E131: 233016 | F131: 1 | G131: =VLOOKUP(E131,Sheet2!$A$2:$B$986,2,FALSE) -> Buy | H131: =VLOOKUP(E131,Sheet2!$A$2:$E$986,4,FALSE) -> 战魂之阵
A132: 1011 | B132: Buy | D132: 1001 | E132: 233017 | F132: 1 | G132: =VLOOKUP(E132,Sheet2!$A$2:$B$986,2,FALSE) -> Buy | H132: =VLOOKUP(E132,Sheet2!$A$2:$E$986,4,FALSE) -> 突袭之阵
A133: 1012 | B133: Buy_Jewel | D133: 1001 | E133: 215002 | F133: 1 | G133: =VLOOKUP(E133,Sheet2!$A$2:$B$986,2,FALSE) -> Buy_Jewel | H133: =VLOOKUP(E133,Sheet2!$A$2:$E$986,4,FALSE) -> 超级精炼石
A134: 1013 | B134: Buy_Jewel | D134: 1001 | E134: 213004 | F134: 1 | G134: =VLOOKUP(E134,Sheet2!$A$2:$B$986,2,FALSE) -> Buy_Jewel | H134: =VLOOKUP(E134,Sheet2!$A$2:$E$986,4,FALSE) -> 海蓝石
... A203: 1082 | B203: Buy | D203: 1001 | E203: 213007 | F203: 1 | G203: =VLOOKUP(E203,Sheet2!$A$2:$B$986,2,FALSE) -> Buy | H203: =VLOOKUP(E203,Sheet2!$A$2:$E$986,4,FALSE) -> 中级秘传书

Sheet Sheet2
A1: itemId | B1: BuySE
A2: 212001 | B2: Buy | D2: 初级经验卷轴 | E2: 低级角色升级经验道具
A3: 213001 | B3: Buy | D3: 中级经验卷轴 | E3: 中级角色升级经验道具
A4: 214001 | B4: Buy | D4: 高级经验卷轴 | E4: 高级角色升级经验道具
A5: 215001 | B5: Buy | D5: 超级经验卷轴 | E5: 超级角色升级经验道具
A6: 212002 | B6: Buy_Jewel | D6: 低级精炼石 | E6: 用于装备精炼等级+1至+5
A7: 213002 | B7: Buy_Jewel | D7: 中级精炼石 | E7: 用于装备精炼等级+6至+10
A8: 214002 | B8: Buy_Jewel | D8: 高级精炼石 | E8: 用于装备精炼等级+11至+15
A9: 215002 | B9: Buy_Jewel | D9: 超级精炼石 | E9: 用于装备精炼等级+16至+20
A10: 212004 | B10: Buy_Jewel | D10: 精钢石 | E10: 低级打孔道具，用于1至20级装备的打孔
A11: 213004 | B11: Buy_Jewel | D11: 海蓝石 | E11: 中级打孔道具，用于21至40级装备的打孔
A12: 214004 | B12: Buy_Jewel | D12: 钢岩石 | E12: 高级打孔道具，用于41至60级装备的打孔
A13: 215004 | B13: Buy_Jewel | D13: 圣辉石 | E13: 超级打孔道具，用于61至80级装备的打孔
... A27: 215007 | B27: Buy | D27: 奥义秘传书 | E27: 获得巨量技能点数
A28: 212107 | B28: Buy | D28: 动物系初级秘传书
A29: 213107 | B29: Buy | D29: 动物系中级秘传书
A30: 214107 | B30: Buy | D30: 动物系高级秘传书
A31: 215107 | B31: Buy | D31: 动物系奥义秘传书
A32: 212207 | B32: Buy | D32: 自然系初级秘传书
A33: 213207 | B33: Buy | D33: 自然系中级秘传书
A34: 214207 | B34: Buy | D34: 自然系高级秘传书
A35: 215207 | B35: Buy | D35: 自然系奥义秘传书
A36: 212307 | B36: Buy | D36: 超人系初级秘传书
A37: 213307 | B37: Buy | D37: 超人系中级秘传书
A38: 214307 | B38: Buy | D38: 超人系高级秘传书
A39: 215307 | B39: Buy | D39: 超人系奥义秘传书
... A51: 215607 | B51: Buy | D51: 射击系奥义秘传书
A52: 214003 | B52: Buy_Jewel | D52: 英雄之石 | E52: 用于装备精炼等级+11至+20的提升
A53: 214008 | B53: Buy | D53: 遗忘之书 | E53: 可重置角色所有技能点
A54: 214010 | B54: Buy | D54: 改名卡 | E54: 用于角色改名
A55: 214011 | B55: Buy | D55: 普通抽卡券 | E55: 用于普通抽卡。
A56: 215011 | B56: Buy | D56: 高级抽卡券(天塌了也不改ID的神奇道具） | E56: 用于高级抽卡。
A57: 214012 | B57: Buy | D57: 电话虫 | E57: 可以发起全服广播。
A58: 214016 | B58: Buy | D58: 初级玉匣 | E58: 普通角色宝箱，随机开出R卡或SR卡。
A59: 215016 | B59: Buy | D59: 高级玉匣 | E59: 稀有角色宝箱，随机开出SR卡。
A60: 213016 | B60: Buy_Chest | D60: 烟鬼宝箱 | E60: 开出烟鬼
A61: 225001 | B61: Buy_Keys | D61: 黄金之匙
A62: 225002 | B62: Buy_Keys | D62: 勇者之匙
A63: 610001 | B63: Buy_Spirite | D63: 克比碎片 | E63: 集齐30个可召唤克比
A64: 610002 | B64: Buy_Spirite | D64: 斧手蒙卡碎片 | E64: 集齐30个可召唤斧手蒙卡
...
