Workbook

Sheet Sheet1
A1: 7 | B1: 1 | C1: 9999 | D1: 3
A2: 英雄id | B2: 体力上限 | C2: 技能
A3: heroId | B3: maxEnergy | C3: skills
A4: int | B4: int | C4: string
A5: primary | B5: none | C5: none
A6: heroId | B6: maxEnergy | C6: skills
A7: 112028 | B7: 480 | C7: 59,0,1 | I7: 战桃丸 | N7: 1 | O7: 生产钻石时，工作进度提升20%
A8: 113001 | B8: 360 | C8: 8,0,1 | I8: 鳄鱼 | N8: 2 | O8: 生产钻石时，工作进度提升25%
A9: 113002 | B9: 360 | C9: 66,0,1 | I9: 艾尼路 | N9: 3 | O9: 生产钻石时，工作进度提升30%
A10: 113003 | B10: 360 | C10: 57,0,1;65,1,6 | I10: 青雉 | N10: 4 | O10: 生产钻石时，工作进度提升35%
A11: 113004 | B11: 480 | C11: 37,0,1;82,1,6 | I11: 卡普 | N11: 5 | O11: 生产钻石时，工作进度提升40%
A12: 113005 | B12: 360 | C12: 108,0,1 | I12: 莫利亚 | N12: 6 | O12: 生产钻石时，工作进度提升45%
A13: 113006 | B13: 480 | C13: 30,0,1 | I13: 大熊 | N13: 7 | O13: 生产钻石时，工作进度提升50%
A14: 113007 | B14: 240 | C14: 8,0,1 | I14: 黄猿 | N14: 8 | O14: 生产宝石时，工作进度提升20%
A15: 113008 | B15: 240 | C15: 2,0,1;73,0,60 | I15: 艾斯 | N15: 9 | O15: 生产宝石时，工作进度提升25%
A16: 113009 | B16: 360 | C16: 59,0,1 | I16: 赤犬 | N16: 10 | O16: 生产宝石时，工作进度提升30%
A17: 113010 | B17: 360 | C17: 17,0,1 | I17: 鹰眼 | N17: 11 | O17: 生产宝石时，工作进度提升35%
A18: 113012 | B18: 480 | C18: 74,0,1;83,1,7 | I18: 甚平 | N18: 12 | O18: 生产宝石时，工作进度提升40%
... A160: 113114 | B160: 480 | C160: 77,0,1;83,0,1 | I160: 未来岛黑胡子 | N160: 109 | O160: 生产时体力消耗-10%，生产精华加速20%

Sheet Sheet2

Sheet Sheet3
A1: 7 | B1: 1 | C1: 9999 | G1: 3
A2: 英雄id | B2: 体力上限 | C2: 技能
A3: heroId | B3: maxEnergy | C3: skills
A4: int | B4: int | C4: string
A5: primary | B5: none | C5: none
A6: heroId | B6: maxEnergy | C6: skills | L6: 技能ID | O6: 出现次数 | P6: 技能
A7: 112028 | B7: 480 | C7: 59 | H7: 战桃丸 | I7: 1 | J7: 生产钻石时，工作进度提升20% | L7: 1 | O7: =COUNTIF(C$92:D$1048576,L7) -> 2 | P7: =VLOOKUP(L7,Sheet4!A:E,5,FALSE) -> 生产蓝钻时，工作进度提升20%
A8: 113001 | B8: 360 | C8: 8 | H8: 鳄鱼 | I8: 2 | J8: 生产钻石时，工作进度提升25% | L8: 2 | O8: =COUNTIF(C$92:D$1048576,L8) -> 5 | P8: =VLOOKUP(L8,Sheet4!A:E,5,FALSE) -> 生产蓝钻时，工作进度提升25%
A9: 113002 | B9: 360 | C9: 66 | H9: 艾尼路 | I9: 3 | J9: 生产钻石时，工作进度提升30% | L9: 3 | O9: =COUNTIF(C$92:D$1048576,L9) -> 1 | P9: =VLOOKUP(L9,Sheet4!A:E,5,FALSE) -> 生产蓝钻时，工作进度提升30%
A10: 113003 | B10: 360 | C10: 57 | D10: 65 | E10: 1 | F10: 6 | H10: 青雉 | I10: 4 | J10: 生产钻石时，工作进度提升35% | L10: 8 | O10: =COUNTIF(C$92:D$1048576,L10) -> 3 | P10: =VLOOKUP(L10,Sheet4!A:E,5,FALSE) -> 生产宝石时，工作进度提升20%
A11: 113004 | B11: 480 | C11: 37 | D11: 82 | E11: 1 | F11: 6 | H11: 卡普 | I11: 5 | J11: 生产钻石时，工作进度提升40% | L11: 9 | O11: =COUNTIF(C$92:D$1048576,L11) -> 3 | P11: =VLOOKUP(L11,Sheet4!A:E,5,FALSE) -> 生产宝石时，工作进度提升25%
A12: 113005 | B12: 360 | C12: 108 | H12: 莫利亚 | I12: 6 | J12: 生产钻石时，工作进度提升45% | L12: 10 | O12: =COUNTIF(C$92:D$1048576,L12) -> 1 | P12: =VLOOKUP(L12,Sheet4!A:E,5,FALSE) -> 生产宝石时，工作进度提升30%
A13: 113006 | B13: 480 | C13: 30 | H13: 大熊 | I13: 7 | J13: 生产钻石时，工作进度提升50% | L13: 15 | O13: =COUNTIF(C$92:D$1048576,L13) -> 1 | P13: =VLOOKUP(L13,Sheet4!A:E,5,FALSE) -> 生产精炼石时，工作进度提升20%
A14: 113007 | B14: 240 | C14: 8 | H14: 黄猿 | I14: 8 | J14: 生产宝石时，工作进度提升20% | L14: 17 | O14: =COUNTIF(C$92:D$1048576,L14) -> 3 | P14: =VLOOKUP(L14,Sheet4!A:E,5,FALSE) -> 生产精炼石时，工作进度提升30%
A15: 113008 | B15: 240 | C15: 2 | D15: 73 | E15: 0 | F15: 60 | H15: 艾斯 | I15: 9 | J15: 生产宝石时，工作进度提升25% | L15: 22 | O15: =COUNTIF(C$92:D$1048576,L15) -> 3 | P15: =VLOOKUP(L15,Sheet4!A:E,5,FALSE) -> 生产英雄之石时，工作进度提升20%
A16: 113009 | B16: 360 | C16: 59 | H16: 赤犬 | I16: 10 | J16: 生产宝石时，工作进度提升30% | L16: 23 | O16: =COUNTIF(C$92:D$1048576,L16) -> 0 | P16: =VLOOKUP(L16,Sheet4!A:E,5,FALSE) -> 生产英雄之石时，工作进度提升25%
A17: 113010 | B17: 360 | C17: 17 | H17: 鹰眼 | I17: 11 | J17: 生产宝石时，工作进度提升35% | L17: 24 | O17: =COUNTIF(C$92:D$1048576,L17) -> 4 | P17: =VLOOKUP(L17,Sheet4!A:E,5,FALSE) -> 生产英雄之石时，工作进度提升30%
A18: 113012 | B18: 480 | C18: 74 | D18: 83 | E18: 1 | F18: 7 | H18: 甚平 | I18: 12 | J18: 生产宝石时，工作进度提升40% | L18: 30 | O18: =COUNTIF(C$92:D$1048576,L18) -> 0 | P18: =VLOOKUP(L18,Sheet4!A:E,5,FALSE) -> 生产古铜锭、锡铁锭、精金锭时，工作进度提升25%
A19: 113013 | B19: 480 | C19: 109 | D19: 110 | E19: 1 | F19: 6 | H19: 女帝 | I19: 13 | J19: 生产宝石时，工作进度提升45% | L19: 31 | O19: =COUNTIF(C$92:D$1048576,L19) -> 1 | P19: =VLOOKUP(L19,Sheet4!A:E,5,FALSE) -> 生产古铜锭、锡铁锭、精金锭时，工作进度提升30%
A20: 113014 | B20: 240 | C20: 58 | D20: 78 | E20: 0 | F20: 80 | H20: 罗 | I20: 14 | J20: 生产宝石时，工作进度提升50% | L20: 36 | O20: =COUNTIF(C$92:D$1048576,L20) -> 2 | P20: =VLOOKUP(L20,Sheet4!A:E,5,FALSE) -> 在精炼厂工作时，工作进度提升20%
A21: 113015 | B21: 360 | C21: 38 | H21: 基德 | I21: 15 | J21: 生产精炼石时，工作进度提升20% | L21: 37 | O21: =COUNTIF(C$92:D$1048576,L21) -> 4 | P21: =VLOOKUP(L21,Sheet4!A:E,5,FALSE) -> 在精炼厂工作时，工作进度提升25%
A22: 113017 | B22: 360 | C22: 45 | H22: 战国 | I22: 16 | J22: 生产精炼石时，工作进度提升25% | L22: 38 | O22: =COUNTIF(C$92:D$1048576,L22) -> 6 | P22: =VLOOKUP(L22,Sheet4!A:E,5,FALSE) -> 在精炼厂工作时，工作进度提升30%
A23: 113016 | B23: 240 | C23: 24 | H23: 雷利 | I23: 17 | J23: 生产精炼石时，工作进度提升30% | L23: 43 | O23: =COUNTIF(C$92:D$1048576,L23) -> 3 | P23: =VLOOKUP(L23,Sheet4!A:E,5,FALSE) -> 生产经验书时，工作进度提升20%
A24: 113018 | B24: 360 | C24: 37 | H24: 麦哲伦 | I24: 18 | J24: 生产精炼石时，工作进度提升35% | L24: 45 | O24: =COUNTIF(C$92:D$1048576,L24) -> 5 | P24: =VLOOKUP(L24,Sheet4!A:E,5,FALSE) -> 生产经验书时，工作进度提升30%
A25: 113019 | B25: 480 | C25: 58 | D25: 75 | E25: 1 | F25: 6 | H25: 人妖王 | I25: 19 | J25: 生产精炼石时，工作进度提升40% | L25: 57 | O25: =COUNTIF(C$92:D$1048576,L25) -> 1 | P25: =VLOOKUP(L25,Sheet4!A:E,5,FALSE) -> 在图书馆工作时，工作进度提升20%
A26: 113020 | B26: 360 | C26: 3 | D26: 81 | E26: 1 | F26: 6 | H26: 乔兹 | I26: 20 | J26: 生产精炼石时，工作进度提升45% | L26: 58 | O26: =COUNTIF(C$92:D$1048576,L26) -> 1 | P26: =VLOOKUP(L26,Sheet4!A:E,5,FALSE) -> 在图书馆工作时，工作进度提升25%
A27: 113022 | B27: 360 | C27: 37 | D27: 79 | E27: 0 | F27: 80 | H27: 马尔高 | I27: 21 | J27: 生产精炼石时，工作进度提升50% | L27: 59 | O27: =COUNTIF(C$92:D$1048576,L27) -> 3 | P27: =VLOOKUP(L27,Sheet4!A:E,5,FALSE) -> 在图书馆工作时，工作进度提升30%
A28: 113021 | B28: 480 | C28: 59 | H28: 白胡子 | I28: 22 | J28: 生产英雄之石时，工作进度提升20% | L28: 59 | M28: 0 | N28: 80 | O28: =COUNTIF(C$92:D$1048576,L28) -> 3 | P28: =VLOOKUP(L28,Sheet4!A:E,5,FALSE) -> 在图书馆工作时，工作进度提升30%
A29: 113023 | B29: 480 | C29: 31 | H29: 比斯塔 | I29: 23 | J29: 生产英雄之石时，工作进度提升25% | L29: 64 | O29: =COUNTIF(C$92:D$1048576,L29) -> 2 | P29: =VLOOKUP(L29,Sheet4!A:E,5,FALSE) -> 生产附魂卷时，工作进度提升20%
A30: 113024 | B30: 480 | C30: 66 | H30: 红发 | I30: 24 | J30: 生产英雄之石时，工作进度提升30% | L30: 65 | O30: =COUNTIF(C$92:D$1048576,L30) -> 2 | P30: =VLOOKUP(L30,Sheet4!A:E,5,FALSE) -> 生产附魂卷时，工作进度提升25%
A31: 113026 | B31: 360 | C31: 17 | H31: 新世界索隆 | I31: 25 | J31: 生产英雄之石时，工作进度提升35% | L31: 65 | M31: 1 | N31: 6 | O31: =COUNTIF(C$92:D$1048576,L31) -> 2 | P31: =VLOOKUP(L31,Sheet4!A:E,5,FALSE) -> 生产附魂卷时，工作进度提升25%
A32: 113025 | B32: 360 | C32: 38 | H32: 新世界乌索普 | I32: 26 | J32: 生产英雄之石时，工作进度提升40% | L32: 66 | O32: =COUNTIF(C$92:D$1048576,L32) -> 8 | P32: =VLOOKUP(L32,Sheet4!A:E,5,FALSE) -> 生产附魂卷时，工作进度提升30%
A33: 113027 | B33: 360 | C33: 83 | H33: 黑胡子 | I33: 27 | J33: 生产英雄之石时，工作进度提升45% | L33: 73 | M33: 0 | N33: 60 | O33: =COUNTIF(C$92:D$1048576,L33) -> 0 | P33: =VLOOKUP(L33,Sheet4!A:E,5,FALSE) -> 入住宿舍，体力恢复速度提升12%
A34: 113028 | B34: 240 | C34: 9 | H34: 新世界娜美 | I34: 28 | J34: 生产英雄之石时，工作进度提升50% | L34: 73 | M34: 0 | N34: 50 | O34: =COUNTIF(C$92:D$1048576,L34) -> 0 | P34: =VLOOKUP(L34,Sheet4!A:E,5,FALSE) -> 入住宿舍，体力恢复速度提升12%
A35: 113030 | B35: 480 | C35: 1 | H35: 明哥 | I35: 29 | J35: 生产古铜锭、锡铁锭、精金锭时，工作进度提升20% | L35: 74 | O35: =COUNTIF(C$92:D$1048576,L35) -> 0 | P35: =VLOOKUP(L35,Sheet4!A:E,5,FALSE) -> 入住宿舍，体力恢复速度提升16%
A36: 113029 | B36: 240 | C36: 9 | H36: 新世界罗宾 | I36: 30 | J36: 生产古铜锭、锡铁锭、精金锭时，工作进度提升25% | L36: 75 | M36: 1 | N36: 6 | O36: =COUNTIF(C$92:D$1048576,L36) -> 1 | P36: =VLOOKUP(L36,Sheet4!A:E,5,FALSE) -> 在宿舍时，加快宿舍内角色体力恢复速度15%
A37: 113031 | B37: 360 | C37: 65 | H37: 新世界路飞 | I37: 31 | J37: 生产古铜锭、锡铁锭、精金锭时，工作进度提升30% | L37: 75 | M37: 0 | N37: 80 | O37: =COUNTIF(C$92:D$1048576,L37) -> 1 | P37: =VLOOKUP(L37,Sheet4!A:E,5,FALSE) -> 在宿舍时，加快宿舍内角色体力恢复速度15%
A38: 112001 | B38: 360 | C38: 43 | H38: 路飞 | I38: 32 | J38: 生产古铜锭、锡铁锭、精金锭时，工作进度提升35% | L38: 76 | M38: 0 | N38: 80 | O38: =COUNTIF(C$92:D$1048576,L38) -> 0 | P38: =VLOOKUP(L38,Sheet4!A:E,5,FALSE) -> 在宿舍时，加快宿舍内角色体力恢复速度20%
A39: 112002 | B39: 360 | C39: 111 | H39: 索隆 | I39: 33 | J39: 生产古铜锭、锡铁锭、精金锭时，工作进度提升40% | L39: 77 | O39: =COUNTIF(C$92:D$1048576,L39) -> 2 | P39: =VLOOKUP(L39,Sheet4!A:E,5,FALSE) -> 生产时，体力消耗减少10%
A40: 112008 | B40: 480 | C40: 36 | H40: 弗兰奇 | I40: 34 | J40: 生产古铜锭、锡铁锭、精金锭时，工作进度提升45% | L40: 77 | M40: 0 | N40: 50 | O40: =COUNTIF(C$92:D$1048576,L40) -> 2 | P40: =VLOOKUP(L40,Sheet4!A:E,5,FALSE) -> 生产时，体力消耗减少10%
...

Sheet Sheet4
A1: 7 | B1: 1 | C1: 9999 | D1: 5
A2: 技能id | B2: buff列表 | C2: 技能名 | D2: 技能图标 | E2: 技能描述 | G2: 类型
A3: skillId | B3: buffs | C3: skillName | D3: skillIcon | E3: skillDescription
A4: int | B4: string | C4: string | D4: string | E4: string
A5: primary | B5: none | C5: none | D5: none | E5: none
A6: skillId | B6: buffs
A7: 1 | B7: 10101 | C7: 切割学II | D7: jy_Diamond2 | E7: 生产蓝钻时，工作进度提升20% | G7: 钻石
A8: 2 | B8: 10102 | C8: 钻石工艺I | D8: jy_Diamond3 | E8: 生产蓝钻时，工作进度提升25% | G8: 钻石
A9: 3 | B9: 10103 | C9: 钻石工艺II | D9: jy_Diamond3 | E9: 生产蓝钻时，工作进度提升30% | G9: 钻石
A10: 4 | B10: 10104 | C10: 切割学II | D10: jy_Diamond2 | E10: 生产蓝钻时，工作进度提升35% | G10: 钻石
A11: 5 | B11: 10105 | C11: 钻石工艺I | D11: jy_Diamond3 | E11: 生产蓝钻时，工作进度提升40% | G11: 钻石
A12: 6 | B12: 10106 | C12: 钻石工艺II | D12: jy_Diamond3 | E12: 生产蓝钻时，工作进度提升45% | G12: 钻石
A13: 7 | B13: 10107 | C13: 钻石工艺III | D13: jy_Diamond3 | E13: 生产蓝钻时，工作进度提升50% | G13: 钻石
A14: 8 | B14: 10201 | C14: 宝石工匠I | D14: jy_gemstone3 | E14: 生产宝石时，工作进度提升20% | G14: 宝石
A15: 9 | B15: 10202,10209,10216 | C15: 宝石工匠II | D15: jy_gemstone3 | E15: 生产宝石时，工作进度提升25% | G15: 宝石
A16: 10 | B16: 10203,10210,10217 | C16: 能工巧匠I | D16: jy_gemstone2 | E16: 生产宝石时，工作进度提升30% | G16: 宝石
A17: 11 | B17: 10204,10211,10218 | C17: 能工巧匠II | D17: jy_gemstone2 | E17: 生产宝石时，工作进度提升35% | G17: 宝石
A18: 12 | B18: 10205,10212,10219 | C18: 宝石工匠I | D18: jy_gemstone3 | E18: 生产宝石时，工作进度提升40% | G18: 宝石
A19: 13 | B19: 10206,10213,10220 | C19: 宝石工匠II | D19: jy_gemstone3 | E19: 生产宝石时，工作进度提升45% | G19: 宝石
A20: 14 | B20: 10207,10214,10221 | C20: 宝石工匠III | D20: jy_gemstone3 | E20: 生产宝石时，工作进度提升50% | G20: 宝石
A21: 15 | B21: 10301 | C21: 标准化I | D21: jy_stone4 | E21: 生产精炼石时，工作进度提升20% | G21: 装备工坊
A22: 16 | B22: 10302 | C22: 标准化II | D22: jy_stone4 | E22: 生产精炼石时，工作进度提升25% | G22: 装备工坊
A23: 17 | B23: 10303 | C23: 标准化II | D23: jy_stone4 | E23: 生产精炼石时，工作进度提升30% | G23: 装备工坊
A24: 18 | B24: 10304 | C24: 标准化I | D24: jy_stone4 | E24: 生产精炼石时，工作进度提升35% | G24: 装备工坊
A25: 19 | B25: 10305 | C25: 标准化V | D25: jy_stone4 | E25: 生产精炼石时，工作进度提升40% | G25: 装备工坊
A26: 20 | B26: 10306 | C26: 标准化II | D26: jy_stone4 | E26: 生产精炼石时，工作进度提升45% | G26: 装备工坊
A27: 21 | B27: 10307 | C27: 标准化III | D27: jy_stone4 | E27: 生产精炼石时，工作进度提升50% | G27: 装备工坊
A28: 22 | B28: 10701 | C28: 工艺指导II | D28: jy_stone5 | E28: 生产英雄之石时，工作进度提升20% | G28: 装备工坊
A29: 23 | B29: 10702 | C29: 工艺指导III | D29: jy_stone5 | E29: 生产英雄之石时，工作进度提升25% | G29: 装备工坊
A30: 24 | B30: 10703 | C30: 工艺指导IV | D30: jy_stone5 | E30: 生产英雄之石时，工作进度提升30% | G30: 装备工坊
A31: 25 | B31: 10704 | C31: 工艺指导II | D31: jy_stone5 | E31: 生产英雄之石时，工作进度提升35% | G31: 装备工坊
A32: 26 | B32: 10705 | C32: 工艺指导V | D32: jy_stone5 | E32: 生产英雄之石时，工作进度提升40% | G32: 装备工坊
... A34: 28 | B34: 10707 | C34: 工艺指导IV | D34: jy_stone5 | E34: 生产英雄之石时，工作进度提升50% | G34: 装备工坊
A35: 29 | B35: 10401,10501,10601 | C35: 冶金学I | D35: jy_stone6 | E35: 生产古铜锭、锡铁锭、精金锭时，工作进度提升20% | G35: 装备工坊
A36: 30 | B36: 10402,10502,10602 | C36: 冶金学II | D36: jy_stone6 | E36: 生产古铜锭、锡铁锭、精金锭时，工作进度提升25% | G36: 装备工坊
A37: 31 | B37: 10403,10503,10603 | C37: 冶金学III | D37: jy_stone6 | E37: 生产古铜锭、锡铁锭、精金锭时，工作进度提升30% | G37: 装备工坊
A38: 32 | B38: 10404,10504,10604 | C38: 冶金学II | D38: jy_stone6 | E38: 生产古铜锭、锡铁锭、精金锭时，工作进度提升35% | G38: 装备工坊
A39: 33 | B39: 10405,10505,10605 | C39: 冶金学III | D39: jy_stone6 | E39: 生产古铜锭、锡铁锭、精金锭时，工作进度提升40% | G39: 装备工坊
A40: 34 | B40: 10406,10506,10606 | C40: 冶金学VI | D40: jy_stone6 | E40: 生产古铜锭、锡铁锭、精金锭时，工作进度提升45% | G40: 装备工坊
A41: 35 | B41: 10407,10507,10607 | C41: 冶金学VII | D41: jy_stone6 | E41: 生产古铜锭、锡铁锭、精金锭时，工作进度提升50% | G41: 装备工坊
...
