Workbook

Sheet Sheet1
A1: 7 | B1: 1 | C1: 9999 | D1: 14
A2: 自增id | B2: 装备id | C2: 战斗buff | D2: 增强等级 | E2: 消耗物 | F2: 货币消耗 | G2: 装备绑定的英雄id | H2: 战斗力系数B | I2: 战斗力系数C | J2: 战斗力系数D | K2: 老服buff描述 | L2: 老服buff未激活描述 | M2: 新服buff描述 | N2: 新服buff未激活描述
A3: int | B3: int | C3: int | D3: int | E3: string | F3: string | G3: int | H3: int | I3: float | J3: int | K3: string | L3: string | M3: string | N3: string
A4: primary | B4: none | C4: none | D4: none | E4: none | F4: none | G4: none | H4: none | I4: none | J4: none | K4: none | L4: none | M4: none | N4: none
A5: id | B5: equipId | C5: fightBuffId | D5: upgradeLevel | E5: costItem | F5: coinCost | G5: heroId | H5: powerFactorB | I5: powerFactorC | J5: powerFactorD
A6: 1 | B6: 504201 | C6: 30186 | D6: 1 | E6: 1001,619134,2 | F6: 5,0,10000 | G6: 113077 | I6: 0.001 | K6: <color=#88622E>[1级增强]命中时附加攻击</color><color=#DB5637>80%</color><color=#88622E>的风、雷属性伤害，且该伤害无视敌方的免疫负面效果。</color> | L6: <color=#44433F>[1级增强]命中时附加攻击80%的风、雷属性伤害，且该伤害无视敌方的免疫负面效果。</color> | M6: <color=#88622E>[1级增强]对有护盾角色伤害增加</color><color=#DB5637>10%</color> | N6: <color=#44433F>[1级增强]对有护盾角色伤害增加10%</color>
A7: 2 | B7: 504201 | C7: 30187 | D7: 2 | E7: 1001,619134,3 | F7: 5,0,10000 | G7: 113077 | I7: 0.0015 | K7: <color=#88622E>[2级增强]命中时附加攻击</color><color=#DB5637>90%</color><color=#88622E>的风、雷属性伤害，且该伤害无视敌方的免疫负面效果。</color> | L7: <color=#44433F>[2级增强]命中时附加攻击90%的风、雷属性伤害，且该伤害无视敌方的免疫负面效果。</color> | M7: <color=#88622E>[2级增强]对有护盾角色伤害增加</color><color=#DB5637>20%</color> | N7: <color=#44433F>[2级增强]对有护盾角色伤害增加20%</color>
A8: 3 | B8: 504201 | C8: 30188 | D8: 3 | E8: 1001,619134,5 | F8: 5,0,10000 | G8: 113077 | I8: 0.002 | K8: <color=#88622E>[3级增强]命中时附加攻击</color><color=#DB5637>100%</color><color=#88622E>的风、雷属性伤害，且该伤害无视敌方的免疫负面效果。</color> | L8: <color=#44433F>[3级增强]命中时附加攻击100%的风、雷属性伤害，且该伤害无视敌方的免疫负面效果。</color> | M8: <color=#88622E>[3级增强]对有护盾角色伤害增加</color><color=#DB5637>30%</color> | N8: <color=#44433F>[3级增强]对有护盾角色伤害增加30%</color>
A9: 4 | B9: 504201 | C9: 30189 | D9: 4 | G9: 113077 | I9: 0.0025 | K9: <color=#88622E>[4级增强]命中时附加攻击</color><color=#DB5637>110%</color><color=#88622E>的风、雷属性伤害，且该伤害无视敌方的免疫负面效果。</color> | L9: <color=#44433F>[4级增强]命中时附加攻击110%的风、雷属性伤害，且该伤害无视敌方的免疫负面效果。</color> | M9: <color=#88622E>[4级增强]对有护盾角色伤害增加</color><color=#DB5637>40%</color> | N9: <color=#44433F>[4级增强]对有护盾角色伤害增加40%</color>
A10: 5 | B10: 504202 | C10: 30190 | D10: 1 | E10: 1001,619134,1 | F10: 5,0,10000 | G10: 113077 | I10: 0.001 | K10: <color=#88622E>[1级增强]复活后打断对方，并使自身持续到下次行动时，不会受到伤害，且恢复自身</color><color=#DB5637>40%</color><color=#88622E>生命值护盾。每场战斗只能触发一次</color> | L10: <color=#44433F>[1级增强]复活后打断对方，并使自身持续到下次行动时，不会受到伤害，且恢复自身40%生命值护盾。每场战斗只能触发一次</color> | M10: <color=#88622E>[1级增强]复活后打断对方，并恢复自身</color><color=#DB5637>40%</color><color=#88622E>生命值护盾</color> | N10: <color=#44433F>[1级增强]复活后打断对方，并恢复自身40%生命值护盾</color>
A11: 6 | B11: 504202 | C11: 30191 | D11: 2 | E11: 1001,619134,2 | F11: 5,0,10000 | G11: 113077 | I11: 0.0015 | K11: <color=#88622E>[2级增强]复活后打断对方，并使自身持续到下次行动时，不会受到伤害，并恢复自身</color><color=#DB5637>60%</color><color=#88622E>生命值护盾。每场战斗只能触发一次</color> | L11: <color=#44433F>[2级增强]复活后打断对方，并使自身持续到下次行动时，不会受到伤害，并恢复自身60%生命值护盾。每场战斗只能触发一次</color> | M11: <color=#88622E>[2级增强]复活后打断对方，并恢复自身</color><color=#DB5637>60%</color><color=#88622E>生命值护盾</color> | N11: <color=#44433F>[2级增强]复活后打断对方，并恢复自身60%生命值护盾</color>
A12: 7 | B12: 504202 | C12: 30192 | D12: 3 | E12: 1001,619134,4 | F12: 5,0,10000 | G12: 113077 | I12: 0.002 | K12: <color=#88622E>[3级增强]复活后打断对方，并使自身持续到下次行动时，不会受到伤害，并恢复自身</color><color=#DB5637>80%</color><color=#88622E>生命值护盾。每场战斗只能触发一次</color> | L12: <color=#44433F>[3级增强]复活后打断对方，并使自身持续到下次行动时，不会受到伤害，并恢复自身80%生命值护盾。每场战斗只能触发一次</color> | M12: <color=#88622E>[3级增强]复活后打断对方，并恢复自身</color><color=#DB5637>80%</color><color=#88622E>生命值护盾</color> | N12: <color=#44433F>[3级增强]复活后打断对方，并恢复自身80%生命值护盾</color>
A13: 8 | B13: 504202 | C13: 30193 | D13: 4 | G13: 113077 | I13: 0.0025 | K13: <color=#88622E>[4级增强]复活后打断对方，并使自身持续到下次行动时，不会受到伤害，并恢复自身</color><color=#DB5637>100%</color><color=#88622E>生命值护盾。每场战斗只能触发一次</color> | L13: <color=#44433F>[4级增强]复活后打断对方，并使自身持续到下次行动时，不会受到伤害，并恢复自身100%生命值护盾。每场战斗只能触发一次</color> | M13: <color=#88622E>[4级增强]复活后打断对方，并恢复自身</color><color=#DB5637>100%</color><color=#88622E>生命值护盾</color> | N13: <color=#44433F>[4级增强]复活后打断对方，并恢复自身100%生命值护盾</color>
A14: 9 | B14: 504203 | C14: 30198 | D14: 1 | E14: 1001,619134,2 | F14: 5,0,10000 | G14: 113077 | I14: 0.001 | K14: <color=#88622E>[1级增强]本回合释放技能魂玉消耗减少</color><color=#DB5637>1</color><color=#88622E>点，有</color><color=#DB5637>50%</color><color=#88622E>概率额外减少</color><color=#DB5637>1</color><color=#88622E>点，且正常获得怒气</color> | L14: <color=#44433F>[1级增强]本回合释放技能魂玉消耗减少1点，有50%概率额外减少1点，且正常获得怒气</color> | M14: <color=#88622E>[1级增强]释放技能魂玉消耗减少</color><color=#DB5637>1</color><color=#88622E>点，有</color><color=#DB5637>50%</color><color=#88622E>概率额外减少</color><color=#DB5637>1</color><color=#88622E>点，且正常获得怒气</color> | N14: <color=#44433F>[1级增强]释放技能魂玉消耗减少1点，有50%概率额外减少1点，且正常获得怒气</color>
A15: 10 | B15: 504203 | C15: 30199 | D15: 2 | E15: 1001,619134,3 | F15: 5,0,10000 | G15: 113077 | I15: 0.0015 | K15: <color=#88622E>[2级增强]本回合释放技能魂玉消耗减少</color><color=#DB5637>1</color><color=#88622E>点，有</color><color=#DB5637>100%</color><color=#88622E>概率额外减少</color><color=#DB5637>1</color><color=#88622E>点，且正常获得怒气</color> | L15: <color=#44433F>[2级增强]本回合释放技能魂玉消耗减少1点，有100%概率额外减少1点，且正常获得怒气</color> | M15: <color=#88622E>[2级增强]释放技能魂玉消耗减少</color><color=#DB5637>1</color><color=#88622E>点，有</color><color=#DB5637>100%</color><color=#88622E>概率额外减少</color><color=#DB5637>1</color><color=#88622E>点，且正常获得怒气</color> | N15: <color=#44433F>[2级增强]释放技能魂玉消耗减少1点，有100%概率额外减少1点，且正常获得怒气</color>
A16: 11 | B16: 504203 | C16: 30200 | D16: 3 | E16: 1001,619134,5 | F16: 5,0,10000 | G16: 113077 | I16: 0.002 | K16: <color=#88622E>[3级增强]本回合释放技能魂玉消耗减少</color><color=#DB5637>2</color><color=#88622E>点，有</color><color=#DB5637>50%</color><color=#88622E>概率额外减少</color><color=#DB5637>1</color><color=#88622E>点，且正常获得怒气</color> | L16: <color=#44433F>[3级增强]本回合释放技能魂玉消耗减少2点，有50%概率额外减少1点，且正常获得怒气</color> | M16: <color=#88622E>[3级增强]释放技能魂玉消耗减少</color><color=#DB5637>2</color><color=#88622E>点，有</color><color=#DB5637>50%</color><color=#88622E>概率额外减少</color><color=#DB5637>1</color><color=#88622E>点，且正常获得怒气</color> | N16: <color=#44433F>[3级增强]释放技能魂玉消耗减少2点，有50%概率额外减少1点，且正常获得怒气</color>
A17: 12 | B17: 504203 | C17: 30201 | D17: 4 | G17: 113077 | I17: 0.0025 | K17: <color=#88622E>[4级增强]本回合释放技能魂玉消耗减少</color><color=#DB5637>2</color><color=#88622E>点，有</color><color=#DB5637>100%</color><color=#88622E>概率额外减少</color><color=#DB5637>1</color><color=#88622E>点，且正常获得怒气</color> | L17: <color=#44433F>[4级增强]本回合释放技能魂玉消耗减少2点，有100%概率额外减少1点，且正常获得怒气</color> | M17: <color=#88622E>[4级增强]释放技能魂玉消耗减少</color><color=#DB5637>2</color><color=#88622E>点，有</color><color=#DB5637>100%</color><color=#88622E>概率额外减少</color><color=#DB5637>1</color><color=#88622E>点，且正常获得怒气</color> | N17: <color=#44433F>[4级增强]释放技能魂玉消耗减少2点，有100%概率额外减少1点，且正常获得怒气</color>
A18: 13 | B18: 504204 | C18: 30194 | D18: 1 | E18: 1001,619134,1 | F18: 5,0,10000 | G18: 113077 | I18: 0.001 | K18: <color=#88622E>[1级增强]行动结束时，如果自身魂玉不少于</color><color=#DB5637>10</color><color=#88622E>点，立即清除自身所有敌方角色附加的效果再行动一次，一场战斗最多触发</color><color=#DB5637>1</color><color=#88622E>次</color> | L18: <color=#44433F>[1级增强]行动结束时，如果自身魂玉不少于10点，立即清除自身所有敌方角色附加的效果再行动一次，一场战斗最多触发1次</color> | M18: <color=#88622E>[1级增强]命中时附加自身攻击力</color><color=#DB5637>80%</color><color=#88622E>的真实伤害</color> | N18: <color=#44433F>[1级增强]命中时附加自身攻击力80%的真实伤害</color>
A19: 14 | B19: 504204 | C19: 30195 | D19: 2 | E19: 1001,619134,2 | F19: 5,0,10000 | G19: 113077 | I19: 0.0015 | K19: <color=#88622E>[2级增强]行动结束时，如果自身魂玉不少于</color><color=#DB5637>10</color><color=#88622E>点，立即清除自身所有敌方角色附加的效果再行动一次，一场战斗最多触发</color><color=#DB5637>2</color><color=#88622E>次</color> | L19: <color=#44433F>[2级增强]行动结束时，如果自身魂玉不少于10点，立即清除自身所有敌方角色附加的效果再行动一次，一场战斗最多触发2次</color> | M19: <color=#88622E>[2级增强]命中时附加自身攻击力</color><color=#DB5637>90%</color><color=#88622E>的真实伤害</color> | N19: <color=#44433F>[2级增强]命中时附加自身攻击力90%的真实伤害</color>
A20: 15 | B20: 504204 | C20: 30196 | D20: 3 | E20: 1001,619134,4 | F20: 5,0,10000 | G20: 113077 | I20: 0.002 | K20: <color=#88622E>[3级增强]行动结束时，如果自身魂玉不少于</color><color=#DB5637>10</color><color=#88622E>点，立即清除自身所有敌方角色附加的效果再行动一次，一场战斗最多触发</color><color=#DB5637>3</color><color=#88622E>次</color> | L20: <color=#44433F>[3级增强]行动结束时，如果自身魂玉不少于10点，立即清除自身所有敌方角色附加的效果再行动一次，一场战斗最多触发3次</color> | M20: <color=#88622E>[3级增强]命中时附加自身攻击力</color><color=#DB5637>100%</color><color=#88622E>的真实伤害</color> | N20: <color=#44433F>[3级增强]命中时附加自身攻击力100%的真实伤害</color>
A21: 16 | B21: 504204 | C21: 30197 | D21: 4 | G21: 113077 | I21: 0.0025 | K21: <color=#88622E>[4级增强]行动结束时，如果自身魂玉不少于</color><color=#DB5637>10</color><color=#88622E>点，立即清除自身所有敌方角色附加的效果再行动一次，一场战斗最多触发</color><color=#DB5637>4</color><color=#88622E>次</color> | L21: <color=#44433F>[4级增强]行动结束时，如果自身魂玉不少于10点，立即清除自身所有敌方角色附加的效果再行动一次，一场战斗最多触发4次</color> | M21: <color=#88622E>[4级增强]命中时附加自身攻击力</color><color=#DB5637>110%</color><color=#88622E>的真实伤害</color> | N21: <color=#44433F>[4级增强]命中时附加自身攻击力110%的真实伤害</color>
A22: 17 | B22: 504301 | C22: 30233 | D22: 1 | E22: 1001,619134,2 | F22: 5,0,10000 | G22: 113088 | I22: 0.001 | K22: <color=#88622E>[1级增强]前</color><color=#DB5637>3</color><color=#88622E>回合，有</color><color=#DB5637>80%</color><color=#88622E>概率不会被打断且速度提升</color><color=#DB5637>40%</color> | L22: <color=#44433F>[1级增强]前3回合，有80%概率不会被打断且速度提升40%</color> | M22: <color=#88622E>[1级增强]前</color><color=#DB5637>3</color><color=#88622E>回合，有</color><color=#DB5637>80%</color><color=#88622E>概率不会被打断</color> | N22: <color=#44433F>[1级增强]前3回合，有80%概率不会被打断</color>
A23: 18 | B23: 504301 | C23: 30234 | D23: 2 | E23: 1001,619134,3 | F23: 5,0,10000 | G23: 113088 | I23: 0.0015 | K23: <color=#88622E>[2级增强]前</color><color=#DB5637>3</color><color=#88622E>回合，有</color><color=#DB5637>90%</color><color=#88622E>概率不会被打断且速度提升</color><color=#DB5637>40%</color> | L23: <color=#44433F>[2级增强]前3回合，有90%概率不会被打断且速度提升40%</color> | M23: <color=#88622E>[2级增强]前</color><color=#DB5637>3</color><color=#88622E>回合，有</color><color=#DB5637>90%</color><color=#88622E>概率不会被打断</color> | N23: <color=#44433F>[2级增强]前3回合，有90%概率不会被打断</color>
A24: 19 | B24: 504301 | C24: 30235 | D24: 3 | E24: 1001,619134,5 | F24: 5,0,10000 | G24: 113088 | I24: 0.002 | K24: <color=#88622E>[3级增强]前</color><color=#DB5637>3</color><color=#88622E>回合，有</color><color=#DB5637>100%</color><color=#88622E>概率不会被打断且速度提升</color><color=#DB5637>40%</color> | L24: <color=#44433F>[3级增强]前3回合，有100%概率不会被打断且速度提升40%</color> | M24: <color=#88622E>[3级增强]前</color><color=#DB5637>3</color><color=#88622E>回合，有</color><color=#DB5637>100%</color><color=#88622E>概率不会被打断</color> | N24: <color=#44433F>[3级增强]前3回合，有100%概率不会被打断</color>
A25: 20 | B25: 504301 | C25: 30236 | D25: 4 | G25: 113088 | I25: 0.0025 | K25: <color=#88622E>[4级增强]前</color><color=#DB5637>4</color><color=#88622E>回合，有</color><color=#DB5637>100%</color><color=#88622E>概率不会被打断且速度提升</color><color=#DB5637>40%</color> | L25: <color=#44433F>[4级增强]前4回合，有100%概率不会被打断且速度提升40%</color> | M25: <color=#88622E>[4级增强]前</color><color=#DB5637>4</color><color=#88622E>回合，有</color><color=#DB5637>100%</color><color=#88622E>概率不会被打断</color> | N25: <color=#44433F>[4级增强]前4回合，有100%概率不会被打断</color>
A26: 21 | B26: 504302 | C26: 30221 | D26: 1 | E26: 1001,619134,1 | F26: 5,0,10000 | G26: 113088 | I26: 0.001 | K26: <color=#88622E>[1级增强]前</color><color=#DB5637>2</color><color=#88622E>回合，首次被攻击时，如果自身有护盾，有</color><color=#DB5637>80%</color><color=#88622E>概率获得生命值不会降到</color><color=#DB5637>20%</color><color=#88622E>以下效果，持续本回合</color> | L26: <color=#44433F>[1级增强]前2回合，首次被攻击时，如果自身有护盾，有80%概率获得生命值不会降到20%以下效果，持续本回合</color> | M26: <color=#88622E>[1级增强]前</color><color=#DB5637>2</color><color=#88622E>回合，首次被攻击时，如果自身有护盾，有</color><color=#DB5637>80%</color><color=#88622E>概率免疫所有敌方附加的效果，持续本回合</color> | N26: <color=#44433F>[1级增强]前2回合，首次被攻击时，如果自身有护盾，有80%概率免疫所有敌方附加的效果，持续本回合</color>
A27: 22 | B27: 504302 | C27: 30222 | D27: 2 | E27: 1001,619134,2 | F27: 5,0,10000 | G27: 113088 | I27: 0.0015 | K27: <color=#88622E>[2级增强]前</color><color=#DB5637>2</color><color=#88622E>回合，首次被攻击时，如果自身有护盾，有</color><color=#DB5637>100%</color><color=#88622E>概率获得生命值不会降到</color><color=#DB5637>20%</color><color=#88622E>以下效果，持续本回合</color> | L27: <color=#44433F>[2级增强]前2回合，首次被攻击时，如果自身有护盾，有100%概率获得生命值不会降到20%以下效果，持续本回合</color> | M27: <color=#88622E>[2级增强]前</color><color=#DB5637>2</color><color=#88622E>回合，首次被攻击时，如果自身有护盾，有</color><color=#DB5637>100%</color><color=#88622E>概率免疫所有敌方附加的效果，持续本回合</color> | N27: <color=#44433F>[2级增强]前2回合，首次被攻击时，如果自身有护盾，有100%概率免疫所有敌方附加的效果，持续本回合</color>
A28: 23 | B28: 504302 | C28: 30223 | D28: 3 | E28: 1001,619134,4 | F28: 5,0,10000 | G28: 113088 | I28: 0.002 | K28: <color=#88622E>[3级增强]前</color><color=#DB5637>3</color><color=#88622E>回合，首次被攻击时，如果自身有护盾，有</color><color=#DB5637>100%</color><color=#88622E>概率获得生命值不会降到</color><color=#DB5637>20%</color><color=#88622E>以下效果，持续本回合</color> | L28: <color=#44433F>[3级增强]前3回合，首次被攻击时，如果自身有护盾，有100%概率获得生命值不会降到20%以下效果，持续本回合</color> | M28: <color=#88622E>[3级增强]前</color><color=#DB5637>3</color><color=#88622E>回合，首次被攻击时，如果自身有护盾，有</color><color=#DB5637>100%</color><color=#88622E>概率免疫所有敌方附加的效果，持续本回合</color> | N28: <color=#44433F>[3级增强]前3回合，首次被攻击时，如果自身有护盾，有100%概率免疫所有敌方附加的效果，持续本回合</color>
A29: 24 | B29: 504302 | C29: 30224 | D29: 4 | G29: 113088 | I29: 0.0025 | K29: <color=#88622E>[4级增强]前</color><color=#DB5637>4</color><color=#88622E>回合，首次被攻击时，如果自身有护盾，有</color><color=#DB5637>100%</color><color=#88622E>概率获得生命值不会降到</color><color=#DB5637>20%</color><color=#88622E>以下效果，持续本回合</color> | L29: <color=#44433F>[4级增强]前4回合，首次被攻击时，如果自身有护盾，有100%概率获得生命值不会降到20%以下效果，持续本回合</color> | M29: <color=#88622E>[4级增强]前</color><color=#DB5637>4</color><color=#88622E>回合，首次被攻击时，如果自身有护盾，有</color><color=#DB5637>100%</color><color=#88622E>概率免疫所有敌方附加的效果，持续本回合</color> | N29: <color=#44433F>[4级增强]前4回合，首次被攻击时，如果自身有护盾，有100%概率免疫所有敌方附加的效果，持续本回合</color>
A30: 25 | B30: 504303 | C30: 30225 | D30: 1 | E30: 1001,619134,2 | F30: 5,0,10000 | G30: 113088 | I30: 0.001 | K30: <color=#88622E>[1级增强]造成的雷、火属性伤害每回合提升</color><color=#DB5637>25%</color><color=#88622E>，PVP战斗中</color><color=#DB5637>5</color><color=#88622E>回合之后，每回合提升效果增加</color><color=#DB5637>2</color><color=#88622E>倍，所有属性伤害减免提升</color><color=#DB5637>80%</color><color=#88622E>，战斗开始时，获得</color><color=#DB5637>70</color><color=#88622E>点怒气</color> | L30: <color=#44433F>[1级增强]造成的雷、火属性伤害每回合提升25%，PVP战斗中5回合之后，每回合提升效果增加2倍，所有属性伤害减免提升80%，战斗开始时，获得70点怒气</color> | M30: <color=#88622E>[1级增强]造成的雷、火属性伤害每回合提升</color><color=#DB5637>20%</color><color=#88622E>，PVP战斗中</color><color=#DB5637>5</color><color=#88622E>回合之后，每回合提升效果增加</color><color=#DB5637>2</color><color=#88622E>倍，战斗开始时，获得</color><color=#DB5637>70</color><color=#88622E>点怒气</color> | N30: <color=#44433F>[1级增强]造成的雷、火属性伤害每回合提升20%，PVP战斗中5回合之后，每回合提升效果增加2倍，战斗开始时，获得70点怒气</color>
A31: 26 | B31: 504303 | C31: 30226 | D31: 2 | E31: 1001,619134,3 | F31: 5,0,10000 | G31: 113088 | I31: 0.0015 | K31: <color=#88622E>[2级增强]造成的雷、火属性伤害每回合提升</color><color=#DB5637>30%</color><color=#88622E>，PVP战斗中</color><color=#DB5637>5</color><color=#88622E>回合之后，每回合提升效果增加</color><color=#DB5637>2</color><color=#88622E>倍，所有属性伤害减免提升</color><color=#DB5637>90%</color><color=#88622E>，战斗开始时，获得</color><color=#DB5637>80</color><color=#88622E>点怒气</color> | L31: <color=#44433F>[2级增强]造成的雷、火属性伤害每回合提升30%，PVP战斗中5回合之后，每回合提升效果增加2倍，所有属性伤害减免提升90%，战斗开始时，获得80点怒气</color> | M31: <color=#88622E>[2级增强]造成的雷、火属性伤害每回合提升</color><color=#DB5637>25%</color><color=#88622E>，PVP战斗中</color><color=#DB5637>5</color><color=#88622E>回合之后，每回合提升效果增加</color><color=#DB5637>2</color><color=#88622E>倍，战斗开始时，获得</color><color=#DB5637>80</color><color=#88622E>点怒气</color> | N31: <color=#44433F>[2级增强]造成的雷、火属性伤害每回合提升25%，PVP战斗中5回合之后，每回合提升效果增加2倍，战斗开始时，获得80点怒气</color>
A32: 27 | B32: 504303 | C32: 30227 | D32: 3 | E32: 1001,619134,5 | F32: 5,0,10000 | G32: 113088 | I32: 0.002 | K32: <color=#88622E>[3级增强]造成的雷、火属性伤害每回合提升</color><color=#DB5637>35%</color><color=#88622E>，PVP战斗中</color><color=#DB5637>5</color><color=#88622E>回合之后，每回合提升效果增加</color><color=#DB5637>2</color><color=#88622E>倍，所有属性伤害减免提升</color><color=#DB5637>100%</color><color=#88622E>，战斗开始时，获得</color><color=#DB5637>90</color><color=#88622E>点怒气</color> | L32: <color=#44433F>[3级增强]造成的雷、火属性伤害每回合提升35%，PVP战斗中5回合之后，每回合提升效果增加2倍，所有属性伤害减免提升100%，战斗开始时，获得90点怒气</color> | M32: <color=#88622E>[3级增强]造成的雷、火属性伤害每回合提升</color><color=#DB5637>30%</color><color=#88622E>，PVP战斗中</color><color=#DB5637>5</color><color=#88622E>回合之后，每回合提升效果增加</color><color=#DB5637>2</color><color=#88622E>倍，战斗开始时，获得</color><color=#DB5637>90</color><color=#88622E>点怒气</color> | N32: <color=#44433F>[3级增强]造成的雷、火属性伤害每回合提升30%，PVP战斗中5回合之后，每回合提升效果增加2倍，战斗开始时，获得90点怒气</color>
A33: 28 | B33: 504303 | C33: 30228 | D33: 4 | G33: 113088 | I33: 0.0025 | K33: <color=#88622E>[4级增强]造成的雷、火属性伤害每回合提升</color><color=#DB5637>40%</color><color=#88622E>，PVP战斗中</color><color=#DB5637>5</color><color=#88622E>回合之后，每回合提升效果增加</color><color=#DB5637>2</color><color=#88622E>倍，所有属性伤害减免提升</color><color=#DB5637>110%</color><color=#88622E>，战斗开始时，获得</color><color=#DB5637>100</color><color=#88622E>点怒气</color> | L33: <color=#44433F>[4级增强]造成的雷、火属性伤害每回合提升40%，PVP战斗中5回合之后，每回合提升效果增加2倍，所有属性伤害减免提升110%，战斗开始时，获得100点怒气</color> | M33: <color=#88622E>[4级增强]造成的雷、火属性伤害每回合提升</color><color=#DB5637>35%</color><color=#88622E>，PVP战斗中</color><color=#DB5637>5</color><color=#88622E>回合之后，每回合提升效果增加</color><color=#DB5637>2</color><color=#88622E>倍，战斗开始时，获得</color><color=#DB5637>100</color><color=#88622E>点怒气</color> | N33: <color=#44433F>[4级增强]造成的雷、火属性伤害每回合提升35%，PVP战斗中5回合之后，每回合提升效果增加2倍，战斗开始时，获得100点怒气</color>
A34: 29 | B34: 504304 | C34: 30229 | D34: 1 | E34: 1001,619134,1 | F34: 5,0,10000 | G34: 113088 | I34: 0.001 | K34: <color=#88622E>[1级增强]首回合开始时，对敌方全体造成大妈最大生命</color><color=#DB5637>20%</color><color=#88622E>的真实伤害，且大妈获得必中效果，持续</color><color=#DB5637>2</color><color=#88622E>回合</color> | L34: <color=#44433F>[1级增强]首回合开始时，对敌方全体造成大妈最大生命20%的真实伤害，且大妈获得必中效果，持续2回合</color> | M34: <color=#88622E>[1级增强]首回合开始时，对敌方全体造成大妈最大生命</color><color=#DB5637>20%</color><color=#88622E>的真实伤害</color> | N34: <color=#44433F>[1级增强]首回合开始时，对敌方全体造成大妈最大生命20%的真实伤害</color>
A35: 30 | B35: 504304 | C35: 30230 | D35: 2 | E35: 1001,619134,2 | F35: 5,0,10000 | G35: 113088 | I35: 0.0015 | K35: <color=#88622E>[2级增强]首回合开始时，对敌方全体造成大妈最大生命</color><color=#DB5637>24%</color><color=#88622E>的真实伤害，且大妈获得必中效果，持续</color><color=#DB5637>2</color><color=#88622E>回合</color> | L35: <color=#44433F>[2级增强]首回合开始时，对敌方全体造成大妈最大生命24%的真实伤害，且大妈获得必中效果，持续2回合</color> | M35: <color=#88622E>[2级增强]首回合开始时，对敌方全体造成大妈最大生命</color><color=#DB5637>24%</color><color=#88622E>的真实伤害</color> | N35: <color=#44433F>[2级增强]首回合开始时，对敌方全体造成大妈最大生命24%的真实伤害</color>
A36: 31 | B36: 504304 | C36: 30231 | D36: 3 | E36: 1001,619134,4 | F36: 5,0,10000 | G36: 113088 | I36: 0.002 | K36: <color=#88622E>[3级增强]首回合开始时，对敌方全体造成大妈最大生命</color><color=#DB5637>28%</color><color=#88622E>的真实伤害，且大妈获得必中效果，持续</color><color=#DB5637>2</color><color=#88622E>回合</color> | L36: <color=#44433F>[3级增强]首回合开始时，对敌方全体造成大妈最大生命28%的真实伤害，且大妈获得必中效果，持续2回合</color> | M36: <color=#88622E>[3级增强]首回合开始时，对敌方全体造成大妈最大生命</color><color=#DB5637>28%</color><color=#88622E>的真实伤害</color> | N36: <color=#44433F>[3级增强]首回合开始时，对敌方全体造成大妈最大生命28%的真实伤害</color>
A37: 32 | B37: 504304 | C37: 30232 | D37: 4 | G37: 113088 | I37: 0.0025 | K37: <color=#88622E>[4级增强]首回合开始时，对敌方全体造成大妈最大生命</color><color=#DB5637>32%</color><color=#88622E>的真实伤害，且大妈获得必中效果，持续</color><color=#DB5637>2</color><color=#88622E>回合</color> | L37: <color=#44433F>[4级增强]首回合开始时，对敌方全体造成大妈最大生命32%的真实伤害，且大妈获得必中效果，持续2回合</color> | M37: <color=#88622E>[4级增强]首回合开始时，对敌方全体造成大妈最大生命</color><color=#DB5637>32%</color><color=#88622E>的真实伤害</color> | N37: <color=#44433F>[4级增强]首回合开始时，对敌方全体造成大妈最大生命32%的真实伤害</color>
A38: 33 | B38: 504501 | C38: 82550 | D38: 1 | E38: 1001,619134,2 | F38: 5,0,10000 | G38: 113100 | I38: 0.001 | K38: [1级增强]从第1回合开始时，自身速度提升15%，持续4回合。 | L38: [1级增强]从第1回合开始时，自身速度提升15%，持续4回合。 | M38: [1级增强]从第1回合开始时，自身速度提升15%，持续4回合。 | N38: [1级增强]从第1回合开始时，自身速度提升15%，持续4回合。
A39: 34 | B39: 504501 | C39: 82551 | D39: 2 | E39: 1001,619134,3 | F39: 5,0,10000 | G39: 113100 | I39: 0.0015 | K39: [2级增强]从第1回合开始时，自身速度提升20%，持续4回合。 | L39: [2级增强]从第1回合开始时，自身速度提升20%，持续4回合。 | M39: [2级增强]从第1回合开始时，自身速度提升20%，持续4回合。 | N39: [2级增强]从第1回合开始时，自身速度提升20%，持续4回合。
A40: 35 | B40: 504501 | C40: 82552 | D40: 3 | E40: 1001,619134,5 | F40: 5,0,10000 | G40: 113100 | I40: 0.002 | K40: [3级增强]从第1回合开始时，自身速度提升25%，持续4回合。 | L40: [3级增强]从第1回合开始时，自身速度提升25%，持续4回合。 | M40: [3级增强]从第1回合开始时，自身速度提升25%，持续4回合。 | N40: [3级增强]从第1回合开始时，自身速度提升25%，持续4回合。
...

Sheet 制作表
A1: 增强等级上限 | B1: 4 | C1: 装备ID | D1: 位置 | E1: 英雄 | F1: 增强等级 | G1: 武器 | H1: 衣服 | I1: 项链 | J1: 戒指 | K1: 1 | L1: 2 | M1: 3 | N1: 4 | P1: 位置 | Q1: 道具 | R1: 数量 | S1: 装备id | T1: 战斗buff | U1: 增强等级 | V1: 消耗物 | W1: 货币消耗 | X1: 绑定英雄 | Y1: 战力系数B | Z1: 战力系数C | AA1: 战力系数D | AB1: buff描述 | AC1: 未激活BUFF描述 | AD1: 新服buff描述 | AE1: 新服buff未激活描述
C2: 504201 | D2: 武器 | E2: 113077 | F2: 1 | G2: 2 | H2: 1 | I2: 1 | J2: 2 | K2: =SUMPRODUCT((文本!$A:$A=$E2)*(文本!$B:$B=$D2)*(文本!$D:$D=K$1),文本!$C:$C) | L2: =SUMPRODUCT((文本!$A:$A=$E2)*(文本!$B:$B=$D2)*(文本!$D:$D=L$1),文本!$C:$C) | M2: =SUMPRODUCT((文本!$A:$A=$E2)*(文本!$B:$B=$D2)*(文本!$D:$D=M$1),文本!$C:$C) | N2: =SUMPRODUCT((文本!$A:$A=$E2)*(文本!$B:$B=$D2)*(文本!$D:$D=N$1),文本!$C:$C) | P2: =VLOOKUP(S2,C:D,2,FALSE) | Q2: 619134 | R2: =IF(U2=B$1,"",INDEX($F$1:$J$4,MATCH(U2,$F$1:$F$4,0),MATCH(P2,$F$1:$J$1,0))) | S2: =INDEX(C:C,ROUNDUP((ROW()-1)/B$1,0)+1) | T2: =INDEX($C$1:$N$5,MATCH(S2,$C$1:$C$5,0),MATCH(U2,$C$1:$N$1,0)) | U2: 1 | V2: =IF(U2=B$1,"",1001&","&Q2&","&R2) | W2: =IF(U2=B$1,"",5&","&0&","&10000) | X2: =VLOOKUP(S2,C:E,3,FALSE) | Z2: 0.001 | AB2: =VLOOKUP($T2,文本!$C:$J,4,FALSE) | AC2: =VLOOKUP($T2,文本!$C:$J,5,FALSE) | AD2: =VLOOKUP($T2,文本!$C:$J,7,FALSE) | AE2: =VLOOKUP($T2,文本!$C:$J,8,FALSE)
C3: 504202 | D3: 衣服 | E3: 113077 | F3: 2 | G3: 3 | H3: 2 | I3: 2 | J3: 3 | K3: =SUMPRODUCT((文本!$A:$A=$E3)*(文本!$B:$B=$D3)*(文本!$D:$D=K$1),文本!$C:$C) | L3: =SUMPRODUCT((文本!$A:$A=$E3)*(文本!$B:$B=$D3)*(文本!$D:$D=L$1),文本!$C:$C) | M3: =SUMPRODUCT((文本!$A:$A=$E3)*(文本!$B:$B=$D3)*(文本!$D:$D=M$1),文本!$C:$C) | N3: =SUMPRODUCT((文本!$A:$A=$E3)*(文本!$B:$B=$D3)*(文本!$D:$D=N$1),文本!$C:$C) | P3: =VLOOKUP(S3,C:D,2,FALSE) | Q3: 619134 | R3: =IF(U3=B$1,"",INDEX($F$1:$J$4,MATCH(U3,$F$1:$F$4,0),MATCH(P3,$F$1:$J$1,0))) | S3: =INDEX(C:C,ROUNDUP((ROW()-1)/B$1,0)+1) | T3: =INDEX($C$1:$N$5,MATCH(S3,$C$1:$C$5,0),MATCH(U3,$C$1:$N$1,0)) | U3: =IF(U2=B$1,1,U2+1) | V3: =IF(U3=B$1,"",1001&","&Q3&","&R3) | W3: =IF(U3=B$1,"",5&","&0&","&10000) | X3: =VLOOKUP(S3,C:E,3,FALSE) | Z3: 0.0015 | AB3: =VLOOKUP($T3,文本!$C:$J,4,FALSE) | AC3: =VLOOKUP($T3,文本!$C:$J,5,FALSE) | AD3: =VLOOKUP($T3,文本!$C:$J,7,FALSE) | AE3: =VLOOKUP($T3,文本!$C:$J,8,FALSE)
C4: 504203 | D4: 戒指 | E4: 113077 | F4: 3 | G4: 5 | H4: 4 | I4: 4 | J4: 5 | K4: =SUMPRODUCT((文本!$A:$A=$E4)*(文本!$B:$B=$D4)*(文本!$D:$D=K$1),文本!$C:$C) | L4: =SUMPRODUCT((文本!$A:$A=$E4)*(文本!$B:$B=$D4)*(文本!$D:$D=L$1),文本!$C:$C) | M4: =SUMPRODUCT((文本!$A:$A=$E4)*(文本!$B:$B=$D4)*(文本!$D:$D=M$1),文本!$C:$C) | N4: =SUMPRODUCT((文本!$A:$A=$E4)*(文本!$B:$B=$D4)*(文本!$D:$D=N$1),文本!$C:$C) | P4: =VLOOKUP(S4,C:D,2,FALSE) | Q4: 619134 | R4: =IF(U4=B$1,"",INDEX($F$1:$J$4,MATCH(U4,$F$1:$F$4,0),MATCH(P4,$F$1:$J$1,0))) | S4: =INDEX(C:C,ROUNDUP((ROW()-1)/B$1,0)+1) | T4: =INDEX($C$1:$N$5,MATCH(S4,$C$1:$C$5,0),MATCH(U4,$C$1:$N$1,0)) | U4: =IF(U3=B$1,1,U3+1) | V4: =IF(U4=B$1,"",1001&","&Q4&","&R4) | W4: =IF(U4=B$1,"",5&","&0&","&10000) | X4: =VLOOKUP(S4,C:E,3,FALSE) | Z4: 0.002 | AB4: =VLOOKUP($T4,文本!$C:$J,4,FALSE) | AC4: =VLOOKUP($T4,文本!$C:$J,5,FALSE) | AD4: =VLOOKUP($T4,文本!$C:$J,7,FALSE) | AE4: =VLOOKUP($T4,文本!$C:$J,8,FALSE)
C5: 504204 | D5: 项链 | E5: 113077 | K5: =SUMPRODUCT((文本!$A:$A=$E5)*(文本!$B:$B=$D5)*(文本!$D:$D=K$1),文本!$C:$C) | L5: =SUMPRODUCT((文本!$A:$A=$E5)*(文本!$B:$B=$D5)*(文本!$D:$D=L$1),文本!$C:$C) | M5: =SUMPRODUCT((文本!$A:$A=$E5)*(文本!$B:$B=$D5)*(文本!$D:$D=M$1),文本!$C:$C) | N5: =SUMPRODUCT((文本!$A:$A=$E5)*(文本!$B:$B=$D5)*(文本!$D:$D=N$1),文本!$C:$C) | P5: =VLOOKUP(S5,C:D,2,FALSE) | Q5: 619134 | R5: =IF(U5=B$1,"",INDEX($F$1:$J$4,MATCH(U5,$F$1:$F$4,0),MATCH(P5,$F$1:$J$1,0))) | S5: =INDEX(C:C,ROUNDUP((ROW()-1)/B$1,0)+1) | T5: =INDEX($C$1:$N$5,MATCH(S5,$C$1:$C$5,0),MATCH(U5,$C$1:$N$1,0)) | U5: =IF(U4=B$1,1,U4+1) | V5: =IF(U5=B$1,"",1001&","&Q5&","&R5) | W5: =IF(U5=B$1,"",5&","&0&","&10000) | X5: =VLOOKUP(S5,C:E,3,FALSE) | Z5: 0.0025 | AB5: =VLOOKUP($T5,文本!$C:$J,4,FALSE) | AC5: =VLOOKUP($T5,文本!$C:$J,5,FALSE) | AD5: =VLOOKUP($T5,文本!$C:$J,7,FALSE) | AE5: =VLOOKUP($T5,文本!$C:$J,8,FALSE)
C6: 504301 | D6: 武器 | E6: 113088 | F6: 1 | G6: 2 | H6: 1 | I6: 1 | J6: 2 | K6: =SUMPRODUCT((文本!$A:$A=$E6)*(文本!$B:$B=$D6)*(文本!$D:$D=K$1),文本!$C:$C) | L6: =SUMPRODUCT((文本!$A:$A=$E6)*(文本!$B:$B=$D6)*(文本!$D:$D=L$1),文本!$C:$C) | M6: =SUMPRODUCT((文本!$A:$A=$E6)*(文本!$B:$B=$D6)*(文本!$D:$D=M$1),文本!$C:$C) | N6: =SUMPRODUCT((文本!$A:$A=$E6)*(文本!$B:$B=$D6)*(文本!$D:$D=N$1),文本!$C:$C) | P6: =VLOOKUP(S6,C:D,2,FALSE) | Q6: 619134 | R6: =IF(U6=B$1,"",INDEX($F$1:$J$4,MATCH(U6,$F$1:$F$4,0),MATCH(P6,$F$1:$J$1,0))) | S6: =INDEX(C:C,ROUNDUP((ROW()-1)/B$1,0)+1) | T6: =INDEX($C$1:$N$5,MATCH(S6,$C$1:$C$5,0),MATCH(U6,$C$1:$N$1,0)) | U6: =IF(U5=B$1,1,U5+1) | V6: =IF(U6=B$1,"",1001&","&Q6&","&R6) | W6: =IF(U6=B$1,"",5&","&0&","&10000) | X6: =VLOOKUP(S6,C:E,3,FALSE) | Z6: 0.001 | AB6: =VLOOKUP($T6,文本!$C:$J,4,FALSE) | AC6: =VLOOKUP($T6,文本!$C:$J,5,FALSE) | AD6: =VLOOKUP($T6,文本!$C:$J,7,FALSE) | AE6: =VLOOKUP($T6,文本!$C:$J,8,FALSE)
C7: 504302 | D7: 衣服 | E7: 113088 | F7: 2 | G7: 3 | H7: 2 | I7: 2 | J7: 3 | K7: =SUMPRODUCT((文本!$A:$A=$E7)*(文本!$B:$B=$D7)*(文本!$D:$D=K$1),文本!$C:$C) | L7: =SUMPRODUCT((文本!$A:$A=$E7)*(文本!$B:$B=$D7)*(文本!$D:$D=L$1),文本!$C:$C) | M7: =SUMPRODUCT((文本!$A:$A=$E7)*(文本!$B:$B=$D7)*(文本!$D:$D=M$1),文本!$C:$C) | N7: =SUMPRODUCT((文本!$A:$A=$E7)*(文本!$B:$B=$D7)*(文本!$D:$D=N$1),文本!$C:$C) | P7: =VLOOKUP(S7,C:D,2,FALSE) | Q7: 619134 | R7: =IF(U7=B$1,"",INDEX($F$1:$J$4,MATCH(U7,$F$1:$F$4,0),MATCH(P7,$F$1:$J$1,0))) | S7: =INDEX(C:C,ROUNDUP((ROW()-1)/B$1,0)+1) | T7: =INDEX($C$1:$N$5,MATCH(S7,$C$1:$C$5,0),MATCH(U7,$C$1:$N$1,0)) | U7: =IF(U6=B$1,1,U6+1) | V7: =IF(U7=B$1,"",1001&","&Q7&","&R7) | W7: =IF(U7=B$1,"",5&","&0&","&10000) | X7: =VLOOKUP(S7,C:E,3,FALSE) | Z7: 0.0015 | AB7: =VLOOKUP($T7,文本!$C:$J,4,FALSE) | AC7: =VLOOKUP($T7,文本!$C:$J,5,FALSE) | AD7: =VLOOKUP($T7,文本!$C:$J,7,FALSE) | AE7: =VLOOKUP($T7,文本!$C:$J,8,FALSE)
C8: 504303 | D8: 戒指 | E8: 113088 | F8: 3 | G8: 5 | H8: 4 | I8: 4 | J8: 5 | K8: =SUMPRODUCT((文本!$A:$A=$E8)*(文本!$B:$B=$D8)*(文本!$D:$D=K$1),文本!$C:$C) | L8: =SUMPRODUCT((文本!$A:$A=$E8)*(文本!$B:$B=$D8)*(文本!$D:$D=L$1),文本!$C:$C) | M8: =SUMPRODUCT((文本!$A:$A=$E8)*(文本!$B:$B=$D8)*(文本!$D:$D=M$1),文本!$C:$C) | N8: =SUMPRODUCT((文本!$A:$A=$E8)*(文本!$B:$B=$D8)*(文本!$D:$D=N$1),文本!$C:$C) | P8: =VLOOKUP(S8,C:D,2,FALSE) | Q8: 619134 | R8: =IF(U8=B$1,"",INDEX($F$1:$J$4,MATCH(U8,$F$1:$F$4,0),MATCH(P8,$F$1:$J$1,0))) | S8: =INDEX(C:C,ROUNDUP((ROW()-1)/B$1,0)+1) | T8: =INDEX($C$1:$N$5,MATCH(S8,$C$1:$C$5,0),MATCH(U8,$C$1:$N$1,0)) | U8: =IF(U7=B$1,1,U7+1) | V8: =IF(U8=B$1,"",1001&","&Q8&","&R8) | W8: =IF(U8=B$1,"",5&","&0&","&10000) | X8: =VLOOKUP(S8,C:E,3,FALSE) | Z8: 0.002 | AB8: =VLOOKUP($T8,文本!$C:$J,4,FALSE) | AC8: =VLOOKUP($T8,文本!$C:$J,5,FALSE) | AD8: =VLOOKUP($T8,文本!$C:$J,7,FALSE) | AE8: =VLOOKUP($T8,文本!$C:$J,8,FALSE)
C9: 504304 | D9: 项链 | E9: 113088 | K9: =SUMPRODUCT((文本!$A:$A=$E9)*(文本!$B:$B=$D9)*(文本!$D:$D=K$1),文本!$C:$C) | L9: =SUMPRODUCT((文本!$A:$A=$E9)*(文本!$B:$B=$D9)*(文本!$D:$D=L$1),文本!$C:$C) | M9: =SUMPRODUCT((文本!$A:$A=$E9)*(文本!$B:$B=$D9)*(文本!$D:$D=M$1),文本!$C:$C) | N9: =SUMPRODUCT((文本!$A:$A=$E9)*(文本!$B:$B=$D9)*(文本!$D:$D=N$1),文本!$C:$C) | P9: =VLOOKUP(S9,C:D,2,FALSE) | Q9: 619134 | R9: =IF(U9=B$1,"",INDEX($F$1:$J$4,MATCH(U9,$F$1:$F$4,0),MATCH(P9,$F$1:$J$1,0))) | S9: =INDEX(C:C,ROUNDUP((ROW()-1)/B$1,0)+1) | T9: =INDEX($C$1:$N$5,MATCH(S9,$C$1:$C$5,0),MATCH(U9,$C$1:$N$1,0)) | U9: =IF(U8=B$1,1,U8+1) | V9: =IF(U9=B$1,"",1001&","&Q9&","&R9) | W9: =IF(U9=B$1,"",5&","&0&","&10000) | X9: =VLOOKUP(S9,C:E,3,FALSE) | Z9: 0.0025 | AB9: =VLOOKUP($T9,文本!$C:$J,4,FALSE) | AC9: =VLOOKUP($T9,文本!$C:$J,5,FALSE) | AD9: =VLOOKUP($T9,文本!$C:$J,7,FALSE) | AE9: =VLOOKUP($T9,文本!$C:$J,8,FALSE)
P10: =VLOOKUP(S10,C:D,2,FALSE) | Q10: 619134 | R10: =IF(U10=B$1,"",INDEX($F$1:$J$4,MATCH(U10,$F$1:$F$4,0),MATCH(P10,$F$1:$J$1,0))) | S10: =INDEX(C:C,ROUNDUP((ROW()-1)/B$1,0)+1) | T10: =INDEX($C$1:$N$5,MATCH(S10,$C$1:$C$5,0),MATCH(U10,$C$1:$N$1,0)) | U10: =IF(U9=B$1,1,U9+1) | V10: =IF(U10=B$1,"",1001&","&Q10&","&R10) | W10: =IF(U10=B$1,"",5&","&0&","&10000) | X10: =VLOOKUP(S10,C:E,3,FALSE) | Z10: 0.001 | AB10: =VLOOKUP($T10,文本!$C:$J,4,FALSE) | AC10: =VLOOKUP($T10,文本!$C:$J,5,FALSE) | AD10: =VLOOKUP($T10,文本!$C:$J,7,FALSE) | AE10: =VLOOKUP($T10,文本!$C:$J,8,FALSE)
P11: =VLOOKUP(S11,C:D,2,FALSE) | Q11: 619134 | R11: =IF(U11=B$1,"",INDEX($F$1:$J$4,MATCH(U11,$F$1:$F$4,0),MATCH(P11,$F$1:$J$1,0))) | S11: =INDEX(C:C,ROUNDUP((ROW()-1)/B$1,0)+1) | T11: =INDEX($C$1:$N$5,MATCH(S11,$C$1:$C$5,0),MATCH(U11,$C$1:$N$1,0)) | U11: =IF(U10=B$1,1,U10+1) | V11: =IF(U11=B$1,"",1001&","&Q11&","&R11) | W11: =IF(U11=B$1,"",5&","&0&","&10000) | X11: =VLOOKUP(S11,C:E,3,FALSE) | Z11: 0.0015 | AB11: =VLOOKUP($T11,文本!$C:$J,4,FALSE) | AC11: =VLOOKUP($T11,文本!$C:$J,5,FALSE) | AD11: =VLOOKUP($T11,文本!$C:$J,7,FALSE) | AE11: =VLOOKUP($T11,文本!$C:$J,8,FALSE)
P12: =VLOOKUP(S12,C:D,2,FALSE) | Q12: 619134 | R12: =IF(U12=B$1,"",INDEX($F$1:$J$4,MATCH(U12,$F$1:$F$4,0),MATCH(P12,$F$1:$J$1,0))) | S12: =INDEX(C:C,ROUNDUP((ROW()-1)/B$1,0)+1) | T12: =INDEX($C$1:$N$5,MATCH(S12,$C$1:$C$5,0),MATCH(U12,$C$1:$N$1,0)) | U12: =IF(U11=B$1,1,U11+1) | V12: =IF(U12=B$1,"",1001&","&Q12&","&R12) | W12: =IF(U12=B$1,"",5&","&0&","&10000) | X12: =VLOOKUP(S12,C:E,3,FALSE) | Z12: 0.002 | AB12: =VLOOKUP($T12,文本!$C:$J,4,FALSE) | AC12: =VLOOKUP($T12,文本!$C:$J,5,FALSE) | AD12: =VLOOKUP($T12,文本!$C:$J,7,FALSE) | AE12: =VLOOKUP($T12,文本!$C:$J,8,FALSE)
P13: =VLOOKUP(S13,C:D,2,FALSE) | Q13: 619134 | R13: =IF(U13=B$1,"",INDEX($F$1:$J$4,MATCH(U13,$F$1:$F$4,0),MATCH(P13,$F$1:$J$1,0))) | S13: =INDEX(C:C,ROUNDUP((ROW()-1)/B$1,0)+1) | T13: =INDEX($C$1:$N$5,MATCH(S13,$C$1:$C$5,0),MATCH(U13,$C$1:$N$1,0)) | U13: =IF(U12=B$1,1,U12+1) | V13: =IF(U13=B$1,"",1001&","&Q13&","&R13) | W13: =IF(U13=B$1,"",5&","&0&","&10000) | X13: =VLOOKUP(S13,C:E,3,FALSE) | Z13: 0.0025 | AB13: =VLOOKUP($T13,文本!$C:$J,4,FALSE) | AC13: =VLOOKUP($T13,文本!$C:$J,5,FALSE) | AD13: =VLOOKUP($T13,文本!$C:$J,7,FALSE) | AE13: =VLOOKUP($T13,文本!$C:$J,8,FALSE)
P14: =VLOOKUP(S14,C:D,2,FALSE) | Q14: 619134 | R14: =IF(U14=B$1,"",INDEX($F$1:$J$4,MATCH(U14,$F$1:$F$4,0),MATCH(P14,$F$1:$J$1,0))) | S14: =INDEX(C:C,ROUNDUP((ROW()-1)/B$1,0)+1) | T14: =INDEX($C$1:$N$5,MATCH(S14,$C$1:$C$5,0),MATCH(U14,$C$1:$N$1,0)) | U14: =IF(U13=B$1,1,U13+1) | V14: =IF(U14=B$1,"",1001&","&Q14&","&R14) | W14: =IF(U14=B$1,"",5&","&0&","&10000) | X14: =VLOOKUP(S14,C:E,3,FALSE) | Z14: 0.001 | AB14: =VLOOKUP($T14,文本!$C:$J,4,FALSE) | AC14: =VLOOKUP($T14,文本!$C:$J,5,FALSE) | AD14: =VLOOKUP($T14,文本!$C:$J,7,FALSE) | AE14: =VLOOKUP($T14,文本!$C:$J,8,FALSE)
P15: =VLOOKUP(S15,C:D,2,FALSE) | Q15: 619134 | R15: =IF(U15=B$1,"",INDEX($F$1:$J$4,MATCH(U15,$F$1:$F$4,0),MATCH(P15,$F$1:$J$1,0))) | S15: =INDEX(C:C,ROUNDUP((ROW()-1)/B$1,0)+1) | T15: =INDEX($C$1:$N$5,MATCH(S15,$C$1:$C$5,0),MATCH(U15,$C$1:$N$1,0)) | U15: =IF(U14=B$1,1,U14+1) | V15: =IF(U15=B$1,"",1001&","&Q15&","&R15) | W15: =IF(U15=B$1,"",5&","&0&","&10000) | X15: =VLOOKUP(S15,C:E,3,FALSE) | Z15: 0.0015 | AB15: =VLOOKUP($T15,文本!$C:$J,4,FALSE) | AC15: =VLOOKUP($T15,文本!$C:$J,5,FALSE) | AD15: =VLOOKUP($T15,文本!$C:$J,7,FALSE) | AE15: =VLOOKUP($T15,文本!$C:$J,8,FALSE)
P16: =VLOOKUP(S16,C:D,2,FALSE) | Q16: 619134 | R16: =IF(U16=B$1,"",INDEX($F$1:$J$4,MATCH(U16,$F$1:$F$4,0),MATCH(P16,$F$1:$J$1,0))) | S16: =INDEX(C:C,ROUNDUP((ROW()-1)/B$1,0)+1) | T16: =INDEX($C$1:$N$5,MATCH(S16,$C$1:$C$5,0),MATCH(U16,$C$1:$N$1,0)) | U16: =IF(U15=B$1,1,U15+1) | V16: =IF(U16=B$1,"",1001&","&Q16&","&R16) | W16: =IF(U16=B$1,"",5&","&0&","&10000) | X16: =VLOOKUP(S16,C:E,3,FALSE) | Z16: 0.002 | AB16: =VLOOKUP($T16,文本!$C:$J,4,FALSE) | AC16: =VLOOKUP($T16,文本!$C:$J,5,FALSE) | AD16: =VLOOKUP($T16,文本!$C:$J,7,FALSE) | AE16: =VLOOKUP($T16,文本!$C:$J,8,FALSE)
P17: =VLOOKUP(S17,C:D,2,FALSE) | Q17: 619134 | R17: =IF(U17=B$1,"",INDEX($F$1:$J$4,MATCH(U17,$F$1:$F$4,0),MATCH(P17,$F$1:$J$1,0))) | S17: =INDEX(C:C,ROUNDUP((ROW()-1)/B$1,0)+1) | T17: =INDEX($C$1:$N$5,MATCH(S17,$C$1:$C$5,0),MATCH(U17,$C$1:$N$1,0)) | U17: =IF(U16=B$1,1,U16+1) | V17: =IF(U17=B$1,"",1001&","&Q17&","&R17) | W17: =IF(U17=B$1,"",5&","&0&","&10000) | X17: =VLOOKUP(S17,C:E,3,FALSE) | Z17: 0.0025 | AB17: =VLOOKUP($T17,文本!$C:$J,4,FALSE) | AC17: =VLOOKUP($T17,文本!$C:$J,5,FALSE) | AD17: =VLOOKUP($T17,文本!$C:$J,7,FALSE) | AE17: =VLOOKUP($T17,文本!$C:$J,8,FALSE)
P18: =VLOOKUP(S18,C:D,2,FALSE) | Q18: 619134 | R18: =IF(U18=B$1,"",INDEX($F$1:$J$4,MATCH(U18,$F$1:$F$4,0),MATCH(P18,$F$1:$J$1,0))) | S18: =INDEX(C:C,ROUNDUP((ROW()-1)/B$1,0)+1) | T18: =INDEX($C$1:$N$9,MATCH(S18,$C$1:$C$9,0),MATCH(U18,$C$1:$N$1,0)) | U18: 1 | V18: =IF(U18=B$1,"",1001&","&Q18&","&R18) | W18: =IF(U18=B$1,"",5&","&0&","&10000) | X18: =VLOOKUP(S18,C:E,3,FALSE) | Z18: 0.001 | AB18: =VLOOKUP($T18,文本!$C:$J,4,FALSE) | AC18: =VLOOKUP($T18,文本!$C:$J,5,FALSE) | AD18: =VLOOKUP($T18,文本!$C:$J,7,FALSE) | AE18: =VLOOKUP($T18,文本!$C:$J,8,FALSE)
P19: =VLOOKUP(S19,C:D,2,FALSE) | Q19: 619134 | R19: =IF(U19=B$1,"",INDEX($F$1:$J$4,MATCH(U19,$F$1:$F$4,0),MATCH(P19,$F$1:$J$1,0))) | S19: =INDEX(C:C,ROUNDUP((ROW()-1)/B$1,0)+1) | T19: =INDEX($C$1:$N$9,MATCH(S19,$C$1:$C$9,0),MATCH(U19,$C$1:$N$1,0)) | U19: =IF(U18=B$1,1,U18+1) | V19: =IF(U19=B$1,"",1001&","&Q19&","&R19) | W19: =IF(U19=B$1,"",5&","&0&","&10000) | X19: =VLOOKUP(S19,C:E,3,FALSE) | Z19: 0.0015 | AB19: =VLOOKUP($T19,文本!$C:$J,4,FALSE) | AC19: =VLOOKUP($T19,文本!$C:$J,5,FALSE) | AD19: =VLOOKUP($T19,文本!$C:$J,7,FALSE) | AE19: =VLOOKUP($T19,文本!$C:$J,8,FALSE)
P20: =VLOOKUP(S20,C:D,2,FALSE) | Q20: 619134 | R20: =IF(U20=B$1,"",INDEX($F$1:$J$4,MATCH(U20,$F$1:$F$4,0),MATCH(P20,$F$1:$J$1,0))) | S20: =INDEX(C:C,ROUNDUP((ROW()-1)/B$1,0)+1) | T20: =INDEX($C$1:$N$9,MATCH(S20,$C$1:$C$9,0),MATCH(U20,$C$1:$N$1,0)) | U20: =IF(U19=B$1,1,U19+1) | V20: =IF(U20=B$1,"",1001&","&Q20&","&R20) | W20: =IF(U20=B$1,"",5&","&0&","&10000) | X20: =VLOOKUP(S20,C:E,3,FALSE) | Z20: 0.002 | AB20: =VLOOKUP($T20,文本!$C:$J,4,FALSE) | AC20: =VLOOKUP($T20,文本!$C:$J,5,FALSE) | AD20: =VLOOKUP($T20,文本!$C:$J,7,FALSE) | AE20: =VLOOKUP($T20,文本!$C:$J,8,FALSE)
P21: =VLOOKUP(S21,C:D,2,FALSE) | Q21: 619134 | R21: =IF(U21=B$1,"",INDEX($F$1:$J$4,MATCH(U21,$F$1:$F$4,0),MATCH(P21,$F$1:$J$1,0))) | S21: =INDEX(C:C,ROUNDUP((ROW()-1)/B$1,0)+1) | T21: =INDEX($C$1:$N$9,MATCH(S21,$C$1:$C$9,0),MATCH(U21,$C$1:$N$1,0)) | U21: =IF(U20=B$1,1,U20+1) | V21: =IF(U21=B$1,"",1001&","&Q21&","&R21) | W21: =IF(U21=B$1,"",5&","&0&","&10000) | X21: =VLOOKUP(S21,C:E,3,FALSE) | Z21: 0.0025 | AB21: =VLOOKUP($T21,文本!$C:$J,4,FALSE) | AC21: =VLOOKUP($T21,文本!$C:$J,5,FALSE) | AD21: =VLOOKUP($T21,文本!$C:$J,7,FALSE) | AE21: =VLOOKUP($T21,文本!$C:$J,8,FALSE)
P22: =VLOOKUP(S22,C:D,2,FALSE) | Q22: 619134 | R22: =IF(U22=B$1,"",INDEX($F$1:$J$4,MATCH(U22,$F$1:$F$4,0),MATCH(P22,$F$1:$J$1,0))) | S22: =INDEX(C:C,ROUNDUP((ROW()-1)/B$1,0)+1) | T22: =INDEX($C$1:$N$9,MATCH(S22,$C$1:$C$9,0),MATCH(U22,$C$1:$N$1,0)) | U22: =IF(U21=B$1,1,U21+1) | V22: =IF(U22=B$1,"",1001&","&Q22&","&R22) | W22: =IF(U22=B$1,"",5&","&0&","&10000) | X22: =VLOOKUP(S22,C:E,3,FALSE) | Z22: 0.001 | AB22: =VLOOKUP($T22,文本!$C:$J,4,FALSE) | AC22: =VLOOKUP($T22,文本!$C:$J,5,FALSE) | AD22: =VLOOKUP($T22,文本!$C:$J,7,FALSE) | AE22: =VLOOKUP($T22,文本!$C:$J,8,FALSE)
P23: =VLOOKUP(S23,C:D,2,FALSE) | Q23: 619134 | R23: =IF(U23=B$1,"",INDEX($F$1:$J$4,MATCH(U23,$F$1:$F$4,0),MATCH(P23,$F$1:$J$1,0))) | S23: =INDEX(C:C,ROUNDUP((ROW()-1)/B$1,0)+1) | T23: =INDEX($C$1:$N$9,MATCH(S23,$C$1:$C$9,0),MATCH(U23,$C$1:$N$1,0)) | U23: =IF(U22=B$1,1,U22+1) | V23: =IF(U23=B$1,"",1001&","&Q23&","&R23) | W23: =IF(U23=B$1,"",5&","&0&","&10000) | X23: =VLOOKUP(S23,C:E,3,FALSE) | Z23: 0.0015 | AB23: =VLOOKUP($T23,文本!$C:$J,4,FALSE) | AC23: =VLOOKUP($T23,文本!$C:$J,5,FALSE) | AD23: =VLOOKUP($T23,文本!$C:$J,7,FALSE) | AE23: =VLOOKUP($T23,文本!$C:$J,8,FALSE)
P24: =VLOOKUP(S24,C:D,2,FALSE) | Q24: 619134 | R24: =IF(U24=B$1,"",INDEX($F$1:$J$4,MATCH(U24,$F$1:$F$4,0),MATCH(P24,$F$1:$J$1,0))) | S24: =INDEX(C:C,ROUNDUP((ROW()-1)/B$1,0)+1) | T24: =INDEX($C$1:$N$9,MATCH(S24,$C$1:$C$9,0),MATCH(U24,$C$1:$N$1,0)) | U24: =IF(U23=B$1,1,U23+1) | V24: =IF(U24=B$1,"",1001&","&Q24&","&R24) | W24: =IF(U24=B$1,"",5&","&0&","&10000) | X24: =VLOOKUP(S24,C:E,3,FALSE) | Z24: 0.002 | AB24: =VLOOKUP($T24,文本!$C:$J,4,FALSE) | AC24: =VLOOKUP($T24,文本!$C:$J,5,FALSE) | AD24: =VLOOKUP($T24,文本!$C:$J,7,FALSE) | AE24: =VLOOKUP($T24,文本!$C:$J,8,FALSE)
P25: =VLOOKUP(S25,C:D,2,FALSE) | Q25: 619134 | R25: =IF(U25=B$1,"",INDEX($F$1:$J$4,MATCH(U25,$F$1:$F$4,0),MATCH(P25,$F$1:$J$1,0))) | S25: =INDEX(C:C,ROUNDUP((ROW()-1)/B$1,0)+1) | T25: =INDEX($C$1:$N$9,MATCH(S25,$C$1:$C$9,0),MATCH(U25,$C$1:$N$1,0)) | U25: =IF(U24=B$1,1,U24+1) | V25: =IF(U25=B$1,"",1001&","&Q25&","&R25) | W25: =IF(U25=B$1,"",5&","&0&","&10000) | X25: =VLOOKUP(S25,C:E,3,FALSE) | Z25: 0.0025 | AB25: =VLOOKUP($T25,文本!$C:$J,4,FALSE) | AC25: =VLOOKUP($T25,文本!$C:$J,5,FALSE) | AD25: =VLOOKUP($T25,文本!$C:$J,7,FALSE) | AE25: =VLOOKUP($T25,文本!$C:$J,8,FALSE)
P26: =VLOOKUP(S26,C:D,2,FALSE) | Q26: 619134 | R26: =IF(U26=B$1,"",INDEX($F$1:$J$4,MATCH(U26,$F$1:$F$4,0),MATCH(P26,$F$1:$J$1,0))) | S26: =INDEX(C:C,ROUNDUP((ROW()-1)/B$1,0)+1) | T26: =INDEX($C$1:$N$9,MATCH(S26,$C$1:$C$9,0),MATCH(U26,$C$1:$N$1,0)) | U26: =IF(U25=B$1,1,U25+1) | V26: =IF(U26=B$1,"",1001&","&Q26&","&R26) | W26: =IF(U26=B$1,"",5&","&0&","&10000) | X26: =VLOOKUP(S26,C:E,3,FALSE) | Z26: 0.001 | AB26: =VLOOKUP($T26,文本!$C:$J,4,FALSE) | AC26: =VLOOKUP($T26,文本!$C:$J,5,FALSE) | AD26: =VLOOKUP($T26,文本!$C:$J,7,FALSE) | AE26: =VLOOKUP($T26,文本!$C:$J,8,FALSE)
P27: =VLOOKUP(S27,C:D,2,FALSE) | Q27: 619134 | R27: =IF(U27=B$1,"",INDEX($F$1:$J$4,MATCH(U27,$F$1:$F$4,0),MATCH(P27,$F$1:$J$1,0))) | S27: =INDEX(C:C,ROUNDUP((ROW()-1)/B$1,0)+1) | T27: =INDEX($C$1:$N$9,MATCH(S27,$C$1:$C$9,0),MATCH(U27,$C$1:$N$1,0)) | U27: =IF(U26=B$1,1,U26+1) | V27: =IF(U27=B$1,"",1001&","&Q27&","&R27) | W27: =IF(U27=B$1,"",5&","&0&","&10000) | X27: =VLOOKUP(S27,C:E,3,FALSE) | Z27: 0.0015 | AB27: =VLOOKUP($T27,文本!$C:$J,4,FALSE) | AC27: =VLOOKUP($T27,文本!$C:$J,5,FALSE) | AD27: =VLOOKUP($T27,文本!$C:$J,7,FALSE) | AE27: =VLOOKUP($T27,文本!$C:$J,8,FALSE)
P28: =VLOOKUP(S28,C:D,2,FALSE) | Q28: 619134 | R28: =IF(U28=B$1,"",INDEX($F$1:$J$4,MATCH(U28,$F$1:$F$4,0),MATCH(P28,$F$1:$J$1,0))) | S28: =INDEX(C:C,ROUNDUP((ROW()-1)/B$1,0)+1) | T28: =INDEX($C$1:$N$9,MATCH(S28,$C$1:$C$9,0),MATCH(U28,$C$1:$N$1,0)) | U28: =IF(U27=B$1,1,U27+1) | V28: =IF(U28=B$1,"",1001&","&Q28&","&R28) | W28: =IF(U28=B$1,"",5&","&0&","&10000) | X28: =VLOOKUP(S28,C:E,3,FALSE) | Z28: 0.002 | AB28: =VLOOKUP($T28,文本!$C:$J,4,FALSE) | AC28: =VLOOKUP($T28,文本!$C:$J,5,FALSE) | AD28: =VLOOKUP($T28,文本!$C:$J,7,FALSE) | AE28: =VLOOKUP($T28,文本!$C:$J,8,FALSE)
P29: =VLOOKUP(S29,C:D,2,FALSE) | Q29: 619134 | R29: =IF(U29=B$1,"",INDEX($F$1:$J$4,MATCH(U29,$F$1:$F$4,0),MATCH(P29,$F$1:$J$1,0))) | S29: =INDEX(C:C,ROUNDUP((ROW()-1)/B$1,0)+1) | T29: =INDEX($C$1:$N$9,MATCH(S29,$C$1:$C$9,0),MATCH(U29,$C$1:$N$1,0)) | U29: =IF(U28=B$1,1,U28+1) | V29: =IF(U29=B$1,"",1001&","&Q29&","&R29) | W29: =IF(U29=B$1,"",5&","&0&","&10000) | X29: =VLOOKUP(S29,C:E,3,FALSE) | Z29: 0.0025 | AB29: =VLOOKUP($T29,文本!$C:$J,4,FALSE) | AC29: =VLOOKUP($T29,文本!$C:$J,5,FALSE) | AD29: =VLOOKUP($T29,文本!$C:$J,7,FALSE) | AE29: =VLOOKUP($T29,文本!$C:$J,8,FALSE)
P30: =VLOOKUP(S30,C:D,2,FALSE) | Q30: 619134 | R30: =IF(U30=B$1,"",INDEX($F$1:$J$4,MATCH(U30,$F$1:$F$4,0),MATCH(P30,$F$1:$J$1,0))) | S30: =INDEX(C:C,ROUNDUP((ROW()-1)/B$1,0)+1) | T30: =INDEX($C$1:$N$9,MATCH(S30,$C$1:$C$9,0),MATCH(U30,$C$1:$N$1,0)) | U30: =IF(U29=B$1,1,U29+1) | V30: =IF(U30=B$1,"",1001&","&Q30&","&R30) | W30: =IF(U30=B$1,"",5&","&0&","&10000) | X30: =VLOOKUP(S30,C:E,3,FALSE) | Z30: 0.001 | AB30: =VLOOKUP($T30,文本!$C:$J,4,FALSE) | AC30: =VLOOKUP($T30,文本!$C:$J,5,FALSE) | AD30: =VLOOKUP($T30,文本!$C:$J,7,FALSE) | AE30: =VLOOKUP($T30,文本!$C:$J,8,FALSE)
... P33: =VLOOKUP(S33,C:D,2,FALSE) | Q33: 619134 | R33: =IF(U33=B$1,"",INDEX($F$1:$J$4,MATCH(U33,$F$1:$F$4,0),MATCH(P33,$F$1:$J$1,0))) | S33: =INDEX(C:C,ROUNDUP((ROW()-1)/B$1,0)+1) | T33: =INDEX($C$1:$N$9,MATCH(S33,$C$1:$C$9,0),MATCH(U33,$C$1:$N$1,0)) | U33: =IF(U32=B$1,1,U32+1) | V33: =IF(U33=B$1,"",1001&","&Q33&","&R33) | W33: =IF(U33=B$1,"",5&","&0&","&10000) | X33: =VLOOKUP(S33,C:E,3,FALSE) | Z33: 0.0025 | AB33: =VLOOKUP($T33,文本!$C:$J,4,FALSE) | AC33: =VLOOKUP($T33,文本!$C:$J,5,FALSE) | AD33: =VLOOKUP($T33,文本!$C:$J,7,FALSE) | AE33: =VLOOKUP($T33,文本!$C:$J,8,FALSE)

Sheet 文本
A1: 英雄 | B1: 部位 | C1: ID | D1: 等级 | E1: 老服BUFF | F1: 老服激活 | G1: 老服未激活 | H1: 新服BUFF | I1: 新服激活 | J1: 新服未激活
A2: 113077 | B2: 武器 | C2: 30186 | D2: 1 | E2: 命中时附加攻击80%的风、雷属性伤害，且该伤害无视敌方的免疫负面效果。 | F2: <color=#88622E>[1级增强]命中时附加攻击</color><color=#DB5637>80%</color><color=#88622E>的风、雷属性伤害，且该伤害无视敌方的免疫负面效果。</color> | G2: ="<color=#44433F>["&$D2&"级增强]"&E2&"</color>" | H2: 对有护盾角色伤害增加10% | I2: <color=#88622E>[1级增强]对有护盾角色伤害增加</color><color=#DB5637>10%</color> | J2: ="<color=#44433F>["&D2&"级增强]"&H2&"</color>"
A3: 113077 | B3: 武器 | C3: 30187 | D3: 2 | E3: 命中时附加攻击90%的风、雷属性伤害，且该伤害无视敌方的免疫负面效果。 | F3: <color=#88622E>[2级增强]命中时附加攻击</color><color=#DB5637>90%</color><color=#88622E>的风、雷属性伤害，且该伤害无视敌方的免疫负面效果。</color> | G3: ="<color=#44433F>["&$D3&"级增强]"&E3&"</color>" | H3: 对有护盾角色伤害增加20% | I3: <color=#88622E>[2级增强]对有护盾角色伤害增加</color><color=#DB5637>20%</color> | J3: ="<color=#44433F>["&D3&"级增强]"&H3&"</color>"
A4: 113077 | B4: 武器 | C4: 30188 | D4: 3 | E4: 命中时附加攻击100%的风、雷属性伤害，且该伤害无视敌方的免疫负面效果。 | F4: <color=#88622E>[3级增强]命中时附加攻击</color><color=#DB5637>100%</color><color=#88622E>的风、雷属性伤害，且该伤害无视敌方的免疫负面效果。</color> | G4: ="<color=#44433F>["&$D4&"级增强]"&E4&"</color>" | H4: 对有护盾角色伤害增加30% | I4: <color=#88622E>[3级增强]对有护盾角色伤害增加</color><color=#DB5637>30%</color> | J4: ="<color=#44433F>["&D4&"级增强]"&H4&"</color>"
A5: 113077 | B5: 武器 | C5: 30189 | D5: 4 | E5: 命中时附加攻击110%的风、雷属性伤害，且该伤害无视敌方的免疫负面效果。 | F5: <color=#88622E>[4级增强]命中时附加攻击</color><color=#DB5637>110%</color><color=#88622E>的风、雷属性伤害，且该伤害无视敌方的免疫负面效果。</color> | G5: ="<color=#44433F>["&$D5&"级增强]"&E5&"</color>" | H5: 对有护盾角色伤害增加40% | I5: <color=#88622E>[4级增强]对有护盾角色伤害增加</color><color=#DB5637>40%</color> | J5: ="<color=#44433F>["&D5&"级增强]"&H5&"</color>"
A6: 113077 | B6: 衣服 | C6: 30190 | D6: 1 | E6: 复活后打断对方，并使自身持续到下次行动时，不会受到伤害，且恢复自身40%生命值护盾。每场战斗只能触发一次 | F6: <color=#88622E>[1级增强]复活后打断对方，并使自身持续到下次行动时，不会受到伤害，且恢复自身</color><color=#DB5637>40%</color><color=#88622E>生命值护盾。每场战斗只能触发一次</color> | G6: ="<color=#44433F>["&$D6&"级增强]"&E6&"</color>" | H6: 复活后打断对方，并恢复自身40%生命值护盾 | I6: <color=#88622E>[1级增强]复活后打断对方，并恢复自身</color><color=#DB5637>40%</color><color=#88622E>生命值护盾</color> | J6: ="<color=#44433F>["&D6&"级增强]"&H6&"</color>"
A7: 113077 | B7: 衣服 | C7: 30191 | D7: 2 | E7: 复活后打断对方，并使自身持续到下次行动时，不会受到伤害，并恢复自身60%生命值护盾。每场战斗只能触发一次 | F7: <color=#88622E>[2级增强]复活后打断对方，并使自身持续到下次行动时，不会受到伤害，并恢复自身</color><color=#DB5637>60%</color><color=#88622E>生命值护盾。每场战斗只能触发一次</color> | G7: ="<color=#44433F>["&$D7&"级增强]"&E7&"</color>" | H7: 复活后打断对方，并恢复自身60%生命值护盾 | I7: <color=#88622E>[2级增强]复活后打断对方，并恢复自身</color><color=#DB5637>60%</color><color=#88622E>生命值护盾</color> | J7: ="<color=#44433F>["&D7&"级增强]"&H7&"</color>"
A8: 113077 | B8: 衣服 | C8: 30192 | D8: 3 | E8: 复活后打断对方，并使自身持续到下次行动时，不会受到伤害，并恢复自身80%生命值护盾。每场战斗只能触发一次 | F8: <color=#88622E>[3级增强]复活后打断对方，并使自身持续到下次行动时，不会受到伤害，并恢复自身</color><color=#DB5637>80%</color><color=#88622E>生命值护盾。每场战斗只能触发一次</color> | G8: ="<color=#44433F>["&$D8&"级增强]"&E8&"</color>" | H8: 复活后打断对方，并恢复自身80%生命值护盾 | I8: <color=#88622E>[3级增强]复活后打断对方，并恢复自身</color><color=#DB5637>80%</color><color=#88622E>生命值护盾</color> | J8: ="<color=#44433F>["&D8&"级增强]"&H8&"</color>"
A9: 113077 | B9: 衣服 | C9: 30193 | D9: 4 | E9: 复活后打断对方，并使自身持续到下次行动时，不会受到伤害，并恢复自身100%生命值护盾。每场战斗只能触发一次 | F9: <color=#88622E>[4级增强]复活后打断对方，并使自身持续到下次行动时，不会受到伤害，并恢复自身</color><color=#DB5637>100%</color><color=#88622E>生命值护盾。每场战斗只能触发一次</color> | G9: ="<color=#44433F>["&$D9&"级增强]"&E9&"</color>" | H9: 复活后打断对方，并恢复自身100%生命值护盾 | I9: <color=#88622E>[4级增强]复活后打断对方，并恢复自身</color><color=#DB5637>100%</color><color=#88622E>生命值护盾</color> | J9: ="<color=#44433F>["&D9&"级增强]"&H9&"</color>"
A10: 113077 | B10: 项链 | C10: 30194 | D10: 1 | E10: 行动结束时，如果自身魂玉不少于10点，立即清除自身所有敌方角色附加的效果再行动一次，一场战斗最多触发1次 | F10: <color=#88622E>[1级增强]行动结束时，如果自身魂玉不少于</color><color=#DB5637>10</color><color=#88622E>点，立即清除自身所有敌方角色附加的效果再行动一次，一场战斗最多触发</color><color=#DB5637>1</color><color=#88622E>次</color> | G10: ="<color=#44433F>["&$D10&"级增强]"&E10&"</color>" | H10: 命中时附加自身攻击力80%的真实伤害 | I10: <color=#88622E>[1级增强]命中时附加自身攻击力</color><color=#DB5637>80%</color><color=#88622E>的真实伤害</color> | J10: ="<color=#44433F>["&D10&"级增强]"&H10&"</color>"
A11: 113077 | B11: 项链 | C11: 30195 | D11: 2 | E11: 行动结束时，如果自身魂玉不少于10点，立即清除自身所有敌方角色附加的效果再行动一次，一场战斗最多触发2次 | F11: <color=#88622E>[2级增强]行动结束时，如果自身魂玉不少于</color><color=#DB5637>10</color><color=#88622E>点，立即清除自身所有敌方角色附加的效果再行动一次，一场战斗最多触发</color><color=#DB5637>2</color><color=#88622E>次</color> | G11: ="<color=#44433F>["&$D11&"级增强]"&E11&"</color>" | H11: 命中时附加自身攻击力90%的真实伤害 | I11: <color=#88622E>[2级增强]命中时附加自身攻击力</color><color=#DB5637>90%</color><color=#88622E>的真实伤害</color> | J11: ="<color=#44433F>["&D11&"级增强]"&H11&"</color>"
A12: 113077 | B12: 项链 | C12: 30196 | D12: 3 | E12: 行动结束时，如果自身魂玉不少于10点，立即清除自身所有敌方角色附加的效果再行动一次，一场战斗最多触发3次 | F12: <color=#88622E>[3级增强]行动结束时，如果自身魂玉不少于</color><color=#DB5637>10</color><color=#88622E>点，立即清除自身所有敌方角色附加的效果再行动一次，一场战斗最多触发</color><color=#DB5637>3</color><color=#88622E>次</color> | G12: ="<color=#44433F>["&$D12&"级增强]"&E12&"</color>" | H12: 命中时附加自身攻击力100%的真实伤害 | I12: <color=#88622E>[3级增强]命中时附加自身攻击力</color><color=#DB5637>100%</color><color=#88622E>的真实伤害</color> | J12: ="<color=#44433F>["&D12&"级增强]"&H12&"</color>"
A13: 113077 | B13: 项链 | C13: 30197 | D13: 4 | E13: 行动结束时，如果自身魂玉不少于10点，立即清除自身所有敌方角色附加的效果再行动一次，一场战斗最多触发4次 | F13: <color=#88622E>[4级增强]行动结束时，如果自身魂玉不少于</color><color=#DB5637>10</color><color=#88622E>点，立即清除自身所有敌方角色附加的效果再行动一次，一场战斗最多触发</color><color=#DB5637>4</color><color=#88622E>次</color> | G13: ="<color=#44433F>["&$D13&"级增强]"&E13&"</color>" | H13: 命中时附加自身攻击力110%的真实伤害 | I13: <color=#88622E>[4级增强]命中时附加自身攻击力</color><color=#DB5637>110%</color><color=#88622E>的真实伤害</color> | J13: ="<color=#44433F>["&D13&"级增强]"&H13&"</color>"
... A17: 113077 | B17: 戒指 | C17: 30201 | D17: 4 | E17: 本回合释放技能魂玉消耗减少2点，有100%概率额外减少1点，且正常获得怒气 | F17: <color=#88622E>[4级增强]本回合释放技能魂玉消耗减少</color><color=#DB5637>2</color><color=#88622E>点，有</color><color=#DB5637>100%</color><color=#88622E>概率额外减少</color><color=#DB5637>1</color><color=#88622E>点，且正常获得怒气</color> | G17: ="<color=#44433F>["&$D17&"级增强]"&E17&"</color>" | H17: 释放技能魂玉消耗减少2点，有100%概率额外减少1点，且正常获得怒气 | I17: <color=#88622E>[4级增强]释放技能魂玉消耗减少</color><color=#DB5637>2</color><color=#88622E>点，有</color><color=#DB5637>100%</color><color=#88622E>概率额外减少</color><color=#DB5637>1</color><color=#88622E>点，且正常获得怒气</color> | J17: ="<color=#44433F>["&D17&"级增强]"&H17&"</color>"
A18: 113088 | B18: 武器 | C18: 30233 | D18: 1 | E18: 前3回合，有80%概率不会被打断且速度提升40% | F18: <color=#88622E>[1级增强]前</color><color=#DB5637>3</color><color=#88622E>回合，有</color><color=#DB5637>80%</color><color=#88622E>概率不会被打断且速度提升</color><color=#DB5637>40%</color> | G18: ="<color=#44433F>["&$D18&"级增强]"&E18&"</color>" | H18: 前3回合，有80%概率不会被打断 | I18: <color=#88622E>[1级增强]前</color><color=#DB5637>3</color><color=#88622E>回合，有</color><color=#DB5637>80%</color><color=#88622E>概率不会被打断</color> | J18: ="<color=#44433F>["&$D18&"级增强]"&H18&"</color>"
A19: 113088 | B19: 武器 | C19: 30234 | D19: 2 | E19: 前3回合，有90%概率不会被打断且速度提升40% | F19: <color=#88622E>[2级增强]前</color><color=#DB5637>3</color><color=#88622E>回合，有</color><color=#DB5637>90%</color><color=#88622E>概率不会被打断且速度提升</color><color=#DB5637>40%</color> | G19: ="<color=#44433F>["&$D19&"级增强]"&E19&"</color>" | H19: 前3回合，有90%概率不会被打断 | I19: <color=#88622E>[2级增强]前</color><color=#DB5637>3</color><color=#88622E>回合，有</color><color=#DB5637>90%</color><color=#88622E>概率不会被打断</color> | J19: ="<color=#44433F>["&$D19&"级增强]"&H19&"</color>"
A20: 113088 | B20: 武器 | C20: 30235 | D20: 3 | E20: 前3回合，有100%概率不会被打断且速度提升40% | F20: <color=#88622E>[3级增强]前</color><color=#DB5637>3</color><color=#88622E>回合，有</color><color=#DB5637>100%</color><color=#88622E>概率不会被打断且速度提升</color><color=#DB5637>40%</color> | G20: ="<color=#44433F>["&$D20&"级增强]"&E20&"</color>" | H20: 前3回合，有100%概率不会被打断 | I20: <color=#88622E>[3级增强]前</color><color=#DB5637>3</color><color=#88622E>回合，有</color><color=#DB5637>100%</color><color=#88622E>概率不会被打断</color> | J20: ="<color=#44433F>["&$D20&"级增强]"&H20&"</color>"
A21: 113088 | B21: 武器 | C21: 30236 | D21: 4 | E21: 前4回合，有100%概率不会被打断且速度提升40% | F21: <color=#88622E>[4级增强]前</color><color=#DB5637>4</color><color=#88622E>回合，有</color><color=#DB5637>100%</color><color=#88622E>概率不会被打断且速度提升</color><color=#DB5637>40%</color> | G21: ="<color=#44433F>["&$D21&"级增强]"&E21&"</color>" | H21: 前4回合，有100%概率不会被打断 | I21: <color=#88622E>[4级增强]前</color><color=#DB5637>4</color><color=#88622E>回合，有</color><color=#DB5637>100%</color><color=#88622E>概率不会被打断</color> | J21: ="<color=#44433F>["&$D21&"级增强]"&H21&"</color>"
A22: 113088 | B22: 衣服 | C22: 30221 | D22: 1 | E22: 前2回合，首次被攻击时，如果自身有护盾，有80%概率获得生命值不会降到20%以下效果，持续本回合 | F22: <color=#88622E>[1级增强]前</color><color=#DB5637>2</color><color=#88622E>回合，首次被攻击时，如果自身有护盾，有</color><color=#DB5637>80%</color><color=#88622E>概率获得生命值不会降到</color><color=#DB5637>20%</color><color=#88622E>以下效果，持续本回合</color> | G22: ="<color=#44433F>["&$D22&"级增强]"&E22&"</color>" | H22: 前2回合，首次被攻击时，如果自身有护盾，有80%概率免疫所有敌方附加的效果，持续本回合 | I22: <color=#88622E>[1级增强]前</color><color=#DB5637>2</color><color=#88622E>回合，首次被攻击时，如果自身有护盾，有</color><color=#DB5637>80%</color><color=#88622E>概率免疫所有敌方附加的效果，持续本回合</color> | J22: ="<color=#44433F>["&$D22&"级增强]"&H22&"</color>"
A23: 113088 | B23: 衣服 | C23: 30222 | D23: 2 | E23: 前2回合，首次被攻击时，如果自身有护盾，有100%概率获得生命值不会降到20%以下效果，持续本回合 | F23: <color=#88622E>[2级增强]前</color><color=#DB5637>2</color><color=#88622E>回合，首次被攻击时，如果自身有护盾，有</color><color=#DB5637>100%</color><color=#88622E>概率获得生命值不会降到</color><color=#DB5637>20%</color><color=#88622E>以下效果，持续本回合</color> | G23: ="<color=#44433F>["&$D23&"级增强]"&E23&"</color>" | H23: 前2回合，首次被攻击时，如果自身有护盾，有100%概率免疫所有敌方附加的效果，持续本回合 | I23: <color=#88622E>[2级增强]前</color><color=#DB5637>2</color><color=#88622E>回合，首次被攻击时，如果自身有护盾，有</color><color=#DB5637>100%</color><color=#88622E>概率免疫所有敌方附加的效果，持续本回合</color> | J23: ="<color=#44433F>["&$D23&"级增强]"&H23&"</color>"
A24: 113088 | B24: 衣服 | C24: 30223 | D24: 3 | E24: 前3回合，首次被攻击时，如果自身有护盾，有100%概率获得生命值不会降到20%以下效果，持续本回合 | F24: <color=#88622E>[3级增强]前</color><color=#DB5637>3</color><color=#88622E>回合，首次被攻击时，如果自身有护盾，有</color><color=#DB5637>100%</color><color=#88622E>概率获得生命值不会降到</color><color=#DB5637>20%</color><color=#88622E>以下效果，持续本回合</color> | G24: ="<color=#44433F>["&$D24&"级增强]"&E24&"</color>" | H24: 前3回合，首次被攻击时，如果自身有护盾，有100%概率免疫所有敌方附加的效果，持续本回合 | I24: <color=#88622E>[3级增强]前</color><color=#DB5637>3</color><color=#88622E>回合，首次被攻击时，如果自身有护盾，有</color><color=#DB5637>100%</color><color=#88622E>概率免疫所有敌方附加的效果，持续本回合</color> | J24: ="<color=#44433F>["&$D24&"级增强]"&H24&"</color>"
A25: 113088 | B25: 衣服 | C25: 30224 | D25: 4 | E25: 前4回合，首次被攻击时，如果自身有护盾，有100%概率获得生命值不会降到20%以下效果，持续本回合 | F25: <color=#88622E>[4级增强]前</color><color=#DB5637>4</color><color=#88622E>回合，首次被攻击时，如果自身有护盾，有</color><color=#DB5637>100%</color><color=#88622E>概率获得生命值不会降到</color><color=#DB5637>20%</color><color=#88622E>以下效果，持续本回合</color> | G25: ="<color=#44433F>["&$D25&"级增强]"&E25&"</color>" | H25: 前4回合，首次被攻击时，如果自身有护盾，有100%概率免疫所有敌方附加的效果，持续本回合 | I25: <color=#88622E>[4级增强]前</color><color=#DB5637>4</color><color=#88622E>回合，首次被攻击时，如果自身有护盾，有</color><color=#DB5637>100%</color><color=#88622E>概率免疫所有敌方附加的效果，持续本回合</color> | J25: ="<color=#44433F>["&$D25&"级增强]"&H25&"</color>"
A26: 113088 | B26: 项链 | C26: 30229 | D26: 1 | E26: 首回合开始时，对敌方全体造成大妈最大生命20%的真实伤害，且大妈获得必中效果，持续2回合 | F26: <color=#88622E>[1级增强]首回合开始时，对敌方全体造成大妈最大生命</color><color=#DB5637>20%</color><color=#88622E>的真实伤害，且大妈获得必中效果，持续</color><color=#DB5637>2</color><color=#88622E>回合</color> | G26: ="<color=#44433F>["&$D26&"级增强]"&E26&"</color>" | H26: 首回合开始时，对敌方全体造成大妈最大生命20%的真实伤害 | I26: <color=#88622E>[1级增强]首回合开始时，对敌方全体造成大妈最大生命</color><color=#DB5637>20%</color><color=#88622E>的真实伤害</color> | J26: ="<color=#44433F>["&$D26&"级增强]"&H26&"</color>"
A27: 113088 | B27: 项链 | C27: 30230 | D27: 2 | E27: 首回合开始时，对敌方全体造成大妈最大生命24%的真实伤害，且大妈获得必中效果，持续2回合 | F27: <color=#88622E>[2级增强]首回合开始时，对敌方全体造成大妈最大生命</color><color=#DB5637>24%</color><color=#88622E>的真实伤害，且大妈获得必中效果，持续</color><color=#DB5637>2</color><color=#88622E>回合</color> | G27: ="<color=#44433F>["&$D27&"级增强]"&E27&"</color>" | H27: 首回合开始时，对敌方全体造成大妈最大生命24%的真实伤害 | I27: <color=#88622E>[2级增强]首回合开始时，对敌方全体造成大妈最大生命</color><color=#DB5637>24%</color><color=#88622E>的真实伤害</color> | J27: ="<color=#44433F>["&$D27&"级增强]"&H27&"</color>"
A28: 113088 | B28: 项链 | C28: 30231 | D28: 3 | E28: 首回合开始时，对敌方全体造成大妈最大生命28%的真实伤害，且大妈获得必中效果，持续2回合 | F28: <color=#88622E>[3级增强]首回合开始时，对敌方全体造成大妈最大生命</color><color=#DB5637>28%</color><color=#88622E>的真实伤害，且大妈获得必中效果，持续</color><color=#DB5637>2</color><color=#88622E>回合</color> | G28: ="<color=#44433F>["&$D28&"级增强]"&E28&"</color>" | H28: 首回合开始时，对敌方全体造成大妈最大生命28%的真实伤害 | I28: <color=#88622E>[3级增强]首回合开始时，对敌方全体造成大妈最大生命</color><color=#DB5637>28%</color><color=#88622E>的真实伤害</color> | J28: ="<color=#44433F>["&$D28&"级增强]"&H28&"</color>"
A29: 113088 | B29: 项链 | C29: 30232 | D29: 4 | E29: 首回合开始时，对敌方全体造成大妈最大生命32%的真实伤害，且大妈获得必中效果，持续2回合 | F29: <color=#88622E>[4级增强]首回合开始时，对敌方全体造成大妈最大生命</color><color=#DB5637>32%</color><color=#88622E>的真实伤害，且大妈获得必中效果，持续</color><color=#DB5637>2</color><color=#88622E>回合</color> | G29: ="<color=#44433F>["&$D29&"级增强]"&E29&"</color>" | H29: 首回合开始时，对敌方全体造成大妈最大生命32%的真实伤害 | I29: <color=#88622E>[4级增强]首回合开始时，对敌方全体造成大妈最大生命</color><color=#DB5637>32%</color><color=#88622E>的真实伤害</color> | J29: ="<color=#44433F>["&$D29&"级增强]"&H29&"</color>"
... A33: 113088 | B33: 戒指 | C33: 30228 | D33: 4 | E33: 造成的雷、火属性伤害每回合提升40%，PVP战斗中5回合之后，每回合提升效果增加2倍，所有属性伤害减免提升110%，战斗开始时，获得100点怒气 | F33: <color=#88622E>[4级增强]造成的雷、火属性伤害每回合提升</color><color=#DB5637>40%</color><color=#88622E>，PVP战斗中</color><color=#DB5637>5</color><color=#88622E>回合之后，每回合提升效果增加</color><color=#DB5637>2</color><color=#88622E>倍，所有属性伤害减免提升</color><color=#DB5637>110%</color><color=#88622E>，战斗开始时，获得</color><color=#DB5637>100</color><color=#88622E>点怒气</color> | G33: ="<color=#44433F>["&$D33&"级增强]"&E33&"</color>" | H33: 造成的雷、火属性伤害每回合提升35%，PVP战斗中5回合之后，每回合提升效果增加2倍，战斗开始时，获得100点怒气 | I33: <color=#88622E>[4级增强]造成的雷、火属性伤害每回合提升</color><color=#DB5637>35%</color><color=#88622E>，PVP战斗中</color><color=#DB5637>5</color><color=#88622E>回合之后，每回合提升效果增加</color><color=#DB5637>2</color><color=#88622E>倍，战斗开始时，获得</color><color=#DB5637>100</color><color=#88622E>点怒气</color> | J33: ="<color=#44433F>["&$D33&"级增强]"&H33&"</color>"

Sheet 来源
A1: 武器 | B1: 初始 | C1: 每释放一个技能，命中永久提升10%，最多提升8次
A2: 武器 | B2: 1级 | C2: 每释放一个技能，命中永久提升15%，最多提升8次
A3: 武器 | B3: 2级 | C3: 每释放一个技能，命中永久提升20%，最多提升8次
A4: 武器 | B4: 3级 | C4: 每释放一个技能，命中永久提升25%，最多提升8次
A5: 衣服 | B5: 初始 | C5: 复活后打断对方，并使自身持续到下次行动时，不会受到伤害，且恢复自身40%生命值护盾
A6: 衣服 | B6: 1级 | C6: 复活后打断对方，并使自身持续到下次行动时，不会受到伤害，并恢复自身60%生命值护盾
A7: 衣服 | B7: 2级 | C7: 复活后打断对方，并使自身持续到下次行动时，不会受到伤害，并恢复自身80%生命值护盾
A8: 衣服 | B8: 3级 | C8: 复活后打断对方，并使自身持续到下次行动时，不会受到伤害，并恢复自身100%生命值护盾
A9: 项链 | B9: 初始 | C9: 行动结束时，如果自身魂玉不少于10点，立即清除自身所有敌方的buff效果再行动一次，一场战斗最多触发1次
A10: 项链 | B10: 1级 | C10: 行动结束时，如果自身魂玉不少于10点，立即清除自身所有敌方的buff效果再行动一次，一场战斗最多触发2次
A11: 项链 | B11: 2级 | C11: 行动结束时，如果自身魂玉不少于10点，立即清除自身所有敌方的buff效果再行动一次，一场战斗最多触发3次
A12: 项链 | B12: 3级 | C12: 行动结束时，如果自身魂玉不少于10点，立即清除自身所有敌方的buff效果再行动一次，一场战斗最多触发4次
... A33: 戒指 | B33: 3级 | C33: 前4回合，有100%概率不会被打断
C34: 老区 | D34: 新区
A35: 武器 | B35: 初始 | C35: 前3回合，有80%概率不会被打断且速度提升40% | D35: 前3回合，有80%概率不会被打断 | E35: 30233
A36: 武器 | B36: 1级 | C36: 前3回合，有90%概率不会被打断且速度提升40% | D36: 前3回合，有90%概率不会被打断 | E36: 30234
A37: 武器 | B37: 2级 | C37: 前3回合，有100%概率不会被打断且速度提升40% | D37: 前3回合，有100%概率不会被打断 | E37: 30235
A38: 武器 | B38: 3级 | C38: 前4回合，有100%概率不会被打断且速度提升40% | D38: 前4回合，有100%概率不会被打断 | E38: 30236
A39: 衣服 | B39: 初始 | C39: 前2回合，首次被攻击时，如果自身有护盾，有80%概率获得生命值不会降到20%以下效果，持续本回合 | D39: 前2回合，首次被攻击时，如果自身有护盾，有80%概率免疫所有敌方附加的效果，持续本回合 | E39: 30221
A40: 衣服 | B40: 1级 | C40: 前2回合，首次被攻击时，如果自身有护盾，有100%概率获得生命值不会降到20%以下效果，持续本回合 | D40: 前2回合，首次被攻击时，如果自身有护盾，有100%概率免疫所有敌方附加的效果，持续本回合 | E40: 30222
A41: 衣服 | B41: 2级 | C41: 前3回合，首次被攻击时，如果自身有护盾，有100%概率获得生命值不会降到20%以下效果，持续本回合 | D41: 前3回合，首次被攻击时，如果自身有护盾，有100%概率免疫所有敌方附加的效果，持续本回合 | E41: 30223
A42: 衣服 | B42: 3级 | C42: 前4回合，首次被攻击时，如果自身有护盾，有100%概率获得生命值不会降到20%以下效果，持续本回合 | D42: 前4回合，首次被攻击时，如果自身有护盾，有100%概率免疫所有敌方附加的效果，持续本回合 | E42: 30224
A43: 项链 | B43: 初始 | C43: 首回合开始时，对敌方全体造成大妈最大生命20%的真实伤害，且大妈获得必中效果，持续2回合 | D43: 首回合开始时，对敌方全体造成大妈最大生命20%的真实伤害 | E43: 30229
A44: 项链 | B44: 1级 | C44: 首回合开始时，对敌方全体造成大妈最大生命24%的真实伤害，且大妈获得必中效果，持续2回合 | D44: 首回合开始时，对敌方全体造成大妈最大生命24%的真实伤害 | E44: 30230
A45: 项链 | B45: 2级 | C45: 首回合开始时，对敌方全体造成大妈最大生命28%的真实伤害，且大妈获得必中效果，持续2回合 | D45: 首回合开始时，对敌方全体造成大妈最大生命28%的真实伤害 | E45: 30231
A46: 项链 | B46: 3级 | C46: 首回合开始时，对敌方全体造成大妈最大生命32%的真实伤害，且大妈获得必中效果，持续2回合 | D46: 首回合开始时，对敌方全体造成大妈最大生命32%的真实伤害 | E46: 30232
... A50: 戒指 | B50: 3级 | C50: 造成的雷、火属性伤害每回合提升40%，PVP战斗中5回合之后，每回合提升效果增加2倍，所有属性伤害减免提升110%，战斗开始时，获得100点怒气 | D50: 造成的雷、火属性伤害每回合提升35%，PVP战斗中5回合之后，每回合提升效果增加2倍，战斗开始时，获得100点怒气 | E50: 30228
