Workbook

Sheet Sheet1
A1: 7 | B1: 1 | C1: 9999 | D1: 24
A2: 序号 | B2: 怪群id | C2: 星级 | D2: 逃跑时间 | E2: 公开时间 | F2: 发现分 | G2: 伤害总分 | H2: 最后一击分数 | I2: mvp分 | J2: 击杀奖励的疲劳值 | K2: 权重 | L2: 是否新区 | M2: 等级权重 | N2: 总血量 | O2: 技能列表 | P2: BOSS头像 | Q2: 模型id | R2: 展示用heroid | S2: 展示偏移x | T2: 展示偏移y | U2: 展示偏移z | V2: 展示缩放 | W2: 稀有boss | X2: 稀有奖励
A3: bossId | B3: enemyId | N3: allHP | O3: skills | P3: headIcon | Q3: modelId | R3: heroId | S3: heroPosX | T3: heroPosY | U3: heroPosZ | V3: heroScale | W3: isSpecial | X3: specialReward
A4: int | B4: int | C4: int | D4: long | E4: long | F4: int | G4: int | H4: int | I4: int | J4: int | K4: int | L4: int | M4: int | N4: double | O4: string | P4: string | Q4: int | R4: int | S4: float | T4: float | U4: float | V4: float | W4: int | X4: string
A5: primary | B5: none | C5: none | D5: none | E5: none | F5: none | G5: none | H5: none | I5: none | J5: none | K5: none | L5: none | M5: none | N5: none | O5: none | P5: none | Q5: none | R5: none | S5: none | T5: none | U5: none | V5: none | W5: none | X5: none
A6: bossId | B6: enemyId | C6: star | D6: runTime | E6: shareTime | F6: findPoint | G6: hurtPoint | H6: killPoint | I6: mvpPoint | J6: killReward | K6: weight | L6: isNew | M6: levelWeight | N6: bossHp | W6: isSpecial | X6: specialReward
A7: 1 | B7: 150001 | C7: 1 | D7: 2400 | E7: 1800 | F7: 105 | G7: 150 | H7: 9 | I7: 36 | J7: 0 | K7: 5 | L7: 1 | M7: 0 | N7: 4000000 | O7: 1000017 | P7: =VLOOKUP(R7,Sheet3!$A:$C,3,FALSE) -> hero_2d_1002 | Q7: =VLOOKUP(R7,Sheet3!A:B,2,FALSE) -> 18 | R7: 1111002 | S7: -89 | T7: 0 | U7: 0 | V7: 180 | W7: 1 | X7: 3002,0,1
A8: 2 | B8: 150002 | C8: 1 | D8: 2400 | E8: 1800 | F8: 105 | G8: 150 | H8: 9 | I8: 36 | J8: 0 | K8: 5 | L8: 1 | M8: 0 | N8: 4000000 | O8: 1000017 | P8: =VLOOKUP(R8,Sheet3!$A:$C,3,FALSE) -> hero_2d_1006 | Q8: =VLOOKUP(R8,Sheet3!A:B,2,FALSE) -> 21 | R8: 1111006 | S8: -89 | T8: 0 | U8: 0 | V8: 180
A9: 3 | B9: 150003 | C9: 1 | D9: 2400 | E9: 1800 | F9: 105 | G9: 150 | H9: 9 | I9: 36 | J9: 0 | K9: 5 | L9: 1 | M9: 0 | N9: 4000000 | O9: 1000017 | P9: =VLOOKUP(R9,Sheet3!$A:$C,3,FALSE) -> hero_2d_2010 | Q9: =VLOOKUP(R9,Sheet3!A:B,2,FALSE) -> 9 | R9: 1112010 | S9: -89 | T9: 0 | U9: 0 | V9: 180
A10: 4 | B10: 150004 | C10: 1 | D10: 2400 | E10: 1800 | F10: 105 | G10: 150 | H10: 9 | I10: 36 | J10: 0 | K10: 5 | L10: 1 | M10: 0 | N10: 4000000 | O10: 1000017 | P10: =VLOOKUP(R10,Sheet3!$A:$C,3,FALSE) -> hero_2d_1009 | Q10: =VLOOKUP(R10,Sheet3!A:B,2,FALSE) -> 20 | R10: 1111009 | S10: -89 | T10: 0 | U10: 0 | V10: 180
A11: 5 | B11: 150005 | C11: 2 | D11: 2400 | E11: 1800 | F11: 210 | G11: 300 | H11: 18 | I11: 72 | J11: 0 | K11: 5 | L11: 1 | M11: 0 | N11: 8000000 | O11: 1000017 | P11: =VLOOKUP(R11,Sheet3!$A:$C,3,FALSE) -> hero_2d_1013 | Q11: =VLOOKUP(R11,Sheet3!A:B,2,FALSE) -> 44 | R11: 1111013 | S11: -89 | T11: 0 | U11: 0 | V11: 180 | W11: 1 | X11: 3002,0,1
A12: 6 | B12: 150006 | C12: 2 | D12: 2400 | E12: 1800 | F12: 210 | G12: 300 | H12: 18 | I12: 72 | J12: 0 | K12: 5 | L12: 1 | M12: 0 | N12: 8000000 | O12: 1000017 | P12: =VLOOKUP(R12,Sheet3!$A:$C,3,FALSE) -> hero_2d_3001 | Q12: =VLOOKUP(R12,Sheet3!A:B,2,FALSE) -> 35 | R12: 1113001 | S12: -89 | T12: 0 | U12: 0 | V12: 180
A13: 7 | B13: 150007 | C13: 2 | D13: 2400 | E13: 1800 | F13: 210 | G13: 300 | H13: 18 | I13: 72 | J13: 0 | K13: 5 | L13: 1 | M13: 0 | N13: 8000000 | O13: 1000017 | P13: =VLOOKUP(R13,Sheet3!$A:$C,3,FALSE) -> hero_2d_3002 | Q13: =VLOOKUP(R13,Sheet3!A:B,2,FALSE) -> 36 | R13: 1113002 | S13: -89 | T13: 0 | U13: 0 | V13: 180
A14: 8 | B14: 150008 | C14: 2 | D14: 2400 | E14: 1800 | F14: 210 | G14: 300 | H14: 18 | I14: 72 | J14: 0 | K14: 5 | L14: 1 | M14: 0 | N14: 8000000 | O14: 1000017 | P14: =VLOOKUP(R14,Sheet3!$A:$C,3,FALSE) -> hero_2d_21092 | Q14: =VLOOKUP(R14,Sheet3!A:B,2,FALSE) -> 1082 | R14: 121092 | S14: -89 | T14: 0 | U14: 0 | V14: 180
A15: 9 | B15: 150009 | C15: 3 | D15: 2400 | E15: 1800 | F15: 280 | G15: 400 | H15: 24 | I15: 96 | J15: 0 | K15: 5 | L15: 1 | M15: 0 | N15: 40000000 | O15: 1000017 | P15: =VLOOKUP(R15,Sheet3!$A:$C,3,FALSE) -> hero_2d_2022 | Q15: =VLOOKUP(R15,Sheet3!A:B,2,FALSE) -> 17 | R15: 1112022 | S15: -89 | T15: 0 | U15: 0 | V15: 180 | W15: 1 | X15: 3002,0,1
A16: 10 | B16: 150010 | C16: 3 | D16: 2400 | E16: 1800 | F16: 280 | G16: 400 | H16: 24 | I16: 96 | J16: 0 | K16: 5 | L16: 1 | M16: 0 | N16: 40000000 | O16: 1000017 | P16: =VLOOKUP(R16,Sheet3!$A:$C,3,FALSE) -> hero_2d_3005 | Q16: =VLOOKUP(R16,Sheet3!A:B,2,FALSE) -> 53 | R16: 1113005 | S16: -89 | T16: 0 | U16: 0 | V16: 180 | W16: 1 | X16: 3002,0,1
A17: 11 | B17: 150011 | C17: 3 | D17: 2400 | E17: 1800 | F17: 280 | G17: 400 | H17: 24 | I17: 96 | J17: 0 | K17: 5 | L17: 1 | M17: 0 | N17: 40000000 | O17: 1000017 | P17: =VLOOKUP(R17,Sheet3!$A:$C,3,FALSE) -> hero_2d_3006 | Q17: =VLOOKUP(R17,Sheet3!A:B,2,FALSE) -> 39 | R17: 1113006 | S17: -89 | T17: 0 | U17: 0 | V17: 180
A18: 12 | B18: 150012 | C18: 3 | D18: 2400 | E18: 1800 | F18: 280 | G18: 400 | H18: 24 | I18: 96 | J18: 0 | K18: 5 | L18: 1 | M18: 0 | N18: 40000000 | O18: 1000017 | P18: =VLOOKUP(R18,Sheet3!$A:$C,3,FALSE) -> hero_2d_2028 | Q18: =VLOOKUP(R18,Sheet3!A:B,2,FALSE) -> 59 | R18: 1112028 | S18: -89 | T18: 0 | U18: 0 | V18: 180
A19: 13 | B19: 150013 | C19: 3 | D19: 2400 | E19: 1800 | F19: 280 | G19: 400 | H19: 24 | I19: 96 | J19: 0 | K19: 5 | L19: 1 | M19: 0 | N19: 40000000 | O19: 1000017 | P19: =VLOOKUP(R19,Sheet3!$A:$C,3,FALSE) -> hero_2d_3013 | Q19: =VLOOKUP(R19,Sheet3!A:B,2,FALSE) -> 56 | R19: 1113013 | S19: -89 | T19: 0 | U19: 0 | V19: 180
A20: 14 | B20: 150014 | C20: 3 | D20: 2400 | E20: 1800 | F20: 280 | G20: 400 | H20: 24 | I20: 96 | J20: 0 | K20: 5 | L20: 1 | M20: 0 | N20: 40000000 | O20: 1000017 | P20: =VLOOKUP(R20,Sheet3!$A:$C,3,FALSE) -> hero_2d_3018 | Q20: =VLOOKUP(R20,Sheet3!A:B,2,FALSE) -> 62 | R20: 1113018 | S20: -89 | T20: 0 | U20: 0 | V20: 180
A21: 15 | B21: 150015 | C21: 4 | D21: 3600 | E21: 2400 | F21: 630 | G21: 900 | H21: 54 | I21: 216 | J21: 2 | K21: 5 | L21: 1 | M21: 0 | N21: 100000000 | O21: 1000001 | P21: =VLOOKUP(R21,Sheet3!$A:$C,3,FALSE) -> hero_2d_3027 | Q21: =VLOOKUP(R21,Sheet3!A:B,2,FALSE) -> 78 | R21: 1113027 | S21: -89 | T21: 0 | U21: 0 | V21: 180 | W21: 1 | X21: 3002,0,1
A22: 16 | B22: 150016 | C22: 4 | D22: 3600 | E22: 2400 | F22: 630 | G22: 900 | H22: 54 | I22: 216 | J22: 2 | K22: 5 | L22: 1 | M22: 0 | N22: 100000000 | O22: 1000002 | P22: =VLOOKUP(R22,Sheet3!$A:$C,3,FALSE) -> hero_2d_3003 | Q22: =VLOOKUP(R22,Sheet3!A:B,2,FALSE) -> 16 | R22: 1113003 | S22: -89 | T22: 0 | U22: 0 | V22: 180 | W22: 1 | X22: 3002,0,1
A23: 17 | B23: 150017 | C23: 4 | D23: 3600 | E23: 2400 | F23: 630 | G23: 900 | H23: 54 | I23: 216 | J23: 2 | K23: 5 | L23: 1 | M23: 0 | N23: 100000000 | O23: 1000003 | P23: =VLOOKUP(R23,Sheet3!$A:$C,3,FALSE) -> hero_2d_3007 | Q23: =VLOOKUP(R23,Sheet3!A:B,2,FALSE) -> 52 | R23: 1113007 | S23: -89 | T23: 0 | U23: 0 | V23: 180
A24: 18 | B24: 150018 | C24: 4 | D24: 3600 | E24: 2400 | F24: 630 | G24: 900 | H24: 54 | I24: 216 | J24: 2 | K24: 5 | L24: 1 | M24: 0 | N24: 100000000 | O24: 1000004 | P24: =VLOOKUP(R24,Sheet3!$A:$C,3,FALSE) -> hero_2d_3009 | Q24: =VLOOKUP(R24,Sheet3!A:B,2,FALSE) -> 40 | R24: 1113009 | S24: -89 | T24: 0 | U24: 0 | V24: 180
A25: 19 | B25: 150019 | C25: 4 | D25: 3600 | E25: 2400 | F25: 630 | G25: 900 | H25: 54 | I25: 216 | J25: 2 | K25: 5 | L25: 1 | M25: 0 | N25: 100000000 | O25: 1000005 | P25: =VLOOKUP(R25,Sheet3!$A:$C,3,FALSE) -> hero_2d_21185 | Q25: =VLOOKUP(R25,Sheet3!A:B,2,FALSE) -> 1193 | R25: 121208 | S25: -89 | T25: 0 | U25: 0 | V25: 180
A26: 20 | B26: 150020 | C26: 4 | D26: 3600 | E26: 2400 | F26: 630 | G26: 900 | H26: 54 | I26: 216 | J26: 2 | K26: 5 | L26: 1 | M26: 0 | N26: 100000000 | O26: 1000006 | P26: =VLOOKUP(R26,Sheet3!$A:$C,3,FALSE) -> hero_2d_21186 | Q26: =VLOOKUP(R26,Sheet3!A:B,2,FALSE) -> 1194 | R26: 121209 | S26: -89 | T26: 0 | U26: 0 | V26: 180
A27: 21 | B27: 150021 | C27: 4 | D27: 3600 | E27: 2400 | F27: 630 | G27: 900 | H27: 54 | I27: 216 | J27: 2 | K27: 5 | L27: 1 | M27: 0 | N27: 100000000 | O27: 1000007 | P27: =VLOOKUP(R27,Sheet3!$A:$C,3,FALSE) -> hero_2d_3041 | Q27: =VLOOKUP(R27,Sheet3!A:B,2,FALSE) -> 1200 | R27: 1113041 | S27: -89 | T27: 0 | U27: 0 | V27: 180
A28: 22 | B28: 150022 | C28: 4 | D28: 3600 | E28: 2400 | F28: 630 | G28: 900 | H28: 54 | I28: 216 | J28: 2 | K28: 5 | L28: 1 | M28: 0 | N28: 100000000 | O28: 1000008 | P28: =VLOOKUP(R28,Sheet3!$A:$C,3,FALSE) -> hero_2d_3043 | Q28: =VLOOKUP(R28,Sheet3!A:B,2,FALSE) -> 85 | R28: 1113043 | S28: -89 | T28: 0 | U28: 0 | V28: 180
A29: 23 | B29: 150023 | C29: 5 | D29: 4800 | E29: 3600 | F29: 1925 | G29: 2750 | H29: 165 | I29: 660 | J29: 3 | K29: 5 | L29: 1 | M29: 0 | N29: 600000000 | O29: 1000009 | P29: =VLOOKUP(R29,Sheet3!$A:$C,3,FALSE) -> hero_2d_3030 | Q29: =VLOOKUP(R29,Sheet3!A:B,2,FALSE) -> 2174 | R29: 1113030 | S29: -89 | T29: 0 | U29: 0 | V29: 180
A30: 24 | B30: 150024 | C30: 5 | D30: 4800 | E30: 3600 | F30: 1925 | G30: 2750 | H30: 165 | I30: 660 | J30: 3 | K30: 5 | L30: 1 | M30: 0 | N30: 600000000 | O30: 1000010 | P30: =VLOOKUP(R30,Sheet3!$A:$C,3,FALSE) -> hero_2d_21243 | Q30: =VLOOKUP(R30,Sheet3!A:B,2,FALSE) -> 1251 | R30: 121272 | S30: -89 | T30: 0 | U30: 0 | V30: 180 | W30: 1 | X30: 3002,0,1
A31: 25 | B31: 150025 | C31: 5 | D31: 4800 | E31: 3600 | F31: 1925 | G31: 2750 | H31: 165 | I31: 660 | J31: 3 | K31: 5 | L31: 1 | M31: 0 | N31: 600000000 | O31: 1000011 | P31: =VLOOKUP(R31,Sheet3!$A:$C,3,FALSE) -> hero_2d_3040 | Q31: =VLOOKUP(R31,Sheet3!A:B,2,FALSE) -> 83 | R31: 113040 | S31: -89 | T31: 0 | U31: 0 | V31: 144 | W31: 1 | X31: 3002,0,1
A32: 26 | B32: 150026 | C32: 5 | D32: 4800 | E32: 3600 | F32: 1925 | G32: 2750 | H32: 165 | I32: 660 | J32: 3 | K32: 5 | L32: 1 | M32: 0 | N32: 600000000 | O32: 1000012 | P32: =VLOOKUP(R32,Sheet3!$A:$C,3,FALSE) -> hero_2d_3044 | Q32: =VLOOKUP(R32,Sheet3!A:B,2,FALSE) -> 87 | R32: 1113044 | S32: -89 | T32: 0 | U32: 0 | V32: 162
A33: 27 | B33: 150027 | C33: 5 | D33: 4800 | E33: 3600 | F33: 1925 | G33: 2750 | H33: 165 | I33: 660 | J33: 3 | K33: 5 | L33: 1 | M33: 0 | N33: 600000000 | O33: 1000013 | P33: =VLOOKUP(R33,Sheet3!$A:$C,3,FALSE) -> hero_2d_3079 | Q33: =VLOOKUP(R33,Sheet3!A:B,2,FALSE) -> 127 | R33: 1113084 | S33: -89 | T33: 0 | U33: 0 | V33: 180
A34: 28 | B34: 150028 | C34: 6 | D34: 6600 | E34: 4800 | F34: 3500 | G34: 5000 | H34: 300 | I34: 1200 | J34: 5 | K34: 5 | L34: 1 | M34: 0 | N34: 2000000000 | O34: 1000014 | P34: =VLOOKUP(R34,Sheet3!$A:$C,3,FALSE) -> hero_2d_3077 | Q34: =VLOOKUP(R34,Sheet3!A:B,2,FALSE) -> 125 | R34: 1113082 | S34: -89 | T34: 0 | U34: 0 | V34: 180 | W34: 1 | X34: 3002,0,1
A35: 29 | B35: 150029 | C35: 6 | D35: 6600 | E35: 4800 | F35: 3500 | G35: 5000 | H35: 300 | I35: 1200 | J35: 5 | K35: 5 | L35: 1 | M35: 0 | N35: 2000000000 | O35: 1000015 | P35: =VLOOKUP(R35,Sheet3!$A:$C,3,FALSE) -> hero_2d_3074 | Q35: =VLOOKUP(R35,Sheet3!A:B,2,FALSE) -> 122 | R35: 1113079 | S35: -89 | T35: 0 | U35: 0 | V35: 156 | W35: 1 | X35: 3002,0,1
A36: 30 | B36: 150030 | C36: 6 | D36: 6600 | E36: 4800 | F36: 3500 | G36: 5000 | H36: 300 | I36: 1200 | J36: 5 | K36: 5 | L36: 1 | M36: 0 | N36: 2000000000 | O36: 1000016 | P36: =VLOOKUP(R36,Sheet3!$A:$C,3,FALSE) -> hero_2d_3046 | Q36: =VLOOKUP(R36,Sheet3!A:B,2,FALSE) -> 93 | R36: 113047 | S36: -89 | T36: 0 | U36: 0 | V36: 120 | W36: 1 | X36: 3002,0,1
A37: 31 | B37: 151001 | C37: 1 | D37: 2400 | E37: 1800 | F37: 105 | G37: 150 | H37: 9 | I37: 36 | J37: 0 | K37: 5 | L37: 0 | M37: 0 | N37: 4000000 | O37: 1000017 | P37: hero_2d_1002 | Q37: 18 | R37: 1111002 | S37: -89 | T37: 0 | U37: 0 | V37: 180 | W37: 1 | X37: 3002,0,1
A38: 32 | B38: 151002 | C38: 1 | D38: 2400 | E38: 1800 | F38: 105 | G38: 150 | H38: 9 | I38: 36 | J38: 0 | K38: 5 | L38: 0 | M38: 0 | N38: 4000000 | O38: 1000017 | P38: hero_2d_1006 | Q38: 21 | R38: 1111006 | S38: -89 | T38: 0 | U38: 0 | V38: 180
A39: 33 | B39: 151003 | C39: 1 | D39: 2400 | E39: 1800 | F39: 105 | G39: 150 | H39: 9 | I39: 36 | J39: 0 | K39: 5 | L39: 0 | M39: 0 | N39: 4000000 | O39: 1000017 | P39: hero_2d_2010 | Q39: 9 | R39: 1112010 | S39: -89 | T39: 0 | U39: 0 | V39: 180
A40: 34 | B40: 151004 | C40: 1 | D40: 2400 | E40: 1800 | F40: 105 | G40: 150 | H40: 9 | I40: 36 | J40: 0 | K40: 5 | L40: 0 | M40: 0 | N40: 4000000 | O40: 1000017 | P40: hero_2d_1009 | Q40: 20 | R40: 1111009 | S40: -89 | T40: 0 | U40: 0 | V40: 180
...

Sheet Sheet2
E1: 54166667 | F1: =E1*6 -> 3.25e+08
A2: 150001 | B2: 1000000 | E2: 57500000 | F2: =E2*6 -> 3.45e+08
A3: 150001 | B3: 1000000 | E3: 60833333 | F3: =E3*6 -> 3.65e+08 | H3: 53333333 | I3: =ROUNDUP(H3,0) -> 53333334
A4: 150001 | B4: 1000000 | E4: 74166667 | F4: =E4*6 -> 4.45e+08 | H4: 56666667 | I4: =ROUNDUP(H4,0) -> 56666667
A5: 150001 | B5: 1000000 | E5: 1.0166667e+08 | F5: =E5*6 -> 6.1e+08 | H5: 60000000 | I5: =ROUNDUP(H5,0) -> 60000000
A6: 150002 | B6: 1000000 | E6: 1.2e+08 | F6: =E6*6 -> 7.2e+08 | H6: 63333333 | I6: =ROUNDUP(H6,0) -> 63333334
A7: 150002 | B7: 1000000 | E7: 95000000 | F7: =E7*6 -> 5.7e+08 | H7: 1.0666667e+08 | I7: =ROUNDUP(H7,0) -> 106666667
A8: 150002 | B8: 1000000 | E8: 1.425e+08 | F8: =E8*6 -> 8.55e+08 | H8: 1.0833333e+08 | I8: =ROUNDUP(H8,0) -> 108333334
A9: 150002 | B9: 2000000 | E9: 1.4616667e+08 | F9: =E9*6 -> 8.77e+08 | H9: 1e+08 | I9: =ROUNDUP(H9,0) -> 100000001
A10: 150003 | B10: 500000 | E10: 1.4783333e+08 | F10: =E10*6 -> 8.87e+08 | H10: 1.4166667e+08 | I10: =ROUNDUP(H10,0) -> 141666667
A11: 150003 | B11: 500000 | E11: 1.4933333e+08 | F11: =E11*6 -> 8.96e+08 | H11: 1.4583333e+08 | I11: =ROUNDUP(H11,0) -> 145833334
A12: 150003 | B12: 500000 | E12: 1.5033333e+08 | F12: =E12*6 -> 9.02e+08 | H12: 147500000 | I12: =ROUNDUP(H12,0) -> 147500000
A13: 150003 | B13: 2000000 | E13: 1.52e+08 | F13: =E13*6 -> 9.12e+08 | H13: 1.4916667e+08 | I13: =ROUNDUP(H13,0) -> 149166667
A14: 150004 | B14: 1000000 | E14: 1.56e+08 | F14: =E14*6 -> 9.36e+08 | H14: 150000000 | I14: =ROUNDUP(H14,0) -> 150000000
... A32: 150008 | B32: 1600000 | E32: 86250000 | F32: =E32*6 -> 517500000 | H32: 1250000000 | I32: =ROUNDUP(H32,0) -> 1250000000
A33: 150008 | B33: 1600000 | E33: 91250000 | F33: =E33*6 -> 547500000
A34: 150008 | B34: 1600000 | E34: 111250000 | F34: =E34*6 -> 667500000
A35: 150008 | B35: 1600000 | E35: 152500000 | F35: =E35*6 -> 915000000
A36: 150008 | B36: 1600000 | E36: 180000000 | F36: =E36*6 -> 1080000000
A37: 150009 | B37: 20000000 | E37: 142500000 | F37: =E37*6 -> 855000000
A38: 150009 | B38: 5000000 | E38: 213750000 | F38: =E38*6 -> 1282500000
A39: 150009 | B39: 5000000 | E39: 219250000 | F39: =E39*6 -> 1315500000
A40: 150009 | B40: 5000000 | E40: 221750000 | F40: =E40*6 -> 1330500000
A41: 150010 | B41: 20000000 | E41: 224000000 | F41: =E41*6 -> 1344000000
A42: 150010 | B42: 5000000 | E42: 225500000 | F42: =E42*6 -> 1353000000
A43: 150010 | B43: 5000000 | E43: 228000000 | F43: =E43*6 -> 1368000000
A44: 150011 | B44: 20000000 | E44: 234000000 | F44: =E44*6 -> 1404000000
... A60: 150014 | B60: 5000000 | E60: 1575000000 | F60: =E60*6 -> 9450000000
A61: 150015 | B61: 25000000
A62: 150015 | B62: 25000000
A63: 150015 | B63: 25000000
A64: 150015 | B64: 25000000
A65: 150015 | B65: 25000000
A66: 150016 | B66: 20000000
A67: 150016 | B67: 20000000
A68: 150016 | B68: 20000000
A69: 150016 | B69: 20000000
A70: 150016 | B70: 40000000
A71: 150017 | B71: 25000000
A72: 150017 | B72: 25000000
...

Sheet Sheet3
A1: ，
A2: 英雄id | B2: 主模型Id | C2: 2D立绘
A3: heroId | B3: modelId | C3: heroPaint
A4: int | B4: int | C4: string(intern)
A5: primary | B5: none | C5: none
A6: heroId | B6: modelId | C6: heroPaint
A7: 111001 | B7: 23 | C7: hero_2d_1001 | G7: 150001 | H7: 18 | I7: 180 | J7: morgan001_body | L7: 108*2
A8: 111002 | B8: 18 | C8: hero_2d_1002 | G8: 150002 | H8: 21 | I8: 180 | J8: krieg001_body
A9: 111003 | B9: 24 | C9: hero_2d_1003 | G9: 150003 | H9: 9 | I9: 180 | J9: buggy001_body
A10: 111004 | B10: 19 | C10: hero_2d_1004 | G10: 150004 | H10: 20 | I10: 180 | J10: arlong001_body
A11: 111005 | B11: 8 | C11: hero_2d_1005 | G11: 150005 | H11: 44 | I11: 180 | J11: wapol001_body
A12: 111006 | B12: 21 | C12: hero_2d_1006 | G12: 150006 | H12: 35 | I12: 180 | J12: crocodile001_body
A13: 111007 | B13: 22 | C13: hero_2d_1007 | G13: 150007 | H13: 36 | I13: 180 | J13: enel001_body
A14: 111008 | B14: 32 | C14: hero_2d_1008 | G14: 150008 | H14: 1082 | I14: 180 | J14: blueno001_body
A15: 111009 | B15: 20 | C15: hero_2d_1009 | G15: 150009 | H15: 17 | I15: 180 | J15: roblucci001_body
A16: 111010 | B16: 29 | C16: hero_2d_1010 | G16: 150010 | H16: 53 | I16: 180 | J16: moria001_body
A17: 111011 | B17: 45 | C17: hero_2d_1011 | G17: 150011 | H17: 39 | I17: 180 | J17: kuma001_body
A18: 111012 | B18: 31 | C18: hero_2d_1012 | G18: 150012 | H18: 59 | I18: 180 | J18: sentoumaru_body
A19: 111013 | B19: 44 | C19: hero_2d_1013 | G19: 150013 | H19: 56 | I19: 180 | J19: hancock001_body
... A36: 112012 | B36: 13 | C36: hero_2d_2012 | G36: 150030 | H36: 93 | I36: 120 | J36: kaido001_body
A37: 112013 | B37: 12 | C37: hero_2d_2013
A38: 112014 | B38: 15 | C38: hero_2d_2014
A39: 112015 | B39: 14 | C39: hero_2d_2015
A40: 112016 | B40: 46 | C40: hero_2d_2016
A41: 112017 | B41: 28 | C41: hero_2d_2017
A42: 112018 | B42: 48 | C42: hero_2d_2018
A43: 112019 | B43: 30003 | C43: hero_2d_2019
A44: 112020 | B44: 41 | C44: hero_2d_2020
A45: 112021 | B45: 43 | C45: hero_2d_2021
A46: 112022 | B46: 17 | C46: hero_2d_2022
A47: 112023 | B47: 27 | C47: hero_2d_2023
A48: 112024 | B48: 51 | C48: hero_2d_2024
... A127: 113073 | B127: 117 | C127: hero_2d_3070
A128: 113074 | B128: 30066
A129: 113075 | B129: 119 | C129: hero_2d_3072
A130: 113076 | B130: 120 | C130: hero_2d_3071
A131: 113077 | B131: 119 | C131: hero_2d_3072
A132: 113078 | B132: 121 | C132: hero_2d_3073
A133: 113079 | B133: 122 | C133: hero_2d_3074
A134: 113080 | B134: 123 | C134: hero_2d_3075
...
