Workbook

Sheet Sheet1
A1: 7 | B1: 1 | C1: 999 | D1: 20
A2: Id | B2: 英雄id | C2: 怪群Id | D2: 名字 | E2: 刷新组 | F2: 组内权重 | G2: 头像 | H2: 显示技能 | I2: 对抗技巧（描述） | J2: 战斗地图
A3: id | B3: heroId | C3: enemyId | D3: name | E3: refreshGroup | F3: groupWeight | G3: headIcon | H3: showSkill | I3: desc
A4: int | B4: int | C4: int | D4: string | E4: int | F4: int | G4: string | H4: array_int | I4: string | J4: int
A5: primary | B5: none | C5: none | D5: none | E5: none | F5: none | G5: none | H5: none | I5: none | J5: none
A6: bossId | B6: heroId | C6: enemyId | D6: name | E6: refreshGroup | F6: groupWeight | J6: fightMapId
A7: 1 | B7: 1112001 | C7: 812001 | D7: 路飞 | G7: hero2d/hero_2d_2001 | H7: 600059&&500002&&500006&&600060 | I7: 草帽一伙船长，橡胶果实能力者，弹性的身体使物理攻击对他效果很差。上阵带有属性伤害的角色是战胜他的最好办法。 | J7: 1
A8: 2 | B8: 1112002 | C8: 812002 | D8: 佐罗 | G8: hero2d/hero_2d_2002 | H8: 600061&&500027&&500025&&600062 | I8: 草帽一伙剑士，三刀流所向披靡。刀锋所指任何敌人无不溃散，攻防一体毫无弱点的真正剑士！想战胜他无法取巧，用男人的方式正面对决吧！ | J8: 1
A9: 3 | B9: 1112003 | C9: 812003 | D9: 奈美 | G9: hero2d/hero_2d_2003 | H9: 600067&&500066&&500065&&600068 | I9: 草帽一伙航海士，利用手中的天候棒可以自由操控天气。和她对战的时候经常看看头顶才是最重要的事情。 | J9: 1
A10: 4 | B10: 1112004 | C10: 812004 | D10: 撒谎布 | G10: hero2d/hero_2d_2004 | H10: 600065&&500058&&500057&&600066 | I10: 草帽一伙狙击手，能使用各种弹丸造成不同属性伤害的天才狙击手，极其擅长范围攻击。上阵脆弱的角色很容易被范围伤害击杀。 | J10: 1
A11: 5 | B11: 1112005 | C11: 812005 | D11: 山智 | G11: hero2d/hero_2d_2005 | H11: 600063&&500052&&500050&&600064 | I11: 草帽一伙厨师，速度一流的踢技型战士，双足的高力道能将任何敌人击晕。拥有极高血量和物理抗性的前排战士是对战他的最优选择。 | J11: 1
A12: 6 | B12: 1112006 | C12: 812006 | D12: 乔巴 | G12: hero2d/hero_2d_2006 | H12: 500084&&500023&&500182&&600069 | I12: 草帽一伙医师，吃了人人果实的驯鹿。能根据战况自由变换形态，治疗能力也极其优秀。被他拖入消耗战的话败北的几率将大大增加，速战速决是对战他的关键要素。 | J12: 1
A13: 19 | B13: 1112007 | C13: 51112007 | D13: 罗宾 | G13: hero2d/hero_2d_2007 | H13: 500323&&500325&&500324&&500328 | I13: 草帽一伙历史学家，作为奥哈拉的幸存者年仅8岁就被悬赏千万。花花果实能力者，能让身体的任何部位像开花一样绽放在视线范围内的任何有形体的事物上并作出攻击或其他用途。 | J13: 1
A14: 7 | B14: 1112008 | C14: 812008 | D14: 弗兰奇 | G14: hero2d/hero_2d_2008 | H14: 500076&&500079&&500080&&600070 | I14: 草帽一伙船工，改造人，因为是自己改造所以只改造了正面。两只手臂都隐藏了强力的武器，星星盾牌的存在也使其攻防一体。 | J14: 1
A15: 15 | B15: 1112009 | C15: 812009 | D15: 布鲁克 | G15: hero2d/hero_2d_2009 | H15: 500382&&500383&&500384&&500385 | I15: 草帽一伙音乐家，黄泉果实能力者。因为浑身只剩骨头所以速度出奇的快，配合自身独特的剑术敌人往往还没有看到他就已经倒在了剑下。 | J15: 1
A16: 8 | B16: 1112010 | C16: 812010 | D16: 巴奇 | G16: hero2d/hero_2d_2010 | H16: 600071&&500095&&500094&&600072 | I16: 巴基海盗团船长，四分五裂果实能力者，被他手中的飞刀击中都将被附加流血效果。范围攻击的特质巴基弹更是附带燃烧与眩晕效果。 | J16: 1
A17: 9 | B17: 1112011 | C17: 812011 | D17: 烟鬼 | G17: hero2d/hero_2d_2011 | H17: 600073&&500110&&500108&&600074 | I17: 海军大佐，烟雾果实能力者。是个极其痛恨海盗的男人，拥有极其强力的单体伤害技能。上阵恢复型角色和强力前排才能抵挡住他的进攻! | J17: 1
A18: 10 | B18: 1112012 | C18: 812012 | D18: 塔希米 | G18: hero2d/hero_2d_2012 | H18: 600075&&500128&&500129&&600076 | I18: 海军剑士，拥有和可爱长相不符的高超剑术。强力的全体伤害技能可以轻松击杀脆弱的角色。 | J18: 1
... A38: 24 | B38: 1113010 | C38: 813010 | D38: 米霍克 | G38: hero2d/hero_2d_3010 | H38: 600083&&600084&&500304&&600085 | I38: 世界第一剑士，手中的黑刀能将任何敌人劈成碎片，厚重的前排战士在鹰眼眼中脆弱不堪。治疗型角色能有效的减缓鹰眼进攻的步伐，角色尽量避免站在一列。 | J38: 1

Sheet Sheet2
A1: CommonEnemy 怪群id | B1: 普攻 | C1: 技能1 | E1: 技能2 | G1: 技能3 | I1: 大招 | K1: 被动 | N1: 展示技能
A2: 812001 | B2: 600037 | C2: 600059 | D2: , | E2: 500002 | F2: , | G2: 500006 | H2: , | I2: 600060 | K2: 600102,1 | M2: =C2&D2&E2&F2&G2&H2&I2 -> 600059,500002,500006,600060 | N2: 600059,500002,500006,600060
A3: 812002 | B3: 600038 | C3: 600061 | D3: , | E3: 500027 | F3: , | G3: 500025 | H3: , | I3: 600062 | K3: 600103,1 | M3: =C3&D3&E3&F3&G3&H3&I3 -> 600061,500027,500025,600062 | N3: 600061,500027,500025,600062
A4: 812005 | B4: 600039 | C4: 600063 | D4: , | E4: 500052 | F4: , | G4: 500050 | H4: , | I4: 600064 | K4: 600106,1 | M4: =C4&D4&E4&F4&G4&H4&I4 -> 600063,500052,500050,600064 | N4: 600063,500052,500050,600064
A5: 812004 | B5: 600040 | C5: 600065 | D5: , | E5: 500058 | F5: , | G5: 500057 | H5: , | I5: 600066 | K5: 600105,1 | M5: =C5&D5&E5&F5&G5&H5&I5 -> 600065,500058,500057,600066 | N5: 600065,500058,500057,600066
A6: 812003 | B6: 600041 | C6: 600067 | D6: , | E6: 500066 | F6: , | G6: 500065 | H6: , | I6: 600068 | K6: 600104,1 | M6: =C6&D6&E6&F6&G6&H6&I6 -> 600067,500066,500065,600068 | N6: 600067,500066,500065,600068
A7: 812006 | B7: 600042 | C7: 500084 | D7: , | E7: 500023 | F7: , | G7: 500182 | H7: , | I7: 600069 | K7: 600107,1 | M7: =C7&D7&E7&F7&G7&H7&I7 -> 500084,500023,500182,600069 | N7: 500084,500023,500182,600069
A8: 812008 | B8: 600043 | C8: 500076 | D8: , | E8: 500079 | F8: , | G8: 500080 | H8: , | I8: 600070 | K8: 600108,1 | M8: =C8&D8&E8&F8&G8&H8&I8 -> 500076,500079,500080,600070 | N8: 500076,500079,500080,600070
A9: 812010 | B9: 600044 | C9: 600071 | D9: , | E9: 500095 | F9: , | G9: 500094 | H9: , | I9: 600072 | K9: 600109,1 | M9: =C9&D9&E9&F9&G9&H9&I9 -> 600071,500095,500094,600072 | N9: 600071,500095,500094,600072
A10: 812011 | B10: 600045 | C10: 600073 | D10: , | E10: 500110 | F10: , | G10: 500108 | H10: , | I10: 600074 | K10: 600110,1 | M10: =C10&D10&E10&F10&G10&H10&I10 -> 600073,500110,500108,600074 | N10: 600073,500110,500108,600074
A11: 812012 | B11: 600046 | C11: 600075 | D11: , | E11: 500128 | F11: , | G11: 500129 | H11: , | I11: 600076 | K11: 600111,1 | M11: =C11&D11&E11&F11&G11&H11&I11 -> 600075,500128,500129,600076 | N11: 600075,500128,500129,600076
A12: 812013 | B12: 600047 | C12: 600026 | D12: , | E12: 500119 | F12: , | G12: 500121 | H12: , | I12: 600027 | K12: 600112,1 | M12: =C12&D12&E12&F12&G12&H12&I12 -> 600026,500119,500121,600027 | N12: 600026,500119,500121,600027
A13: 812014 | B13: 600048 | C13: 500143 | D13: , | E13: 500144 | F13: , | G13: 500141 | H13: , | I13: 600029 | K13: 600113,1 | M13: =C13&D13&E13&F13&G13&H13&I13 -> 500143,500144,500141,600029 | N13: 500143,500144,500141,600029
A14: 812015 | B14: 600049 | C14: 600031 | D14: , | E14: 600030 | F14: , | G14: 500136 | H14: , | K14: 600114,1 | M14: =C14&D14&E14&F14&G14&H14&I14 -> 600031,600030,500136, | N14: 600031,600030,500136,600114
A15: 812016 | B15: 600050 | C15: 600032 | D15: , | E15: 600033 | F15: , | G15: 500310 | H15: , | I15: 600034 | K15: 600115,1 | M15: =C15&D15&E15&F15&G15&H15&I15 -> 600032,600033,500310,600034 | N15: 600032,600033,500310,600034
A16: 812017 | B16: 600051 | C16: 600035 | D16: , | E16: 500215 | F16: , | G16: 500214 | H16: , | I16: 600036 | K16: 600116,1 | M16: =C16&D16&E16&F16&G16&H16&I16 -> 600035,500215,500214,600036 | N16: 600035,500215,500214,600036
A17: 812009 | B17: 500378 | C17: 500382 | D17: , | E17: 500383 | F17: , | G17: 500384 | H17: , | I17: 500385 | M17: =C17&D17&E17&F17&G17&H17&I17 -> 500382,500383,500384,500385 | N17: 500382,500383,500384,500385
A18: 812018 | B18: 500255 | C18: 500262 | D18: , | E18: 500259 | F18: , | G18: 500257 | H18: , | I18: 500261 | M18: =C18&D18&E18&F18&G18&H18&I18 -> 500262,500259,500257,500261 | N18: 500262,500259,500257,500261
A19: 812019 | B19: 500278 | C19: 500280 | D19: , | E19: 500283 | F19: , | G19: 500281 | H19: , | I19: 500285 | M19: =C19&D19&E19&F19&G19&H19&I19 -> 500280,500283,500281,500285 | N19: 500280,500283,500281,500285
A20: 812020 | B20: 500357 | C20: 500358 | D20: , | E20: 500359 | F20: , | G20: 500360 | H20: , | I20: 500362 | M20: =C20&D20&E20&F20&G20&H20&I20 -> 500358,500359,500360,500362 | N20: 500358,500359,500360,500362
A21: 812021 | B21: 500197 | C21: 500198 | D21: , | E21: 500201 | F21: , | G21: 500200 | H21: , | I21: 500203 | M21: =C21&D21&E21&F21&G21&H21&I21 -> 500198,500201,500200,500203 | N21: 500198,500201,500200,500203
A22: 812022 | B22: 500348 | C22: 500354 | D22: , | E22: 500349 | F22: , | G22: 500350 | H22: , | I22: 500355 | M22: =C22&D22&E22&F22&G22&H22&I22 -> 500354,500349,500350,500355 | N22: 500354,500349,500350,500355
A23: 812023 | B23: 500189 | C23: 500190 | D23: , | E23: 500192 | F23: , | G23: 500194 | H23: , | I23: 500191 | M23: =C23&D23&E23&F23&G23&H23&I23 -> 500190,500192,500194,500191 | N23: 500190,500192,500194,500191
A24: 812024 | B24: 500205 | C24: 500206 | D24: , | E24: 500207 | F24: , | G24: 500208 | H24: , | I24: 500210 | M24: =C24&D24&E24&F24&G24&H24&I24 -> 500206,500207,500208,500210 | N24: 500206,500207,500208,500210
A25: 813001 | B25: 600052 | C25: 600077 | D25: , | E25: 500242 | F25: , | G25: 500243 | H25: , | I25: 600078 | K25: 600117,1 | M25: =C25&D25&E25&F25&G25&H25&I25 -> 600077,500242,500243,600078 | N25: 600077,500242,500243,600078
A26: 813003 | B26: 600053 | C26: 600079 | D26: , | E26: 600080 | F26: , | G26: 600081 | H26: , | I26: 600082 | K26: 600119,1 | M26: =C26&D26&E26&F26&G26&H26&I26 -> 600079,600080,600081,600082 | N26: 600079,600080,600081,600082
A27: 813010 | B27: 600054 | C27: 600083 | D27: , | E27: 600084 | F27: , | G27: 500304 | H27: , | I27: 600085 | K27: 600123,1 | M27: =C27&D27&E27&F27&G27&H27&I27 -> 600083,600084,500304,600085 | N27: 600083,600084,500304,600085
A28: 813002 | B28: 600055 | C28: 600086 | D28: , | E28: 600087 | F28: , | G28: 600088 | H28: , | I28: 500252 | K28: 600118,1 | M28: =C28&D28&E28&F28&G28&H28&I28 -> 600086,600087,600088,500252 | N28: 600086,600087,600088,500252
A29: 813004 | B29: 600056 | C29: 600090 | D29: , | E29: 600091 | F29: , | G29: 600093 | H29: , | K29: 600120,1 | M29: =C29&D29&E29&F29&G29&H29&I29 -> 600090,600091,600093, | N29: 600090,600091,600093,600120
A30: 813005 | B30: 500401 | C30: 500402 | D30: , | E30: 500405 | F30: , | G30: 500407 | H30: , | I30: 500408 | M30: =C30&D30&E30&F30&G30&H30&I30 -> 500402,500405,500407,500408 | N30: 500402,500405,500407,500408
A31: 813006 | B31: 600057 | C31: 600094 | D31: , | E31: 600096 | F31: , | G31: 500268 | H31: , | I31: 600097 | K31: 600121,1 | M31: =C31&D31&E31&F31&G31&H31&I31 -> 600094,600096,500268,600097 | N31: 600094,600096,500268,600097
A32: 813008 | B32: 600058 | C32: 600098 | D32: , | E32: 600099 | F32: , | G32: 600100 | H32: , | I32: 600101 | K32: 600122,1 | M32: =C32&D32&E32&F32&G32&H32&I32 -> 600098,600099,600100,600101 | N32: 600098,600099,600100,600101
A33: 813007 | B33: 500386 | C33: 500390 | D33: , | E33: 500388 | F33: , | G33: 500389 | H33: , | I33: 500393 | M33: =C33&D33&E33&F33&G33&H33&I33 -> 500390,500388,500389,500393 | N33: 500390,500388,500389,500393
A34: 813009 | B34: 500394 | C34: 500395 | D34: , | E34: 500396 | F34: , | G34: 500397 | H34: , | I34: 500400 | M34: =C34&D34&E34&F34&G34&H34&I34 -> 500395,500396,500397,500400 | N34: 500395,500396,500397,500400
A35: 813022 | B35: 500156 | C35: 500157 | D35: , | E35: 500158 | F35: , | G35: 500159 | H35: , | I35: 500161 | M35: =C35&D35&E35&F35&G35&H35&I35 -> 500157,500158,500159,500161 | N35: 500157,500158,500159,500161
A36: 813023 | B36: 500401 | C36: 500407 | D36: , | E36: 600582 | F36: , | G36: 600583 | H36: , | I36: 600585 | K36: 600584,1 | M36: =C36&D36&E36&F36&G36&H36&I36 -> 500407,600582,600583,600585 | N36: 500407,600582,600583,600585
A37: 813024 | B37: 500440 | C37: 500441 | D37: , | E37: 600587 | F37: , | G37: 700120 | H37: , | I37: 600588 | K37: 600586,1 | M37: =C37&D37&E37&F37&G37&H37&I37 -> 500441,600587,700120,600588 | N37: 500441,600587,700120,600588
A38: 813025 | B38: 500410 | C38: 700129 | D38: , | E38: 700130 | F38: , | G38: 700131 | H38: , | I38: 700135 | K38: 600589,1 | M38: =C38&D38&E38&F38&G38&H38&I38 -> 700129,700130,700131,700135 | N38: 700129,700130,700131,700135
A39: 813026 | B39: 600412 | C39: 600590 | D39: , | E39: 600591 | F39: , | G39: 600593 | H39: , | I39: 600597 | M39: =C39&D39&E39&F39&G39&H39&I39 -> 600590,600591,600593,600597 | N39: 600590,600591,600593,600597
A40: 813027 | B40: 600576 | C40: 600580 | D40: , | E40: 600579 | F40: , | G40: 600577 | H40: , | I40: 600578 | K40: 600581,1 | M40: =C40&D40&E40&F40&G40&H40&I40 -> 600580,600579,600577,600578 | N40: 600580,600579,600577,600578
...

Sheet Sheet3
A1: 7 | B1: 1 | C1: 999 | D1: 20
A2: Id | B2: 英雄id | C2: 怪群Id | D2: 名字 | E2: 刷新组 | F2: 组内权重 | G2: 头像 | H2: 显示技能
A3: id | B3: heroId | C3: enemyId | D3: name | E3: refreshGroup | F3: groupWeight | G3: headIcon | H3: showSkill
A4: int | B4: int | C4: int | D4: string | E4: int | F4: int | G4: string | H4: array_int
A5: primary | B5: none | C5: none | D5: none | E5: none | F5: none | G5: none | H5: none
A6: bossId | B6: heroId | C6: enemyId | E6: refreshGroup | F6: groupWeight
A7: 1 | B7: 1112001 | C7: 812001 | D7: 路飞 | H7: =VLOOKUP(C7,Sheet2!$A$1:$P$68,14,FALSE) -> 600059,500002,500006,600060 | I7: 600059&&500002&&500006&&600060
A8: 2 | B8: 1112002 | C8: 812002 | D8: 佐罗 | H8: =VLOOKUP(C8,Sheet2!$A$1:$P$68,14,FALSE) -> 600061,500027,500025,600062 | I8: 600061&&500027&&500025&&600062
A9: 3 | B9: 1112003 | C9: 812003 | D9: 奈美 | H9: =VLOOKUP(C9,Sheet2!$A$1:$P$68,14,FALSE) -> 600067,500066,500065,600068 | I9: 600067&&500066&&500065&&600068
A10: 4 | B10: 1112004 | C10: 812004 | D10: 撒谎布 | H10: =VLOOKUP(C10,Sheet2!$A$1:$P$68,14,FALSE) -> 600065,500058,500057,600066 | I10: 600065&&500058&&500057&&600066
A11: 5 | B11: 1112005 | C11: 812005 | D11: 山智 | H11: =VLOOKUP(C11,Sheet2!$A$1:$P$68,14,FALSE) -> 600063,500052,500050,600064 | I11: 600063&&500052&&500050&&600064
A12: 6 | B12: 1112006 | C12: 812006 | D12: 乔巴 | H12: =VLOOKUP(C12,Sheet2!$A$1:$P$68,14,FALSE) -> 500084,500023,500182,600069 | I12: 500084&&500023&&500182&&600069
A13: 19 | B13: 1112007 | C13: 51112007 | D13: 罗宾 | H13: =VLOOKUP(C13,Sheet2!$A$1:$P$68,14,FALSE) -> 500323,500325,500324,500328 | I13: 500323&&500325&&500324&&500328
A14: 7 | B14: 1112008 | C14: 812008 | D14: 弗兰奇 | H14: =VLOOKUP(C14,Sheet2!$A$1:$P$68,14,FALSE) -> 500076,500079,500080,600070 | I14: 500076&&500079&&500080&&600070
A15: 15 | B15: 1112009 | C15: 812009 | D15: 布鲁克 | H15: =VLOOKUP(C15,Sheet2!$A$1:$P$68,14,FALSE) -> 500382,500383,500384,500385 | I15: 500382&&500383&&500384&&500385
A16: 8 | B16: 1112010 | C16: 812010 | D16: 巴奇 | H16: =VLOOKUP(C16,Sheet2!$A$1:$P$68,14,FALSE) -> 600071,500095,500094,600072 | I16: 600071&&500095&&500094&&600072
A17: 9 | B17: 1112011 | C17: 812011 | D17: 烟鬼 | H17: =VLOOKUP(C17,Sheet2!$A$1:$P$68,14,FALSE) -> 600073,500110,500108,600074 | I17: 600073&&500110&&500108&&600074
A18: 10 | B18: 1112012 | C18: 812012 | D18: 塔希米 | H18: =VLOOKUP(C18,Sheet2!$A$1:$P$68,14,FALSE) -> 600075,500128,500129,600076 | I18: 600075&&500128&&500129&&600076
... A38: 24 | B38: 1113010 | C38: 813010 | D38: 米霍克 | H38: =VLOOKUP(C38,Sheet2!$A$1:$P$68,14,FALSE) -> 600083,600084,500304,600085 | I38: 600083&&600084&&500304&&600085

Sheet Sheet4
A1: id
A2: 393 | B2: 1
A3: 394 | B3: 1
A4: 395 | B4: 1
A5: 396 | B5: 1
A6: 401 | B6: 1
A7: 402 | B7: 1
A8: 403 | B8: 1
A9: 404 | B9: 1
A10: 500002 | B10: 1
A11: 500006 | B11: 1
A12: 500023 | B12: 1
A13: 500025 | B13: 1
... A173: 700135 | B173: 1

Sheet Sheet5
C1: 技能类型 1-普通技能 2-奥义技能 3-被动技能 4-普攻 | D1: 技能类型 0-普攻 1-主动技能 2-奥义 3-被动技能 4-附加技能 5-特殊机制 6-怒气延展 7-奥义延展主动 | E1: 技能所在阶段 | F1: 最大等级 | G1: 是否是 延展技 | H1: 关联 技能Id | I1: 是否是被 关联技能 | J1: 技能名称 | K1: 技能描述 | L1: 基础技能描述 （等级为0时） | M1: 技能图标
A2: skillId | B2: heroId | C2: skillType | D2: skillCostType | E2: skillStep | F2: maxLevel | G2: isExtensionSkill | H2: relationSkillId | I2: isRelationSkill | J2: skillName | K2: skillDesc | L2: skillDescBase | M2: skillIcon
A3: 500002 | B3: 1112001 | C3: 1 | D3: 1 | E3: 1 | F3: 1 | G3: 0 | H3: 0 | I3: 0 | J3: 橡皮·机关枪 | K3: 对<color=#d14e0d>敌方单体</color>造成自身攻击力<color=#d14e0d>{atkper}%</color>的技能伤害。 | M3: skill_icon_112001_1 | O3: 1
A4: 500006 | B4: 1112001 | C4: 1 | D4: 1 | E4: 1 | F4: 1 | G4: 0 | H4: 0 | I4: 0 | J4: 橡皮·回旋弹 | K4: 对<color=#d14e0d>敌方直线三格</color>造成自身攻击力<color=#d14e0d>{atkper}%</color>的技能伤害。 | M4: skill_icon_112001_5 | O4: 1
A5: 600059 | B5: 1112001 | C5: 1 | D5: 1 | E5: 1 | F5: 1 | G5: 0 | H5: 0 | I5: 0 | J5: 橡皮·巨人枪 | K5: 对<color=#d14e0d>敌方单体</color>造成自身攻击力<color=#d14e0d>{atkper}%</color>的技能伤害。 | M5: skill_icon_112001_2 | O5: 1
A6: 600060 | B6: 1112001 | C6: 2 | D6: 2 | E6: 1 | F6: 1 | G6: 0 | H6: 0 | I6: 0 | J6: 橡皮·火箭炮 | K6: 对<color=#d14e0d>敌方单体</color>造成自身攻击力<color=#d14e0d>{atkper}%</color>的技能伤害。 | M6: skill_icon_112001_9 | O6: 1
A7: 500025 | B7: 1112002 | C7: 1 | D7: 1 | E7: 1 | F7: 1 | G7: 0 | H7: 0 | I7: 0 | J7: 三千世界 | K7: 对<color=#d14e0d>敌方单体</color>造成<color=#d14e0d>{atkper}%</color>的攻击伤害。 | M7: skill_icon_112002_1 | O7: 1
A8: 500027 | B8: 1112002 | C8: 1 | D8: 1 | E8: 1 | F8: 1 | G8: 0 | H8: 0 | I8: 0 | J8: 鬼斩 | K8: 对<color=#d14e0d>敌方单体</color>造成<color=#d14e0d>{atkper}%</color>的攻击伤害。 | M8: skill_icon_112002_3 | O8: 1
A9: 600061 | B9: 1112002 | C9: 1 | D9: 1 | E9: 1 | F9: 1 | G9: 0 | H9: 0 | I9: 0 | J9: 一百零八烦恼凤 | K9: 对<color=#d14e0d>敌方直线四格</color>造成自身攻击力<color=#d14e0d>{atkper}%</color>的技能伤害。 | M9: skill_icon_112002_2 | O9: 1
A10: 600062 | B10: 1112002 | C10: 2 | D10: 2 | E10: 1 | F10: 1 | G10: 0 | H10: 0 | I10: 0 | J10: 狮子歌歌 | K10: 对<color=#d14e0d>敌方单体</color>造成<color=#d14e0d>{atkper}%</color>的攻击伤害。 | M10: skill_icon_112002_4 | O10: 1
A11: 500065 | B11: 1112003 | C11: 1 | D11: 1 | E11: 1 | F11: 1 | G11: 0 | H11: 500068 | I11: 0 | J11: 电气泡 | K11: 对<color=#d14e0d>敌方单体</color>造成<color=#d14e0d>{atkper}%</color>的攻击伤害。 | M11: skill_icon_112003_2 | O11: 1
A12: 500066 | B12: 1112003 | C12: 1 | D12: 1 | E12: 1 | F12: 1 | G12: 0 | H12: 500069 | I12: 0 | J12: 风向标 | K12: 对<color=#d14e0d>敌方单体</color>造成<color=#d14e0d>{atkper}%</color>的攻击伤害。 | M12: skill_icon_112003_3 | O12: 1
A13: 600067 | B13: 1112003 | C13: 1 | D13: 1 | E13: 1 | F13: 1 | G13: 0 | H13: 0 | I13: 0 | J13: 龙卷风天候 | K13: 对<color=#d14e0d>敌方直线四格</color>造成<color=#d14e0d>{atkper}%</color>的攻击伤害。 | M13: skill_icon_112003_7 | O13: 1
A14: 600068 | B14: 1112003 | C14: 2 | D14: 2 | E14: 1 | F14: 1 | G14: 0 | H14: 0 | I14: 0 | J14: 雷光枪天候 | K14: 对<color=#d14e0d>敌方单体</color>造成<color=#d14e0d>{atkper}%</color>的攻击伤害。 | M14: skill_icon_112003_4 | O14: 1
A15: 500057 | B15: 1112004 | C15: 1 | D15: 1 | E15: 1 | F15: 1 | G15: 0 | H15: 0 | I15: 0 | J15: 撒谎布黄金重磅 | K15: 对<color=#d14e0d>敌方单体</color>造成<color=#d14e0d>{atkper}%</color>的攻击伤害。 | M15: skill_icon_112004_2 | O15: 1
A16: 500058 | B16: 1112004 | C16: 1 | D16: 1 | E16: 1 | F16: 1 | G16: 0 | H16: 0 | I16: 0 | J16: 手里剑流星群 | K16: 对<color=#d14e0d>敌方单体</color>造成<color=#d14e0d>{atkper}%</color>的攻击伤害。 | M16: skill_icon_112004_3 | O16: 1
A17: 600065 | B17: 1112004 | C17: 1 | D17: 1 | E17: 1 | F17: 1 | G17: 0 | H17: 0 | I17: 0 | J17: 火鸟星 | K17: 对<color=#d14e0d>敌方直线四格</color>造成<color=#d14e0d>{atkper}%</color>的攻击伤害。 | M17: skill_icon_112004_1 | O17: 1
... A24: 500023 | B24: 1112006 | C24: 1 | D24: 1 | E24: 1 | F24: 1 | G24: 0 | H24: 0 | I24: 0 | J24: 紧急治疗 | K24: 对<color=#d14e0d>己方单体</color>造成<color=#d14e0d>{atkper}%</color>的攻击伤害。 | M24: skill_icon_112006_7 | O24: 1
A25: 500084 | B25: 1112006 | C25: 1 | D25: 1 | E25: 1 | F25: 1 | G25: 0 | H25: 0 | I25: 0 | J25: 防御强化 | K25: 对<color=#d14e0d>敌方单体</color>造成<color=#d14e0d>{atkper}%</color>的攻击伤害。 | O25: 1
A26: 500182 | B26: 1112006 | C26: 1 | D26: 1 | E26: 1 | F26: 1 | G26: 0 | H26: 0 | I26: 0 | J26: 绷带 | K26: 对<color=#d14e0d>敌方周围十字</color>造成<color=#d14e0d>{atkper}%</color>的攻击伤害。 | M26: skill_icon_112006_9 | O26: 1
A27: 500323 | B27: 1112007 | C27: 1 | D27: 1 | E27: 1 | F27: 20 | G27: 0 | H27: 0 | I27: 0 | J27: 二十轮花开·风车 | K27: 对<color=#d14e0d>敌方全体</color>造成自身攻击力<color=#d14e0d>{atkper}%</color>的技能伤害。 | M27: skill_icon_112007_2 | O27: 1
A28: 500324 | B28: 1112007 | C28: 1 | D28: 1 | E28: 1 | F28: 20 | G28: 0 | H28: 0 | I28: 0 | J28: 起重机分离 | K28: 对<color=#d14e0d>敌方单体</color>造成自身攻击力<color=#d14e0d>{atkper}%</color>的技能伤害。 | M28: skill_icon_112007_3 | O28: 1
A29: 500325 | B29: 1112007 | C29: 1 | D29: 1 | E29: 1 | F29: 20 | G29: 0 | H29: 0 | I29: 0 | J29: 三十轮花开·滑翔 | K29: 对<color=#d14e0d>敌方横向两排</color>造成自身攻击力<color=#d14e0d>{atkper}%</color>的技能伤害。 | M29: skill_icon_112007_4 | O29: 1
A30: 500328 | B30: 1112007 | C30: 2 | D30: 2 | E30: 5 | F30: 20 | G30: 0 | H30: 0 | I30: 0 | J30: 八十轮花·四棵树·重击 | K30: 对<color=#d14e0d>敌方全体</color>造成<color=#d14e0d>{atkper}%</color>的攻击伤害。 | M30: skill_icon_112007_7 | O30: 1
A31: 500076 | B31: 1112008 | C31: 1 | D31: 1 | E31: 1 | F31: 1 | G31: 0 | H31: 0 | I31: 0 | J31: 力量右拳 | K31: 对<color=#d14e0d>敌方单体</color>造成<color=#d14e0d>{atkper}%</color>的攻击伤害。 | M31: skill_icon_112008_3 | O31: 1
A32: 500079 | B32: 1112008 | C32: 1 | D32: 1 | E32: 1 | F32: 1 | G32: 0 | H32: 0 | I32: 0 | J32: 星星盾 | K32: 对<color=#d14e0d>自身</color>附加一层<color=#d14e0d>护盾</color>，护盾的生命值为自身血量的<color=#d14e0d>{buffper1}%</color>，护盾的生命值为0时护盾将消失，护盾持续<color=#d14e0d>2回合</color>。 | M32: skill_icon_112008_6 | O32: 1
A33: 500080 | B33: 1112008 | C33: 1 | D33: 1 | E33: 1 | F33: 1 | G33: 0 | H33: 0 | I33: 0 | J33: 弗兰奇拳击 | K33: 对<color=#d14e0d>敌方单体</color>造成<color=#d14e0d>{atkper}%</color>的攻击伤害。 | M33: skill_icon_112008_7 | O33: 1
A34: 600070 | B34: 1112008 | C34: 2 | D34: 2 | E34: 1 | F34: 1 | G34: 0 | H34: 0 | I34: 0 | J34: 风来炮 | K34: 对<color=#d14e0d>敌方全体</color>造成<color=#d14e0d>{atkper}%</color>的攻击伤害。 | M34: skill_icon_112008_4 | O34: 1
A35: 500382 | B35: 1112009 | C35: 1 | D35: 1 | E35: 1 | F35: 1 | G35: 0 | H35: 0 | I35: 0 | J35: 催眠曲 | K35: 对<color=#d14e0d>自身 </color>造成<color=#d14e0d>{atkper}%</color>的攻击伤害。 | M35: skill_icon_112009_4 | O35: 1
A36: 500383 | B36: 1112009 | C36: 1 | D36: 1 | E36: 1 | F36: 1 | G36: 0 | H36: 0 | I36: 0 | J36: 酒桶舞曲·后退 | K36: 对<color=#d14e0d>自身 </color>造成<color=#d14e0d>{atkper}%</color>的攻击伤害。 | M36: skill_icon_112009_5 | O36: 1
A37: 500384 | B37: 1112009 | C37: 1 | D37: 1 | E37: 1 | F37: 1 | G37: 0 | H37: 0 | I37: 0 | J37: 革命舞曲·前跳 | K37: 对<color=#d14e0d>敌方单体</color>造成<color=#d14e0d>{atkper}%</color>的攻击伤害。 | M37: skill_icon_112009_6 | O37: 1
A38: 500385 | B38: 1112009 | C38: 2 | D38: 2 | E38: 1 | F38: 1 | G38: 0 | H38: 0 | I38: 0 | J38: 鼻哼三步·箭羽斩 | K38: 对<color=#d14e0d>敌方全体</color>造成<color=#d14e0d>{atkper}%</color>的攻击伤害。 | M38: skill_icon_112009_7 | O38: 1
... A58: 600029 | B58: 1112014 | C58: 2 | D58: 2 | E58: 1 | F58: 1 | G58: 0 | H58: 0 | I58: 0 | J58: 冬日晴空的回忆录 | K58: 对<color=#d14e0d>敌方单体</color>造成<color=#d14e0d>{atkper}%</color>的攻击伤害。 | M58: skill_icon_112014_5 | O58: 1
A59: 600114 | B59: 1112015 | C59: 3 | D59: 3 | E59: 1 | F59: 1 | G59: 0 | H59: 0 | I59: 0 | O59: 1
A60: 500136 | B60: 1112015 | C60: 1 | D60: 1 | E60: 1 | F60: 1 | G60: 0 | H60: 0 | I60: 0 | J60: 蜡烛锥 | K60: 对<color=#d14e0d>敌方直线四格</color>造成<color=#d14e0d>{atkper}%</color>的攻击伤害。 | M60: skill_icon_112015_4 | O60: 1
A61: 600030 | B61: 1112015 | C61: 1 | D61: 1 | E61: 1 | F61: 1 | G61: 0 | H61: 0 | I61: 0 | J61: 蜡烛锁 | K61: 对<color=#d14e0d>敌方单体</color>造成<color=#d14e0d>{atkper}%</color>的攻击伤害。 | M61: skill_icon_112015_2 | O61: 1
A62: 600031 | B62: 1112015 | C62: 1 | D62: 1 | E62: 1 | F62: 1 | G62: 0 | H62: 0 | I62: 0 | J62: 蜡烛壁 | K62: 对<color=#d14e0d>敌方单体</color>造成<color=#d14e0d>{atkper}%</color>的攻击伤害。 | M62: skill_icon_112015_3 | O62: 1
A63: 500310 | B63: 1112016 | C63: 1 | D63: 1 | E63: 1 | F63: 1 | G63: 0 | H63: 0 | I63: 0 | O63: 1
A64: 600032 | B64: 1112016 | C64: 1 | D64: 1 | E64: 1 | F64: 1 | G64: 0 | H64: 0 | I64: 0 | O64: 1
A65: 600033 | B65: 1112016 | C65: 1 | D65: 1 | E65: 1 | F65: 1 | G65: 0 | H65: 0 | I65: 0 | O65: 1
...
