Workbook

Sheet Sheet1
A1: 7 | B1: 1 | C1: 9999 | D1: 8
A2: id | B2: 英雄Id | C2: 星级 | D2: 自身加成 | E2: 光环加成 | F2: 职业阵容加成
A3: id | B3: heroId | C3: star | D3: selfAddition | E3: haloAddition | F3: professionAddition
A4: int | B4: int | C4: int | D4: string | E4: string | F4: string
A5: primary | B5: none | C5: none | D5: none | E5: none | F5: none
A6: id | B6: heroId | C6: star | D6: selfAddition | E6: haloAddition | F6: professionAddition
A7: 1 | B7: =VLOOKUP(ROUNDUP(A7/8,0),Sheet2!A:B,2,FALSE()) -> 111001 | C7: 1 | D7: =VLOOKUP(C7,Sheet2!$BK$11:$BN$19,VLOOKUP(B7,Sheet2!B:BC,21,FALSE)+1,FALSE) -> 1 | E7: 0 | F7: 1,0;2,1;3,0
A8: 2 | B8: =VLOOKUP(ROUNDUP(A8/8,0),Sheet2!A:B,2,FALSE()) -> 111001 | C8: 2 | D8: =VLOOKUP(C8,Sheet2!$BK$11:$BN$19,VLOOKUP(B8,Sheet2!B:BC,21,FALSE)+1,FALSE) -> 1 | E8: 0 | F8: 1,0;2,1;3,0
A9: 3 | B9: =VLOOKUP(ROUNDUP(A9/8,0),Sheet2!A:B,2,FALSE()) -> 111001 | C9: 3 | D9: =VLOOKUP(C9,Sheet2!$BK$11:$BN$19,VLOOKUP(B9,Sheet2!B:BC,21,FALSE)+1,FALSE) -> 1 | E9: 0 | F9: 1,0;2,1;3,0
A10: 4 | B10: =VLOOKUP(ROUNDUP(A10/8,0),Sheet2!A:B,2,FALSE()) -> 111001 | C10: 4 | D10: =VLOOKUP(C10,Sheet2!$BK$11:$BN$19,VLOOKUP(B10,Sheet2!B:BC,21,FALSE)+1,FALSE) -> 1 | E10: 0 | F10: 1,0;2,1;3,0
A11: 5 | B11: =VLOOKUP(ROUNDUP(A11/8,0),Sheet2!A:B,2,FALSE()) -> 111001 | C11: 5 | D11: =VLOOKUP(C11,Sheet2!$BK$11:$BN$19,VLOOKUP(B11,Sheet2!B:BC,21,FALSE)+1,FALSE) -> 1 | E11: 0 | F11: 1,0;2,1;3,0
A12: 6 | B12: =VLOOKUP(ROUNDUP(A12/8,0),Sheet2!A:B,2,FALSE()) -> 111001 | C12: 6 | D12: =VLOOKUP(C12,Sheet2!$BK$11:$BN$19,VLOOKUP(B12,Sheet2!B:BC,21,FALSE)+1,FALSE) -> 1.2 | E12: 0 | F12: 1,0;2,1;3,0
A13: 7 | B13: =VLOOKUP(ROUNDUP(A13/8,0),Sheet2!A:B,2,FALSE()) -> 111001 | C13: 7 | D13: =VLOOKUP(C13,Sheet2!$BK$11:$BN$19,VLOOKUP(B13,Sheet2!B:BC,21,FALSE)+1,FALSE) -> 1.2 | E13: 0 | F13: 1,0;2,1;3,0
A14: 8 | B14: =VLOOKUP(ROUNDUP(A14/8,0),Sheet2!A:B,2,FALSE()) -> 111001 | C14: 8 | D14: =VLOOKUP(C14,Sheet2!$BK$11:$BN$19,VLOOKUP(B14,Sheet2!B:BC,21,FALSE)+1,FALSE) -> 1.2 | E14: 0 | F14: 1,0;2,1;3,0
A15: 9 | B15: =VLOOKUP(ROUNDUP(A15/8,0),Sheet2!A:B,2,FALSE()) -> 111002 | C15: =C7 -> 1 | D15: =VLOOKUP(C15,Sheet2!$BK$11:$BN$19,VLOOKUP(B15,Sheet2!B:BC,21,FALSE)+1,FALSE) -> 1 | E15: 0 | F15: 1,0.3;2,0.3;3,0
A16: 10 | B16: =VLOOKUP(ROUNDUP(A16/8,0),Sheet2!A:B,2,FALSE()) -> 111002 | C16: =C8 -> 2 | D16: =VLOOKUP(C16,Sheet2!$BK$11:$BN$19,VLOOKUP(B16,Sheet2!B:BC,21,FALSE)+1,FALSE) -> 1 | E16: 0 | F16: 1,0.3;2,0.3;3,0
A17: 11 | B17: =VLOOKUP(ROUNDUP(A17/8,0),Sheet2!A:B,2,FALSE()) -> 111002 | C17: =C9 -> 3 | D17: =VLOOKUP(C17,Sheet2!$BK$11:$BN$19,VLOOKUP(B17,Sheet2!B:BC,21,FALSE)+1,FALSE) -> 1 | E17: 0 | F17: 1,0.3;2,0.3;3,0
A18: 12 | B18: =VLOOKUP(ROUNDUP(A18/8,0),Sheet2!A:B,2,FALSE()) -> 111002 | C18: =C10 -> 4 | D18: =VLOOKUP(C18,Sheet2!$BK$11:$BN$19,VLOOKUP(B18,Sheet2!B:BC,21,FALSE)+1,FALSE) -> 1 | E18: 0 | F18: 1,0.3;2,0.3;3,0
A19: 13 | B19: =VLOOKUP(ROUNDUP(A19/8,0),Sheet2!A:B,2,FALSE()) -> 111002 | C19: =C11 -> 5 | D19: =VLOOKUP(C19,Sheet2!$BK$11:$BN$19,VLOOKUP(B19,Sheet2!B:BC,21,FALSE)+1,FALSE) -> 1 | E19: 0 | F19: 1,0.3;2,0.3;3,0
A20: 14 | B20: =VLOOKUP(ROUNDUP(A20/8,0),Sheet2!A:B,2,FALSE()) -> 111002 | C20: =C12 -> 6 | D20: =VLOOKUP(C20,Sheet2!$BK$11:$BN$19,VLOOKUP(B20,Sheet2!B:BC,21,FALSE)+1,FALSE) -> 1.2 | E20: 0 | F20: 1,0.3;2,0.3;3,0
A21: 15 | B21: =VLOOKUP(ROUNDUP(A21/8,0),Sheet2!A:B,2,FALSE()) -> 111002 | C21: =C13 -> 7 | D21: =VLOOKUP(C21,Sheet2!$BK$11:$BN$19,VLOOKUP(B21,Sheet2!B:BC,21,FALSE)+1,FALSE) -> 1.2 | E21: 0 | F21: 1,0.3;2,0.3;3,0
A22: 16 | B22: =VLOOKUP(ROUNDUP(A22/8,0),Sheet2!A:B,2,FALSE()) -> 111002 | C22: =C14 -> 8 | D22: =VLOOKUP(C22,Sheet2!$BK$11:$BN$19,VLOOKUP(B22,Sheet2!B:BC,21,FALSE)+1,FALSE) -> 1.2 | E22: 0 | F22: 1,0.3;2,0.3;3,0
A23: 17 | B23: =VLOOKUP(ROUNDUP(A23/8,0),Sheet2!A:B,2,FALSE()) -> 111003 | C23: =C15 -> 1 | D23: =VLOOKUP(C23,Sheet2!$BK$11:$BN$19,VLOOKUP(B23,Sheet2!B:BC,21,FALSE)+1,FALSE) -> 1 | E23: 0 | F23: 1,1;2,0;3,0
A24: 18 | B24: =VLOOKUP(ROUNDUP(A24/8,0),Sheet2!A:B,2,FALSE()) -> 111003 | C24: =C16 -> 2 | D24: =VLOOKUP(C24,Sheet2!$BK$11:$BN$19,VLOOKUP(B24,Sheet2!B:BC,21,FALSE)+1,FALSE) -> 1 | E24: 0 | F24: 1,1;2,0;3,0
A25: 19 | B25: =VLOOKUP(ROUNDUP(A25/8,0),Sheet2!A:B,2,FALSE()) -> 111003 | C25: =C17 -> 3 | D25: =VLOOKUP(C25,Sheet2!$BK$11:$BN$19,VLOOKUP(B25,Sheet2!B:BC,21,FALSE)+1,FALSE) -> 1 | E25: 0 | F25: 1,1;2,0;3,0
A26: 20 | B26: =VLOOKUP(ROUNDUP(A26/8,0),Sheet2!A:B,2,FALSE()) -> 111003 | C26: =C18 -> 4 | D26: =VLOOKUP(C26,Sheet2!$BK$11:$BN$19,VLOOKUP(B26,Sheet2!B:BC,21,FALSE)+1,FALSE) -> 1 | E26: 0 | F26: 1,1;2,0;3,0
... A862: 856 | B862: =VLOOKUP(ROUNDUP(A862/8,0),Sheet2!A:B,2,FALSE()) -> 113059 | C862: =C854 -> 8 | D862: =VLOOKUP(C862,Sheet2!$BK$11:$BN$19,VLOOKUP(B862,Sheet2!B:BC,21,FALSE)+1,FALSE) -> 2 | E862: 2 | F862: 1,0.1;2,0.1;3,0.1
A863: 857 | B863: =VLOOKUP(ROUNDUP(A863/8,0),Sheet2!A:B,2,FALSE()) -> 113060 | C863: =C855 -> 1 | D863: 1 | E863: 0 | F863: 1,0.1;2,0.1;3,0.1
A864: 858 | B864: =VLOOKUP(ROUNDUP(A864/8,0),Sheet2!A:B,2,FALSE()) -> 113060 | C864: =C856 -> 2 | D864: 1 | E864: 0 | F864: 1,0.1;2,0.1;3,0.1
A865: 859 | B865: =VLOOKUP(ROUNDUP(A865/8,0),Sheet2!A:B,2,FALSE()) -> 113060 | C865: =C857 -> 3 | D865: 1 | E865: 0 | F865: 1,0.1;2,0.1;3,0.1
A866: 860 | B866: =VLOOKUP(ROUNDUP(A866/8,0),Sheet2!A:B,2,FALSE()) -> 113060 | C866: =C858 -> 4 | D866: 2 | E866: 0 | F866: 1,0.1;2,0.1;3,0.1
A867: 861 | B867: =VLOOKUP(ROUNDUP(A867/8,0),Sheet2!A:B,2,FALSE()) -> 113060 | C867: =C859 -> 5 | D867: 2 | E867: 0 | F867: 1,0.1;2,0.1;3,0.1
A868: 862 | B868: =VLOOKUP(ROUNDUP(A868/8,0),Sheet2!A:B,2,FALSE()) -> 113060 | C868: =C860 -> 6 | D868: 4 | E868: 0 | F868: 1,0.1;2,0.1;3,0.1
A869: 863 | B869: =VLOOKUP(ROUNDUP(A869/8,0),Sheet2!A:B,2,FALSE()) -> 113060 | C869: =C861 -> 7 | D869: 4 | E869: 0 | F869: 1,0.1;2,0.1;3,0.1
A870: 864 | B870: =VLOOKUP(ROUNDUP(A870/8,0),Sheet2!A:B,2,FALSE()) -> 113060 | C870: =C862 -> 8 | D870: 8 | E870: 0 | F870: 1,0.1;2,0.1;3,0.1
A871: 865 | B871: =VLOOKUP(ROUNDUP(A871/8,0),Sheet2!A:B,2,FALSE()) -> 113061 | C871: =C863 -> 1 | D871: =VLOOKUP(C871,Sheet2!$BK$11:$BN$19,VLOOKUP(B871,Sheet2!B:BC,21,FALSE)+1,FALSE) -> 1.2 | E871: 0 | F871: 1,0.1;2,0.1;3,0.1
A872: 866 | B872: =VLOOKUP(ROUNDUP(A872/8,0),Sheet2!A:B,2,FALSE()) -> 113061 | C872: =C864 -> 2 | D872: =VLOOKUP(C872,Sheet2!$BK$11:$BN$19,VLOOKUP(B872,Sheet2!B:BC,21,FALSE)+1,FALSE) -> 1.2 | E872: 0 | F872: 1,0.1;2,0.1;3,0.1
A873: 867 | B873: =VLOOKUP(ROUNDUP(A873/8,0),Sheet2!A:B,2,FALSE()) -> 113061 | C873: =C865 -> 3 | D873: =VLOOKUP(C873,Sheet2!$BK$11:$BN$19,VLOOKUP(B873,Sheet2!B:BC,21,FALSE)+1,FALSE) -> 1.2 | E873: 0 | F873: 1,0.1;2,0.1;3,0.1
A874: 868 | B874: =VLOOKUP(ROUNDUP(A874/8,0),Sheet2!A:B,2,FALSE()) -> 113061 | C874: =C866 -> 4 | D874: =VLOOKUP(C874,Sheet2!$BK$11:$BN$19,VLOOKUP(B874,Sheet2!B:BC,21,FALSE)+1,FALSE) -> 1.5 | E874: 0 | F874: 1,0.1;2,0.1;3,0.1
A875: 869 | B875: =VLOOKUP(ROUNDUP(A875/8,0),Sheet2!A:B,2,FALSE()) -> 113061 | C875: =C867 -> 5 | D875: =VLOOKUP(C875,Sheet2!$BK$11:$BN$19,VLOOKUP(B875,Sheet2!B:BC,21,FALSE)+1,FALSE) -> 1.5 | E875: 0 | F875: 1,0.1;2,0.1;3,0.1
...

Sheet Sheet2
B1: 7 | C1: 1 | D1: 9999 | E1: 56
B2: 英雄id | C2: 同源英雄Id（不可同时上2个同源英雄） | D2: 英雄名称 | F2: 复活时是否走召唤 1-召唤 0-不召唤 默认0 | G2: 英雄性别 0：男的 1：女的 2：人妖 3：无性别 | H2: 角色传记介绍 | I2: 角色特点 | J2: 角色定位描述 | K2: 攻击目标描述 | L2: 角色能力描述 | M2: 技能介绍 | N2: 是否是英雄 | O2: 是否在图鉴中 | P2: 英雄类型 | Q2: 远征技能 1-动物系 2-自然系 3-超人系 4-格斗系 5-剑道系 6-射击系 7- | R2: 所属阵营Id | S2: 作为BOSS时的称号 | T2: 英雄初始星级 | U2: 英雄最高星级 | V2: 英雄资质 1-R 2-SR 3-SSR | W2: 主模型Id | X2: 2D立绘 | Y2: 招募图片 | Z2: 对应碎片ItemId | AA2: 对应战魂ItemId | AB2: 战魂Item | AC2: 碎片合成所需数量 | AD2: 分解得到碎片数量 | AE2: 攻击 | AF2: 防御 | AG2: 血量 | AH2: 速度 | AI2: 暴击 | AJ2: 抗暴 | AK2: 命中 | AL2: 闪避 | AM2: 二级属性初始值 | AN2: 胜利语音 | AO2: 出场语间 | AP2: 上阵时语音 | AQ2: 普通语音 | AR2: 场景模型常驻特效限制星级 | AS2: 英雄属性图 例如 (范围,辅助,控制,伤害,生存,爆发) | AT2: 英雄推荐位置 | AU2: 声优 | AV2: 介绍技能 | AW2: 额外分组 | AX2: 英雄类型，0没有限制，1海军 2海盗 3七武海 4其他 | AY2: 英雄定义类型 1坦克 2战士 3刺客 4法师 | BA2: 英雄类型（阵容排序） 1：草帽 2：海军 3：海盗 4：其他 | BB2: 卡牌顺序序号列（阵容排序） 100开始：SSR 1000开始：SR 10000开始：R | BC2: 勋章id | BD2: 勋章数量
B3: heroId | C3: sourceHeroId | D3: heroName | G3: gender | H3: heroDesc | I3: heroFeature | J3: heroStyle | K3: heroAttackTarget | L3: heroAbility | M3: skillsIntroduction | N3: isHero | O3: heroInManual | P3: heroType | Q3: expedtionSkills | R3: heroGroupId | S3: heroBossTitle | T3: defaultStar | U3: maxStar | V3: quality | W3: modelId | X3: heroPaint | Y3: recruitPoint | Z3: fragItemId | AA3: soulItemId | AB3: soulExchangeFragNum | AC3: fragNeedNum | AD3: diposeFragNum | AE3: atk | AF3: def | AG3: hp | AH3: speed | AI3: cri | AJ3: anticri | AK3: hit | AL3: dodge | AM3: attributeBase | AN3: winSound | AO3: enterSound | AP3: formationOnSound | AQ3: normalSound | AR3: ModelParticleStarLimit | AS3: heroGraph | AT3: heroPosition | AU3: heroActor | AV3: introSkillId | AW3: extraHeroGroups | AY3: definitionType | BA3: arrayHeroType | BB3: cardOrderId | BC3: medalItemId | BD3: medalItemNum
B4: int | C4: int | D4: string(intern) | F4: int | G4: int | H4: string | I4: string | J4: string(intern) | K4: string(intern) | L4: string(intern) | M4: string | N4: int | O4: int | P4: int | Q4: string(intern) | R4: int | S4: string(intern) | T4: int | U4: int | V4: int | W4: int | X4: string(intern) | Y4: string | Z4: int | AA4: int | AB4: int | AC4: int | AD4: int | AE4: double | AF4: double | AG4: double | AH4: double | AI4: double | AJ4: double | AK4: double | AL4: double | AM4: string(intern) | AN4: string(intern) | AO4: string(intern) | AP4: string | AQ4: string | AR4: int | AS4: string(intern) | AT4: string(intern) | AU4: string(intern) | AV4: int | AW4: string | AY4: int | BA4: int | BB4: int | BC4: int | BD4: int
B5: primary | C5: none | D5: none | F5: none | G5: none | H5: none | I5: none | J5: none | K5: none | L5: none | M5: none | N5: none | O5: none | P5: none | Q5: none | R5: none | S5: none | T5: none | U5: none | V5: none | W5: none | X5: none | Y5: none | Z5: none | AA5: none | AB5: none | AC5: none | AD5: none | AE5: none | AF5: none | AG5: none | AH5: none | AI5: none | AJ5: none | AK5: none | AL5: none | AM5: none | AN5: none | AO5: none | AP5: none | AQ5: none | AR5: none | AS5: none | AT5: none | AU5: none | AV5: none | AW5: none | AY5: none | BA5: none | BB5: none | BC5: none | BD5: none
B6: heroId | C6: sourceHeroId | D6: heroName | F6: summonWhenReiv | G6: gender | H6: heroDesc | N6: isHero | O6: heroInManual | P6: heroType | Q6: expedtionSkills | R6: heroGroupId | T6: defaultStar | U6: maxStar | V6: quality | W6: modelId | X6: heroPaint | Z6: fragItemId | AA6: soulItemId | AB6: soulExchangeFragNum | AC6: fragNeedNum | AD6: diposeFragNum | AE6: atk | AF6: def | AG6: hp | AH6: speed | AI6: cri | AJ6: anticri | AK6: hit | AL6: dodge | AM6: attributeBase | AW6: extraHeroGroups | AX6: heroRoleType | AY6: definitionType | BC6: medalItemId | BD6: medalItemNum
A7: 1 | B7: 111001 | C7: 111001 | D7: 可比 | E7: 可比 | G7: 0 | H7: 凭借自身努力和毅力，以成为将校为目标的年轻海军士兵。被路飞所救，并加入了向往的海军。 | I7: 以成为将校为目标的海军士兵，攻防兼备。\n攻击技能附带减速效果，牵制单个敌人。\n治疗技能可提升自身防御力。 | J7: 自我治疗 | K7: 前排优先 | L7: 无 | M7: 185,184 | N7: 1 | O7: 1 | P7: 4 | Q7: 4 | R7: 2 | S7: 海军 | T7: 2 | U7: 6 | V7: 1 | W7: 23 | X7: hero_2d_1001 | Y7: hero_long2d_111001 | Z7: 610001 | AA7: 214005 | AB7: 10 | AC7: 10 | AD7: 10 | AE7: 98 | AF7: 13 | AG7: 237 | AH7: 25 | AI7: 0.0072 | AJ7: 0.0096 | AK7: 1.0096 | AL7: 0.0024 | AM7: 9,1.5;39,1.5;40,0.5;10,0.007211 | AR7: 8 | AS7: 10,10,50,10,60,50 | AT7: heroPosition_1 | AU7: heroActor_1001 | AV7: 184 | AX7: 1 | AY7: 1 | AZ7: 163 | BA7: 2 | BB7: 10001
A8: 2 | B8: 111002 | C8: 111002 | D8: 摩根 | E8: 斧手摩根 | G8: 0 | H8: 凡是胆敢反抗自己的人，即使是同伴也毫不留情地给予处刑。对于权力和地位随意滥用的谢尔兹镇海军上校。 | I8: 原海军总部上校，攻防兼备。\n斧头可击破敌人的护甲，降低敌方防御。\n对处于破甲状态的敌人，造成更多伤害。 | J8: 攻守平衡 | K8: 前排优先 | L8: 无 | M8: 166,165 | N8: 1 | O8: 1 | P8: 4 | Q8: 4 | R8: 2 | S8: 海军 | T8: 2 | U8: 6 | V8: 1 | W8: 18 | X8: hero_2d_1002 | Y8: hero_long2d_111002 | Z8: 610002 | AA8: 214005 | AB8: 10 | AC8: 10 | AD8: 10 | AE8: 84 | AF8: 13 | AG8: 269 | AH8: 20 | AJ8: 0.012 | AK8: 1.006 | AL8: 0.006 | AM8: 9,1.5;39,1.5;40,0.5;10,0.01211 | AR8: 8 | AS8: 30,0,0,30,20,50 | AT8: heroPosition_2 | AU8: heroActor_1002 | AV8: 166 | AX8: 1 | AY8: 2 | AZ8: 141 | BA8: 2 | BB8: 10002
A9: 3 | B9: 111003 | C9: 111003 | D9: 卡巴奇 | E9: 卡巴奇 | G9: 0 | H9: 擅长利用陀螺等杂技出其不意地攻击对手并且能得心应手地使用剑术的杂技剑士。 | I9: 爱用独轮车的杂技剑士，擅长进攻。\n杂技可造成火焰伤害和灼烧效果。\n身形灵巧，杂技技能可提升速度和闪避。 | J9: 单点爆发 | K9: 前排优先 | L9: 无 | M9: 188,187 | N9: 1 | O9: 1 | P9: 5 | Q9: 5 | R9: 3 | S9: 巴基海盗团 | T9: 2 | U9: 6 | V9: 1 | W9: 24 | X9: hero_2d_1003 | Y9: hero_long2d_111003 | Z9: 610003 | AA9: 214005 | AB9: 10 | AC9: 10 | AD9: 10 | AE9: 127 | AF9: 9 | AG9: 123 | AH9: 50 | AI9: 0.012 | AK9: 1.006 | AL9: 0.0064 | AM9: 9,1.56;39,1.5;40,0.5;11,0.0036 | AR9: 8 | AS9: 0,10,0,40,40,50 | AT9: heroPosition_4 | AU9: heroActor_1003 | AV9: 188 | AX9: 2 | AY9: 3 | AZ9: 167 | BA9: 3 | BB9: 10003
A10: 4 | B10: 111004 | C10: 111004 | D10: 克洛 | E10: 克洛 | G10: 0 | H10: 黑猫海盗团原船长，老谋深算的男人，做事谨慎！擅长用神速的“无声步”秒杀敌人！ | I10: 擅用诡计的黑猫海盗团原船长，擅长进攻。\n使目标流血，且对流血目标造成额外伤害。\n能够使用高速暗杀术，精通速度和闪避。 | J10: 单点爆发 | K10: 前排优先 | L10: 无 | M10: 168,169 | N10: 1 | O10: 1 | P10: 4 | Q10: 4 | R10: 3 | S10: 黑猫海盗团 | T10: 2 | U10: 6 | V10: 1 | W10: 19 | X10: hero_2d_1004 | Y10: hero_long2d_111004 | Z10: 610004 | AA10: 214005 | AB10: 10 | AC10: 10 | AD10: 10 | AE10: 148 | AF10: 7 | AG10: 100 | AH10: 56 | AI10: 0.012 | AK10: 1.006 | AL10: 0.0064 | AM10: 9,1.56;39,1.5;40,0.5;11,0.0036 | AN10: CV_kuro03 | AO10: CV_kuro01 | AR10: 8 | AS10: 0,0,0,60,40,60 | AT10: heroPosition_4 | AU10: heroActor_1004 | AV10: 169 | AX10: 2 | AY10: 4 | AZ10: 168 | BA10: 3 | BB10: 10004
A11: 5 | B11: 111005 | C11: 111005 | D11: 强高 | E11: 强高 | G11: 0 | H11: 黑猫海盗团的现任船长，非常搞笑的催眠师！缺点是催眠时连他自己都会被催眠。 | I11: 非常搞笑的催眠师，擅长辅助。\n催眠敌方可使其无法行动，但被击即会醒来\n催眠友方可增加攻击，但同时会降低防御。 | J11: 团队控制 | K11: 前排优先 | L11: 无 | M11: 90,300048 | N11: 1 | O11: 1 | P11: 6 | Q11: 6 | R11: 3 | S11: 海军 | T11: 2 | U11: 6 | V11: 1 | W11: 8 | X11: hero_2d_1005 | Y11: hero_long2d_111005 | Z11: 610005 | AA11: 214005 | AB11: 10 | AC11: 10 | AD11: 10 | AE11: 81 | AF11: 12 | AG11: 199 | AH11: 35 | AI11: 0.009 | AJ11: 0.0096 | AK11: 1.0024 | AL11: 0.006 | AM11: 9,1.545;39,1.5;40,0.5; | AN11: CV_jango03 | AO11: CV_jango04 | AR11: 8 | AS11: 0,10,60,0,40,50 | AT11: heroPosition_5 | AU11: heroActor_1005 | AV11: 89 | AX11: 2 | AY11: 1 | AZ11: 62 | BA11: 3 | BB11: 10005 | BL11: 1 | BM11: 2 | BN11: 3
A12: 6 | B12: 111006 | C12: 111006 | D12: 克里克 | E12: 克里克 | G12: 0 | H12: 率领着5000名部下和50艘海盗船组成的“海盗舰队”，是克里克海盗团的首领。全身都藏着武器的“无敌男人”。为达到目的，不择手段，进行冷酷无情的掠夺行为。 | I12: 全身都藏着武器的“无敌男人”，擅长防守\n长枪技能可造成灼烧伤害和流血伤害。\n剑山斗篷可反弹近战伤害。 | J12: 攻守平衡 | K12: 前排优先 | L12: 无 | M12: 177,176 | N12: 1 | O12: 1 | P12: 6 | Q12: 6 | R12: 3 | S12: 克里克海盗团 | T12: 2 | U12: 6 | V12: 1 | W12: 21 | X12: hero_2d_1006 | Y12: hero_long2d_111006 | Z12: 610006 | AA12: 214005 | AB12: 10 | AC12: 10 | AD12: 10 | AE12: 49 | AF12: 13 | AG12: 264 | AH12: 18 | AJ12: 0.012 | AK12: 1.006 | AL12: 0.006 | AM12: 9,1.5;39,1.5;40,0.5;10,0.01211 | AN12: CV_kreig03 | AO12: CV_kreig01 | AR12: 8 | AS12: 40,10,0,30,60,40 | AT12: heroPosition_2 | AU12: heroActor_1006 | AV12: 176 | AX12: 2 | AY12: 2 | AZ12: 154 | BA12: 3 | BB12: 10006 | BK12: 1 | BL12: 1 | BM12: 1 | BN12: 1.2
A13: 7 | B13: 111007 | C13: 111007 | D13: 阿金 | E13: 阿金 | G13: 0 | H13: 克里克海盗团战斗总队长，也是克里克的左右手。他在饿得濒死的时候被山智所救，后来心境发生了很大变化。 | I13: 人称“鬼人”的战斗队长，擅长进攻。\n技能附带破甲和眩晕效果，牵制单个敌人。\n技能附加暴击效果，伤害暴击。 | J13: 攻守平衡 | K13: 前排优先 | L13: 无 | M13: 181,180 | N13: 1 | O13: 1 | P13: 4 | Q13: 4 | R13: 3 | S13: 克里克海盗团 | T13: 2 | U13: 6 | V13: 1 | W13: 22 | X13: hero_2d_1007 | Y13: hero_long2d_111007 | Z13: 610007 | AA13: 214005 | AB13: 10 | AC13: 10 | AD13: 10 | AE13: 124 | AF13: 12 | AG13: 176 | AH13: 26 | AI13: 0.0072 | AJ13: 0.0096 | AK13: 1.0096 | AL13: 0.0024 | AM13: 9,1.5;39,1.5;40,0.5;10,0.007211 | AN13: CV_gin02 | AO13: CV_gin01 | AR13: 8 | AS13: 0,0,50,60,40,50 | AT13: heroPosition_2 | AU13: heroActor_1007 | AV13: 181 | AX13: 2 | AY13: 3 | AZ13: 160 | BA13: 3 | BB13: 10007 | BK13: 2 | BL13: 1 | BM13: 1 | BN13: 1.2
A14: 8 | B14: 111008 | C14: 111008 | D14: 帕鲁 | E14: 帕鲁 | G14: 0 | H14: 克里克海盗团第二部队队长，号称在战斗中从不受伤，全身装备的盾牌具有攻守兼备的效果，但只要受了小伤，看到自己流血，就有点火的坏毛病。 | I14: 人称“铁壁帕鲁”，擅长防御。\n抵抗击退效果和火焰伤害。\n血量较低时，防御力大幅提升。 | J14: 防御壁垒 | K14: 前排优先 | L14: 无 | M14: 298,297 | N14: 1 | O14: 1 | P14: 4 | Q14: 4 | R14: 3 | S14: 海盗舰队 | T14: 2 | U14: 6 | V14: 1 | W14: 32 | X14: hero_2d_1008 | Y14: hero_long2d_111008 | Z14: 610008 | AA14: 214005 | AB14: 10 | AC14: 10 | AD14: 10 | AE14: 81 | AF14: 13 | AG14: 275 | AH14: 17 | AJ14: 0.012 | AK14: 1.006 | AL14: 0.006 | AM14: 9,1.5;39,1.5;40,0.5;10,0.01211 | AR14: 8 | AS14: 0,10,10,10,60,50 | AT14: heroPosition_1 | AU14: heroActor_1008 | AV14: 298 | AX14: 2 | AY14: 4 | AZ14: 298 | BA14: 3 | BB14: 10008 | BK14: 3 | BL14: 1 | BM14: 1 | BN14: 1.2
A15: 9 | B15: 111009 | C15: 111009 | D15: 阿龙 | E15: 阿龙 | G15: 0 | H15: 把人类当作下等的生物，企图支配“东海”的鱼人船长，只把人类看作道具。 | I15: 企图支配东海的鱼人船长，擅长进攻。\n对破甲的敌人造成更多伤害。\n低血量时攻击大幅提升，但防御降低。 | J15: 攻守平衡 | K15: 前排优先 | L15: 无 | M15: 173,172 | N15: 1 | O15: 1 | P15: 4 | Q15: 4 | R15: 3 | S15: 阿龙一伙 | T15: 2 | U15: 6 | V15: 1 | W15: 20 | X15: hero_2d_1009 | Y15: hero_long2d_111009 | Z15: 610009 | AA15: 214005 | AB15: 10 | AC15: 10 | AD15: 10 | AE15: 93 | AF15: 13 | AG15: 246 | AH15: 24 | AI15: 0.0096 | AJ15: 0.006 | AK15: 1.012 | AM15: 9,1.5;39,1.5;40,0.5;11,0.0084 | AR15: 8 | AS15: 40,10,10,50,30,50 | AT15: heroPosition_2 | AU15: heroActor_1009 | AV15: 173 | AX15: 2 | AY15: 1 | AZ15: 172 | BA15: 3 | BB15: 10009 | BK15: 4 | BL15: 1 | BM15: 1.2 | BN15: 1.5
A16: 10 | B16: 111010 | C16: 111010 | D16: 小八 | E16: 小八 | G16: 0 | H16: 使用“六刀流”的章鱼鱼人，虽然是海盗，但性格非常和善，让人讨厌不起来。 | I16: 熟练使用六刀流的章鱼鱼人，擅长防御。\n技能可提升自身防御。\n血量较低时，闪避率大幅提升。 | J16: 攻守平衡 | K16: 前排优先 | L16: 无 | M16: 223,222 | N16: 1 | O16: 1 | P16: 5 | Q16: 5 | R16: 3 | S16: 阿龙一伙 | T16: 2 | U16: 6 | V16: 1 | W16: 29 | X16: hero_2d_1010 | Y16: hero_long2d_111010 | Z16: 610010 | AA16: 214005 | AB16: 10 | AC16: 10 | AD16: 10 | AE16: 85 | AF16: 12 | AG16: 278 | AH16: 22 | AJ16: 0.012 | AK16: 1.006 | AL16: 0.006 | AM16: 9,1.5;39,1.5;40,0.5;10,0.01211 | AR16: 8 | AS16: 0,0,30,30,60,40 | AT16: heroPosition_1 | AU16: heroActor_1010 | AV16: 222 | AX16: 2 | AY16: 2 | AZ16: 205 | BA16: 3 | BB16: 10010 | BK16: 5 | BL16: 1 | BM16: 1.2 | BN16: 1.5
A17: 11 | B17: 111011 | C17: 111011 | D17: 薇薇 | E17: 薇薇 | G17: 1 | H17: 阿鲁巴拿的公主，为了保护自己的国家，潜入巴洛克工作社内部。以Ms.星期三的身份探查危害国家的情况。 | I17: 阿拉巴斯坦的公主，擅长辅助。\n技能附带减速效果，可削弱敌方行动速度。\n技能附带封印效果，可禁用敌方奥义技。 | J17: 团队辅助 | K17: 前排优先 | L17: 无 | M17: 318,319 | N17: 1 | O17: 1 | P17: 6 | Q17: 6 | R17: 8 | S17: 巴洛克工作室 | T17: 2 | U17: 6 | V17: 1 | W17: 45 | X17: hero_2d_1011 | Y17: hero_long2d_111011 | Z17: 610011 | AA17: 214005 | AB17: 10 | AC17: 10 | AD17: 10 | AE17: 83 | AF17: 13 | AG17: 187 | AH17: 36 | AI17: 0.009 | AJ17: 0.0096 | AK17: 1.0024 | AL17: 0.006 | AM17: 9,1.545;39,1.5;40,0.5; | AO17: CV_vivi01 | AR17: 8 | AS17: 30,50,30,30,20,30 | AT17: heroPosition_4 | AU17: heroActor_1011 | AV17: 318 | AX17: 4 | AY17: 3 | AZ17: 318 | BA17: 4 | BB17: 10011 | BK17: 6 | BL17: 1.2 | BM17: 1.4 | BN17: 1.7
A18: 12 | B18: 111012 | C18: 111012 | D18: Mr.5 | E18: Mr.5 | G18: 0 | H18: 巴洛克工作社的高级指挥，炸弹之果的能力者，喜欢挖鼻孔。他在执行任务的过程中沉着冷静，对自己有极大的自信。 | I18: 冷酷执行任务的炸弹男，擅长属性伤害。\n技能附带火属性伤害和灼烧效果。\n炸弹之果天赋提升火属性伤害。 | J18: 持续输出 | K18: 前排优先 | L18: 炸弹之果 | M18: 228,229 | N18: 1 | O18: 1 | P18: 3 | Q18: 3 | R18: 5 | S18: 巴洛克工作室 | T18: 2 | U18: 6 | V18: 1 | W18: 31 | X18: hero_2d_1012 | Y18: hero_long2d_111012 | Z18: 610012 | AA18: 214005 | AB18: 10 | AC18: 10 | AD18: 10 | AE18: 138 | AF18: 10 | AG18: 176 | AH18: 29 | AI18: 0.0108 | AK18: 1.0096 | AM18: 9,1.542;39,1.5;40,0.5;11,0.0072 | AR18: 8 | AS18: 0,10,20,60,30,50 | AT18: heroPosition_4 | AU18: heroActor_1012 | AV18: 229 | AX18: 4 | AY18: 4 | AZ18: 212 | BA18: 4 | BB18: 10012 | BK18: 7 | BL18: 1.2 | BM18: 1.4 | BN18: 1.7
A19: 13 | B19: 111013 | C19: 111013 | D19: 瓦波尔 | E19: 瓦波尔 | G19: 0 | H19: 贪生怕死、舍弃国家的铁桶王国国王。后假扮海盗，企图复辟王权。是狼吞虎咽之果的能力者，什么都能吃下去。 | I19: 舍弃国家的铁桶王国国王，擅长防御。\n技能附带减伤效果，可减少受到的伤害。\n拥有自我治疗能力，且免疫1次致死伤害。 | J19: 防御壁垒 | K19: 前排优先 | L19: 吞吞之果 | M19: 233,234 | N19: 1 | O19: 1 | P19: 3 | Q19: 3 | R19: 3 | S19: 白铁海盗团 | T19: 2 | U19: 6 | V19: 1 | W19: 44 | X19: hero_2d_1013 | Y19: hero_long2d_111013 | Z19: 610013 | AA19: 214005 | AB19: 10 | AC19: 10 | AD19: 10 | AE19: 84 | AF19: 13 | AG19: 272 | AH19: 16 | AJ19: 0.012 | AK19: 1.006 | AL19: 0.006 | AM19: 9,1.5;39,1.5;40,0.5;10,0.01211 | AR19: 8 | AS19: 0,20,20,30,60,30 | AT19: heroPosition_4 | AU19: heroActor_1013 | AV19: 233 | AX19: 2 | AY19: 1 | AZ19: 216 | BA19: 3 | BB19: 10013 | BK19: 8 | BL19: 1.2 | BM19: 1.6 | BN19: 2
A20: 14 | B20: 111014 | C20: 111014 | D20: Mr.4 | E20: Mr.4 | G20: 0 | H20: 巴洛克工作社的高级指挥，拥有强大的力量，与自己宠物合作可以形成巨大的破坏力。 | I20: 动作迟缓但威力无限，擅长进攻。\n技能附带击飞效果，可打破敌方阵型。\n拥有全力打击天赋，伤害提升但速度下降。 | J20: 单点爆发 | K20: 前排优先 | L20: 无 | M20: 226,225 | N20: 1 | O20: 1 | P20: 6 | Q20: 6 | R20: 5 | S20: 巴洛克工作室 | T20: 2 | U20: 6 | V20: 1 | W20: 30 | X20: hero_2d_1014 | Y20: hero_long2d_111014 | Z20: 610014 | AA20: 214005 | AB20: 10 | AC20: 10 | AD20: 10 | AE20: 116 | AF20: 9 | AG20: 152 | AH20: 40 | AI20: 0.0108 | AK20: 1.0096 | AM20: 9,1.542;39,1.5;40,0.5;11,0.0072 | AR20: 8 | AS20: 0,10,30,40,40,60 | AT20: heroPosition_4 | AU20: heroActor_1014 | AV20: 226 | AX20: 4 | AY20: 2 | AZ20: 209 | BA20: 4 | BB20: 10014
A21: 15 | B21: 111015 | C21: 111015 | D21: Ms.黄金周 | E21: Miss.黄金周 | G21: 1 | H21: 巴洛克工作社高级指挥Mr.3的搭档，是个喜欢喝茶的小姑娘画家，可以通过画板的颜料控制他人的感情。 | I21: 擅长使用彩色颜料的写实画家，擅长辅助。\n技能附带驱散效果，消除敌方的增益状态。\n拥有情绪控制天赋，增加友方怒气获得量。 | J21: 团队辅助 | K21: 前排优先 | L21: 无 | M21: 236,237 | N21: 1 | O21: 1 | P21: 6 | Q21: 6 | R21: 5 | S21: 巴洛克工作室 | T21: 2 | U21: 6 | V21: 1 | W21: 33 | X21: hero_2d_1015 | Y21: hero_long2d_111015 | Z21: 610015 | AA21: 214005 | AB21: 10 | AC21: 10 | AD21: 10 | AE21: 67 | AF21: 13 | AG21: 217 | AH21: 23 | AI21: 0.009 | AJ21: 0.0096 | AK21: 1.0024 | AL21: 0.006 | AM21: 9,1.545;39,1.5;40,0.5; | AR21: 8 | AS21: 0,30,60,30,40,40 | AT21: heroPosition_4 | AU21: heroActor_1015 | AV21: 237 | AX21: 4 | AY21: 3 | AZ21: 220 | BA21: 4 | BB21: 10015
A22: 16 | B22: 111016 | C22: 111016 | D22: 猫头鹰 | E22: 猫头鹰 | G22: 0 | H22: 非常讲义气的赏金猎人，佐罗的小弟。教会了路飞鼻孔舞。 | J22: 0 | K22: 0 | L22: 0 | N22: 0 | O22: 1 | P22: 4 | Q22: 4 | R22: 4 | S22: 世界政府 | T22: 2 | U22: 6 | V22: 1 | W22: 49 | X22: hero_2d_1016 | Z22: 9999 | AA22: 214005 | AB22: 10 | AC22: 10 | AD22: 10 | AE22: 40 | AF22: 12 | AG22: 302 | AH22: 10 | AJ22: 0.012 | AK22: 1.006 | AL22: 0.006 | AM22: 9,1.5;39,1.5;40,0.5;10,0.01211 | AR22: 8 | AT22: heroPosition_4 | AU22: heroActor_1015 | AX22: 4 | AY22: 4 | BB22: 90001
A23: 17 | B23: 111017 | C23: 111017 | D23: 脸谱 | E23: 脸谱 | G23: 0 | H23: CP9成员，喜欢表演切腹自杀，口头禅是“哟哟咿”。拥有六式非常独特的“生命归还”技能。 | J23: 0 | K23: 0 | L23: 0 | N23: 0 | O23: 1 | P23: 4 | Q23: 4 | R23: 4 | S23: 世界政府 | T23: 2 | U23: 6 | V23: 1 | W23: 1089 | X23: hero_2d_1017 | Z23: 9999 | AA23: 214005 | AB23: 10 | AC23: 10 | AD23: 10 | AE23: 40 | AF23: 12 | AG23: 302 | AH23: 10 | AJ23: 0.012 | AK23: 1.006 | AL23: 0.006 | AM23: 9,1.5;39,1.5;40,0.5;10,0.01211 | AR23: 8 | AT23: heroPosition_4 | AU23: heroActor_1015 | AX23: 4 | BB23: 90002
A24: 18 | B24: 111018 | C24: 111018 | D24: 约撒 | E24: 约撒 | G24: 0 | H24: 非常讲义气的赏金猎人，佐罗的小弟。教会了路飞鼻孔舞。 | I24: 讲义气重人情的好搭档，擅长进攻。\n技能附带封技效果，可禁用敌人普通技能。\n技能提升自身速度和攻击，增加伤害输出。 | J24: 攻守平衡 | K24: 前排优先 | L24: 无 | M24: 375,376 | N24: 1 | O24: 1 | P24: 5 | Q24: 5 | R24: 8 | S24: 赏金猎人 | T24: 2 | U24: 6 | V24: 1 | W24: 2015 | X24: hero_2d_21031 | Y24: hero_long2d_111018 | Z24: 610018 | AA24: 214005 | AB24: 10 | AC24: 10 | AD24: 10 | AE24: 116 | AF24: 11 | AG24: 211 | AH24: 30 | AJ24: 0.012 | AK24: 1.006 | AL24: 0.006 | AM24: 9,1.5;39,1.5;40,0.5;10,0.01211 | AN24: CV_yosaku02 | AO24: CV_yosaku01 | AR24: 8 | AS24: 30,20,20,30,40,40 | AT24: heroPosition_4 | AU24: heroActor_1015 | AX24: 2 | BA24: 3 | BB24: 10016
A25: 19 | B25: 112001 | C25: 112001 | D25: 路飞 | E25: 路飞 | G25: 0 | H25: 橡皮之果能力者，拥有众多招式。杰克斯托付给他的帽子就是他的宝贝。现在是草帽一伙的船长。 | I25: 力量强悍的能力者，攻防兼备。\n拥有橡皮之果能力，反弹伤害，抵抗雷电。\n对单个目标伤害极高，可打破敌方阵型。 | J25: 攻守平衡 | K25: 前排优先 | L25: 橡皮之果 | M25: 5,3 | N25: 1 | O25: 1 | P25: 3 | Q25: 3 | R25: 1 | S25: 草帽海盗团 | T25: 3 | U25: 7 | V25: 2 | W25: 1 | X25: hero_2d_2001 | Y25: hero_long2d_112001 | Z25: 620001 | AA25: 214005 | AB25: 30 | AC25: 30 | AD25: 30 | AE25: 97 | AF25: 15 | AG25: 314 | AH25: 45 | AJ25: 0.016 | AK25: 1.008 | AL25: 0.008 | AM25: 9,1.5;39,1.5;40,0.5;10,0.01611 | AN25: CV_LuffyCZ_victory | AO25: CV_LuffyCZ_ready | AR25: 8 | AS25: 40,30,40,60,70,60 | AT25: heroPosition_2 | AU25: heroActor_2001 | AV25: 5 | AW25: 9 | AX25: 2 | AZ25: 5 | BA25: 1 | BB25: 1001
A26: 20 | B26: 112002 | C26: 112002 | D26: 佐罗 | E26: 佐罗 | G26: 0 | H26: 想要成为世界第一剑客的三刀流剑士，曾被人们称为“海盗猎人”。但被路飞的梦想和决心所感动，成为了他的第一个伙伴。 | I26: 伤害超高的剑客，擅长进攻。\n不是胜利就是死亡！低血量时伤害骤增。\n嗜血斩杀，附加流血伤害，一击致命。 | J26: 单点爆发 | K26: 前排优先 | L26: 无 | M26: 28,25 | N26: 1 | O26: 1 | P26: 5 | Q26: 5 | R26: 1 | S26: 草帽海盗团 | T26: 3 | U26: 7 | V26: 2 | W26: 2 | X26: hero_2d_2002 | Y26: hero_long2d_112002 | Z26: 620002 | AA26: 214005 | AB26: 30 | AC26: 30 | AD26: 30 | AE26: 127 | AF26: 12 | AG26: 276 | AH26: 55 | AI26: 0.0128 | AJ26: 0.008 | AK26: 1.016 | AM26: 9,1.5;39,1.5;40,0.5;11,0.0112 | AN26: CVZoro_victory | AO26: CVZoro_ready | AR26: 8 | AS26: 60,20,20,70,40,70 | AT26: heroPosition_2 | AU26: heroActor_2002 | AV26: 31 | AW26: 9 | AX26: 2 | AZ26: 16 | BA26: 1 | BB26: 1002
A27: 21 | B27: 112003 | C27: 112003 | D27: 奈美 | E27: 奈美 | G27: 1 | H27: 草帽一伙的天才导航员。在交涉事务方面，无人可与她匹敌。最喜欢金钱。 | I27: 掌控全场的航海士，擅长属性伤害。\n操控战场气候，削弱敌方能力。\n行动迅速，闪避天赋，精通雷电操控。 | J27: 团队控制 | K27: 前排优先 | L27: 无 | M27: 67,70 | N27: 1 | O27: 1 | P27: 6 | Q27: 6 | R27: 1 | S27: 草帽海盗团 | T27: 3 | U27: 7 | V27: 2 | W27: 5 | X27: hero_2d_2003 | Y27: hero_long2d_112003 | Z27: 620003 | AA27: 214005 | AB27: 30 | AC27: 30 | AD27: 30 | AE27: 155 | AF27: 12 | AG27: 200 | AH27: 60 | AI27: 0.0144 | AK27: 1.0128 | AM27: 9,1.556;39,1.5;40,0.5;11,0.0096 | AN27: CV_nami11 | AO27: CV_nami10 | AR27: 8 | AS27: 80,50,40,50,30,50 | AT27: heroPosition_4 | AU27: heroActor_2003 | AV27: 67 | AX27: 2 | AZ27: 37 | BA27: 1 | BB27: 1003
A28: 22 | B28: 112004 | C28: 112004 | D28: 撒谎布 | E28: 撒谎布 | G28: 0 | H28: 撒谎的本领无人能比，草帽一伙的狙击手。理想是成为“光荣的海上战士”！ | I28: 百发百中的神射手，擅长进攻。\n射出附带特殊效果的弹药，削弱敌方能力。\n精准射击，必杀暴击，人称破坏之王。 | J28: 单体控制 | K28: 后排优先 | L28: 无 | M28: 62,56 | N28: 1 | O28: 1 | P28: 6 | Q28: 6 | R28: 1 | S28: 草帽海盗团 | T28: 3 | U28: 7 | V28: 2 | W28: 4 | X28: hero_2d_2004 | Y28: hero_long2d_112004 | Z28: 620004 | AA28: 214005 | AB28: 30 | AC28: 30 | AD28: 30 | AE28: 145 | AF28: 11 | AG28: 156 | AH28: 90 | AI28: 0.0112 | AK28: 1.016 | AL28: 0.0048 | AM28: 9,1.5;39,1.5;40,0.5;11,0.016 | AN28: CV_usopp02 | AO28: CV_usopp01 | AR28: 8 | AS28: 60,30,50,70,50,80 | AT28: heroPosition_4 | AU28: heroActor_2004 | AV28: 62 | AX28: 2 | AZ28: 32 | BA28: 1 | BB28: 1004
A29: 23 | B29: 112005 | C29: 112005 | D29: 山智 | E29: 山智 | G29: 0 | H29: 是个海上厨师，本是海上餐厅的副厨师长，后来加入草帽一伙。目标是传说中的“蓝海”。面对美女就表现的无可救药。 | I29: 愈战愈勇的踢技达人，擅长进攻。\n连续踢技，伤害持续提升。\n技能附带压制效果，牵制单个敌人。 | J29: 极限输出 | K29: 对位优先 | L29: 无 | M29: 51,49 | N29: 1 | O29: 1 | P29: 4 | Q29: 4 | R29: 1 | S29: 草帽海盗团 | T29: 3 | U29: 7 | V29: 2 | W29: 3 | X29: hero_2d_2005 | Y29: hero_long2d_112005 | Z29: 620005 | AA29: 214005 | AB29: 30 | AC29: 30 | AD29: 30 | AE29: 169 | AF29: 9 | AG29: 124 | AH29: 105 | AI29: 0.016 | AK29: 1.008 | AL29: 0.0102 | AM29: 9,1.58;39,1.5;40,0.5;11,0.0048 | AN29: CV_sanji06 | AO29: CV_sanji01 | AR29: 8 | AS29: 0,0,60,80,60,80 | AT29: heroPosition_4 | AU29: heroActor_2005 | AV29: 51 | AX29: 2 | AZ29: 21 | BA29: 1 | BB29: 1005
A30: 24 | B30: 112006 | C30: 112006 | D30: 乔巴 | E30: 乔巴 | G30: 0 | H30: 吃了人人之果的蓝鼻子驯鹿，曾经被鹿群和人类当做怪物。在与西尔尔克相遇后，决心成为医生。现在是草帽一伙的船医。 | I30: 草帽海盗团的船医，擅长治疗。\n可解除友方的负面效果，提供增益效果。\n发动奥义可切换至战斗形态，输出伤害。 | J30: 医疗辅助 | K30: 己方优先 | L30: 人人之果 | M30: 83,85 | N30: 1 | O30: 1 | P30: 1 | Q30: 1 | R30: 1 | S30: 草帽海盗团 | T30: 3 | U30: 7 | V30: 2 | W30: 7 | X30: hero_2d_2006 | Y30: hero_long2d_112006 | Z30: 620006 | AA30: 214005 | AB30: 30 | AC30: 30 | AD30: 30 | AE30: 87 | AF30: 14 | AG30: 256 | AH30: 60 | AI30: 0.012 | AJ30: 0.0128 | AK30: 1.0032 | AL30: 0.008 | AM30: 9,1.56;39,1.5;40,0.5; | AN30: CV_chopper02,CV_chopper07 | AO30: CV_chopper05,CV_chopper08 | AR30: 8 | AS30: 80,80,0,30,80,30 | AT30: heroPosition_4 | AU30: heroActor_2006 | AV30: 83 | AX30: 2 | AZ30: 53 | BA30: 1 | BB30: 1006
A31: 25 | B31: 112007 | C31: 112007 | D31: 罗宾 | E31: 罗宾 | G31: 1 | H31: 不断寻求世界真相的考古学家！是花花之果的能力者，阿鲁巴拿战役后加入了草帽海盗团。 | I31: 探索历史的能力者，擅长偷袭。\n可以给敌方带来多种负面效果。\n扰乱敌方后排，控制敌方，帮助队友输出。 | J31: 功能辅助 | K31: 后排优先 | L31: 花花之果 | M31: 328,324 | N31: 1 | O31: 1 | P31: 3 | Q31: 3 | R31: 1 | S31: 草帽海盗团 | T31: 3 | U31: 7 | V31: 2 | W31: 47 | X31: hero_2d_2007 | Y31: hero_long2d_112007 | Z31: 620007 | AA31: 214005 | AB31: 30 | AC31: 30 | AD31: 30 | AE31: 117 | AF31: 14 | AG31: 187 | AH31: 50 | AI31: 0.0144 | AK31: 1.0128 | AM31: 9,1.556;39,1.5;40,0.5;11,0.0096 | AN31: CV_robinwin | AO31: CV_robin09 | AR31: 8 | AS31: 70,70,80,40,40,40 | AT31: heroPosition_4 | AU31: heroActor_2007 | AV31: 328 | AX31: 2 | AZ31: 328 | BA31: 1 | BB31: 1007
A32: 26 | B32: 112008 | C32: 112008 | D32: 弗兰奇 | E32: 弗兰奇 | G32: 0 | H32: 草帽海盗团钢铁船匠，拥有传说中的造船技术。性格豪放，心地坦荡，而且全身上下都经过了改造！ | I32: 渴望到达世界尽头的钢铁船匠，擅长防御。\n拥有多种被动防御技，拥有自我修复天赋。\n拥有嘲讽技能，可以吸引敌人的火力。 | J32: 防御壁垒 | K32: 前排优先 | L32: 无 | M32: 77,78 | N32: 1 | O32: 1 | P32: 6 | Q32: 6 | R32: 1 | S32: 草帽海盗团 | T32: 3 | U32: 7 | V32: 2 | W32: 6 | X32: hero_2d_2008 | Y32: hero_long2d_112008 | Z32: 620008 | AA32: 214005 | AB32: 30 | AC32: 30 | AD32: 30 | AE32: 88 | AF32: 15 | AG32: 332 | AH32: 40 | AJ32: 0.016 | AK32: 1.008 | AL32: 0.008 | AM32: 9,1.5;39,1.5;40,0.5;10,0.01611 | AN32: CV_franky06,CV_franky10 | AO32: CV_franky08 | AR32: 8 | AS32: 70,20,60,40,60,60 | AT32: heroPosition_4 | AU32: heroActor_2008 | AV32: 77 | AX32: 2 | AZ32: 47 | BA32: 1 | BB32: 1008
A33: 27 | B33: 112009 | C33: 112009 | D33: 布鲁克 | E33: 布鲁克 | G33: 0 | H33: 在黄泉之果的能力下，肉体化为白骨后又再次复活的骷髅人。除担任草帽一伙的音乐家外，还积极参加战斗。 | I33: 快乐作战的音乐家，擅长进攻。\n拥有黄泉之果的能力，阵亡后有概率复活。\n每回合会随机演奏乐曲，提供全体增益效果。 | J33: 单点爆发 | K33: 对位优先 | L33: 黄泉之果 | M33: 106,100 | N33: 1 | O33: 1 | P33: 3 | Q33: 3 | R33: 1 | S33: 草帽海盗团 | T33: 3 | U33: 7 | V33: 2 | W33: 10 | X33: hero_2d_2009 | Y33: hero_long2d_112009 | Z33: 620009 | AA33: 214005 | AB33: 30 | AC33: 30 | AD33: 30 | AE33: 158 | AF33: 9 | AG33: 145 | AH33: 100 | AI33: 0.0112 | AJ33: 0.0048 | AK33: 1 | AL33: 0.023 | AM33: 9,1.54;39,1.5;40,0.5;11,0.008 | AN33: CV_brook06 | AO33: CV_brook02 | AR33: 8 | AS33: 40,20,20,70,40,70 | AT33: heroPosition_4 | AU33: heroActor_2009 | AV33: 77 | AX33: 2 | BA33: 1 | BB33: 1009
A34: 28 | B34: 112010 | C34: 112010 | D34: 巴奇 | E34: 巴奇 | G34: 0 | H34: 巴奇年轻的时候，和杰克斯曾呆在同一艘船上。看上去像马戏团一样的巴奇海盗团的船长，还是四分五裂之果的能力者。 | I34: 拥有群体伤害的能力者，擅长进攻。\n华丽炮击，附带火焰伤害和灼烧效果。\n技能附带压制效果，牵制单个敌人。 | J34: 持续输出 | K34: 前排优先 | L34: 四分五裂之果 | M34: 98,95 | N34: 1 | O34: 1 | P34: 3 | Q34: 3 | R34: 3 | S34: 巴基海盗团 | T34: 3 | U34: 7 | V34: 2 | W34: 9 | X34: hero_2d_2010 | Y34: hero_long2d_112010 | Z34: 620010 | AA34: 214005 | AB34: 30 | AC34: 30 | AD34: 30 | AE34: 152 | AF34: 9 | AG34: 166 | AH34: 95 | AI34: 0.0112 | AJ34: 0.0048 | AK34: 1 | AL34: 0.023 | AM34: 9,1.54;39,1.5;40,0.5;11,0.008 | AN34: CV_buggy06 | AO34: CV_buggy02,CV_buggy05 | AR34: 8 | AS34: 80,20,70,40,80,40 | AT34: heroPosition_4 | AU34: heroActor_2010 | AV34: 98 | AX34: 2 | AZ34: 73 | BA34: 3 | BB34: 1010
A35: 29 | B35: 112011 | C35: 112011 | D35: 烟鬼 | E35: 烟鬼 | G35: 0 | H35: 对于自己逮捕海盗的能力有着绝对自信的海军总部上校，也是全身都能化为烟雾的冒烟之果能力者。路飞曾从其手中逃过一劫，至今他一直在追捕路飞。 | I35: 海军总部准将，攻防兼备。\n执行正义的能力者，对海盗伤害提高。\n防御力强悍，抵抗非属性伤害。 | J35: 攻守平衡 | K35: 前排优先 | L35: 烟雾之果 | M35: 115,113 | N35: 1 | O35: 1 | P35: 2 | Q35: 2 | R35: 2 | S35: 海军 | T35: 3 | U35: 7 | V35: 2 | W35: 11 | X35: hero_2d_2011 | Y35: hero_long2d_112011 | Z35: 620011 | AA35: 214005 | AB35: 30 | AC35: 30 | AD35: 30 | AE35: 121 | AF35: 14 | AG35: 259 | AH35: 54 | AI35: 0.0096 | AJ35: 0.0128 | AK35: 1.0128 | AL35: 0.0032 | AM35: 9,1.5;39,1.5;40,0.5;10,0.009611 | AN35: CV_smoker04 | AO35: CV_smoker06,CV_smoker05 | AR35: 8 | AS35: 70,20,20,80,50,80 | AT35: heroPosition_2 | AU35: heroActor_2011 | AV35: 115 | AX35: 1 | AZ35: 90 | BA35: 2 | BB35: 1011
A36: 30 | B36: 112012 | C36: 112012 | D36: 塔希米 | E36: 塔希米 | G36: 1 | H36: 将正义托付在自己刀剑上的海军剑士。剑术本领一流，但是因视力不好经常出差错。 | I36: 剑术一流的剑士，攻防兼备。\n时雨招式，对单个敌人造成爆发伤害。\n薄霞招式，可造成大量群体伤害。 | J36: 持续输出 | K36: 前排优先 | L36: 无 | M36: 131,130 | N36: 1 | O36: 1 | P36: 5 | Q36: 5 | R36: 2 | S36: 海军 | T36: 3 | U36: 7 | V36: 2 | W36: 13 | X36: hero_2d_2012 | Y36: hero_long2d_112012 | Z36: 620012 | AA36: 214005 | AB36: 30 | AC36: 30 | AD36: 30 | AE36: 127 | AF36: 14 | AG36: 242 | AH36: 53 | AI36: 0.0128 | AJ36: 0.008 | AK36: 1.016 | AM36: 9,1.5;39,1.5;40,0.5;11,0.0112 | AR36: 8 | AS36: 70,30,30,50,50,60 | AT36: heroPosition_2 | AU36: heroActor_2012 | AV36: 131 | AX36: 1 | AZ36: 106 | BA36: 2 | BB36: 1012
A37: 31 | B37: 112013 | C37: 112013 | D37: Mr.1 | E37: Mr.1 | G37: 0 | H37: 巴洛克工作社高级指挥中最强的男人。通过快斩之果的能力可以将全身变成刀刃，同时皮肤也会变得像钢铁一样坚硬。 | I37: 可以斩断一切的刀刃人，攻防兼备。\n技能附带流血效果，持续造成伤害。\n拥有快斩之果天赋，减免受到的伤害。 | J37: 伤害反射 | K37: 前排优先 | L37: 快斩之果 | M37: 123,122 | N37: 1 | O37: 1 | P37: 3 | Q37: 3 | R37: 5 | S37: 巴洛克工作室 | T37: 3 | U37: 7 | V37: 2 | W37: 12 | X37: hero_2d_2013 | Y37: hero_long2d_112013 | Z37: 620013 | AA37: 214005 | AB37: 30 | AC37: 30 | AD37: 30 | AE37: 125 | AF37: 16 | AG37: 221 | AH37: 50 | AJ37: 0.016 | AK37: 1.008 | AL37: 0.008 | AM37: 9,1.5;39,1.5;40,0.5;10,0.01611 | AR37: 8 | AS37: 60,70,20,40,80,60 | AT37: heroPosition_4 | AU37: heroActor_2013 | AV37: 123 | AX37: 4 | AZ37: 98 | BA37: 4 | BB37: 1013
A38: 32 | B38: 112014 | C38: 112014 | D38: Mr.2 | E38: Mr.2 | G38: 2 | H38: 巴洛克工作社唯一没有搭档的高级指挥。是模仿之果的能力者。为人重义气，阿鲁巴拿战役后与草帽海盗团成为好友。 | I38: 坚信人妖之道的能力者，擅长进攻。\n技能可提升属性，大幅提升伤害能力。\n身形灵巧，拥有出色的速度和闪避能力。 | J38: 单点爆发 | K38: 对位优先 | L38: 模仿之果 | M38: 145,141 | N38: 1 | O38: 1 | P38: 3 | Q38: 3 | R38: 5 | S38: 巴洛克工作室 | T38: 3 | U38: 7 | V38: 2 | W38: 15 | X38: hero_2d_2014 | Y38: hero_long2d_112014 | Z38: 620014 | AA38: 214005 | AB38: 30 | AC38: 30 | AD38: 30 | AE38: 158 | AF38: 10 | AG38: 138 | AH38: 90 | AI38: 0.016 | AK38: 1.008 | AL38: 0.0102 | AM38: 9,1.58;39,1.5;40,0.5;11,0.0048 | AN38: CV_mr203 | AO38: CV_mr204 | AR38: 8 | AS38: 0,30,20,70,40,80 | AT38: heroPosition_4 | AU38: heroActor_2014 | AV38: 145 | AX38: 4 | AZ38: 120 | BA38: 4 | BB38: 1014
A39: 33 | B39: 112015 | C39: 112015 | D39: Mr.3 | E39: Mr.3 | G39: 0 | H39: 巴洛克工作社的高级指挥。融化之果的能力者。喜欢把敌人做成蜡烛娃娃，是个作战头脑派。 | I39: 追求疯狂美学的艺术家，擅长防御。\n奥义技会战斗形态，大幅增加防御能力。\n技能附带牵制效果，降低敌人的速度和闪避 | J39: 团队控制 | K39: 后排优先 | L39: 融化之果 | M39: 137,294 | N39: 1 | O39: 1 | P39: 3 | Q39: 3 | R39: 5 | S39: 巴洛克工作室 | T39: 3 | U39: 7 | V39: 2 | W39: 14 | X39: hero_2d_2015 | Y39: hero_long2d_112015 | Z39: 620015 | AA39: 214005 | AB39: 30 | AC39: 30 | AD39: 30 | AE39: 88 | AF39: 16 | AG39: 318 | AH39: 41 | AI39: 0.012 | AJ39: 0.0128 | AK39: 1.0032 | AL39: 0.008 | AM39: 9,1.56;39,1.5;40,0.5; | AR39: 8 | AS39: 60,30,80,20,80,40 | AT39: heroPosition_4 | AU39: heroActor_2015 | AV39: 137 | AX39: 4 | AZ39: 112 | BA39: 4 | BB39: 1015
A40: 34 | B40: 112016 | C40: 112016 | D40: Ms.双手指 | E40: Miss.双手指 | G40: 1 | H40: 巴洛克工作社Mr.1的搭档，荆棘之果能力者。是个性格冷酷的女杀手。 | I40: 危险的尖刺美女，擅长进攻。\n技能附带急速效果，大幅提升行动速度。\n技能附带击退效果，可打破敌方阵型。 | J40: 伤害反射 | K40: 前排优先 | L40: 荆棘之果 | M40: 316,310 | N40: 1 | O40: 1 | P40: 3 | Q40: 3 | R40: 5 | S40: 巴洛克工作室 | T40: 3 | U40: 7 | V40: 2 | W40: 46 | X40: hero_2d_2016 | Y40: hero_long2d_112016 | Z40: 620016 | AA40: 214005 | AB40: 30 | AC40: 30 | AD40: 30 | AE40: 164 | AF40: 10 | AG40: 121 | AH40: 84 | AI40: 0.016 | AK40: 1.008 | AL40: 0.0102 | AM40: 9,1.58;39,1.5;40,0.5;11,0.0048 | AN40: CV_dfinger05 | AO40: CV_dfinger02,CV_dfinger04 | AR40: 8 | AS40: 0,30,20,60,80,60 | AT40: heroPosition_4 | AU40: heroActor_2016 | AV40: 316 | AX40: 4 | AZ40: 316 | BA40: 4 | BB40: 1016
...
