Workbook

Sheet Sheet1
A1: 7 | B1: 1 | C1: 9999 | D1: 20
A2: id | B2: 图片 | C2: 奖励 | D2: 消耗 | E2: 奖励首次 | F2: 归属哪条航线（最外围入口） | G2: 归属第几个据点 | H2: 星级条件 | I2: 怪群 | J2: 战斗地图 | K2: 标题 | L2: 限制等级 | M2: 关卡说明
A3: id | B3: image | C3: reward | D3: cost | E3: rewardFirst | F3: bigChapter | G3: midChapter | H3: starCondition | K3: title | M3: explain
A4: int | B4: string | C4: string | D4: string | E4: string | F4: int | G4: int | H4: string | K4: string | M4: string
A5: primary | B5: none | C5: none | D5: none | E5: none | F5: none | G5: none | H5: none | K5: none | M5: none
A6: id | C6: reward | D6: cost | E6: rewardFirst | F6: bigChapter | G6: midChapter | H6: starCondition | I6: enemyGroupId | J6: fightMapId | L6: limitPlayerLev
A7: 10101 | B7: zhounianqingdian_tenghu | C7: 1001,555532,2 | D7: 2001,0,10 | E7: 1001,555532,10 | F7: 1 | G7: 1 | H7: =VLOOKUP(A7,Sheet2!$R:$T,3,FALSE) -> 1,4;2,3;46,3-1 | I7: 3011000 | J7: 1 | K7: 第1-1关 | L7: 25
A8: 10102 | B8: zhounianqingdian_tenghu | C8: 1001,555532,2 | D8: 2001,0,10 | E8: 1001,555532,10 | F8: 1 | G8: 1 | H8: =VLOOKUP(A8,Sheet2!$R:$T,3,FALSE) -> 1,4;2,3;46,3-1 | I8: 3011001 | J8: 1 | K8: 第1-2关 | L8: 25
A9: 10103 | B9: zhounianqingdian_tenghu | C9: 1001,555532,2 | D9: 2001,0,10 | E9: 1001,555532,10 | F9: 1 | G9: 1 | H9: =VLOOKUP(A9,Sheet2!$R:$T,3,FALSE) -> 1,4;2,3;46,3-1 | I9: 3011002 | J9: 1 | K9: 第1-3关 | L9: 25
A10: 10104 | B10: zhounianqingdian_tenghu | C10: 1001,555532,2 | D10: 2001,0,10 | E10: 1001,555532,10 | F10: 1 | G10: 1 | H10: =VLOOKUP(A10,Sheet2!$R:$T,3,FALSE) -> 1,4;2,3;46,3-1 | I10: 3011003 | J10: 1 | K10: 第1-4关 | L10: 25
A11: 10105 | B11: zhounianqingdian_tenghu | C11: 1001,555532,2 | D11: 2001,0,10 | E11: 1001,555532,10 | F11: 1 | G11: 1 | H11: =VLOOKUP(A11,Sheet2!$R:$T,3,FALSE) -> 1,4;2,3;46,3-1 | I11: 3011004 | J11: 1 | K11: 第1-5关 | L11: 25
A12: 10106 | B12: zhounianqingdian_tenghu | C12: 1001,555532,3 | D12: 2001,0,10 | E12: 1001,555532,10 | F12: 1 | G12: 1 | H12: =VLOOKUP(A12,Sheet2!$R:$T,3,FALSE) -> 1,4;2,4;46,3-2 | I12: 3011005 | J12: 1 | K12: 第1-6关 | L12: 25
A13: 10107 | B13: zhounianqingdian_tenghu | C13: 1001,555532,3 | D13: 2001,0,10 | E13: 1001,555532,10 | F13: 1 | G13: 1 | H13: =VLOOKUP(A13,Sheet2!$R:$T,3,FALSE) -> 1,4;2,4;46,3-2 | I13: 3011006 | J13: 1 | K13: 第1-7关 | L13: 25
A14: 10108 | B14: zhounianqingdian_tenghu | C14: 1001,555532,3 | D14: 2001,0,10 | E14: 1001,555532,10 | F14: 1 | G14: 1 | H14: =VLOOKUP(A14,Sheet2!$R:$T,3,FALSE) -> 1,4;2,4;46,3-2 | I14: 3011007 | J14: 1 | K14: 第1-8关 | L14: 25
A15: 10109 | B15: zhounianqingdian_tenghu | C15: 1001,555532,3 | D15: 2001,0,10 | E15: 1001,555532,10 | F15: 1 | G15: 1 | H15: =VLOOKUP(A15,Sheet2!$R:$T,3,FALSE) -> 1,4;2,4;46,3-2 | I15: 3011008 | J15: 1 | K15: 第1-9关 | L15: 25
A16: 10110 | B16: zhounianqingdian_tenghu | C16: 1001,555532,3 | D16: 2001,0,10 | E16: 1001,555532,10 | F16: 1 | G16: 1 | H16: =VLOOKUP(A16,Sheet2!$R:$T,3,FALSE) -> 1,4;2,4;46,3-2 | I16: 3011009 | J16: 1 | K16: 第1-10关 | L16: 25
A17: 10201 | B17: zhounianqingdian_tenghu | C17: 1001,555541,5 | E17: 1001,555532,10 | F17: 1 | G17: 2 | K17: 第2-1关
A18: 10301 | B18: zhounianqingdian_tenghu | C18: 1001,555532,4 | D18: 2001,0,10 | E18: 1001,555532,20 | F18: 1 | G18: 3 | H18: =VLOOKUP(A18,Sheet2!$R:$T,3,FALSE) -> 1,4;2,4;46,3-2 | I18: 3011010 | J18: 1 | K18: 第3-1关 | L18: 30
A19: 10302 | B19: zhounianqingdian_tenghu | C19: 1001,555532,4 | D19: 2001,0,10 | E19: 1001,555532,20 | F19: 1 | G19: 3 | H19: =VLOOKUP(A19,Sheet2!$R:$T,3,FALSE) -> 1,4;2,4;46,3-2 | I19: 3011011 | J19: 1 | K19: 第3-2关 | L19: 30
A20: 10303 | B20: zhounianqingdian_tenghu | C20: 1001,555532,4 | D20: 2001,0,10 | E20: 1001,555532,20 | F20: 1 | G20: 3 | H20: =VLOOKUP(A20,Sheet2!$R:$T,3,FALSE) -> 1,4;2,4;46,3-2 | I20: 3011012 | J20: 1 | K20: 第3-3关 | L20: 30
A21: 10304 | B21: zhounianqingdian_tenghu | C21: 1001,555532,4 | D21: 2001,0,10 | E21: 1001,555532,20 | F21: 1 | G21: 3 | H21: =VLOOKUP(A21,Sheet2!$R:$T,3,FALSE) -> 1,4;2,4;46,3-2 | I21: 3011013 | J21: 1 | K21: 第3-4关 | L21: 30
A22: 10305 | B22: zhounianqingdian_tenghu | C22: 1001,555532,4 | D22: 2001,0,10 | E22: 1001,555532,20 | F22: 1 | G22: 3 | H22: =VLOOKUP(A22,Sheet2!$R:$T,3,FALSE) -> 1,4;2,4;46,3-2 | I22: 3011014 | J22: 1 | K22: 第3-5关 | L22: 30
A23: 10306 | B23: zhounianqingdian_tenghu | C23: 1001,555532,4 | D23: 2001,0,10 | E23: 1001,555532,20 | F23: 1 | G23: 3 | H23: =VLOOKUP(A23,Sheet2!$R:$T,3,FALSE) -> 1,4;2,4;46,3-2 | I23: 3011015 | J23: 1 | K23: 第3-6关 | L23: 35
A24: 10307 | B24: zhounianqingdian_tenghu | C24: 1001,555532,5 | D24: 2001,0,10 | E24: 1001,555532,20 | F24: 1 | G24: 3 | H24: =VLOOKUP(A24,Sheet2!$R:$T,3,FALSE) -> 1,4;2,4;46,3-2 | I24: 3011016 | J24: 1 | K24: 第3-7关 | L24: 35
A25: 10308 | B25: zhounianqingdian_tenghu | C25: 1001,555532,5 | D25: 2001,0,10 | E25: 1001,555532,20 | F25: 1 | G25: 3 | H25: =VLOOKUP(A25,Sheet2!$R:$T,3,FALSE) -> 1,4;2,4;46,3-2 | I25: 3011017 | J25: 1 | K25: 第3-8关 | L25: 35
A26: 10309 | B26: zhounianqingdian_tenghu | C26: 1001,555532,5 | D26: 2001,0,10 | E26: 1001,555532,20 | F26: 1 | G26: 3 | H26: =VLOOKUP(A26,Sheet2!$R:$T,3,FALSE) -> 1,4;2,4;46,3-2 | I26: 3011018 | J26: 1 | K26: 第3-9关 | L26: 35
A27: 10310 | B27: zhounianqingdian_tenghu | C27: 1001,555532,5 | D27: 2001,0,10 | E27: 1001,555532,20 | F27: 1 | G27: 3 | H27: =VLOOKUP(A27,Sheet2!$R:$T,3,FALSE) -> 1,4;2,4;46,3-2 | I27: 3011019 | J27: 1 | K27: 第3-10关 | L27: 35
A28: 11501 | B28: zhounianqingdian_tenghu | C28: 1001,555533,2 | D28: 2001,0,10 | E28: 1001,555533,10 | F28: 1 | G28: 15 | K28: 第15-1关 | L28: 40
A29: 10401 | B29: zhounianqingdian_tenghu | C29: 1001,555533,2 | D29: 2001,0,10 | E29: 1001,555533,10 | F29: 1 | G29: 4 | H29: =VLOOKUP(A29,Sheet2!$R:$T,3,FALSE) -> 1,3;2,4;46,3-2 | I29: 3011020 | J29: 1 | K29: 第4-1关 | L29: 40
A30: 10402 | B30: zhounianqingdian_tenghu | C30: 1001,555533,2 | D30: 2001,0,10 | E30: 1001,555533,10 | F30: 1 | G30: 4 | H30: =VLOOKUP(A30,Sheet2!$R:$T,3,FALSE) -> 1,3;2,4;46,3-2 | I30: 3011021 | J30: 1 | K30: 第4-2关 | L30: 40
A31: 10403 | B31: zhounianqingdian_tenghu | C31: 1001,555533,2 | D31: 2001,0,10 | E31: 1001,555533,10 | F31: 1 | G31: 4 | H31: =VLOOKUP(A31,Sheet2!$R:$T,3,FALSE) -> 1,3;2,4;46,3-2 | I31: 3011022 | J31: 1 | K31: 第4-3关 | L31: 40
A32: 10404 | B32: zhounianqingdian_tenghu | C32: 1001,555533,3 | D32: 2001,0,10 | E32: 1001,555533,10 | F32: 1 | G32: 4 | H32: =VLOOKUP(A32,Sheet2!$R:$T,3,FALSE) -> 1,3;2,4;46,3-2 | I32: 3011023 | J32: 1 | K32: 第4-4关 | L32: 40
A33: 10405 | B33: zhounianqingdian_tenghu | C33: 1001,555533,3 | D33: 2001,0,10 | E33: 1001,555533,15 | F33: 1 | G33: 4 | H33: =VLOOKUP(A33,Sheet2!$R:$T,3,FALSE) -> 1,3;2,4;46,3-2 | I33: 3011024 | J33: 1 | K33: 第4-5关 | L33: 40
A34: 10406 | B34: zhounianqingdian_tenghu | C34: 1001,555533,3 | D34: 2001,0,10 | E34: 1001,555533,15 | F34: 1 | G34: 4 | H34: =VLOOKUP(A34,Sheet2!$R:$T,3,FALSE) -> 1,3;2,4;46,3-2 | I34: 3011025 | J34: 1 | K34: 第4-6关 | L34: 40
A35: 10407 | B35: zhounianqingdian_tenghu | C35: 1001,555533,3 | D35: 2001,0,10 | E35: 1001,555533,15 | F35: 1 | G35: 4 | H35: =VLOOKUP(A35,Sheet2!$R:$T,3,FALSE) -> 1,3;2,4;46,3-2 | I35: 3011026 | J35: 1 | K35: 第4-7关 | L35: 40
A36: 10408 | B36: zhounianqingdian_tenghu | C36: 1001,555533,4 | D36: 2001,0,10 | E36: 1001,555533,15 | F36: 1 | G36: 4 | H36: =VLOOKUP(A36,Sheet2!$R:$T,3,FALSE) -> 1,3;2,4;46,3-2 | I36: 3011027 | J36: 1 | K36: 第4-8关 | L36: 40
A37: 10409 | B37: zhounianqingdian_tenghu | C37: 1001,555533,4 | D37: 2001,0,10 | E37: 1001,555533,15 | F37: 1 | G37: 4 | H37: =VLOOKUP(A37,Sheet2!$R:$T,3,FALSE) -> 1,3;2,4;46,3-2 | I37: 3011028 | J37: 1 | K37: 第4-9关 | L37: 40
A38: 10410 | B38: zhounianqingdian_tenghu | C38: 1001,555542,10 | D38: 2001,0,10 | E38: 1001,555533,10 | F38: 1 | G38: 4 | H38: =VLOOKUP(A38,Sheet2!$R:$T,3,FALSE) -> 1,3;2,4;46,3-2 | I38: 3011029 | J38: 1 | K38: 第4-10关 | L38: 40
A39: 10501 | B39: zhounianqingdian_tenghu | C39: 1001,215001,10 | E39: 1001,215011,1 | F39: 1 | G39: 5 | K39: 第5-1关
A40: 10601 | B40: zhounianqingdian_tenghu | C40: 1001,555533,4 | D40: 2001,0,10 | E40: 1001,555533,20 | F40: 1 | G40: 6 | H40: =VLOOKUP(A40,Sheet2!$R:$T,3,FALSE) -> 1,3;2,4;46,3-2 | I40: 3011030 | J40: 1 | K40: 第6-1关 | L40: 45
...

Sheet Sheet2
B2: 星级获得参考
B3: 1 | C3: {0}回合内通关 | D3: n几回合通关 | E3: 1,4
B4: 2 | C4: 剩余角色大于{0}人 | D4: 剩余角色大于n人 | E4: 2,1
B5: 22 | C5: 上阵{0}角色不少于{1}个 | D5: 上阵角色中的 男性/女性 角色不少于N个
B6: 46 | C6: {0}角色上阵最少{1}个 | D6: 指定X类型卡牌上阵最少Y个 | E6: 46,type-count
C8: 4回合 | E8: 4回合 | G8: 3回合 | I8: 3回合 | K8: 2回合 | M8: 2回合 | O8: 2回合 | Q8: 2回合
C9: 允许死2个，6关开始死1个 | E9: 允许死1个 | G9: 允许死1个 | I9: 允许死1个 | K9: 不允许死 | M9: 不允许死 | O9: 不允许死 | Q9: 不允许死
C10: 前5对应系上1个，6关开始上2个 | E10: 对应系上2个 | G10: 对应系上2个 | I10: 对应系上2个 | K10: 前4对应系上2个，5关开始上3个 | M10: 对应系上3个 | O10: 对应系上3个 | Q10: 对应系上3个
C11: 1组关 | E11: 2组关 | G11: 3组关 | I11: 4组关 | K11: 5组关 | M11: 6组关 | O11: 7组关 | Q11: 8组关
B12: 1 | C12: 1,4;2,3;46,3-1 | D12: 1 | E12: 1,4;2,4;46,3-2 | F12: 1 | G12: 1,3;2,4;46,3-2 | H12: 1 | I12: 1,3;2,4;46,3-2 | J12: 1 | K12: 1,2;2,5;46,3-2 | L12: 1 | M12: 1,2;2,5;46,3-3 | N12: 1 | O12: 1,2;2,5;46,3-3 | P12: 1 | Q12: 1,2;2,5;46,3-3 | R12: 10101 | S12: =B12 -> 1 | T12: =C12 -> 1,4;2,3;46,3-1 | U12: 20101 | V12: =B24 -> 1 | W12: =C24 -> 1,4;2,3;46,2-1 | X12: 30101 | Y12: =OFFSET(B36,(ROW($1:$1)-1)*10,0) -> 1 | Z12: =OFFSET(C36,(ROW($1:$1)-1)*10,0) -> 1,4;2,3;46,1-1 | AA12: 40101 | AB12: =OFFSET(B48,(ROW($1:$1)-1)*10,0) -> 1 | AC12: =OFFSET(C48,(ROW($1:$1)-1)*10,0) -> 1,4;2,3;46,0-1
B13: 2 | C13: 1,4;2,3;46,3-1 | D13: 2 | E13: 1,4;2,4;46,3-2 | F13: 2 | G13: 1,3;2,4;46,3-2 | H13: 2 | I13: 1,3;2,4;46,3-2 | J13: 2 | K13: 1,2;2,5;46,3-2 | L13: 2 | M13: 1,2;2,5;46,3-3 | N13: 2 | O13: 1,2;2,5;46,3-3 | P13: 2 | Q13: 1,2;2,5;46,3-3 | R13: 10102 | S13: =B13 -> 2 | T13: =C13 -> 1,4;2,3;46,3-1 | U13: 20102 | V13: =B25 -> 2 | W13: =C25 -> 1,4;2,3;46,2-1 | X13: 30102 | Y13: =OFFSET(B37,(ROW($1:$1)-1)*10,0) -> 2 | Z13: =OFFSET(C37,(ROW($1:$1)-1)*10,0) -> 1,4;2,3;46,1-1 | AA13: 40102 | AB13: =OFFSET(B49,(ROW($1:$1)-1)*10,0) -> 2 | AC13: =OFFSET(C49,(ROW($1:$1)-1)*10,0) -> 1,4;2,3;46,0-1
B14: 3 | C14: 1,4;2,3;46,3-1 | D14: 3 | E14: 1,4;2,4;46,3-2 | F14: 3 | G14: 1,3;2,4;46,3-2 | H14: 3 | I14: 1,3;2,4;46,3-2 | J14: 3 | K14: 1,2;2,5;46,3-2 | L14: 3 | M14: 1,2;2,5;46,3-3 | N14: 3 | O14: 1,2;2,5;46,3-3 | P14: 3 | Q14: 1,2;2,5;46,3-3 | R14: 10103 | S14: =B14 -> 3 | T14: =C14 -> 1,4;2,3;46,3-1 | U14: 20103 | V14: =B26 -> 3 | W14: =C26 -> 1,4;2,3;46,2-1 | X14: 30103 | Y14: =OFFSET(B38,(ROW($1:$1)-1)*10,0) -> 3 | Z14: =OFFSET(C38,(ROW($1:$1)-1)*10,0) -> 1,4;2,3;46,1-1 | AA14: 40103 | AB14: =OFFSET(B50,(ROW($1:$1)-1)*10,0) -> 3 | AC14: =OFFSET(C50,(ROW($1:$1)-1)*10,0) -> 1,4;2,3;46,0-1
B15: 4 | C15: 1,4;2,3;46,3-1 | D15: 4 | E15: 1,4;2,4;46,3-2 | F15: 4 | G15: 1,3;2,4;46,3-2 | H15: 4 | I15: 1,3;2,4;46,3-2 | J15: 4 | K15: 1,2;2,5;46,3-2 | L15: 4 | M15: 1,2;2,5;46,3-3 | N15: 4 | O15: 1,2;2,5;46,3-3 | P15: 4 | Q15: 1,2;2,5;46,3-3 | R15: 10104 | S15: =B15 -> 4 | T15: =C15 -> 1,4;2,3;46,3-1 | U15: 20104 | V15: =B27 -> 4 | W15: =C27 -> 1,4;2,3;46,2-1 | X15: 30104 | Y15: =OFFSET(B39,(ROW($1:$1)-1)*10,0) -> 4 | Z15: =OFFSET(C39,(ROW($1:$1)-1)*10,0) -> 1,4;2,3;46,1-1 | AA15: 40104 | AB15: =OFFSET(B51,(ROW($1:$1)-1)*10,0) -> 4 | AC15: =OFFSET(C51,(ROW($1:$1)-1)*10,0) -> 1,4;2,3;46,0-1
B16: 5 | C16: 1,4;2,3;46,3-1 | D16: 5 | E16: 1,4;2,4;46,3-2 | F16: 5 | G16: 1,3;2,4;46,3-2 | H16: 5 | I16: 1,3;2,4;46,3-2 | J16: 5 | K16: 1,2;2,5;46,3-3 | L16: 5 | M16: 1,2;2,5;46,3-3 | N16: 5 | O16: 1,2;2,5;46,3-3 | P16: 5 | Q16: 1,2;2,5;46,3-3 | R16: 10105 | S16: =B16 -> 5 | T16: =C16 -> 1,4;2,3;46,3-1 | U16: 20105 | V16: =B28 -> 5 | W16: =C28 -> 1,4;2,3;46,2-1 | X16: 30105 | Y16: =OFFSET(B40,(ROW($1:$1)-1)*10,0) -> 5 | Z16: =OFFSET(C40,(ROW($1:$1)-1)*10,0) -> 1,4;2,3;46,1-1 | AA16: 40105 | AB16: =OFFSET(B52,(ROW($1:$1)-1)*10,0) -> 5 | AC16: =OFFSET(C52,(ROW($1:$1)-1)*10,0) -> 1,4;2,3;46,0-1
B17: 6 | C17: 1,4;2,4;46,3-2 | D17: 6 | E17: 1,4;2,4;46,3-2 | F17: 6 | G17: 1,3;2,4;46,3-2 | H17: 6 | I17: 1,3;2,4;46,3-2 | J17: 6 | K17: 1,2;2,5;46,3-3 | L17: 6 | M17: 1,2;2,5;46,3-3 | N17: 6 | O17: 1,2;2,5;46,3-3 | P17: 6 | Q17: 1,2;2,5;46,3-3 | R17: 10106 | S17: =B17 -> 6 | T17: =C17 -> 1,4;2,4;46,3-2 | U17: 20106 | V17: =B29 -> 6 | W17: =C29 -> 1,4;2,4;46,2-2 | X17: 30106 | Y17: =OFFSET(B41,(ROW($1:$1)-1)*10,0) -> 6 | Z17: =OFFSET(C41,(ROW($1:$1)-1)*10,0) -> 1,4;2,4;46,1-2 | AA17: 40106 | AB17: =OFFSET(B53,(ROW($1:$1)-1)*10,0) -> 6 | AC17: =OFFSET(C53,(ROW($1:$1)-1)*10,0) -> 1,4;2,4;46,0-2
B18: 7 | C18: 1,4;2,4;46,3-2 | D18: 7 | E18: 1,4;2,4;46,3-2 | F18: 7 | G18: 1,3;2,4;46,3-2 | H18: 7 | I18: 1,3;2,4;46,3-2 | J18: 7 | K18: 1,2;2,5;46,3-3 | L18: 7 | M18: 1,2;2,5;46,3-3 | N18: 7 | O18: 1,2;2,5;46,3-3 | P18: 7 | Q18: 1,2;2,5;46,3-3 | R18: 10107 | S18: =B18 -> 7 | T18: =C18 -> 1,4;2,4;46,3-2 | U18: 20107 | V18: =B30 -> 7 | W18: =C30 -> 1,4;2,4;46,2-2 | X18: 30107 | Y18: =OFFSET(B42,(ROW($1:$1)-1)*10,0) -> 7 | Z18: =OFFSET(C42,(ROW($1:$1)-1)*10,0) -> 1,4;2,4;46,1-2 | AA18: 40107 | AB18: =OFFSET(B54,(ROW($1:$1)-1)*10,0) -> 7 | AC18: =OFFSET(C54,(ROW($1:$1)-1)*10,0) -> 1,4;2,4;46,0-2
B19: 8 | C19: 1,4;2,4;46,3-2 | D19: 8 | E19: 1,4;2,4;46,3-2 | F19: 8 | G19: 1,3;2,4;46,3-2 | H19: 8 | I19: 1,3;2,4;46,3-2 | J19: 8 | K19: 1,2;2,5;46,3-3 | L19: 8 | M19: 1,2;2,5;46,3-3 | N19: 8 | O19: 1,2;2,5;46,3-3 | P19: 8 | Q19: 1,2;2,5;46,3-3 | R19: 10108 | S19: =B19 -> 8 | T19: =C19 -> 1,4;2,4;46,3-2 | U19: 20108 | V19: =B31 -> 8 | W19: =C31 -> 1,4;2,4;46,2-2 | X19: 30108 | Y19: =OFFSET(B43,(ROW($1:$1)-1)*10,0) -> 8 | Z19: =OFFSET(C43,(ROW($1:$1)-1)*10,0) -> 1,4;2,4;46,1-2 | AA19: 40108 | AB19: =OFFSET(B55,(ROW($1:$1)-1)*10,0) -> 8 | AC19: =OFFSET(C55,(ROW($1:$1)-1)*10,0) -> 1,4;2,4;46,0-2
B20: 9 | C20: 1,4;2,4;46,3-2 | D20: 9 | E20: 1,4;2,4;46,3-2 | F20: 9 | G20: 1,3;2,4;46,3-2 | H20: 9 | I20: 1,3;2,4;46,3-2 | J20: 9 | K20: 1,2;2,5;46,3-3 | L20: 9 | M20: 1,2;2,5;46,3-3 | N20: 9 | O20: 1,2;2,5;46,3-3 | P20: 9 | Q20: 1,2;2,5;46,3-3 | R20: 10109 | S20: =B20 -> 9 | T20: =C20 -> 1,4;2,4;46,3-2 | U20: 20109 | V20: =B32 -> 9 | W20: =C32 -> 1,4;2,4;46,2-2 | X20: 30109 | Y20: =OFFSET(B44,(ROW($1:$1)-1)*10,0) -> 9 | Z20: =OFFSET(C44,(ROW($1:$1)-1)*10,0) -> 1,4;2,4;46,1-2 | AA20: 40109 | AB20: =OFFSET(B56,(ROW($1:$1)-1)*10,0) -> 9 | AC20: =OFFSET(C56,(ROW($1:$1)-1)*10,0) -> 1,4;2,4;46,0-2
B21: 10 | C21: 1,4;2,4;46,3-2 | D21: 10 | E21: 1,4;2,4;46,3-2 | F21: 10 | G21: 1,3;2,4;46,3-2 | H21: 10 | I21: 1,3;2,4;46,3-2 | J21: 10 | K21: 1,2;2,5;46,3-3 | L21: 10 | M21: 1,2;2,5;46,3-3 | N21: 10 | O21: 1,2;2,5;46,3-3 | P21: 10 | Q21: 1,2;2,5;46,3-3 | R21: 10110 | S21: =B21 -> 10 | T21: =C21 -> 1,4;2,4;46,3-2 | U21: 20110 | V21: =B33 -> 10 | W21: =C33 -> 1,4;2,4;46,2-2 | X21: 30110 | Y21: =OFFSET(B45,(ROW($1:$1)-1)*10,0) -> 10 | Z21: =OFFSET(C45,(ROW($1:$1)-1)*10,0) -> 1,4;2,4;46,1-2 | AA21: 40110 | AB21: =OFFSET(B57,(ROW($1:$1)-1)*10,0) -> 10 | AC21: =OFFSET(C57,(ROW($1:$1)-1)*10,0) -> 1,4;2,4;46,0-2
R22: 10201 | U22: 20201 | X22: 30201 | AA22: 40201
R23: 10301 | S23: =OFFSET(D12,(ROW($1:$1)-1)*10,0) -> 1 | T23: =OFFSET(E12,(ROW($1:$1)-1)*10,0) -> 1,4;2,4;46,3-2 | U23: 20301 | V23: =OFFSET(D24,(ROW($1:$1)-1)*10,0) -> 1 | W23: =OFFSET(E24,(ROW($1:$1)-1)*10,0) -> 1,4;2,4;46,2-2 | X23: 30301 | Y23: =OFFSET(D36,(ROW($1:$1)-1)*10,0) -> 1 | Z23: =OFFSET(E36,(ROW($1:$1)-1)*10,0) -> 1,4;2,4;46,1-2 | AA23: 40301 | AB23: =OFFSET(D48,(ROW($1:$1)-1)*10,0) -> 1 | AC23: =OFFSET(E48,(ROW($1:$1)-1)*10,0) -> 1,4;2,4;46,0-2
B24: =B12 -> 1 | C24: =REPLACE(C12,12,1,"2") -> 1,4;2,3;46,2-1 | D24: =D12 -> 1 | E24: =REPLACE(E12,12,1,"2") -> 1,4;2,4;46,2-2 | F24: =F12 -> 1 | G24: =REPLACE(G12,12,1,"2") -> 1,3;2,4;46,2-2 | H24: =H12 -> 1 | I24: =REPLACE(I12,12,1,"2") -> 1,3;2,4;46,2-2 | J24: =J12 -> 1 | K24: =REPLACE(K12,12,1,"2") -> 1,2;2,5;46,2-2 | L24: =L12 -> 1 | M24: =REPLACE(M12,12,1,"2") -> 1,2;2,5;46,2-3 | N24: =N12 -> 1 | O24: =REPLACE(O12,12,1,"2") -> 1,2;2,5;46,2-3 | P24: =P12 -> 1 | Q24: =REPLACE(Q12,12,1,"2") -> 1,2;2,5;46,2-3 | R24: 10302 | S24: =OFFSET(D13,(ROW($1:$1)-1)*10,0) -> 2 | T24: =OFFSET(E13,(ROW($1:$1)-1)*10,0) -> 1,4;2,4;46,3-2 | U24: 20302 | V24: =OFFSET(D25,(ROW($1:$1)-1)*10,0) -> 2 | W24: =OFFSET(E25,(ROW($1:$1)-1)*10,0) -> 1,4;2,4;46,2-2 | X24: 30302 | Y24: =OFFSET(D37,(ROW($1:$1)-1)*10,0) -> 2 | Z24: =OFFSET(E37,(ROW($1:$1)-1)*10,0) -> 1,4;2,4;46,1-2 | AA24: 40302 | AB24: =OFFSET(D49,(ROW($1:$1)-1)*10,0) -> 2 | AC24: =OFFSET(E49,(ROW($1:$1)-1)*10,0) -> 1,4;2,4;46,0-2
B25: =B13 -> 2 | C25: =REPLACE(C13,12,1,"2") -> 1,4;2,3;46,2-1 | D25: =D13 -> 2 | E25: =REPLACE(E13,12,1,"2") -> 1,4;2,4;46,2-2 | F25: =F13 -> 2 | G25: =REPLACE(G13,12,1,"2") -> 1,3;2,4;46,2-2 | H25: =H13 -> 2 | I25: =REPLACE(I13,12,1,"2") -> 1,3;2,4;46,2-2 | J25: =J13 -> 2 | K25: =REPLACE(K13,12,1,"2") -> 1,2;2,5;46,2-2 | L25: =L13 -> 2 | M25: =REPLACE(M13,12,1,"2") -> 1,2;2,5;46,2-3 | N25: =N13 -> 2 | O25: =REPLACE(O13,12,1,"2") -> 1,2;2,5;46,2-3 | P25: =P13 -> 2 | Q25: =REPLACE(Q13,12,1,"2") -> 1,2;2,5;46,2-3 | R25: 10303 | S25: =OFFSET(D14,(ROW($1:$1)-1)*10,0) -> 3 | T25: =OFFSET(E14,(ROW($1:$1)-1)*10,0) -> 1,4;2,4;46,3-2 | U25: 20303 | V25: =OFFSET(D26,(ROW($1:$1)-1)*10,0) -> 3 | W25: =OFFSET(E26,(ROW($1:$1)-1)*10,0) -> 1,4;2,4;46,2-2 | X25: 30303 | Y25: =OFFSET(D38,(ROW($1:$1)-1)*10,0) -> 3 | Z25: =OFFSET(E38,(ROW($1:$1)-1)*10,0) -> 1,4;2,4;46,1-2 | AA25: 40303 | AB25: =OFFSET(D50,(ROW($1:$1)-1)*10,0) -> 3 | AC25: =OFFSET(E50,(ROW($1:$1)-1)*10,0) -> 1,4;2,4;46,0-2
B26: =B14 -> 3 | C26: =REPLACE(C14,12,1,"2") -> 1,4;2,3;46,2-1 | D26: =D14 -> 3 | E26: =REPLACE(E14,12,1,"2") -> 1,4;2,4;46,2-2 | F26: =F14 -> 3 | G26: =REPLACE(G14,12,1,"2") -> 1,3;2,4;46,2-2 | H26: =H14 -> 3 | I26: =REPLACE(I14,12,1,"2") -> 1,3;2,4;46,2-2 | J26: =J14 -> 3 | K26: =REPLACE(K14,12,1,"2") -> 1,2;2,5;46,2-2 | L26: =L14 -> 3 | M26: =REPLACE(M14,12,1,"2") -> 1,2;2,5;46,2-3 | N26: =N14 -> 3 | O26: =REPLACE(O14,12,1,"2") -> 1,2;2,5;46,2-3 | P26: =P14 -> 3 | Q26: =REPLACE(Q14,12,1,"2") -> 1,2;2,5;46,2-3 | R26: 10304 | S26: =OFFSET(D15,(ROW($1:$1)-1)*10,0) -> 4 | T26: =OFFSET(E15,(ROW($1:$1)-1)*10,0) -> 1,4;2,4;46,3-2 | U26: 20304 | V26: =OFFSET(D27,(ROW($1:$1)-1)*10,0) -> 4 | W26: =OFFSET(E27,(ROW($1:$1)-1)*10,0) -> 1,4;2,4;46,2-2 | X26: 30304 | Y26: =OFFSET(D39,(ROW($1:$1)-1)*10,0) -> 4 | Z26: =OFFSET(E39,(ROW($1:$1)-1)*10,0) -> 1,4;2,4;46,1-2 | AA26: 40304 | AB26: =OFFSET(D51,(ROW($1:$1)-1)*10,0) -> 4 | AC26: =OFFSET(E51,(ROW($1:$1)-1)*10,0) -> 1,4;2,4;46,0-2
B27: =B15 -> 4 | C27: =REPLACE(C15,12,1,"2") -> 1,4;2,3;46,2-1 | D27: =D15 -> 4 | E27: =REPLACE(E15,12,1,"2") -> 1,4;2,4;46,2-2 | F27: =F15 -> 4 | G27: =REPLACE(G15,12,1,"2") -> 1,3;2,4;46,2-2 | H27: =H15 -> 4 | I27: =REPLACE(I15,12,1,"2") -> 1,3;2,4;46,2-2 | J27: =J15 -> 4 | K27: =REPLACE(K15,12,1,"2") -> 1,2;2,5;46,2-2 | L27: =L15 -> 4 | M27: =REPLACE(M15,12,1,"2") -> 1,2;2,5;46,2-3 | N27: =N15 -> 4 | O27: =REPLACE(O15,12,1,"2") -> 1,2;2,5;46,2-3 | P27: =P15 -> 4 | Q27: =REPLACE(Q15,12,1,"2") -> 1,2;2,5;46,2-3 | R27: 10305 | S27: =OFFSET(D16,(ROW($1:$1)-1)*10,0) -> 5 | T27: =OFFSET(E16,(ROW($1:$1)-1)*10,0) -> 1,4;2,4;46,3-2 | U27: 20305 | V27: =OFFSET(D28,(ROW($1:$1)-1)*10,0) -> 5 | W27: =OFFSET(E28,(ROW($1:$1)-1)*10,0) -> 1,4;2,4;46,2-2 | X27: 30305 | Y27: =OFFSET(D40,(ROW($1:$1)-1)*10,0) -> 5 | Z27: =OFFSET(E40,(ROW($1:$1)-1)*10,0) -> 1,4;2,4;46,1-2 | AA27: 40305 | AB27: =OFFSET(D52,(ROW($1:$1)-1)*10,0) -> 5 | AC27: =OFFSET(E52,(ROW($1:$1)-1)*10,0) -> 1,4;2,4;46,0-2
B28: =B16 -> 5 | C28: =REPLACE(C16,12,1,"2") -> 1,4;2,3;46,2-1 | D28: =D16 -> 5 | E28: =REPLACE(E16,12,1,"2") -> 1,4;2,4;46,2-2 | F28: =F16 -> 5 | G28: =REPLACE(G16,12,1,"2") -> 1,3;2,4;46,2-2 | H28: =H16 -> 5 | I28: =REPLACE(I16,12,1,"2") -> 1,3;2,4;46,2-2 | J28: =J16 -> 5 | K28: =REPLACE(K16,12,1,"2") -> 1,2;2,5;46,2-3 | L28: =L16 -> 5 | M28: =REPLACE(M16,12,1,"2") -> 1,2;2,5;46,2-3 | N28: =N16 -> 5 | O28: =REPLACE(O16,12,1,"2") -> 1,2;2,5;46,2-3 | P28: =P16 -> 5 | Q28: =REPLACE(Q16,12,1,"2") -> 1,2;2,5;46,2-3 | R28: 10306 | S28: =OFFSET(D17,(ROW($1:$1)-1)*10,0) -> 6 | T28: =OFFSET(E17,(ROW($1:$1)-1)*10,0) -> 1,4;2,4;46,3-2 | U28: 20306 | V28: =OFFSET(D29,(ROW($1:$1)-1)*10,0) -> 6 | W28: =OFFSET(E29,(ROW($1:$1)-1)*10,0) -> 1,4;2,4;46,2-2 | X28: 30306 | Y28: =OFFSET(D41,(ROW($1:$1)-1)*10,0) -> 6 | Z28: =OFFSET(E41,(ROW($1:$1)-1)*10,0) -> 1,4;2,4;46,1-2 | AA28: 40306 | AB28: =OFFSET(D53,(ROW($1:$1)-1)*10,0) -> 6 | AC28: =OFFSET(E53,(ROW($1:$1)-1)*10,0) -> 1,4;2,4;46,0-2
B29: =B17 -> 6 | C29: =REPLACE(C17,12,1,"2") -> 1,4;2,4;46,2-2 | D29: =D17 -> 6 | E29: =REPLACE(E17,12,1,"2") -> 1,4;2,4;46,2-2 | F29: =F17 -> 6 | G29: =REPLACE(G17,12,1,"2") -> 1,3;2,4;46,2-2 | H29: =H17 -> 6 | I29: =REPLACE(I17,12,1,"2") -> 1,3;2,4;46,2-2 | J29: =J17 -> 6 | K29: =REPLACE(K17,12,1,"2") -> 1,2;2,5;46,2-3 | L29: =L17 -> 6 | M29: =REPLACE(M17,12,1,"2") -> 1,2;2,5;46,2-3 | N29: =N17 -> 6 | O29: =REPLACE(O17,12,1,"2") -> 1,2;2,5;46,2-3 | P29: =P17 -> 6 | Q29: =REPLACE(Q17,12,1,"2") -> 1,2;2,5;46,2-3 | R29: 10307 | S29: =OFFSET(D18,(ROW($1:$1)-1)*10,0) -> 7 | T29: =OFFSET(E18,(ROW($1:$1)-1)*10,0) -> 1,4;2,4;46,3-2 | U29: 20307 | V29: =OFFSET(D30,(ROW($1:$1)-1)*10,0) -> 7 | W29: =OFFSET(E30,(ROW($1:$1)-1)*10,0) -> 1,4;2,4;46,2-2 | X29: 30307 | Y29: =OFFSET(D42,(ROW($1:$1)-1)*10,0) -> 7 | Z29: =OFFSET(E42,(ROW($1:$1)-1)*10,0) -> 1,4;2,4;46,1-2 | AA29: 40307 | AB29: =OFFSET(D54,(ROW($1:$1)-1)*10,0) -> 7 | AC29: =OFFSET(E54,(ROW($1:$1)-1)*10,0) -> 1,4;2,4;46,0-2
B30: =B18 -> 7 | C30: =REPLACE(C18,12,1,"2") -> 1,4;2,4;46,2-2 | D30: =D18 -> 7 | E30: =REPLACE(E18,12,1,"2") -> 1,4;2,4;46,2-2 | F30: =F18 -> 7 | G30: =REPLACE(G18,12,1,"2") -> 1,3;2,4;46,2-2 | H30: =H18 -> 7 | I30: =REPLACE(I18,12,1,"2") -> 1,3;2,4;46,2-2 | J30: =J18 -> 7 | K30: =REPLACE(K18,12,1,"2") -> 1,2;2,5;46,2-3 | L30: =L18 -> 7 | M30: =REPLACE(M18,12,1,"2") -> 1,2;2,5;46,2-3 | N30: =N18 -> 7 | O30: =REPLACE(O18,12,1,"2") -> 1,2;2,5;46,2-3 | P30: =P18 -> 7 | Q30: =REPLACE(Q18,12,1,"2") -> 1,2;2,5;46,2-3 | R30: 10308 | S30: =OFFSET(D19,(ROW($1:$1)-1)*10,0) -> 8 | T30: =OFFSET(E19,(ROW($1:$1)-1)*10,0) -> 1,4;2,4;46,3-2 | U30: 20308 | V30: =OFFSET(D31,(ROW($1:$1)-1)*10,0) -> 8 | W30: =OFFSET(E31,(ROW($1:$1)-1)*10,0) -> 1,4;2,4;46,2-2 | X30: 30308 | Y30: =OFFSET(D43,(ROW($1:$1)-1)*10,0) -> 8 | Z30: =OFFSET(E43,(ROW($1:$1)-1)*10,0) -> 1,4;2,4;46,1-2 | AA30: 40308 | AB30: =OFFSET(D55,(ROW($1:$1)-1)*10,0) -> 8 | AC30: =OFFSET(E55,(ROW($1:$1)-1)*10,0) -> 1,4;2,4;46,0-2
B31: =B19 -> 8 | C31: =REPLACE(C19,12,1,"2") -> 1,4;2,4;46,2-2 | D31: =D19 -> 8 | E31: =REPLACE(E19,12,1,"2") -> 1,4;2,4;46,2-2 | F31: =F19 -> 8 | G31: =REPLACE(G19,12,1,"2") -> 1,3;2,4;46,2-2 | H31: =H19 -> 8 | I31: =REPLACE(I19,12,1,"2") -> 1,3;2,4;46,2-2 | J31: =J19 -> 8 | K31: =REPLACE(K19,12,1,"2") -> 1,2;2,5;46,2-3 | L31: =L19 -> 8 | M31: =REPLACE(M19,12,1,"2") -> 1,2;2,5;46,2-3 | N31: =N19 -> 8 | O31: =REPLACE(O19,12,1,"2") -> 1,2;2,5;46,2-3 | P31: =P19 -> 8 | Q31: =REPLACE(Q19,12,1,"2") -> 1,2;2,5;46,2-3 | R31: 10309 | S31: =OFFSET(D20,(ROW($1:$1)-1)*10,0) -> 9 | T31: =OFFSET(E20,(ROW($1:$1)-1)*10,0) -> 1,4;2,4;46,3-2 | U31: 20309 | V31: =OFFSET(D32,(ROW($1:$1)-1)*10,0) -> 9 | W31: =OFFSET(E32,(ROW($1:$1)-1)*10,0) -> 1,4;2,4;46,2-2 | X31: 30309 | Y31: =OFFSET(D44,(ROW($1:$1)-1)*10,0) -> 9 | Z31: =OFFSET(E44,(ROW($1:$1)-1)*10,0) -> 1,4;2,4;46,1-2 | AA31: 40309 | AB31: =OFFSET(D56,(ROW($1:$1)-1)*10,0) -> 9 | AC31: =OFFSET(E56,(ROW($1:$1)-1)*10,0) -> 1,4;2,4;46,0-2
B32: =B20 -> 9 | C32: =REPLACE(C20,12,1,"2") -> 1,4;2,4;46,2-2 | D32: =D20 -> 9 | E32: =REPLACE(E20,12,1,"2") -> 1,4;2,4;46,2-2 | F32: =F20 -> 9 | G32: =REPLACE(G20,12,1,"2") -> 1,3;2,4;46,2-2 | H32: =H20 -> 9 | I32: =REPLACE(I20,12,1,"2") -> 1,3;2,4;46,2-2 | J32: =J20 -> 9 | K32: =REPLACE(K20,12,1,"2") -> 1,2;2,5;46,2-3 | L32: =L20 -> 9 | M32: =REPLACE(M20,12,1,"2") -> 1,2;2,5;46,2-3 | N32: =N20 -> 9 | O32: =REPLACE(O20,12,1,"2") -> 1,2;2,5;46,2-3 | P32: =P20 -> 9 | Q32: =REPLACE(Q20,12,1,"2") -> 1,2;2,5;46,2-3 | R32: 10310 | S32: =OFFSET(D21,(ROW($1:$1)-1)*10,0) -> 10 | T32: =OFFSET(E21,(ROW($1:$1)-1)*10,0) -> 1,4;2,4;46,3-2 | U32: 20310 | V32: =OFFSET(D33,(ROW($1:$1)-1)*10,0) -> 10 | W32: =OFFSET(E33,(ROW($1:$1)-1)*10,0) -> 1,4;2,4;46,2-2 | X32: 30310 | Y32: =OFFSET(D45,(ROW($1:$1)-1)*10,0) -> 10 | Z32: =OFFSET(E45,(ROW($1:$1)-1)*10,0) -> 1,4;2,4;46,1-2 | AA32: 40310 | AB32: =OFFSET(D57,(ROW($1:$1)-1)*10,0) -> 10 | AC32: =OFFSET(E57,(ROW($1:$1)-1)*10,0) -> 1,4;2,4;46,0-2
B33: =B21 -> 10 | C33: =REPLACE(C21,12,1,"2") -> 1,4;2,4;46,2-2 | D33: =D21 -> 10 | E33: =REPLACE(E21,12,1,"2") -> 1,4;2,4;46,2-2 | F33: =F21 -> 10 | G33: =REPLACE(G21,12,1,"2") -> 1,3;2,4;46,2-2 | H33: =H21 -> 10 | I33: =REPLACE(I21,12,1,"2") -> 1,3;2,4;46,2-2 | J33: =J21 -> 10 | K33: =REPLACE(K21,12,1,"2") -> 1,2;2,5;46,2-3 | L33: =L21 -> 10 | M33: =REPLACE(M21,12,1,"2") -> 1,2;2,5;46,2-3 | N33: =N21 -> 10 | O33: =REPLACE(O21,12,1,"2") -> 1,2;2,5;46,2-3 | P33: =P21 -> 10 | Q33: =REPLACE(Q21,12,1,"2") -> 1,2;2,5;46,2-3 | R33: 11501 | U33: 21501 | X33: 31501 | AA33: 41501
R34: 10401 | S34: =OFFSET(F12,(ROW($1:$1)-1)*10,0) -> 1 | T34: =OFFSET(G12,(ROW($1:$1)-1)*10,0) -> 1,3;2,4;46,3-2 | U34: 20401 | V34: =OFFSET(F24,(ROW($1:$1)-1)*10,0) -> 1 | W34: =OFFSET(G24,(ROW($1:$1)-1)*10,0) -> 1,3;2,4;46,2-2 | X34: 30401 | Y34: =OFFSET(F36,(ROW($1:$1)-1)*10,0) -> 1 | Z34: =OFFSET(G36,(ROW($1:$1)-1)*10,0) -> 1,3;2,4;46,1-2 | AA34: 40401 | AB34: =OFFSET(F48,(ROW($1:$1)-1)*10,0) -> 1 | AC34: =OFFSET(G48,(ROW($1:$1)-1)*10,0) -> 1,3;2,4;46,0-2
R35: 10402 | S35: =OFFSET(F13,(ROW($1:$1)-1)*10,0) -> 2 | T35: =OFFSET(G13,(ROW($1:$1)-1)*10,0) -> 1,3;2,4;46,3-2 | U35: 20402 | V35: =OFFSET(F25,(ROW($1:$1)-1)*10,0) -> 2 | W35: =OFFSET(G25,(ROW($1:$1)-1)*10,0) -> 1,3;2,4;46,2-2 | X35: 30402 | Y35: =OFFSET(F37,(ROW($1:$1)-1)*10,0) -> 2 | Z35: =OFFSET(G37,(ROW($1:$1)-1)*10,0) -> 1,3;2,4;46,1-2 | AA35: 40402 | AB35: =OFFSET(F49,(ROW($1:$1)-1)*10,0) -> 2 | AC35: =OFFSET(G49,(ROW($1:$1)-1)*10,0) -> 1,3;2,4;46,0-2
B36: =B24 -> 1 | C36: =REPLACE(C12,12,1,"1") -> 1,4;2,3;46,1-1 | D36: =D12 -> 1 | E36: =REPLACE(E12,12,1,"1") -> 1,4;2,4;46,1-2 | F36: =F12 -> 1 | G36: =REPLACE(G12,12,1,"1") -> 1,3;2,4;46,1-2 | H36: =H12 -> 1 | I36: =REPLACE(I12,12,1,"1") -> 1,3;2,4;46,1-2 | J36: =J12 -> 1 | K36: =REPLACE(K12,12,1,"1") -> 1,2;2,5;46,1-2 | L36: =L12 -> 1 | M36: =REPLACE(M12,12,1,"1") -> 1,2;2,5;46,1-3 | N36: =N12 -> 1 | O36: =REPLACE(O12,12,1,"1") -> 1,2;2,5;46,1-3 | P36: =P12 -> 1 | Q36: =REPLACE(Q12,12,1,"1") -> 1,2;2,5;46,1-3 | R36: 10403 | S36: =OFFSET(F14,(ROW($1:$1)-1)*10,0) -> 3 | T36: =OFFSET(G14,(ROW($1:$1)-1)*10,0) -> 1,3;2,4;46,3-2 | U36: 20403 | V36: =OFFSET(F26,(ROW($1:$1)-1)*10,0) -> 3 | W36: =OFFSET(G26,(ROW($1:$1)-1)*10,0) -> 1,3;2,4;46,2-2 | X36: 30403 | Y36: =OFFSET(F38,(ROW($1:$1)-1)*10,0) -> 3 | Z36: =OFFSET(G38,(ROW($1:$1)-1)*10,0) -> 1,3;2,4;46,1-2 | AA36: 40403 | AB36: =OFFSET(F50,(ROW($1:$1)-1)*10,0) -> 3 | AC36: =OFFSET(G50,(ROW($1:$1)-1)*10,0) -> 1,3;2,4;46,0-2
B37: =B25 -> 2 | C37: =REPLACE(C13,12,1,"1") -> 1,4;2,3;46,1-1 | D37: =D13 -> 2 | E37: =REPLACE(E13,12,1,"1") -> 1,4;2,4;46,1-2 | F37: =F13 -> 2 | G37: =REPLACE(G13,12,1,"1") -> 1,3;2,4;46,1-2 | H37: =H13 -> 2 | I37: =REPLACE(I13,12,1,"1") -> 1,3;2,4;46,1-2 | J37: =J13 -> 2 | K37: =REPLACE(K13,12,1,"1") -> 1,2;2,5;46,1-2 | L37: =L13 -> 2 | M37: =REPLACE(M13,12,1,"1") -> 1,2;2,5;46,1-3 | N37: =N13 -> 2 | O37: =REPLACE(O13,12,1,"1") -> 1,2;2,5;46,1-3 | P37: =P13 -> 2 | Q37: =REPLACE(Q13,12,1,"1") -> 1,2;2,5;46,1-3 | R37: 10404 | S37: =OFFSET(F15,(ROW($1:$1)-1)*10,0) -> 4 | T37: =OFFSET(G15,(ROW($1:$1)-1)*10,0) -> 1,3;2,4;46,3-2 | U37: 20404 | V37: =OFFSET(F27,(ROW($1:$1)-1)*10,0) -> 4 | W37: =OFFSET(G27,(ROW($1:$1)-1)*10,0) -> 1,3;2,4;46,2-2 | X37: 30404 | Y37: =OFFSET(F39,(ROW($1:$1)-1)*10,0) -> 4 | Z37: =OFFSET(G39,(ROW($1:$1)-1)*10,0) -> 1,3;2,4;46,1-2 | AA37: 40404 | AB37: =OFFSET(F51,(ROW($1:$1)-1)*10,0) -> 4 | AC37: =OFFSET(G51,(ROW($1:$1)-1)*10,0) -> 1,3;2,4;46,0-2
B38: =B26 -> 3 | C38: =REPLACE(C14,12,1,"1") -> 1,4;2,3;46,1-1 | D38: =D14 -> 3 | E38: =REPLACE(E14,12,1,"1") -> 1,4;2,4;46,1-2 | F38: =F14 -> 3 | G38: =REPLACE(G14,12,1,"1") -> 1,3;2,4;46,1-2 | H38: =H14 -> 3 | I38: =REPLACE(I14,12,1,"1") -> 1,3;2,4;46,1-2 | J38: =J14 -> 3 | K38: =REPLACE(K14,12,1,"1") -> 1,2;2,5;46,1-2 | L38: =L14 -> 3 | M38: =REPLACE(M14,12,1,"1") -> 1,2;2,5;46,1-3 | N38: =N14 -> 3 | O38: =REPLACE(O14,12,1,"1") -> 1,2;2,5;46,1-3 | P38: =P14 -> 3 | Q38: =REPLACE(Q14,12,1,"1") -> 1,2;2,5;46,1-3 | R38: 10405 | S38: =OFFSET(F16,(ROW($1:$1)-1)*10,0) -> 5 | T38: =OFFSET(G16,(ROW($1:$1)-1)*10,0) -> 1,3;2,4;46,3-2 | U38: 20405 | V38: =OFFSET(F28,(ROW($1:$1)-1)*10,0) -> 5 | W38: =OFFSET(G28,(ROW($1:$1)-1)*10,0) -> 1,3;2,4;46,2-2 | X38: 30405 | Y38: =OFFSET(F40,(ROW($1:$1)-1)*10,0) -> 5 | Z38: =OFFSET(G40,(ROW($1:$1)-1)*10,0) -> 1,3;2,4;46,1-2 | AA38: 40405 | AB38: =OFFSET(F52,(ROW($1:$1)-1)*10,0) -> 5 | AC38: =OFFSET(G52,(ROW($1:$1)-1)*10,0) -> 1,3;2,4;46,0-2
B39: =B27 -> 4 | C39: =REPLACE(C15,12,1,"1") -> 1,4;2,3;46,1-1 | D39: =D15 -> 4 | E39: =REPLACE(E15,12,1,"1") -> 1,4;2,4;46,1-2 | F39: =F15 -> 4 | G39: =REPLACE(G15,12,1,"1") -> 1,3;2,4;46,1-2 | H39: =H15 -> 4 | I39: =REPLACE(I15,12,1,"1") -> 1,3;2,4;46,1-2 | J39: =J15 -> 4 | K39: =REPLACE(K15,12,1,"1") -> 1,2;2,5;46,1-2 | L39: =L15 -> 4 | M39: =REPLACE(M15,12,1,"1") -> 1,2;2,5;46,1-3 | N39: =N15 -> 4 | O39: =REPLACE(O15,12,1,"1") -> 1,2;2,5;46,1-3 | P39: =P15 -> 4 | Q39: =REPLACE(Q15,12,1,"1") -> 1,2;2,5;46,1-3 | R39: 10406 | S39: =OFFSET(F17,(ROW($1:$1)-1)*10,0) -> 6 | T39: =OFFSET(G17,(ROW($1:$1)-1)*10,0) -> 1,3;2,4;46,3-2 | U39: 20406 | V39: =OFFSET(F29,(ROW($1:$1)-1)*10,0) -> 6 | W39: =OFFSET(G29,(ROW($1:$1)-1)*10,0) -> 1,3;2,4;46,2-2 | X39: 30406 | Y39: =OFFSET(F41,(ROW($1:$1)-1)*10,0) -> 6 | Z39: =OFFSET(G41,(ROW($1:$1)-1)*10,0) -> 1,3;2,4;46,1-2 | AA39: 40406 | AB39: =OFFSET(F53,(ROW($1:$1)-1)*10,0) -> 6 | AC39: =OFFSET(G53,(ROW($1:$1)-1)*10,0) -> 1,3;2,4;46,0-2
B40: =B28 -> 5 | C40: =REPLACE(C16,12,1,"1") -> 1,4;2,3;46,1-1 | D40: =D16 -> 5 | E40: =REPLACE(E16,12,1,"1") -> 1,4;2,4;46,1-2 | F40: =F16 -> 5 | G40: =REPLACE(G16,12,1,"1") -> 1,3;2,4;46,1-2 | H40: =H16 -> 5 | I40: =REPLACE(I16,12,1,"1") -> 1,3;2,4;46,1-2 | J40: =J16 -> 5 | K40: =REPLACE(K16,12,1,"1") -> 1,2;2,5;46,1-3 | L40: =L16 -> 5 | M40: =REPLACE(M16,12,1,"1") -> 1,2;2,5;46,1-3 | N40: =N16 -> 5 | O40: =REPLACE(O16,12,1,"1") -> 1,2;2,5;46,1-3 | P40: =P16 -> 5 | Q40: =REPLACE(Q16,12,1,"1") -> 1,2;2,5;46,1-3 | R40: 10407 | S40: =OFFSET(F18,(ROW($1:$1)-1)*10,0) -> 7 | T40: =OFFSET(G18,(ROW($1:$1)-1)*10,0) -> 1,3;2,4;46,3-2 | U40: 20407 | V40: =OFFSET(F30,(ROW($1:$1)-1)*10,0) -> 7 | W40: =OFFSET(G30,(ROW($1:$1)-1)*10,0) -> 1,3;2,4;46,2-2 | X40: 30407 | Y40: =OFFSET(F42,(ROW($1:$1)-1)*10,0) -> 7 | Z40: =OFFSET(G42,(ROW($1:$1)-1)*10,0) -> 1,3;2,4;46,1-2 | AA40: 40407 | AB40: =OFFSET(F54,(ROW($1:$1)-1)*10,0) -> 7 | AC40: =OFFSET(G54,(ROW($1:$1)-1)*10,0) -> 1,3;2,4;46,0-2
B41: =B29 -> 6 | C41: =REPLACE(C17,12,1,"1") -> 1,4;2,4;46,1-2 | D41: =D17 -> 6 | E41: =REPLACE(E17,12,1,"1") -> 1,4;2,4;46,1-2 | F41: =F17 -> 6 | G41: =REPLACE(G17,12,1,"1") -> 1,3;2,4;46,1-2 | H41: =H17 -> 6 | I41: =REPLACE(I17,12,1,"1") -> 1,3;2,4;46,1-2 | J41: =J17 -> 6 | K41: =REPLACE(K17,12,1,"1") -> 1,2;2,5;46,1-3 | L41: =L17 -> 6 | M41: =REPLACE(M17,12,1,"1") -> 1,2;2,5;46,1-3 | N41: =N17 -> 6 | O41: =REPLACE(O17,12,1,"1") -> 1,2;2,5;46,1-3 | P41: =P17 -> 6 | Q41: =REPLACE(Q17,12,1,"1") -> 1,2;2,5;46,1-3 | R41: 10408 | S41: =OFFSET(F19,(ROW($1:$1)-1)*10,0) -> 8 | T41: =OFFSET(G19,(ROW($1:$1)-1)*10,0) -> 1,3;2,4;46,3-2 | U41: 20408 | V41: =OFFSET(F31,(ROW($1:$1)-1)*10,0) -> 8 | W41: =OFFSET(G31,(ROW($1:$1)-1)*10,0) -> 1,3;2,4;46,2-2 | X41: 30408 | Y41: =OFFSET(F43,(ROW($1:$1)-1)*10,0) -> 8 | Z41: =OFFSET(G43,(ROW($1:$1)-1)*10,0) -> 1,3;2,4;46,1-2 | AA41: 40408 | AB41: =OFFSET(F55,(ROW($1:$1)-1)*10,0) -> 8 | AC41: =OFFSET(G55,(ROW($1:$1)-1)*10,0) -> 1,3;2,4;46,0-2
B42: =B30 -> 7 | C42: =REPLACE(C18,12,1,"1") -> 1,4;2,4;46,1-2 | D42: =D18 -> 7 | E42: =REPLACE(E18,12,1,"1") -> 1,4;2,4;46,1-2 | F42: =F18 -> 7 | G42: =REPLACE(G18,12,1,"1") -> 1,3;2,4;46,1-2 | H42: =H18 -> 7 | I42: =REPLACE(I18,12,1,"1") -> 1,3;2,4;46,1-2 | J42: =J18 -> 7 | K42: =REPLACE(K18,12,1,"1") -> 1,2;2,5;46,1-3 | L42: =L18 -> 7 | M42: =REPLACE(M18,12,1,"1") -> 1,2;2,5;46,1-3 | N42: =N18 -> 7 | O42: =REPLACE(O18,12,1,"1") -> 1,2;2,5;46,1-3 | P42: =P18 -> 7 | Q42: =REPLACE(Q18,12,1,"1") -> 1,2;2,5;46,1-3 | R42: 10409 | S42: =OFFSET(F20,(ROW($1:$1)-1)*10,0) -> 9 | T42: =OFFSET(G20,(ROW($1:$1)-1)*10,0) -> 1,3;2,4;46,3-2 | U42: 20409 | V42: =OFFSET(F32,(ROW($1:$1)-1)*10,0) -> 9 | W42: =OFFSET(G32,(ROW($1:$1)-1)*10,0) -> 1,3;2,4;46,2-2 | X42: 30409 | Y42: =OFFSET(F44,(ROW($1:$1)-1)*10,0) -> 9 | Z42: =OFFSET(G44,(ROW($1:$1)-1)*10,0) -> 1,3;2,4;46,1-2 | AA42: 40409 | AB42: =OFFSET(F56,(ROW($1:$1)-1)*10,0) -> 9 | AC42: =OFFSET(G56,(ROW($1:$1)-1)*10,0) -> 1,3;2,4;46,0-2
...
